Workbook

Sheet Start Here
A1: CCCL EVENT PROFIT PREDICTOR
A2: Compare towns and venues for the next Cottage Country Combat League show before signing anything. Built for Cody Purtell by Kyle. Opens in Google Sheets or Excel.
B4: Good to know: on Cody's numbers the first show made about $18,000. That profit went into the gym and other projects, which is why it felt like breaking even. Profits on Compare are the show's profit before any money goes to the gym.
B6: HOW TO USE IT
A7: 1 | B7: Haliburton 2026 Check tab | C7: The first show's real numbers. When Cody has the Eventbrite payout report, put the exact profit that went to the gym in Part 2.
A8: 2 | B8: Inputs tab | C8: Cody's real 2026 prices and costs are already in. Replace every ESTIMATE with a real quote or invoice.
A9: 3 | B9: Inputs tab, venue columns | C9: Call each venue (numbers are in the 'Who to call' row) for capacity, the full event price and open dates.
A10: 4 | B10: Compare tab | C10: Read the verdict, the break-even ticket count and how much sponsorship each option needs. Venues whose expected crowd is under Cody's 1,000 minimum get flagged.
A11: 5 | B11: Before committing | C11: Check the stress-test row: can CCCL survive 30% fewer people and half the sponsors pulling out?
A12: 6 | B12: 2027 Venues tab | C12: 24 venues in Cody's 10 towns plus casinos and event centres: capacity, winter use, rates, who to call, clashes and other promotions.
A13: 7 | B13: Town Scout tab | C13: 25 smaller towns within 2 hours, ranked. To compare any venue that isn't on Compare, type it over a venue column on Inputs.
A14: 8 | B14: 19+ Show Check tab | C14: Is an adults-only show worth it? Compares a family show, a family show with a 19+ bar area, and an adults-only show at every venue.
A15: 9 | B15: Ticket Tracker tab | C15: Once tickets are on sale: pick the show, type Eventbrite totals once a week, and see how far from break-even you are.
B17: COLOUR KEY
B18: Yellow cell, blue text | C18: You type here.
B19: Green text | C19: Pulled from another tab. Don't type over it.
B20: Black text | C20: Calculated. Don't type over it.
B21: ESTIMATE in the notes | C21: A placeholder. Replace it with a real quote or invoice.
B23: WHAT IT ANSWERS
C24: • How many tickets do we have to sell at each venue just to break even?
C25: • How much sponsorship do we need if the crowd is small?
C26: • Which town makes the most money at a normal crowd?
C27: • What happens if 30% fewer people come and half the sponsors back out?
B29: SOURCES FOR THE NUMBERS
B30: First show (May 2, 2026) | C30: The Highlander, Mar 12 2026: thehighlander.ca/2026/03/12/fight-night-coming-to-haliburton-county/ (A.J. LaRue Arena, 8-12 amateur bouts, 800-1,000 expected, sanctioned by the Ontario Athletics Commission)
B31: First show real numbers | C31: Cody's answers, Oct 2026: GA $60, VIP $100, tables $1,500 for 8 (6 sold), 400 tickets, 400-600 people, 15 sponsors / $18,000, Eventbrite fees paid by CCCL, bar run by others, costs listed at $29,000. Profit went into the gym and other projects (Kyle).
B32: Haliburton venue rates | C32: Dysart et al facility rentals: dysartetal.ca (A.J. LaRue Community Centre): $1,030/day profit-making event, $30/hr setup with staff
B33: Bancroft venue | C33: Town of Bancroft and mybancroftnow.com (Sept 2026): NHCC upgrades complete; rates and capacity not published; call 613-332-2062
B34: Amateur event permit | C34: O. Reg. 507/24 and ontario.ca: $600 per show (one permit should cover the whole card), $3,000 for up to 8 shows in a year; $2M liability insurance; physician on site. Details on the Fight Night Kit's Rules tab.
B35: Marmora | C35: marmoraandlake.ca community centre: dry floor 1,000 capacity, $600/day event
B36: City arenas | C36: Peterborough Memorial Centre Tech Pack 2024 (setups 1,722 to 5,501); Visit Kingston (Slush Puppie Place 5,700 cold-season); tributecommunitiescentre.com (1,000 to 7,600). None publish rental rates: those columns are ESTIMATES.
B37: 2027 Venues tab | C37: 24 venues and 5 other promotions researched by Claude, October 2026. Sources are in each row.
B38: Town Scout tab | C38: 25 towns researched by Claude from municipal sites and local news, October 2026. Sources are in each row.
B39: Everything else | C39: ESTIMATES by Kyle. Replace with real quotes and invoices.

Sheet Inputs
A1: CCCL EVENT PROFIT PREDICTOR · INPUTS
A2: Type only in YELLOW cells (blue text). Everything on the Compare tab updates by itself. Numbers marked ESTIMATE are placeholders: replace them with real quotes as they come in.
A4: GLOBAL ASSUMPTIONS (same for every venue)
A5: Low crowd: % of sellable capacity that shows up | B5: 0.35 | H5: ESTIMATE. A bad night: weather, a clash with another event, weak card.
A6: Expected crowd: % of sellable capacity | B6: 0.5 | H6: Set from the first show: about 500 people (Cody said 400-600) in a building of about 1,000. Tune it on the 'Haliburton 2026 Check' tab after each show.
A7: High crowd: % of sellable capacity | B7: 0.8 | H7: ESTIMATE. A big card or a strong pre-sale.
A8: People who didn't buy a ticket: % of the crowd | B8: 0.2 | H8: From the first show: 400 tickets sold, about 500 people in the building, so about 1 in 5 came free (sponsor guests, fighters' teams, volunteers, officials). Tune it after each show.
A9: Smallest crowd worth doing a show for (people) | B9: 1000 | H9: Cody, Oct 2026: 1,000+. A venue whose expected crowd is below this gets flagged on Compare.
A11: Ticket tier | B11: Price per person ($) | C11: Share of paid tickets | H11: Prices are what CCCL charged in May 2026 (Cody, Oct 2026). A VIP table is $1,500 and seats 8-10 depending on the venue's tables; 8 seats = $187.50 a seat. Shares: 48 of the 400 tickets were table seats (12%); the GA / VIP split is an ESTIMATE. Shares must add to 100%.
A12: General admission | B12: 60 | C12: 0.78
A13: VIP single seat | B13: 100 | C13: 0.1
A14: VIP table seat ($1,500 table of 8, per seat) | B14: 187.5 | C14: 0.12
A15: Shares add up to (must be 100%) | C15: =SUM(C12:C14) -> 1
A16: Average price per paid ticket | B16: =IF(SUM(C12:C14)=0,0,SUMPRODUCT(B12:B14,C12:C14)/SUM(C12:C14)) -> 79.3
A18: Ticketing fees CCCL pays (% of ticket sales) | B18: 0.079 | H18: CCCL paid the Eventbrite fees in 2026 (Cody). Eventbrite Canada (help centre, Oct 2026): 3.5% + $1.29 per ticket, plus 2.9% processing. That's 8.6% on a $60 ticket, 7.7% on $100 and 6.5% on a $1,500 table, about 7.9% across the 2026 mix. Passing fees to buyers would make this 0%.
A19: HST inside the ticket price that goes to the government (%) | B19: 0 | H19: 0% unless CCCL is registered for HST and the ticket prices included tax. Then use 11.5% (the 13% HST inside a tax-included price). Ask the bookkeeper.
A20: Bar & concession profit per person in the building ($) | B20: 0 | H20: 0: in 2026 the arena or a local group ran the bar and kept it (Cody). If CCCL ever runs or shares the bar, put the profit per person here.
A21: Merch profit per person ($) | B21: 0 | H21: 0 until CCCL sells shirts or hats at shows. $1-3 a person is typical once it does (ESTIMATE).
A22: Livestream / pay-per-view profit per event ($) | B22: 0 | H22: 0: the 2026 livestream didn't bring in money (Cody). The Marketing Kit's Livestream tab works out what a paid stream could bring in.
A23: Contingency buffer (% of fixed costs) | B23: 0.05 | H23: Cushion for surprises. 5-10% is normal for a first or second show.
A24: Stress test: crowd drop vs Expected | B24: 0.3 | H24: What if 30% fewer people show up?
A25: Stress test: sponsorship that falls through | B25: 0.5 | H25: What if half the sponsor money never comes?
A27: VENUE OPTIONS (one column per option)
A28: Venue (building) | B28: A.J. LaRue Arena | C28: North Hastings Community Centre | D28: Dr. Hamilton Crawford Memorial Arena | E28: Peterborough Memorial Centre | F28: Slush Puppie Place | G28: Tribute Communities Centre
A29: Town | B29: Haliburton | C29: Bancroft | D29: Marmora | E29: Peterborough | F29: Kingston | G29: Oshawa
A30: Who to call for a quote | B30: Dysart et al arena 705-457-1740 x635 | C30: Town of Bancroft 613-332-2062, communitycentre@bancroft.ca | D30: Marmora & Lake Parks & Rec 613-472-2410, arena@marmoraandlake.ca | E30: Jose Garcia-Perez, Event Services, 705-743-3561 x2504 | F30: ASM Global 613-650-5000 ('Private Venue Bookings' on slushpuppieplace.com) | G30: Oak View Group 905-438-8881 x116 ('Request a Proposal' online) | H30: Phone numbers from each municipality's website (Oct 2026).
A31: Date idea | B31: May 2027 (2nd annual) | C31: June 2027 (dry floor; the Gemboree fills it on the Civic Holiday weekend) | D31: Aug 2027 (dry floor May to Aug) | E31: Feb or Nov 2027, around Petes home games (holds winter floor events) | F31: Nov 2027, around Frontenacs home games (held BTC MMA in March 2023 and 2024) | G31: Winter 2027 (renovation starts in 2027; PFC plans Oshawa in Nov) | H31: Cody's months for 2027: Jan, Feb, Apr, May, Jun, Aug, Nov. Arenas have ice in winter, so Jan, Feb and Nov need a hall, event centre or casino.
A32: Sellable capacity (people) | B32: 1000 | C32: 800 | D32: 1000 | E32: 2000 | F32: 2000 | G32: 2000 | H32: Set it to about twice the crowd you expect (the Expected crowd % is 50%). Haliburton ~1,000 and Bancroft 800 are ESTIMATES (not published). Marmora 1,000 is published. City arenas are set to 2,000 (ESTIMATE): Peterborough's published setups run 1,722 to 5,501, Kingston lists 5,700 for cold-season events, Oshawa 1,000 to 7,600. Cody's minimum crowd is 1,000.
A33: Venue rental per day ($) | B33: 1500 | C33: 1000 | D33: 600 | E33: 6000 | F33: 8000 | G33: 8000 | H33: Haliburton: $1,500 was the real 2026 arena bill (Cody), entered as one day. Marmora $600/day is published. Bancroft is an ESTIMATE. Peterborough, Kingston and Oshawa don't publish rates: ESTIMATES until they quote (rent, staff, ushers, box office). For scale, Peterborough's smaller Healthy Planet Arena charges $3,700.75 a day for a floor pad.
A34: Days booked (setup + show) | B34: 1 | C34: 2 | D34: 2 | E34: 1 | F34: 1 | G34: 1 | H34: Setup day + show day, unless the venue quotes the whole event.
A35: Venue staff hours (setup + teardown) | B35: 0 | C35: 16 | D35: 16 | E35: 60 | F35: 80 | G35: 80 | H35: ESTIMATE. 0 where the quote already includes staff. City arenas need ushers, box office and a bigger setup crew.
A36: Venue staff rate per hour ($) | B36: 30 | C36: 30 | D36: 30 | E36: 40 | F36: 40 | G36: 40 | H36: Haliburton lists $30/hr for setup and teardown with staff. Others are ESTIMATES.
A37: Ontario Athletics Commission event permit ($) | B37: 600 | C37: 600 | D37: 600 | E37: 600 | F37: 600 | G37: 600 | H37: Ontario Athletics Commission: $600 permit per show. Under the regulation a 'contest' is one bout or several in a row, so one $600 permit should cover the whole card (confirm with the Commission). The $3,000 permit covers up to 8 shows in a year. Assumed to be inside Cody's $15,000 'everything else'.
A38: Cage rental & delivery ($) | B38: 3000 | C38: 3000 | D38: 3000 | E38: 3000 | F38: 3000 | G38: 3000 | H38: Cage, officials, medical, insurance, security and lights/sound/stream are Cody's real 2026 costs. For the three city arenas, security, lights/sound, seating, athlete costs and crew food are raised (ESTIMATES) for a 2,000-seat room and the longer drive. The cage must sit on a platform 3-4 ft high (Ontario rule): make sure the quote includes it.
A39: Officials: referees, judges, timekeeper ($) | B39: 3000 | C39: 3000 | D39: 3000 | E39: 3000 | F39: 3000 | G39: 3000
A40: Medical: ringside doctor, paramedics ($) | B40: 2000 | C40: 2000 | D40: 2000 | E40: 2000 | F40: 2000 | G40: 2000
A41: Event insurance ($) | B41: 2000 | C41: 2000 | D41: 2000 | E41: 2000 | F41: 2000 | G41: 2000
A42: Security ($) | B42: 1500 | C42: 1500 | D42: 1500 | E42: 3500 | F42: 3500 | G42: 3500
A43: Lighting, sound & staging ($) | B43: 1000 | C43: 1000 | D43: 1000 | E43: 3500 | F43: 3500 | G43: 3500
A44: Livestream production ($) | B44: 0 | C44: 0 | D44: 0 | E44: 0 | F44: 0 | G44: 0 | H44: 0: in 2026 the stream was part of the $1,000 lights/sound/stream bill.
...

Sheet Compare
A1: CCCL EVENT PROFIT PREDICTOR · COMPARE VENUES
A2: Nothing to type here. Every number comes from the Inputs tab. Green = pulled from Inputs, black = calculated.
A4: Venue | B4: =IF(Inputs!B28="","(add another city)",Inputs!B28&" · "&Inputs!B29) -> A.J. LaRue Arena · Haliburton | C4: =IF(Inputs!C28="","(add another city)",Inputs!C28&" · "&Inputs!C29) -> North Hastings Community Centre · Bancroft | D4: =IF(Inputs!D28="","(add another city)",Inputs!D28&" · "&Inputs!D29) -> Dr. Hamilton Crawford Memorial Arena · Marmora | E4: =IF(Inputs!E28="","(add another city)",Inputs!E28&" · "&Inputs!E29) -> Peterborough Memorial Centre · Peterborough | F4: =IF(Inputs!F28="","(add another city)",Inputs!F28&" · "&Inputs!F29) -> Slush Puppie Place · Kingston | G4: =IF(Inputs!G28="","(add another city)",Inputs!G28&" · "&Inputs!G29) -> Tribute Communities Centre · Oshawa
A5: Sellable capacity (people) | B5: =Inputs!B32 -> 1000 | C5: =Inputs!C32 -> 800 | D5: =Inputs!D32 -> 1000 | E5: =Inputs!E32 -> 2000 | F5: =Inputs!F32 -> 2000 | G5: =Inputs!G32 -> 2000
A7: COSTS THAT DON'T DEPEND ON THE CROWD
A8: Venue rental (rate × days) | B8: =Inputs!B33*Inputs!B34 -> 1500 | C8: =Inputs!C33*Inputs!C34 -> 2000 | D8: =Inputs!D33*Inputs!D34 -> 1200 | E8: =Inputs!E33*Inputs!E34 -> 6000 | F8: =Inputs!F33*Inputs!F34 -> 8000 | G8: =Inputs!G33*Inputs!G34 -> 8000
A9: Venue staff (hours × rate) | B9: =Inputs!B35*Inputs!B36 -> 0 | C9: =Inputs!C35*Inputs!C36 -> 480 | D9: =Inputs!D35*Inputs!D36 -> 480 | E9: =Inputs!E35*Inputs!E36 -> 2400 | F9: =Inputs!F35*Inputs!F36 -> 3200 | G9: =Inputs!G35*Inputs!G36 -> 3200
A10: All other costs (permit, cage, officials, medical, etc.) | B10: =SUM(Inputs!B37:B49) -> 27500 | C10: =SUM(Inputs!C37:C49) -> 27000 | D10: =SUM(Inputs!D37:D49) -> 28000 | E10: =SUM(Inputs!E37:E49) -> 37600 | F10: =SUM(Inputs!F37:F49) -> 38600 | G10: =SUM(Inputs!G37:G49) -> 38600
A11: Contingency buffer | B11: =(B8+B9+B10)*Inputs!$B$23 -> 1450 | C11: =(C8+C9+C10)*Inputs!$B$23 -> 1474 | D11: =(D8+D9+D10)*Inputs!$B$23 -> 1484 | E11: =(E8+E9+E10)*Inputs!$B$23 -> 2300 | F11: =(F8+F9+F10)*Inputs!$B$23 -> 2490 | G11: =(G8+G9+G10)*Inputs!$B$23 -> 2490
A12: TOTAL EVENT COST | B12: =SUM(B8:B11) -> 30450 | C12: =SUM(C8:C11) -> 30954 | D12: =SUM(D8:D11) -> 31164 | E12: =SUM(E8:E11) -> 48300 | F12: =SUM(F8:F11) -> 52290 | G12: =SUM(G8:G11) -> 52290
A14: WHAT EACH PAID TICKET BRINGS IN
A15: Ticket money after fees and HST (per paid ticket) | B15: =IF(B$5>0,Inputs!$B$16*(1-Inputs!$B$18-Inputs!$B$19),0) -> 73.0353 | C15: =IF(C$5>0,Inputs!$B$16*(1-Inputs!$B$18-Inputs!$B$19),0) -> 73.0353 | D15: =IF(D$5>0,Inputs!$B$16*(1-Inputs!$B$18-Inputs!$B$19),0) -> 73.0353 | E15: =IF(E$5>0,Inputs!$B$16*(1-Inputs!$B$18-Inputs!$B$19),0) -> 73.0353 | F15: =IF(F$5>0,Inputs!$B$16*(1-Inputs!$B$18-Inputs!$B$19),0) -> 73.0353 | G15: =IF(G$5>0,Inputs!$B$16*(1-Inputs!$B$18-Inputs!$B$19),0) -> 73.0353
A16: Bar + merch (per paid ticket, comps included) | B16: =IF(B$5>0,(Inputs!$B$20+Inputs!$B$21)/(1-Inputs!$B$8),0) -> 0 | C16: =IF(C$5>0,(Inputs!$B$20+Inputs!$B$21)/(1-Inputs!$B$8),0) -> 0 | D16: =IF(D$5>0,(Inputs!$B$20+Inputs!$B$21)/(1-Inputs!$B$8),0) -> 0 | E16: =IF(E$5>0,(Inputs!$B$20+Inputs!$B$21)/(1-Inputs!$B$8),0) -> 0 | F16: =IF(F$5>0,(Inputs!$B$20+Inputs!$B$21)/(1-Inputs!$B$8),0) -> 0 | G16: =IF(G$5>0,(Inputs!$B$20+Inputs!$B$21)/(1-Inputs!$B$8),0) -> 0
A17: Total per paid ticket | B17: =B15+B16 -> 73.0353 | C17: =C15+C16 -> 73.0353 | D17: =D15+D16 -> 73.0353 | E17: =E15+E16 -> 73.0353 | F17: =F15+F16 -> 73.0353 | G17: =G15+G16 -> 73.0353
A19: BREAK-EVEN: WHAT IT TAKES NOT TO LOSE MONEY
A20: Paid tickets needed (with expected sponsors) | B20: =IF(AND(B$5>0,B17>0),MAX(0,ROUNDUP((B12-Inputs!B50-Inputs!$B$22)/B17,0)),0) -> 171 | C20: =IF(AND(C$5>0,C17>0),MAX(0,ROUNDUP((C12-Inputs!C50-Inputs!$B$22)/C17,0)),0) -> 260 | D20: =IF(AND(D$5>0,D17>0),MAX(0,ROUNDUP((D12-Inputs!D50-Inputs!$B$22)/D17,0)),0) -> 345 | E20: =IF(AND(E$5>0,E17>0),MAX(0,ROUNDUP((E12-Inputs!E50-Inputs!$B$22)/E17,0)),0) -> 525 | F20: =IF(AND(F$5>0,F17>0),MAX(0,ROUNDUP((F12-Inputs!F50-Inputs!$B$22)/F17,0)),0) -> 634 | G20: =IF(AND(G$5>0,G17>0),MAX(0,ROUNDUP((G12-Inputs!G50-Inputs!$B$22)/G17,0)),0) -> 634
A21: ... as % of capacity | B21: =IF(B$5>0,B20/(1-Inputs!$B$8)/B5,0) -> 0.21375 | C21: =IF(C$5>0,C20/(1-Inputs!$B$8)/C5,0) -> 0.40625 | D21: =IF(D$5>0,D20/(1-Inputs!$B$8)/D5,0) -> 0.43125 | E21: =IF(E$5>0,E20/(1-Inputs!$B$8)/E5,0) -> 0.328125 | F21: =IF(F$5>0,F20/(1-Inputs!$B$8)/F5,0) -> 0.39625 | G21: =IF(G$5>0,G20/(1-Inputs!$B$8)/G5,0) -> 0.39625
A22: Paid tickets needed with NO sponsors | B22: =IF(AND(B$5>0,B17>0),MAX(0,ROUNDUP((B12-Inputs!$B$22)/B17,0)),0) -> 417 | C22: =IF(AND(C$5>0,C17>0),MAX(0,ROUNDUP((C12-Inputs!$B$22)/C17,0)),0) -> 424 | D22: =IF(AND(D$5>0,D17>0),MAX(0,ROUNDUP((D12-Inputs!$B$22)/D17,0)),0) -> 427 | E22: =IF(AND(E$5>0,E17>0),MAX(0,ROUNDUP((E12-Inputs!$B$22)/E17,0)),0) -> 662 | F22: =IF(AND(F$5>0,F17>0),MAX(0,ROUNDUP((F12-Inputs!$B$22)/F17,0)),0) -> 716 | G22: =IF(AND(G$5>0,G17>0),MAX(0,ROUNDUP((G12-Inputs!$B$22)/G17,0)),0) -> 716
A23: Sponsorship needed to break even on a LOW night | B23: =IF(B$5>0,MAX(0,B12-Inputs!$B$22-ROUND(B5*Inputs!$B$5*(1-Inputs!$B$8),0)*B17),0) -> 10000.116 | C23: =IF(C$5>0,MAX(0,C12-Inputs!$B$22-ROUND(C5*Inputs!$B$5*(1-Inputs!$B$8),0)*C17),0) -> 14594.093 | D23: =IF(D$5>0,MAX(0,D12-Inputs!$B$22-ROUND(D5*Inputs!$B$5*(1-Inputs!$B$8),0)*D17),0) -> 10714.116 | E23: =IF(E$5>0,MAX(0,E12-Inputs!$B$22-ROUND(E5*Inputs!$B$5*(1-Inputs!$B$8),0)*E17),0) -> 7400.232 | F23: =IF(F$5>0,MAX(0,F12-Inputs!$B$22-ROUND(F5*Inputs!$B$5*(1-Inputs!$B$8),0)*F17),0) -> 11390.232 | G23: =IF(G$5>0,MAX(0,G12-Inputs!$B$22-ROUND(G5*Inputs!$B$5*(1-Inputs!$B$8),0)*G17),0) -> 11390.232
A24: Sponsorship you expect (from Inputs) | B24: =Inputs!B50 -> 18000 | C24: =Inputs!C50 -> 12000 | D24: =Inputs!D50 -> 6000 | E24: =Inputs!E50 -> 10000 | F24: =Inputs!F50 -> 6000 | G24: =Inputs!G50 -> 6000
A26: SCENARIO: LOW CROWD
A27: Crowd (people in the building) | B27: =ROUND(B5*Inputs!$B$5,0) -> 350 | C27: =ROUND(C5*Inputs!$B$5,0) -> 280 | D27: =ROUND(D5*Inputs!$B$5,0) -> 350 | E27: =ROUND(E5*Inputs!$B$5,0) -> 700 | F27: =ROUND(F5*Inputs!$B$5,0) -> 700 | G27: =ROUND(G5*Inputs!$B$5,0) -> 700
A28: Paid tickets | B28: =ROUND(B27*(1-Inputs!$B$8),0) -> 280 | C28: =ROUND(C27*(1-Inputs!$B$8),0) -> 224 | D28: =ROUND(D27*(1-Inputs!$B$8),0) -> 280 | E28: =ROUND(E27*(1-Inputs!$B$8),0) -> 560 | F28: =ROUND(F27*(1-Inputs!$B$8),0) -> 560 | G28: =ROUND(G27*(1-Inputs!$B$8),0) -> 560
A29: Ticket money after fees | B29: =B28*B15 -> 20449.884 | C29: =C28*C15 -> 16359.907 | D29: =D28*D15 -> 20449.884 | E29: =E28*E15 -> 40899.768 | F29: =F28*F15 -> 40899.768 | G29: =G28*G15 -> 40899.768
A30: Bar + merch | B30: =B27*(Inputs!$B$20+Inputs!$B$21) -> 0 | C30: =C27*(Inputs!$B$20+Inputs!$B$21) -> 0 | D30: =D27*(Inputs!$B$20+Inputs!$B$21) -> 0 | E30: =E27*(Inputs!$B$20+Inputs!$B$21) -> 0 | F30: =F27*(Inputs!$B$20+Inputs!$B$21) -> 0 | G30: =G27*(Inputs!$B$20+Inputs!$B$21) -> 0
A31: Sponsorship + livestream | B31: =IF(B$5>0,Inputs!B50*1+Inputs!$B$22,0) -> 18000 | C31: =IF(C$5>0,Inputs!C50*1+Inputs!$B$22,0) -> 12000 | D31: =IF(D$5>0,Inputs!D50*1+Inputs!$B$22,0) -> 6000 | E31: =IF(E$5>0,Inputs!E50*1+Inputs!$B$22,0) -> 10000 | F31: =IF(F$5>0,Inputs!F50*1+Inputs!$B$22,0) -> 6000 | G31: =IF(G$5>0,Inputs!G50*1+Inputs!$B$22,0) -> 6000
A32: Total money in | B32: =SUM(B29:B31) -> 38449.884 | C32: =SUM(C29:C31) -> 28359.907 | D32: =SUM(D29:D31) -> 26449.884 | E32: =SUM(E29:E31) -> 50899.768 | F32: =SUM(F29:F31) -> 46899.768 | G32: =SUM(G29:G31) -> 46899.768
A33: Total event cost | B33: =B12 -> 30450 | C33: =C12 -> 30954 | D33: =D12 -> 31164 | E33: =E12 -> 48300 | F33: =F12 -> 52290 | G33: =G12 -> 52290
A34: PROFIT / (LOSS) | B34: =B32-B33 -> 7999.884 | C34: =C32-C33 -> -2594.0928 | D34: =D32-D33 -> -4714.116 | E34: =E32-E33 -> 2599.768 | F34: =F32-F33 -> -5390.232 | G34: =G32-G33 -> -5390.232
A36: SCENARIO: EXPECTED CROWD
A37: Crowd (people in the building) | B37: =ROUND(B5*Inputs!$B$6,0) -> 500 | C37: =ROUND(C5*Inputs!$B$6,0) -> 400 | D37: =ROUND(D5*Inputs!$B$6,0) -> 500 | E37: =ROUND(E5*Inputs!$B$6,0) -> 1000 | F37: =ROUND(F5*Inputs!$B$6,0) -> 1000 | G37: =ROUND(G5*Inputs!$B$6,0) -> 1000
A38: Paid tickets | B38: =ROUND(B37*(1-Inputs!$B$8),0) -> 400 | C38: =ROUND(C37*(1-Inputs!$B$8),0) -> 320 | D38: =ROUND(D37*(1-Inputs!$B$8),0) -> 400 | E38: =ROUND(E37*(1-Inputs!$B$8),0) -> 800 | F38: =ROUND(F37*(1-Inputs!$B$8),0) -> 800 | G38: =ROUND(G37*(1-Inputs!$B$8),0) -> 800
A39: Ticket money after fees | B39: =B38*B15 -> 29214.12 | C39: =C38*C15 -> 23371.296 | D39: =D38*D15 -> 29214.12 | E39: =E38*E15 -> 58428.24 | F39: =F38*F15 -> 58428.24 | G39: =G38*G15 -> 58428.24
A40: Bar + merch | B40: =B37*(Inputs!$B$20+Inputs!$B$21) -> 0 | C40: =C37*(Inputs!$B$20+Inputs!$B$21) -> 0 | D40: =D37*(Inputs!$B$20+Inputs!$B$21) -> 0 | E40: =E37*(Inputs!$B$20+Inputs!$B$21) -> 0 | F40: =F37*(Inputs!$B$20+Inputs!$B$21) -> 0 | G40: =G37*(Inputs!$B$20+Inputs!$B$21) -> 0
A41: Sponsorship + livestream | B41: =IF(B$5>0,Inputs!B50*1+Inputs!$B$22,0) -> 18000 | C41: =IF(C$5>0,Inputs!C50*1+Inputs!$B$22,0) -> 12000 | D41: =IF(D$5>0,Inputs!D50*1+Inputs!$B$22,0) -> 6000 | E41: =IF(E$5>0,Inputs!E50*1+Inputs!$B$22,0) -> 10000 | F41: =IF(F$5>0,Inputs!F50*1+Inputs!$B$22,0) -> 6000 | G41: =IF(G$5>0,Inputs!G50*1+Inputs!$B$22,0) -> 6000
A42: Total money in | B42: =SUM(B39:B41) -> 47214.12 | C42: =SUM(C39:C41) -> 35371.296 | D42: =SUM(D39:D41) -> 35214.12 | E42: =SUM(E39:E41) -> 68428.24 | F42: =SUM(F39:F41) -> 64428.24 | G42: =SUM(G39:G41) -> 64428.24
A43: Total event cost | B43: =B12 -> 30450 | C43: =C12 -> 30954 | D43: =D12 -> 31164 | E43: =E12 -> 48300 | F43: =F12 -> 52290 | G43: =G12 -> 52290
A44: PROFIT / (LOSS) | B44: =B42-B43 -> 16764.12 | C44: =C42-C43 -> 4417.296 | D44: =D42-D43 -> 4050.12 | E44: =E42-E43 -> 20128.24 | F44: =F42-F43 -> 12138.24 | G44: =G42-G43 -> 12138.24
A46: SCENARIO: HIGH CROWD
A47: Crowd (people in the building) | B47: =ROUND(B5*Inputs!$B$7,0) -> 800 | C47: =ROUND(C5*Inputs!$B$7,0) -> 640 | D47: =ROUND(D5*Inputs!$B$7,0) -> 800 | E47: =ROUND(E5*Inputs!$B$7,0) -> 1600 | F47: =ROUND(F5*Inputs!$B$7,0) -> 1600 | G47: =ROUND(G5*Inputs!$B$7,0) -> 1600
...

Sheet Haliburton 2026 Check
A1: HALIBURTON MAY 2026: WHAT REALLY HAPPENED
A2: Part 1 adds up Cody's numbers (Oct 2026): about $18,000 profit. That profit went into the gym and other projects (Kyle, Oct 2026), which is why it felt like breaking even. Part 2 records where the money went: type the real amounts once Cody has the Eventbrite payout report. Part 3 checks the model against the real result.
A4: PART 1: THE NUMBERS CODY GAVE (Oct 2026)
A5: General admission price | B5: 60 | C5: From Cody.
A6: VIP single seat price | B6: 100 | C6: From Cody.
A7: VIP table price | B7: 1500 | C7: From Cody. Tables seat 8-10 depending on the venue's tables (Kyle).
A8: Seats per table | B8: 8
A9: VIP tables sold | B9: 6
A10: Tickets sold, all types | B10: 400 | C10: From Cody. Assumed to include the 48 table seats.
A11: VIP single seats sold | B11: 40 | C11: ESTIMATE. Cody didn't split GA and VIP. Fix it from the Eventbrite sales report.
A12: Table seats (tables × seats) | B12: =B9*B8 -> 48
A13: General admission tickets (what's left) | B13: =MAX(0,B10-B12-B11) -> 312
A14: Ticket money before fees | B14: =B13*B5+B11*B6+B9*B7 -> 31720
A15: Eventbrite fees CCCL paid (% from Inputs) | B15: =Inputs!$B$18 -> 0.079
A16: Ticket money after fees | B16: =B14*(1-B15) -> 29214.12
A17: Sponsor money (15 sponsors) | B17: 18000 | C17: From Cody. Title sponsor: Dillabough Millwrighting & Welding.
A18: Bar profit to CCCL | B18: 0 | C18: The arena or a local group ran the bar (Cody).
A19: TOTAL MONEY IN | B19: =B16+B17+B18 -> 47214.12
A21: Arena rental | B21: 1500
A22: Cage | B22: 3000
A23: Medical | B23: 2000
A24: Officials | B24: 3000
A25: Insurance | B25: 2000
A26: Security | B26: 1500
A27: Lights, sound, stream | B27: 1000
A28: Everything else | B28: 15000 | C28: From Cody. What's in this $15,000 is the biggest unknown: the Commission permit, ads, belts and medals, hotels, food, seating?
A29: TOTAL COST | B29: =SUM(B21:B28) -> 29000
A31: PROFIT THESE NUMBERS ADD UP TO | B31: =B19-B29 -> 18214.12
A32: Profit left over that Cody remembers ($) | B32: 0 | C32: Cody said 'broke even, slight profit' because the show's profit went into the gym and other projects (Kyle, Oct 2026).
A33: MONEY TO ACCOUNT FOR | B33: =B31-B32 -> 18214.12
A35: PART 2: WHERE THE MONEY WENT (type what applies, leave the rest at 0)
A36: Show profit put into the gym and other projects ($) | B36: 0 | C36: Left at 0 until Cody has the real amount (Eventbrite payout report and bank records). Kyle's understanding (Oct 2026): the show made money and it went into the gym and other projects. This doesn't lower the show's profit; it's where the profit went.
A37: Anything below made the show's real profit smaller:
A38: VIP table money already counted inside the $18,000 sponsor total ($) | B38: 0 | C38: If tables were sold as part of sponsor packages, up to $9,000 got counted twice.
A39: Free tickets counted inside the 400 (how many) | B39: 0 | C39: Sponsor tickets, fighters' families, volunteers. Valued at the GA price below.
A40: ... worth (free tickets × GA price) | B40: =B39*B5 -> 0
A41: Sponsor money promised but never paid, or given as goods/services instead of cash ($) | B41: 0
A42: HST CCCL sent to the government ($) | B42: 0 | C42: Only if CCCL is HST-registered. On tax-included prices it's about 11.5% of ticket and sponsor money.
A43: Refunds and chargebacks ($) | B43: 0
A44: Bills paid that aren't in the $29,000 ($) | B44: 0 | C44: Fighter travel, hotels, posters and ads, food, gear CCCL bought, the Commission permit if it wasn't in 'everything else'.
...

Sheet Town Scout
A1: TOWN SCOUT: WHERE TO RUN CCCL IN 2027
A2: 25 towns within about 2 hours of Bancroft, scored 1-5 (5 = best). Distance: 5 = 30 min or less, 1 = over 2 h. Overall is the simple average. Researched Oct 2026; drive times are estimates. Confirm rates and capacity with each venue.
A4: # | B4: Town | C4: Overall | D4: Crowd | E4: Venue | F4: Fighters | G4: Competition | H4: Distance | I4: In the Compare tab? | J4: Drive from Bancroft | K4: Population | L4: Best venue | M4: Capacity | N4: Rental rate (as published) | O4: Dry floor season | P4: Combat gyms nearby | Q4: Combat shows nearby | R4: Verdict | S4: Venue source
A5: 1 | B5: Bancroft | C5: 4.2 | D5: 3 | E5: 4 | F5: 4 | G5: 5 | H5: 5 | I5: Yes | J5: 0 km (home base) | K5: 4,065 (Town of Bancroft, 2021 census); town site cites a… | L5: North Hastings Community Centre (NHCC) arena | M5: Not published | N5: Not published. Town said in 2023 that rental agreements/fees for year-round (dry-floor) use were being designed to be 'competitive'; ice fees kept at old Commission rates (Feb 2024). | O5: Ice normally goes in during August (mayor, Mar 2026). 2026: ice delayed to ~Sept 21 by an ice-plant part. Dry floor is expected… | P5: Bancroft Boxing & Grappling | Q5: No 2025-2026 combat events found in Bancroft (2015-05-15) | R5: Best fit for show 2: home gym and home crowd, renovated arena back online, no competition - lock a spring/early-summer 2027 dry-floor date before the Gemboree. | S5: https://bancroft.hosted.civiclive.com/living/recreation___leisure/north_hastings_community_centre
A6: 2 | B6: Haliburton | C6: 4 | D6: 4 | E6: 4 | F6: 3 | G6: 5 | H6: 4 | I6: Yes | J6: ~70 km / ~1 h via Hwy 118 (estimate) | K6: 7,182 (Dysart et al, 2021 census); Haliburton County… | L6: A.J. LaRue Arena & Community Centre | M6: Not published | N6: By-Law 2023-39 (winter rates effective Sept 5, 2023; summer Jan 1, 2024): ice surface rental "$1,030.00 per day" for profit-making events / "$463.50 per day" non-profit; auditorium "$42.45 per hour, maximum of $265.25… | O6: Summer ice runs from 'start of season through Labour Day', so ice can be back in during summer; spring (e.g. early May) dry floor proven… | P6: The Chop Shop MMA | Q6: CCCL 1 - Cottage Country Combat League (2026-05-02) | R6: Proven venue: the 2026 show made about $18,000 on Cody's numbers (exact figure waiting on the Eventbrite payout report). Keep it as the annual anchor show (spring dry floor), not more than once a year to avoid wearing out the market. | S6: https://www.dysartetal.ca/en/explore-and-play/resources/Arena/2023-39%20Parks%20and%20Recreation%20Fees%20and%20Charges.pdf
A7: 3 | B7: Peterborough | C7: 3.8 | D7: 5 | E7: 3 | F7: 5 | G7: 3 | H7: 3 | I7: Yes | J7: ~115 km / ~1 h 25 min south on Hwy 28 (estimate) | K7: 83,651 (City of Peterborough, 2021 census) | L7: Peterborough Memorial Centre | M7: Theatre configuration 2,380; end-stage 4,530; in-the-round… | N7: Not published | O7: Not published | P7: Kawartha Combat; 10th Planet Jiu Jitsu Peterborough; Corcoran's Boxing Club & Fitness Centre; Eastside Boxing; BEL Boxing Club | Q7: OFSAA Wrestling Championship (2026-03-02 to 2026-03-04); GCW live pro wrestling at The Venue, Peterborough (2025-06-29); Homecoming IV (2019-02-09) | R7: Biggest upside but highest cost and risk - target once CCCL has 2-3 shows behind it; test the market via Lakefield first. | S7: https://venuecoalition.com/peterborough-memorial-centre/
A8: 4 | B8: Apsley | C8: 3.6 | D8: 3 | E8: 4 | F8: 2 | G8: 5 | H8: 4 | J8: ~55 km / ~45-50 min south on Hwy 28 (estimate) | K8: 2,877 (North Kawartha, 2021 census) | L8: North Kawartha Community Centre (NKCC) | M8: Banquet hall up to 325; arena floor capacity not published | N8: 2026 page (+HST): arena "Daily flat rate for special events (excluding dances): $600.00"; hall daily flat $300.00 + $50 kitchen/bar; ice primetime $127.05/hr. | O8: Ice late August to mid-March, so dry floor roughly mid-March to late August. | P8: None found | Q8: None found | R8: Low-cost, close, untouched market - good for a smaller spring or summer show; confirm arena floor capacity. | S8: https://northkawartha.ca/living-here/facility-rentals
A9: 5 | B9: Marmora | C9: 3.6 | D9: 3 | E9: 5 | F9: 2 | G9: 5 | H9: 3 | I9: Yes | J9: ~110 km / ~1 h 20 min via Hwy 62 & Hwy 7 (estimate) | K9: 4,267 (Marmora and Lake, 2021 census) | L9: Dr. Hamilton Crawford Memorial Arena, Lions Hall & Fairgrounds Park (Marmora &… | M9: 1,000 (arena dry floor) | N9: Town page (year not stated): arena dry floor "Event: $600/day" (youth $50/hr, adult program $75/hr); Lions Hall public event no bar $300/day, wedding reception with renter-run bar $700/day. Town ran a '2025 Municipal… | O9: Ice September to April; lower level is a dry-floor event space May to August. | P9: None found | Q9: None found | R9: Best-value summer venue on the list (1,000 cap, $600/day, bar) - strong option for a May-August show. | S9: https://marmoraandlake.ca/community-centre
A10: 6 | B10: Lakefield | C10: 3.6 | D10: 4 | E10: 3 | F10: 4 | G10: 4 | H10: 3 | J10: ~100 km / ~1 h 15 min south on Hwy 28 (estimate) | K10: 18,653 (Selwyn Township, 2021 census) | L10: Lakefield-Smith Community Centre | M10: Not published | N10: Selwyn rates page (year not stated): "Arena floor event rate (up to 1am)" $761.23 (covers Ennismore & Lakefield); "Daily Floor Rental (All hours)" $103.07 under Summer Floor Rate (Sports) - facility page instead says… | O10: Summer floor season (dates not given). | P10: BEL Boxing Club; Kawartha Combat; 10th Planet Jiu Jitsu Peterborough; Corcoran's Boxing Club & Fitness Centre | Q10: War in Ennismore: Revival (2022-08-20) | R10: Smart way into the Peterborough market without Memorial Centre costs - good 2027 expansion show. | S10: https://www.selwyntownship.ca/en/township-hall/facility-rental-rates.aspx
A11: 7 | B11: Belleville | C11: 3.6 | D11: 5 | E11: 4 | F11: 5 | G11: 2 | H11: 2 | J11: ~150 km / ~1 h 50 min south on Hwy 62 (estimate) | K11: 55,071 (City of Belleville, 2021 census); Quinte West next… | L11: Quinte Sports & Wellness Centre - main bowl (City lists 'CIBC Place';… | M11: Over 4,400 (City) / 4,365 hockey (Wikipedia); other pads… | N11: City page (excl. HST, year not stated): adult ball hockey/floor $119.75/hr, minor $81.75/hr; "Benefit Exhibition Games: $609.50 plus expenses". No event day rate published. | O11: Floor rates listed year-round; summer ice sold July-August. | P11: Infinite Martial Arts and Fitness; Pinnacle Boxing Academy; Bulldog Boxing Academy | Q11: BTC XXVII: Bellevegas (2025-03-15); Friday Night Fights (2025-09-12) | R11: Big market with real competition (BTC) - only with a distinct amateur/cottage-league angle or a co-promotion. | S11: https://www.belleville.ca/learn-and-play/facilities-and-rentals/arenas/
A12: 8 | B12: Lindsay | C12: 3.6 | D12: 4 | E12: 3 | F12: 5 | G12: 4 | H12: 2 | J12: ~150 km / ~1 h 50 min (estimate) | K12: 79,247 (City of Kawartha Lakes, 2021 census); Ross… | L12: Lindsay Recreation Complex | M12: Not published | N12: Not published (booked via the City's PerfectMind portal) | O12: Many City arenas become floors April through August. | P12: Big Country - Lindsay | Q12: None found | R12: Strong fighter base and market, but far - consider a co-promoted show with Big Country later in 2027. | S12: https://www.kawarthalakes.ca/explore-play/facility-and-park-rentals/arena-and-ice-rentals/
A13: 9 | B13: Wilberforce | C13: 3.4 | D13: 2 | E13: 2 | F13: 3 | G13: 5 | H13: 5 | J13: About a half-hour drive (My Bancroft Now, Sept 2026) | K13: 3,830 (Highlands East, 2021 census) | L13: Keith Tallman Memorial Arena | M13: Not published | N13: Highlands East page (year not stated): "Summer Prime Time ... $40 plus HST" per hour, "Summer Non-Prime ... $25 plus HST"; winter prime $95 + HST; "Full Day Rate not available"; events need $2M liability. | O13: Summer = dry season (ice put in early in 2026 for Bancroft groups) | P13: Bancroft Boxing & Grappling | Q13: None found | R13: Low-cost fallback only (e.g., a small youth grappling/amateur night) - too small for a 1,000+ crowd. | S13: https://www.highlandseast.ca/municipal-services/fees/facility-fees/
A14: 10 | B14: Minden | C14: 3.4 | D14: 4 | E14: 3 | F14: 3 | G14: 4 | H14: 3 | J14: ~95 km / ~1 h 15 min via Haliburton (estimate) | K14: 6,971 (Minden Hills, 2021 census) | L14: S.G. Nesbitt Memorial Arena (Minden Hills Recreation Complex) | M14: 294 seats (Town) / 390 (Stadium Journey) | N14: Town page (year not stated, 2026 site): "Rink area rental $1,147.50 per day or night"; floor sports $55.50/hr; special occasion permit surcharge $222.50; stat holidays +20%; non-resident (outside Haliburton County) ice… | O14: Summer ice is sold June 1-Aug 31, so a summer dry floor is not guaranteed; spring is the likely window - confirm. | P14: The Chop Shop MMA | Q14: None found | R14: Good modern backup to Haliburton, but same market - use only if LaRue is unavailable. | S14: https://www.mindenhills.ca/explore-discover/rent-a-facility/arena-and-ice-rentals/
A15: 11 | B15: Huntsville | C15: 3.4 | D15: 4 | E15: 4 | F15: 3 | G15: 4 | H15: 2 | J15: ~165 km / ~2 h via Hwy 127/60 or Haliburton (estimate) | K15: 21,147 (Town of Huntsville, 2021 census); Muskoka 66,674… | L15: Canada Summit Centre - Don Lough Arena | M15: 2,200 max (incl. standing); 1,371 seated | N15: Not published | O15: Not published (Town also sells summer ice) | P15: Big Country - Muskoka | Q15: Rock Solid Wrestling 'Brace For Impact' (2025-03-29); OFF1: First Strike (2025-05-09) | R15: Great summer-tourist venue but far from the Bancroft base - consider for a 2028 Muskoka expansion with Big Country Muskoka. | S15: https://huntsville.ca/media/czqfwb2f/town-of-huntsville-2025_sales-kit.pdf
A16: 12 | B16: Bracebridge | C16: 3.4 | D16: 4 | E16: 3 | F16: 4 | G16: 4 | H16: 2 | J16: ~145 km / ~1 h 50 min via Hwy 118 (estimate) | K16: 17,305 (Town of Bracebridge, 2021 census) | L16: Muskoka Lumber Arena (Muskoka Lumber Community Centre) | M16: Not published | N16: Not published | O16: Not published | P16: Big Country - Muskoka | Q16: Rock Solid Wrestling 'Brace For Impact' (2025-03-29); OFF1: First Strike (2025-05-09) | R16: Good fighter + crowd mix in Muskoka; get venue capacity before considering. | S16: https://www.bracebridge.ca/be-active/recreation-facilities-and-rentals/
A17: 13 | B17: Maynooth | C17: 3.2 | D17: 2 | E17: 1 | F17: 3 | G17: 5 | H17: 5 | J17: ~22 km / ~20 min north on Hwy 62 (estimate) | K17: 4,385 (Hastings Highlands, 2021 census) | L17: Hastings Highlands Centre (Emond Hall) | M17: 165 | N17: Not listed | O17: N/A (no ice) | P17: Bancroft Boxing & Grappling | Q17: None found | R17: Not viable for a caged show (165-person hall) - treat as Bancroft's catchment. | S17: https://www.hastingshighlands.ca/recreation-culture/facilities-and-rentals/hastings-highlands-centre-emond-hall-program-room/
A18: 14 | B18: Madoc | C18: 3.2 | D18: 3 | E18: 3 | F18: 2 | G18: 5 | H18: 3 | J18: ~95 km / ~1 h 10 min south on Hwy 62 (estimate) | K18: 4,801 (Centre Hastings, 2021 census) | L18: Madoc & District Recreation Centre (arena) | M18: Not published | N18: Not published | O18: Open September to May for ice, so dry floor ~June-August. | P18: None found | Q18: None found | R18: Possible summer show if capacity checks out; secondary option. | S18: https://www.centrehastings.com/media/ntcdeugb/centre-hastings-prc-master-plan-technical-compendium_may2023.pdf
A19: 15 | B19: Fenelon Falls | C19: 3.2 | D19: 3 | E19: 3 | F19: 4 | G19: 4 | H19: 2 | J19: ~140 km / ~1 h 45 min (estimate) | K19: Part of Kawartha Lakes (79,247, 2021 census); village… | L19: Fenelon Falls Community Centre (Roger Bellwood Arena & Gord Innes Community… | M19: 280 arena seats | N19: Not published | O19: City arenas typically floors April-August | P19: Big Country - Lindsay | Q19: None found | R19: Decent summer cottage-crowd option if Lindsay is too big or busy. | S19: https://explorefenelonfalls.com/news-archive/roger-bellwood-arena-and-gord-innes-community-centre-opened-2012
A20: 16 | B20: Barry's Bay | C20: 3 | D20: 3 | E20: 3 | F20: 1 | G20: 5 | H20: 3 | J20: ~80 km / ~1 h north via Hwy 62 (estimate) | K20: 3,927 (Madawaska Valley, 2021 census) | L20: Paul J. Yakabuski Community Centre (PJYCC) | M20: Ice surface 800; upstairs Community Hall 285 | N20: 2026 Schedule of Fees: "PJYCC Renter Run Bar: downstairs ice surface" $1224; Municipal Run Bar downstairs $816; ice regular hourly $173; fundraising/community group rate "50% of rental fee". No dry-floor day rate listed. | O20: Ice mid-September to mid-April, so dry floor ~mid-April to mid-September. | P20: None found | Q20: None found | R20: Workable 800-cap venue in an untouched market, but no fighter base - a later-2027 expansion test. | S20: https://www.madawaskavalley.ca/recreation-tourism/facilities-rentals/paul-j-yakabuski-community-centre/
A21: 17 | B21: Havelock | C21: 3 | D21: 3 | E21: 3 | F21: 2 | G21: 4 | H21: 3 | J21: ~115 km / ~1 h 25 min (estimate) | K21: 5,083 (Havelock-Belmont-Methuen, 2021 census) | L21: Havelock Community Centre (arena) | M21: Not published | N21: Not shown; fees set by By-Law 2024-032 (not retrieved) | O21: Not stated | P21: None found | Q21: None found | R21: Middling - licensed hall on site is a plus, but Marmora is a better-documented option on the same Hwy 7 corridor. | S21: https://www.hbmtwp.ca/play-and-discover/facilities/rent-a-facility
... A29: 25 | B29: Coboconk | C29: 2.4 | D29: 2 | E29: 1 | F29: 2 | G29: 5 | H29: 2 | J29: ~125 km / ~1 h 35 min via Minden & Hwy 35 (estimate) | K29: Part of Kawartha Lakes (79,247, 2021 census) | L29: Coboconk Community Centre (hall) | M29: 175 | N29: Not published | O29: N/A | P29: None found | Q29: None found | R29: Not viable - no arena. | S29: https://www.kawarthalakes.ca/explore-play/facility-and-park-rentals/community-hall-rentals/

Sheet 2027 Venues
A1: 2027 VENUES: WHERE A 1,000+ CROWD OR A WINTER SHOW COULD WORK
A2: Cody's 10 towns plus casinos and event centres up to 3 hours from Bancroft, researched October 2026. Score 1-5 (crowd, venue, fighters, competition, distance). Arenas have ice in winter, so Jan, Feb and Nov need a venue that holds floor events in hockey season.
A4: # | B4: Town | C4: Drive from Bancroft | D4: Venue | E4: Type | F4: Score | G4: Winter OK (Jan/Feb/Nov)? | H4: Event capacity (as published) | I4: Rental rate (as published) | J4: Combat shows held there | K4: Who to call | L4: Town verdict | M4: Clashes to avoid | N4: Source
A5: 1 | B5: Peterborough | C5: ~1 h 37 min | D5: Peterborough Memorial Centre (PMC) | E5: Arena | F5: 4.4 | G5: Yes | H5: Concerts: 'customizable capacity ranging from 1722 to 5501 including floor capacity'; ice events 4,050 max. No boxing/MMA configuration published. | I5: Not published - request a quote | J5: No 2024-2026 boxing/MMA found. Earlier pro 'Homecoming' cards (e.g., Feb 9, 2019, where Cody Purtell was billed; confirm with Cody). OFSAA high-school wrestling, Mar… | K5: Jose Garcia-Perez, Event Services Supervisor, 705-743-3561 ext. 2504, jgarcia-perez@peterborough.ca | L5: Best 2027 bet for a 1,000+ winter show: closest city arena that holds events in Nov-Feb, smallest published setup 1,722, deepest local fighter pool, and no recent MMA competition. Cost is the unknown. | M5: Peterborough Petes (OHL) home games at PMC (Late Sept to March (plus playoffs)); Dean Brody & The Reklaws at PMC (Sat Nov 21, 2026 (one-off; shows PMC books November Saturdays)) | N5: https://venuecoalition.com/wp-content/uploads/2025/02/Tech-Pack-2024.pdf
A6: 2 | B6: Peterborough | C6: ~1 h 37 min | D6: Healthy Planet Arena (formerly Evinrude Centre) | E6: Arena | F6: 4 | G6: No (ice) | H6: Not published | I6: Special events on a floor pad: $3,700.75 per day per pad (City of Peterborough) | J6: None found 2024-2026 (a kickboxing event was held here in 2011 per ptbocanada.com). | K6: Facility Booking 705-742-7777 ext. 2577, facilitybooking@peterborough.ca | L6: Best 2027 bet for a 1,000+ winter show: closest city arena that holds events in Nov-Feb, smallest published setup 1,722, deepest local fighter pool, and no recent MMA competition. Cost is the unknown. | M6: Peterborough Petes (OHL) home games at PMC (Late Sept to March (plus playoffs)); Dean Brody & The Reklaws at PMC (Sat Nov 21, 2026 (one-off; shows PMC books November Saturdays)) | N6: https://www.peterborough.ca/arenas
A7: 3 | B7: Bancroft | C7: 0 (home base) | D7: North Hastings Community Centre (NHCC) arena | E7: Arena | F7: 3.8 | G7: No (ice) | H7: Not published | I7: Not published. The Town has said it wants year-round rentals; the arena ran a $207,350 deficit in 2023. | J7: No MMA or boxing found. Smash Wrestling (pro wrestling) ran here May 15, 2015. | K7: 613-332-2062; communitycentre@bancroft.ca (2023) | L7: Home show for spring or early summer only (no winter option). 1,000+ is unproven: show 1 sold ~400 tickets. Get the NHCC floor capacity before booking. | M7: Rockhound Gemboree (fills NHCC) (Civic Holiday long weekend; 2026 opened Thu Jul 30. In 2027 the Civic Holiday is Mon Aug 2 (calendar).) | N7: https://bancroft.hosted.civiclive.com/living/recreation___leisure/north_hastings_community_centre
A8: 4 | B8: Oshawa | C8: ~2 h 29 min | D8: Tribute Communities Centre (TCC) | E8: Arena | F8: 3.8 | G8: Yes | H8: Main rink seating is flexible: 'can host events that require seating from 1,000 to 7,600'. Hockey 5,180 (6,125 with standing room). | I8: Not published - 'Request a Proposal' via Oak View Group | J8: Rise of the Phoenix (Durham Fight Series, Oshawa's first pro MMA card), June 3, 2023; boxing at the 2015 Pan Am Games | K8: Oak View Group; 905-438-8881 x116; tributecommunitiescentre.com/host-an-event/request-a-proposal | L8: Biggest market within 2.5 h and a winter-capable arena that scales down to 1,000, but crowded: BTC ran there in 2024 and 2025, PFC wants back in, and pro boxing runs in Pickering. TCC's renovation starts in 2027. | M8: Oshawa Generals (OHL) and Oshawa FireWolves (NLL) home dates at TCC (Generals Sept-March; FireWolves home opener Nov 27, 2026, season into spring); Oshawa Peony Festival (next to Children's Arena, 155 Arena St) (Early… | N8: https://www.tributecommunitiescentre.com/host-an-event
A9: 5 | B9: Haliburton | C9: ~54 min | D9: A.J. LaRue Arena & Community Centre | E9: Arena | F9: 3.6 | G9: No (ice) | H9: Not published. Show 1 (May 2, 2026) was planned for 800-1,000 (Highlander). Cody's actual figures: about 400 tickets sold and 400-600 people in the building. | I9: By-Law 2023-39: ice surface $1,030.00/day for profit events ($463.50 non-profit); auditorium $42.45/hr (max $265.25/day); staff set-up $30/hr. These are 2023-24 rates. | J9: CCCL 1 - Cottage Country Combat League amateur MMA, May 2, 2026 | K9: 705-457-1740 ext. 635 (Municipality of Dysart et al) | L9: Proven and cheap, but the crowd was about 400-600, half of the 1,000 target. Keep it as the yearly spring anniversary show only if Cody accepts a smaller house there. | M9: Haliburton County Fair (Minden fairgrounds, 20 min away) (Mid-June; Sat June 13, 2026) | N9: https://www.dysartetal.ca/en/explore-and-play/resources/Arena/2023-39%20Parks%20and%20Recreation%20Fees%20and%20Charges.pdf
A10: 6 | B10: Apsley | C10: ~38 min | D10: North Kawartha Community Centre (NKCC) | E10: Arena | F10: 3.4 | G10: No (ice) | H10: Arena floor not published; banquet hall up to 325 | I10: 2026, plus HST: arena special-event flat rate $600.00/day; hall $300/day + $50 kitchen/bar | J10: None found | K10: 705-656-4445; Shawn Tucker, Parks & Rec Supervisor, s.tucker@northkawartha.ca | L10: Cheapest rental ($600/day) and close, but the population is tiny and floor capacity is unpublished. Use it only for a smaller summer show or one that pulls from Peterborough. | M10: Apsley Lions Home & Cottage Show (at NKCC) (Early May; May 2-3, 2026); Apsley Lions Giant Flea Market (at NKCC) (Mid-July; July 18-19, 2026) | N10: https://northkawartha.ca/living-here/facility-rentals
A11: 7 | B11: Lindsay | C11: ~2 h 02 min (Rome2rio estimate;… | D11: Lindsay Recreation Complex | E11: Arena | F11: 3.4 | G11: No (ice) | H11: Not published | I11: Not published (booked through the City's portal) | J11: None found | K11: Facility Booking 705-324-9411 ext. 1226, facilitybooking@kawarthalakes.ca; complex 705-324-9112 | L11: Strong fighter partner (Big Country), but no verified 1,000+ venue and no winter option. Better to bring Big Country fighters to Peterborough than to run in Lindsay. | M11: Lindsay Exhibition (LEX) (Late September; Sept 23-27, 2026) | N11: https://www.kawarthalakes.ca/explore-play/facility-and-park-rentals/arena-and-ice-rentals/
A12: 8 | B12: Lindsay | C12: ~2 h 02 min (Rome2rio estimate;… | D12: Lindsay Exhibition Grounds | E12: Fairgrounds | F12: 3.4 | G12: No (ice) | H12: Not published | I12: Not found | J12: None found | K12: Lindsay Agricultural Society | L12: Strong fighter partner (Big Country), but no verified 1,000+ venue and no winter option. Better to bring Big Country fighters to Peterborough than to run in Lindsay. | M12: Lindsay Exhibition (LEX) (Late September; Sept 23-27, 2026) | N12: https://ontariovisited.ca/las-presents-the-lex-2026/
A13: 9 | B13: Oshawa | C13: ~2 h 29 min | D13: Children's Arena (City of Oshawa) | E13: Arena | F13: 3.4 | G13: Yes | H13: Not published | I13: Floor, commercial: $120/hr + HST (effective Apr 1, 2026); no event day rate published | J13: BTC 25: Legacy (BTC Fight Promotions), Sept 14, 2024 | K13: Service Oshawa 905-436-3311, service@oshawa.ca; online Arena Rental Application | L13: Biggest market within 2.5 h and a winter-capable arena that scales down to 1,000, but crowded: BTC ran there in 2024 and 2025, PFC wants back in, and pro boxing runs in Pickering. TCC's renovation starts in 2027. | M13: Oshawa Generals (OHL) and Oshawa FireWolves (NLL) home dates at TCC (Generals Sept-March; FireWolves home opener Nov 27, 2026, season into spring); Oshawa Peony Festival (next to Children's Arena, 155 Arena St) (Early… | N13: https://www.oshawa.ca/explore-play/recreation/facilities-and-rentals/arena-rentals/
A14: 10 | B14: Rama / Orillia (Casino Rama) | C14: ~2 h 20 min to Orillia; Casino Rama is… | D14: Casino Rama Resort - Entertainment Centre | E14: Casino | F14: 3.4 | G14: Yes | H14: Over 5,000 seats (Wikipedia); no boxing/MMA configuration published | I14: Not published | J14: Pro boxing Jan 19, 2008 (Orion Sports Management); MMA Apr 2, 2011, billed as Ontario's first sanctioned MMA event; Bellator events 2011 and Bellator 67 (May 2012).… | K14: Casino Rama Resort entertainment / events department | L14: Big winter-proof room with MMA history, but no combat since about 2012 and no rental terms. Worth one inquiry as a future 'big show', not a 2027 base. | N14: https://en.wikipedia.org/wiki/Casino_Rama
A15: 11 | B15: Pickering (Pickering Casino Resort) | C15: ~2 h 40 min | D15: The Arena at Pickering Casino Resort | E15: Casino | F15: 3.4 | G15: Yes | H15: 2,500 seats (opened Apr 26, 2023) | I15: Not published | J15: United Boxing Promotions 'Fight Night at the Casino' pro boxing: 4th edition Oct 21, 2023 (first three reported sold out); Sept 20, 2024; Oct 19, 2024 (announced);… | K15: Pickering Casino Resort events | L15: Right-sized (2,500) winter-proof casino arena that already does combat nights, but it's 2 h 40 min away in a crowded market. A fallback if TCC or PMC fall through. | M15: United Boxing Promotions' recurring casino fight nights at the same venue (Several per year (2023-2024)) | N15: https://blogto.com/music/2023/03/arena-pickering-casino-resort-officially-opening
A16: 12 | B16: Kingston | C16: ~2 h 36 min | D16: Slush Puppie Place (formerly Leon's Centre / K-Rock Centre) | E16: Arena | F16: 3.2 | G16: Yes | H16: 6,700 seats, or 5,700 for cold-season events (Visit Kingston guide); 5,000 for hockey (Wikipedia). No MMA configuration published. | I16: Not published | J16: BTC 19: Fight Night Kingston (pro MMA, Mar 18, 2023) and BTC 23: Revolution (Mar 16, 2024), both as Leon's Centre | K16: Managed by ASM Global; venue 613-650-5000; 'Private Venue Bookings' page on slushpuppieplace.com. Tourism Kingston sport team:… | L16: Arena already proven for winter MMA (BTC held two March cards), in a 132k city. Good for a November show, but the 2.5 h+ drive and a thin known amateur MMA gym base are the drawbacks. | M16: Kingston Frontenacs (OHL) home games (Sept-March; e.g., Nov 27, 2026, Jan 2/13/15/30 and Feb 26, 2027); Spirit of Winter festival (downtown) (February; began Feb 1, 2026); Kingston Fall Fair (Memorial Centre… | N16: https://www.visitkingston.ca/media/documents/sports/Sport-Facilities-Guide.pdf
A17: 13 | B17: Oshawa | C17: ~2 h 29 min | D17: Bond Street Event Centre (BOND|ST) | E17: Event Centre | F17: 3.2 | G17: Yes | H17: Not published | I17: Not published | J17: PFC 24 (Prospect Fighting Championships) was booked here for June 20, 2026, then moved to Caledonia because of the FIFA World Cup | K17: bondst.ca | L17: Biggest market within 2.5 h and a winter-capable arena that scales down to 1,000, but crowded: BTC ran there in 2024 and 2025, PFC wants back in, and pro boxing runs in Pickering. TCC's renovation starts in 2027. | M17: Oshawa Generals (OHL) and Oshawa FireWolves (NLL) home dates at TCC (Generals Sept-March; FireWolves home opener Nov 27, 2026, season into spring); Oshawa Peony Festival (next to Children's Arena, 155 Arena St) (Early… | N17: https://doorsopenontario.on.ca/oshawa/bond-st-event-centre
A18: 14 | B18: Madoc | C18: ~1 h 01 min | D18: Madoc & District Recreation Centre (arena) | E18: Arena | F18: 3 | G18: No (ice) | H18: Not published | I18: Not published | J18: None found | K18: 613-473-4206 | L18: Not a 1,000+ market and there's no winter option. Marmora (25 min away) publishes a 1,000-person dry floor at $600/day and is the better summer pick in this area. | M18: Madoc Fair (at the arena grounds) (3rd weekend of September; Sept 18-20, 2026) | N18: https://www.centrehastings.com/media/ntcdeugb/centre-hastings-prc-master-plan-technical-compendium_may2023.pdf
A19: 15 | B19: Port Perry (Great Blue Heron Casino) | C19: ~2 h 27 min | D19: Great Blue Heron Casino & Hotel - live entertainment/special events venue | E19: Casino | F19: 2.8 | G19: Yes | H19: About 800 seats (12,637 sq ft; banquet, theatre or GA), so under 1,000 | I19: Not published | J19: None found | K19: Great Blue Heron Casino events | L19: Too small (about 800) for the 1,000+ target. Skip. | N19: https://toronto.ctvnews.ca/a-new-entertainment-venue-just-opened-in-the-gta-1.6736507
A20: 16 | B20: Kingston | C20: ~2 h 36 min | D20: Kingston Memorial Centre | E20: Arena | F20: 2.6 | G20: Unclear | H20: 3,300 seats (Wikipedia); Visit Kingston guide says 2,500, or bleachers for up to 1,000. Figures conflict. | I20: Not published | J20: None found. The fairgrounds host the Kingston Fall Fair. | K20: City of Kingston recreation | L20: Arena already proven for winter MMA (BTC held two March cards), in a 132k city. Good for a November show, but the 2.5 h+ drive and a thin known amateur MMA gym base are the drawbacks. | M20: Kingston Frontenacs (OHL) home games (Sept-March; e.g., Nov 27, 2026, Jan 2/13/15/30 and Feb 26, 2027); Spirit of Winter festival (downtown) (February; began Feb 1, 2026); Kingston Fall Fair (Memorial Centre… | N20: https://www.visitkingston.ca/media/documents/sports/Sport-Facilities-Guide.pdf
A21: 17 | B21: Kingston | C21: ~2 h 36 min | D21: Queen's Athletics & Recreation Centre (ARC) main gym | E21: Event Centre | F21: 2.6 | G21: Unclear | H21: Main gym seats 1,904 (15,488 sq ft floor with seats retracted) | I21: Not published | J21: None found | K21: Queen's Athletics & Recreation | L21: Arena already proven for winter MMA (BTC held two March cards), in a 132k city. Good for a November show, but the 2.5 h+ drive and a thin known amateur MMA gym base are the drawbacks. | M21: Kingston Frontenacs (OHL) home games (Sept-March; e.g., Nov 27, 2026, Jan 2/13/15/30 and Feb 26, 2027); Spirit of Winter festival (downtown) (February; began Feb 1, 2026); Kingston Fall Fair (Memorial Centre… | N21: https://www.visitkingston.ca/media/documents/sports/Sport-Facilities-Guide.pdf
A22: 18 | B22: Kingston | C22: ~2 h 36 min | D22: INVISTA Centre | E22: Arena | F22: 2.6 | G22: No (ice) | H22: 725 seats on the main pad (250 on each of three others) plus 1,000 standing room | I22: Not published | J22: None found | K22: City of Kingston | L22: Arena already proven for winter MMA (BTC held two March cards), in a 132k city. Good for a November show, but the 2.5 h+ drive and a thin known amateur MMA gym base are the drawbacks. | M22: Kingston Frontenacs (OHL) home games (Sept-March; e.g., Nov 27, 2026, Jan 2/13/15/30 and Feb 26, 2027); Spirit of Winter festival (downtown) (February; began Feb 1, 2026); Kingston Fall Fair (Memorial Centre… | N22: https://www.visitkingston.ca/media/documents/sports/Sport-Facilities-Guide.pdf
A23: 19 | B23: Oshawa | C23: ~2 h 29 min | D23: General Sikorski Hall | E23: Hall | F23: 2.6 | G23: Yes | H23: 565 max (Grand Ballroom 500), so under 1,000 | I23: Not published | J23: BTC 31: Invictus, Aug 9, 2025 | K23: 289-356-6399 | L23: Biggest market within 2.5 h and a winter-capable arena that scales down to 1,000, but crowded: BTC ran there in 2024 and 2025, PFC wants back in, and pro boxing runs in Pickering. TCC's renovation starts in 2027. | M23: Oshawa Generals (OHL) and Oshawa FireWolves (NLL) home dates at TCC (Generals Sept-March; FireWolves home opener Nov 27, 2026, season into spring); Oshawa Peony Festival (next to Children's Arena, 155 Arena St) (Early… | N23: https://www.eventective.com/oshawa-on/general-sikorski-hall-596553.html
A24: 20 | B24: Niagara Falls | C24: OVER 3 H: ~4 h 29 min | D24: Niagara Falls Convention Centre | E24: Event Centre | F24: 2.8 | G24: Yes | H24: Exhibit Hall A 2,142 theatre; Exhibit Hall ABC 6,400 theatre; Peller Estates Ballroom 1,722 theatre. No boxing configuration published. | I24: Not published | J24: Pro boxing: Lucas Bahdi bouts Jul 2, 2022, May 21, 2023 and Jun 1, 2024. Tarps Off Fight Club 'Brawl by the Falls' MMA, Dec 18, 2021, listed as 'ScotiaBank Convention… | K24: Niagara Falls Convention Centre sales (fallsconventions.com) | L24: Good venues and tourist traffic, but 4.5 h from Bancroft, outside Cody's 3 h limit, and already served by BTC, PFC and pro boxing. Not for 2027. | M24: Winter Festival of Lights (Mid-Nov to early Jan; Nov 14, 2026 to Jan 10, 2027) | N24: https://fallsconventions.com/plan/rooms-spaces
A25: 21 | B25: Niagara Falls | C25: OVER 3 H: ~4 h 29 min | D25: OLG Stage at Fallsview Casino | E25: Casino | F25: 2.6 | G25: Yes | H25: 5,000-seat theatre | I25: Not published | J25: None found (concerts and comedy) | K25: MGE Niagara Entertainment (Mohegan), operator for OLG | L25: Good venues and tourist traffic, but 4.5 h from Bancroft, outside Cody's 3 h limit, and already served by BTC, PFC and pro boxing. Not for 2027. | M25: Winter Festival of Lights (Mid-Nov to early Jan; Nov 14, 2026 to Jan 10, 2027) | N25: https://www.canadiangamingbusiness.com/2022/09/01/fallsview-olg-partner-up-on-new-casino-theatre/
A26: 22 | B26: Alliston (New Tecumseth) | C26: OVER 3 H: ~3 h 16 min | D26: Nottawasaga Inn Resort - Trade Centre | E26: Event Centre | F26: 2.6 | G26: Yes | H26: Trade Centre 20,358 sq ft: 1,000 theatre / 1,000 banquet | I26: Not published | J26: None found | K26: Nottawasaga Resort sales | L26: Over the 3 h limit, with no local fight gym found and only a 1,000-seat hotel hall. Not worth it in 2027. | M26: Alliston Potato Festival (Church Street Fairgrounds) (Early-mid August; Aug 8-10, 2025) | N26: https://www.successfulmeetings.com/Meeting-Event-Venues/Alliston-ON/Convention-Hotel/Nottawasaga-Inn-Resort-Conference-Ctr-p5578841
A27: 23 | B27: Alliston (New Tecumseth) | C27: OVER 3 H: ~3 h 16 min | D27: New Tecumseth Recreation Centre (main arena) | E27: Arena | F27: 2.4 | G27: No (ice) | H27: Main arena seats 750 (2021) | I27: Not published | J27: None found | K27: Town of New Tecumseth | L27: Over the 3 h limit, with no local fight gym found and only a 1,000-seat hotel hall. Not worth it in 2027. | M27: Alliston Potato Festival (Church Street Fairgrounds) (Early-mid August; Aug 8-10, 2025) | N27: https://newtectimes.com/new-tecumseth-recreation-centre-getting-a-new-roof/
A28: 24 | B28: Niagara Falls | C28: OVER 3 H: ~4 h 29 min | D28: Americana Resort (Grande Ballroom) | E28: Event Centre | F28: 2.2 | G28: Yes | H28: Grande Ballroom 750 theatre / 625 banquet, so under 1,000 | I28: Not published | J28: BTC 32: The Battle of Lundy's Lane (pro-am MMA), Sept 13, 2025 | K28: Americana Resort sales | L28: Good venues and tourist traffic, but 4.5 h from Bancroft, outside Cody's 3 h limit, and already served by BTC, PFC and pro boxing. Not for 2027. | M28: Winter Festival of Lights (Mid-Nov to early Jan; Nov 14, 2026 to Jan 10, 2027) | N28: https://www.meetings-conventions.com/Meeting-Event-Venues/Niagara-Falls-ON/Convention-Hotel/Americana-Resort-Spa-Waterpark-p2357166
B30: OTHER PROMOTIONS RUNNING IN THESE MARKETS
B31: Promotion | D31: Where | F31: How often
B32: BTC Fight Promotions (Burlington; owner Irene Starr; pro-am MMA since amateur MMA was legalized on Jan 1, 2025) | D32: Kingston, Oshawa, Belleville, Niagara Falls, Burlington, London | F32: About 5-7 cards a year (estimate from numbering: BTC 25 in Sept 2024 to BTC 37 in June 2026). Moves around Ontario and has already worked Kingston and Oshawa.
B33: Prospect Fighting Championships (PFC; London-based; founder Jamie Champion; pro and amateur; OAC-sanctioned) | D33: London, Sarnia, Niagara-on-the-Lake, Caledonia; Oshawa planned | F33: Six events in 2026, about one every 1-2 months. Organizer said it plans to return to Oshawa in November.
B34: Official Fight Federation (OFF; 'presented by Gary Goodridge') | D34: Barrie / Simcoe County | F34: One event found; no follow-up found
