Workbook

Sheet Start Here
A1: CCCL FIGHT NIGHT KIT
A2: Everything to run a Cottage Country Combat League show: fighters, the bout card, the countdown, the night itself and the report after. Built for Cody Purtell by Kyle. Opens in Google Sheets or Excel.
B4: IN ORDER
A5: 1 | B5: Show Setup | C5: Show name, venue, date and times. Everything else follows these.
A6: 2 | B6: Countdown | C6: Every job from booking the venue to the Commission report after, with due dates worked out from the show date.
A7: 3 | B7: Recruitment | C7: Gyms that could send fighters. Message the head coach through the gym and track who's sending fighters.
A8: 4 | B8: Fighters | C8: Everyone who applies. Works out each fighter's experience class. 'Ready to fight?' turns green once the medical, signed forms, waiver, and parent consent and concussion confirmation where needed are done.
A9: 5 | B9: Bout Card | C9: Pick both corners. It checks the Ontario weight-gap table, experience classes, age divisions and paperwork. Cody and the officials decide.
A10: 6 | B10: Volunteers | C10: Every fight-night role, how many people, who's doing it.
A11: 7 | B11: Production | C11: Cage, lights, sound, livestream, supplies: booked and confirmed.
A12: 8 | B12: Run of Show | C12: The night minute by minute, built from Show Setup and the Bout Card. Print it.
A13: 9 | B13: Press | C13: Media list with each outlet's own way to send news. Three releases per show.
A14: 10 | B14: Results & Report | C14: Real numbers vs the Predictor, the fight results and what to change. Feeds the next forecast.
A15: 11 | B15: Rules | C15: Ontario rules that shape matchmaking and the night, with sources. Confirm with the Commission.
B17: GROUND RULES
B18: Who decides | C18: Cody and the officials decide every bout. The sheet only flags things to look at again. Results go in only once official.
B19: Medical | C19: Medical cleared: Yes, No or Pending. Never write a diagnosis, test result or injury in this sheet.
B20: Youth athletes | C20: First name and last initial only, a parent's consent first, and no photos or video without a parent's OK.
B21: Contact | C21: Reach fighters through their gym or coach. No personal phone numbers in the sheet.
B22: Colour key | C22: Yellow cells with blue text are yours to fill in. Black text is calculated. Green text is pulled from another tab.
B24: WORKS WITH
B25: Profit Predictor | C25: Budget numbers for the Results tab; real numbers go back into it after the show.
B26: Sponsorship Pipeline | C26: Sponsor banners, shirt logos and announcer reads by level (Fulfilment tab).
B27: Claude | C27: The cccl-fight-night skill drafts gym outreach, fighter packages, the announcer script, press releases and the post-show report from this sheet.

Sheet Show Setup
A1: SHOW SETUP
A2: Fill this in first. Every other tab uses these answers: the countdown dates, the run of show times and the bout checks.
A4: THE SHOW
A5: Show name | B5: CCCL 2 | D5: Whatever goes on the poster.
A6: Town | D6: Fill in once the show is booked (no 2027 show is booked yet).
A7: Venue
A8: Show date | D8: Fill in once the show is booked: the Countdown and Run of Show follow it. Until then they stay blank.
A9: Load-in and cage build start (show day) | B9: 0.41666667 | D9: The cage has to sit on a platform 3-4 ft off the floor (Ontario rule).
A10: Weigh-ins start (show day) | B10: 0.67708333 | D10: Ontario rule: on the day, within 3 hours of the first bout. No day-before weigh-ins.
A11: Doors open | B11: 0.75
A12: First bout | B12: 0.79166667
A13: Weigh-in timing check | B13: =IF(AND('Show Setup'!$B$12-'Show Setup'!$B$10<=3/24+0.00001,'Show Setup'!$B$12>'Show Setup'!$B$10),"OK","TOO EARLY: within 3 hours of the first bout") -> OK
A15: BOUT TIMING (for the Run of Show)
A16: Minutes per amateur MMA bout (walkouts, rounds, breaks, decision) | B16: 20 | D16: ESTIMATE. Senior bouts are 3 x 3-minute rounds with 1-minute breaks; youth bouts are shorter.
A17: Minutes per grappling match | B17: 10 | D17: ESTIMATE.
A18: Intermission after bout number | B18: 5 | D18: Sponsor reads and the merch push happen here.
A19: Intermission length (minutes) | B19: 20
A21: MATCHMAKING CHECKS (flags only: Cody and the officials decide every bout)
A22: Amateur MMA weight gap | B22: Ontario table (built in) | D22: Max difference by weight: 4 lb under 148, 9 lb at 148-165, 11 lb at 165-200, 24 lb at 200-265, no limit over 265. See the Lists and Rules tabs.
A23: Grappling: flag a weight gap over (lb) | B23: 10 | D23: STARTING POINT. Use the grappling ruleset's weight classes for the age group (Rules tab).

Sheet Countdown
A1: SHOW COUNTDOWN
A2: Every job from booking the venue to the report after the show. Due dates follow the show date on Show Setup. Mark Done = Yes as things finish. A working list, not legal advice: confirm requirements with the Athletics Commission and the insurer.
A4: Weeks before (minus = days after) | B4: Task | C4: Area | D4: Owner | E4: Due | F4: Done? | G4: Status | H4: Notes
A5: 26 | B5: Pick town and date; check clashes (other combat shows, fairs, long weekends, big UFC cards) | C5: Venue | D5: Cody | E5: =IF('Show Setup'!$B$8="","",IF(A5>=0,'Show Setup'!$B$8-A5*7,'Show Setup'!$B$8-A5)) | G5: =IF(F5="Yes","DONE",IF(E5="","No date yet",IF(E5<TODAY(),"OVERDUE",IF(E5<=TODAY()+7,"This week","Upcoming")))) -> No date yet
A6: 26 | B6: Venue quote: rent for setup + show day, capacity, chairs/tables, staff, who runs the bar and CCCL's share | C6: Venue | D6: Cody | E6: =IF('Show Setup'!$B$8="","",IF(A6>=0,'Show Setup'!$B$8-A6*7,'Show Setup'!$B$8-A6)) | G6: =IF(F6="Yes","DONE",IF(E6="","No date yet",IF(E6<TODAY(),"OVERDUE",IF(E6<=TODAY()+7,"This week","Upcoming")))) -> No date yet
A7: 24 | B7: Run the Profit Predictor with the real quote; go / no-go | C7: Money | D7: Cody | E7: =IF('Show Setup'!$B$8="","",IF(A7>=0,'Show Setup'!$B$8-A7*7,'Show Setup'!$B$8-A7)) | G7: =IF(F7="Yes","DONE",IF(E7="","No date yet",IF(E7<TODAY(),"OVERDUE",IF(E7<=TODAY()+7,"This week","Upcoming")))) -> No date yet
A8: 22 | B8: Hold the date with a deposit; council approval if the venue needs it | C8: Venue | D8: Cody | E8: =IF('Show Setup'!$B$8="","",IF(A8>=0,'Show Setup'!$B$8-A8*7,'Show Setup'!$B$8-A8)) | G8: =IF(F8="Yes","DONE",IF(E8="","No date yet",IF(E8<TODAY(),"OVERDUE",IF(E8<=TODAY()+7,"This week","Upcoming")))) -> No date yet
A9: 20 | B9: Sponsor push starts: 2026 sponsors first (Sponsorship Pipeline) | C9: Sponsors | D9: Cody | E9: =IF('Show Setup'!$B$8="","",IF(A9>=0,'Show Setup'!$B$8-A9*7,'Show Setup'!$B$8-A9)) | G9: =IF(F9="Yes","DONE",IF(E9="","No date yet",IF(E9<TODAY(),"OVERDUE",IF(E9<=TODAY()+7,"This week","Upcoming")))) -> No date yet
A10: 18 | B10: Apply for the Athletics Commission event permit: $600 for one show (one permit should cover the whole card; confirm). At least 30 days ahead; 120 days for any rule change | C10: Commission | D10: Cody | E10: =IF('Show Setup'!$B$8="","",IF(A10>=0,'Show Setup'!$B$8-A10*7,'Show Setup'!$B$8-A10)) | G10: =IF(F10="Yes","DONE",IF(E10="","No date yet",IF(E10<TODAY(),"OVERDUE",IF(E10<=TODAY()+7,"This week","Upcoming")))) -> No date yet
A11: 18 | B11: Book officials for every bout: referee, 3 judges, timekeeper, scorekeeper, plus a neutral cut-person | C11: Commission | D11: Cody | E11: =IF('Show Setup'!$B$8="","",IF(A11>=0,'Show Setup'!$B$8-A11*7,'Show Setup'!$B$8-A11)) | G11: =IF(F11="Yes","DONE",IF(E11="","No date yet",IF(E11<TODAY(),"OVERDUE",IF(E11<=TODAY()+7,"This week","Upcoming")))) -> No date yet
A12: 18 | B12: Book the physician (Ontario-licensed, on site all night) and a second medical person. Ask the Commission if it wants an ambulance | C12: Medical | D12: Cody | E12: =IF('Show Setup'!$B$8="","",IF(A12>=0,'Show Setup'!$B$8-A12*7,'Show Setup'!$B$8-A12)) | G12: =IF(F12="Yes","DONE",IF(E12="","No date yet",IF(E12<TODAY(),"OVERDUE",IF(E12<=TODAY()+7,"This week","Upcoming")))) -> No date yet
A13: 16 | B13: $2M liability insurance certificate that also covers referees, judges, officials and the Commissioner | C13: Commission | D13: Cody | E13: =IF('Show Setup'!$B$8="","",IF(A13>=0,'Show Setup'!$B$8-A13*7,'Show Setup'!$B$8-A13)) | G13: =IF(F13="Yes","DONE",IF(E13="","No date yet",IF(E13<TODAY(),"OVERDUE",IF(E13<=TODAY()+7,"This week","Upcoming")))) -> No date yet
A14: 16 | B14: Book the cage on a platform raised 3-4 ft (Ontario rule) and delivery | C14: Production | D14: Cody | E14: =IF('Show Setup'!$B$8="","",IF(A14>=0,'Show Setup'!$B$8-A14*7,'Show Setup'!$B$8-A14)) | G14: =IF(F14="Yes","DONE",IF(E14="","No date yet",IF(E14<TODAY(),"OVERDUE",IF(E14<=TODAY()+7,"This week","Upcoming")))) -> No date yet
A15: 16 | B15: Youth grappling: confirm it's covered by the CCCL permit or sanctioned by the Ontario Grappling Association | C15: Commission | D15: Cody | E15: =IF('Show Setup'!$B$8="","",IF(A15>=0,'Show Setup'!$B$8-A15*7,'Show Setup'!$B$8-A15)) | G15: =IF(F15="Yes","DONE",IF(E15="","No date yet",IF(E15<TODAY(),"OVERDUE",IF(E15<=TODAY()+7,"This week","Upcoming")))) -> No date yet
A16: 14 | B16: Tickets on sale on Eventbrite (GA, VIP seats, VIP tables) | C16: Tickets | D16: Kyle | E16: =IF('Show Setup'!$B$8="","",IF(A16>=0,'Show Setup'!$B$8-A16*7,'Show Setup'!$B$8-A16)) | G16: =IF(F16="Yes","DONE",IF(E16="","No date yet",IF(E16<TODAY(),"OVERDUE",IF(E16<=TODAY()+7,"This week","Upcoming")))) -> No date yet
... A43: -14 | B43: Post-event report to the Commission within 14 days: contestants, bouts, injuries without names, officials | C43: Commission | D43: Cody | E43: =IF('Show Setup'!$B$8="","",IF(A43>=0,'Show Setup'!$B$8-A43*7,'Show Setup'!$B$8-A43)) | G43: =IF(F43="Yes","DONE",IF(E43="","No date yet",IF(E43<TODAY(),"OVERDUE",IF(E43<=TODAY()+7,"This week","Upcoming")))) -> No date yet
E44: =IF(OR(B44="",'Show Setup'!$B$8=""),"",IF(A44>=0,'Show Setup'!$B$8-A44*7,'Show Setup'!$B$8-A44)) | G44: =IF(B44="","",IF(F44="Yes","DONE",IF(E44="","No date yet",IF(E44<TODAY(),"OVERDUE",IF(E44<=TODAY()+7,"This week","Upcoming")))))
E45: =IF(OR(B45="",'Show Setup'!$B$8=""),"",IF(A45>=0,'Show Setup'!$B$8-A45*7,'Show Setup'!$B$8-A45)) | G45: =IF(B45="","",IF(F45="Yes","DONE",IF(E45="","No date yet",IF(E45<TODAY(),"OVERDUE",IF(E45<=TODAY()+7,"This week","Upcoming")))))
E46: =IF(OR(B46="",'Show Setup'!$B$8=""),"",IF(A46>=0,'Show Setup'!$B$8-A46*7,'Show Setup'!$B$8-A46)) | G46: =IF(B46="","",IF(F46="Yes","DONE",IF(E46="","No date yet",IF(E46<TODAY(),"OVERDUE",IF(E46<=TODAY()+7,"This week","Upcoming")))))
E47: =IF(OR(B47="",'Show Setup'!$B$8=""),"",IF(A47>=0,'Show Setup'!$B$8-A47*7,'Show Setup'!$B$8-A47)) | G47: =IF(B47="","",IF(F47="Yes","DONE",IF(E47="","No date yet",IF(E47<TODAY(),"OVERDUE",IF(E47<=TODAY()+7,"This week","Upcoming")))))
E48: =IF(OR(B48="",'Show Setup'!$B$8=""),"",IF(A48>=0,'Show Setup'!$B$8-A48*7,'Show Setup'!$B$8-A48)) | G48: =IF(B48="","",IF(F48="Yes","DONE",IF(E48="","No date yet",IF(E48<TODAY(),"OVERDUE",IF(E48<=TODAY()+7,"This week","Upcoming")))))
E49: =IF(OR(B49="",'Show Setup'!$B$8=""),"",IF(A49>=0,'Show Setup'!$B$8-A49*7,'Show Setup'!$B$8-A49)) | G49: =IF(B49="","",IF(F49="Yes","DONE",IF(E49="","No date yet",IF(E49<TODAY(),"OVERDUE",IF(E49<=TODAY()+7,"This week","Upcoming")))))
E50: =IF(OR(B50="",'Show Setup'!$B$8=""),"",IF(A50>=0,'Show Setup'!$B$8-A50*7,'Show Setup'!$B$8-A50)) | G50: =IF(B50="","",IF(F50="Yes","DONE",IF(E50="","No date yet",IF(E50<TODAY(),"OVERDUE",IF(E50<=TODAY()+7,"This week","Upcoming")))))
E51: =IF(OR(B51="",'Show Setup'!$B$8=""),"",IF(A51>=0,'Show Setup'!$B$8-A51*7,'Show Setup'!$B$8-A51)) | G51: =IF(B51="","",IF(F51="Yes","DONE",IF(E51="","No date yet",IF(E51<TODAY(),"OVERDUE",IF(E51<=TODAY()+7,"This week","Upcoming")))))
E52: =IF(OR(B52="",'Show Setup'!$B$8=""),"",IF(A52>=0,'Show Setup'!$B$8-A52*7,'Show Setup'!$B$8-A52)) | G52: =IF(B52="","",IF(F52="Yes","DONE",IF(E52="","No date yet",IF(E52<TODAY(),"OVERDUE",IF(E52<=TODAY()+7,"This week","Upcoming")))))
E53: =IF(OR(B53="",'Show Setup'!$B$8=""),"",IF(A53>=0,'Show Setup'!$B$8-A53*7,'Show Setup'!$B$8-A53)) | G53: =IF(B53="","",IF(F53="Yes","DONE",IF(E53="","No date yet",IF(E53<TODAY(),"OVERDUE",IF(E53<=TODAY()+7,"This week","Upcoming")))))
E54: =IF(OR(B54="",'Show Setup'!$B$8=""),"",IF(A54>=0,'Show Setup'!$B$8-A54*7,'Show Setup'!$B$8-A54)) | G54: =IF(B54="","",IF(F54="Yes","DONE",IF(E54="","No date yet",IF(E54<TODAY(),"OVERDUE",IF(E54<=TODAY()+7,"This week","Upcoming")))))
E55: =IF(OR(B55="",'Show Setup'!$B$8=""),"",IF(A55>=0,'Show Setup'!$B$8-A55*7,'Show Setup'!$B$8-A55)) | G55: =IF(B55="","",IF(F55="Yes","DONE",IF(E55="","No date yet",IF(E55<TODAY(),"OVERDUE",IF(E55<=TODAY()+7,"This week","Upcoming")))))
... E58: =IF(OR(B58="",'Show Setup'!$B$8=""),"",IF(A58>=0,'Show Setup'!$B$8-A58*7,'Show Setup'!$B$8-A58)) | G58: =IF(B58="","",IF(F58="Yes","DONE",IF(E58="","No date yet",IF(E58<TODAY(),"OVERDUE",IF(E58<=TODAY()+7,"This week","Upcoming")))))

Sheet Recruitment
A1: FIGHTER RECRUITMENT: GYMS
A2: Gyms that could send amateur fighters. Contact the head coach through the gym, never the athletes directly. Track who's been asked and how many fighters they can send.
A4: Gym | B4: Town | C4: Disciplines | D4: Competition team? | E4: Contact (public) | F4: Website | G4: Stage | H4: Fighters offered | I4: Last contact | J4: Next follow-up | K4: Follow-up due? | L4: Notes | M4: Source
A5: Big Country MMA - Lindsay | B5: Lindsay (~1h50 drive) | C5: MMA, BJJ (gi/no-gi), Muay Thai, kickboxing, boxing, wrestling | D5: yes | E5: bigcountrymma1@gmail.com; 705-344-2662; 50 Mary St W, Lindsay | F5: https://bigcountrylindsay.gymdesk.com/ | G5: Not contacted | K5: =IF(OR(A5="",J5="",G5="Sending fighters",G5="Not this time"),"",IF(J5<=TODAY(),"DUE","")) | L5: The best partner gym: it already sends several fighters per card. Head coach Joe Elliott (BJJ black, Muay Thai red) teaches across all three Big Country locations. Competition: Sherdog: Jake Parsons (CCCL 1 main-event winner) and Levi Oram, both Lindsay / Big Country MMA. The CCCL 1 winner Cooper Elliott shares his name with a coach on the instructor list (not confirmed as the same person). The Highlander said Big Country's amateur champion would fight on CCCL 1. Pros: James Clarke (12-4, BTC 26 winner) and Blake Oswald. | M5: https://bigcountrylindsay.gymdesk.com/page/home
A6: Grizzly Gym | B6: Kingston (~2h30 drive) | C6: MMA, BJJ, Muay Thai, Kung Fu, Sanda/SAW, Tai Chi | D6: yes | E6: mike@grizzlygym.com (decoded from its site); 613-483-7522; 541 Days Rd, Kingston | F6: https://www.grizzlygym.com/ | G6: Not contacted | K6: =IF(OR(A6="",J6="",G6="Sending fighters",G6="Not this time"),"",IF(J6<=TODAY(),"DUE","")) | L6: Has already sent a fighter to CCCL. Strong partner for a Kingston show. Competition: Sherdog: Joshua Henshaw (Kingston, Grizzly Gym) fought at CCCL 1 (May 2026), BTC 34 (Nov 2025), PFC 20 (Oct 2025) and Rising Stars (Aug 2025). The head instructor has 'competed more than 250 times'. | M6: https://www.sherdog.com/fighter/Joshua-Henshaw-355453
A7: van Jango Studio of Martial Arts | B7: Kingston (~2h30 drive) | C7: BJJ, Muay Thai, MMA, striking & conditioning | D7: yes | E7: manager@vanjango.com; 343-333-8433; 629 Division St (lower level), Kingston | F7: https://www.vanjango.com/ | G7: Not contacted | K7: =IF(OR(A7="",J7="",G7="Sending fighters",G7="Not this time"),"",IF(J7<=TODAY(),"DUE","")) | L7: Competition: Sherdog: Jesse Van Vlack (Kingston, 'Van Jango MMA') has 8 amateur MMA bouts (2024-2026), including PFC 25 (win), Cage Wars 73/76, VCFC 39 and Fightquest 57. Striking coach Daniel Goel is an amateur Muay Thai fighter. | M7: https://www.sherdog.com/fighter/Jesse-Van-Vlack-464451
A8: Oshawa BJJ & Fitness | B8: Oshawa (~2h40 drive) | C8: BJJ gi/no-gi, Muay Thai, women's kickboxing, kids wrestling, conditioning | D8: yes | E8: mocaiberbjj@gmail.com; 289-980-0484; 350 Wentworth St E Unit 4-5, Oshawa (waiver lists 1160 Simcoe St S) | F8: https://oshawabjj.com/ | G8: Not contacted | K8: =IF(OR(A8="",J8="",G8="Sending fighters",G8="Not this time"),"",IF(J8<=TODAY(),"DUE","")) | L8: Good source of youth grapplers. A BBG 12-year-old won gold at the Durham Classic BJJ event in Oshawa (Feb 2026). Competition: Schedule includes 'KIDS COMPETITION' and 'WOMEN'S COMPETITION' classes, led by 'two multiple time world champions' (Igor Mocaiber, 3rd-degree black belt). | M8: https://oshawabjj.com/
A9: Evolution Jiu Jitsu (Petawawa) | B9: Petawawa (~1h50-2h drive) | C9: BJJ, Muay Thai (adult and youth), women's BJJ | D9: yes | E9: evolutionbjjpetawawa@hotmail.com; 613-687-2833; Army Fitness Centre, 3 Festubert Blvd Bldg Q-103, Petawawa | G9: Not contacted | K9: =IF(OR(A9="",J9="",G9="Sending fighters",G9="Not this time"),"",IF(J9<=TODAY(),"DUE","")) | L9: On CFB Petawawa, with a military athlete pool. About as close to Bancroft as Peterborough, via Barry's Bay. Competition: The base club page says the team 'participates in numerous provincial, national and international level competitions'. | M9: https://cfmws.ca/petawawa/evolution-jiu-jitsu-club
A10: Corcoran's Boxing Club & Fitness Centre (BEL Boxing Club listed at same address) | B10: Peterborough / Selwyn Twp (~1h45 drive) | C10: Olympic-style amateur boxing, youth programs, fitness | D10: yes | E10: corcoranboxing@gmail.com; 705-872-1086 / 705-957-1142; 1625 Chemong Rd. BEL Boxing Club (same address): belboxing@gmail.com, 705-768-0340 (from its kawarthaNOW listing) | F10: https://corcoransboxingandfitness.com | G10: Not contacted | K10: =IF(OR(A10="",J10="",G10="Sending fighters",G10="Not this time"),"",IF(J10<=TODAY(),"DUE","")) | L10: Boxing only, no MMA, but it runs its own amateur boxing shows. Check whether BEL Boxing is the same club rebranded. Competition: Ran a 12-bout Ontario Boxing-sanctioned amateur card, 'War in Ennismore: Revival' (Aug 2022), as a fundraiser for its youth program and competitive team. | M10: https://corcoransboxingandfitness.com
A11: Kawartha Wrestling Club | B11: Peterborough (~1h45 drive) | C11: Amateur wrestling (OAWA member club) | D11: yes | E11: Club contact on the OAWA club listing (https://www.oawa.ca/oawa-club-listing); the listed email is a personal address, so it isn't copied here | G11: Not contacted | K11: =IF(OR(A11="",J11="",G11="Sending fighters",G11="Not this time"),"",IF(J11<=TODAY(),"DUE","")) | L11: Wrestlers transitioning to MMA are good novice-card prospects. Competition: OAWA-registered competitive wrestling club. | M11: https://www.oawa.ca/oawa-club-listing
A12: Kingston Wrestling Club | B12: Kingston (~2h30 drive) | C12: Amateur wrestling (OAWA member club) | D12: yes | E12: Marcus Niemann: kingstonwrestling@hotmail.com (OAWA club listing) | G12: Not contacted | K12: =IF(OR(A12="",J12="",G12="Sending fighters",G12="Not this time"),"",IF(J12<=TODAY(),"DUE","")) | L12: Competition: OAWA-registered competitive club. | M12: https://www.oawa.ca/oawa-club-listing
A13: Kingston Combat Wrestling Club | B13: Kingston (~2h30 drive) | C13: Amateur wrestling (OAWA member club) | D13: yes | E13: Club contact on the OAWA club listing (https://www.oawa.ca/oawa-club-listing); the listed email is a personal address, so it isn't copied here | G13: Not contacted | K13: =IF(OR(A13="",J13="",G13="Sending fighters",G13="Not this time"),"",IF(J13<=TODAY(),"DUE","")) | L13: Competition: OAWA-registered competitive club. | M13: https://www.oawa.ca/oawa-club-listing
A14: Mariposa Wrestling Club | B14: Orillia (~2h15-2h30 drive) | C14: Amateur wrestling (OAWA member club) | D14: yes | E14: Club contact on the OAWA club listing (https://www.oawa.ca/oawa-club-listing); the listed email is a personal address, so it isn't copied here | G14: Not contacted | K14: =IF(OR(A14="",J14="",G14="Sending fighters",G14="Not this time"),"",IF(J14<=TODAY(),"DUE","")) | L14: Competition: OAWA-registered competitive club. | M14: https://www.oawa.ca/oawa-club-listing
A15: Ottawa Valley Boxing | B15: Petawawa (~1h50-2h drive) | C15: Boxing: competitive, recreational, women's and kids | D15: yes | E15: Nshangraw@ottawavalleysports.com; 1959 Petawawa Blvd Unit 3 (per a Town of Petawawa story) | F15: https://ottawavalleyboxing.com/ | G15: Not contacted | K15: =IF(OR(A15="",J15="",G15="Sending fighters",G15="Not this time"),"",IF(J15<=TODAY(),"DUE","")) | L15: Boxing only. Competition: 'REGISTERED COMPETITION CLUB WITH BOXING ONTARIO'; offers a Competitive Fighters program for ages 12+. | M15: https://ottawavalleyboxing.com/
A16: Pinnacle Wrestling Club | B16: Petawawa (~1h50-2h drive) | C16: Amateur wrestling (OAWA member club) | D16: yes | E16: Nigel Yantha: pinnaclewrestling2025@gmail.com (OAWA club listing) | G16: Not contacted | K16: =IF(OR(A16="",J16="",G16="Sending fighters",G16="Not this time"),"",IF(J16<=TODAY(),"DUE","")) | L16: Competition: OAWA-registered competitive club. | M16: https://www.oawa.ca/oawa-club-listing
A17: Pinnacle Boxing Academy | B17: Belleville (~1h45 drive) | C17: Amateur boxing | D17: yes | E17: No official contact found. Ask Boxing Ontario or check the club's social pages. | G17: Not contacted | K17: =IF(OR(A17="",J17="",G17="Sending fighters",G17="Not this time"),"",IF(J17<=TODAY(),"DUE","")) | L17: Boxing only. Runs its own boxing club shows. Competition: Hosted the Boxing Ontario 'Friday Night Fights' club show (Sept 12 2025); its boxers won provincial medals (inQuinte, Oct 2025). Low confidence: check the contact first. | M17: https://www.inquinte.ca/2025/10/local-boxers-fight-their-way-to-medals-at-provincial-championships/
A18: Big Country - Orillia | B18: Orillia (~2h15-2h30 drive) | C18: BJJ, Muay Thai, kickboxing, boxing, judo, MMA (adult MMA class) | D18: unknown | E18: orilliabigcountry@gmail.com; 27 West St S, Orillia | F18: https://bigcountryorillia.gymdesk.com | G18: Not contacted | K18: =IF(OR(A18="",J18="",G18="Sending fighters",G18="Not this time"),"",IF(J18<=TODAY(),"DUE","")) | L18: Competition: Part of the Big Country network (Joe Elliott teaches the MMA class). It runs in-house BJJ competitions, but its site names no MMA fight team. | M18: https://bigcountryorillia.gymdesk.com
A19: Big Country - Muskoka | B19: Bracebridge (~1h50-2h drive) | C19: BJJ (incl. no-gi), Muay Thai, kickboxing, boxing | D19: unknown | E19: bigcountrymuskoka@gmail.com; 705-706-1631; 75 Manitoba St, Bracebridge | F19: https://bigcountrymuskoka.gymdesk.com/ | G19: Not contacted | K19: =IF(OR(A19="",J19="",G19="Sending fighters",G19="Not this time"),"",IF(J19<=TODAY(),"DUE","")) | L19: Competition: Same Big Country coaching group, but its site lists no MMA class or fight team. | M19: https://bigcountrymuskoka.gymdesk.com/
A20: The Chop Shop MMA | B20: Haliburton (~1h drive) | C20: BJJ, fitness kickboxing, kids programs (head coach also trains Muay Thai) | D20: unknown | E20: 705-854-3773; 175 Industrial Park Rd Unit A, Haliburton; Facebook /TheChopShopHaliburton; Instagram @thechopshophaliburton | F20: https://www.thechopshop.ca/ | G20: Not contacted | K20: =IF(OR(A20="",J20="",G20="Sending fighters",G20="Not this time"),"",IF(J20<=TODAY(),"DUE","")) | L20: Closest gym to CCCL's Haliburton venue. Good for youth grappling bouts and as a local co-host. Competition: New gym, opened May 30 2026. The owners (Chris and Janet Wellstood) ran Hayabusa Academy in Kingston for over 10 years; Chris has produced six black belts and Janet won silver at the 2018 World Master Jiu-Jitsu Championships. There is no fight team yet; they're likely to supply youth/BJJ grapplers before MMA fighters. | M20: https://www.thechopshop.ca/
A21: Kawartha Combat | B21: Peterborough (~1h45 drive) | C21: Muay Thai, kickboxing (incl. ladies and junior), BJJ, private coaching | D21: unknown | E21: kawarthacombat@live.com (on its own site); 705-868-1119 (directory listing); 910 High St Unit 15 | F21: https://www.kawarthacombat.com/ | G21: Not contacted | K21: =IF(OR(A21="",J21="",G21="Sending fighters",G21="Not this time"),"",IF(J21<=TODAY(),"DUE","")) | L21: Competition: Its site names no fight team. Head coach is Kevin Henry (named in a testimonial). A 2017 Examiner headline, 'Larger venue for Muay Thai', suggests it has hosted Muay Thai events. | M21: https://www.kawarthacombat.com/
A22: Eris Martial Arts / 10th Planet Jiu Jitsu Peterborough | B22: Peterborough (~1h45 drive) | C22: BJJ gi and no-gi (10th Planet), Muay Thai, competition training | D22: unknown | E22: info@erismartialarts.com; 705-768-1514; 306 George St N, Peterborough | F22: http://erismartialarts.com/ | G22: Not contacted | K22: =IF(OR(A22="",J22="",G22="Sending fighters",G22="Not this time"),"",IF(J22<=TODAY(),"DUE","")) | L22: The 10th Planet listing gives an older address (910 High St Unit 15). Use the George St N address from Eris's own site. Competition: Its site says it is 'helping build strong competitors for the growing sport of BJJ' and offers 'sport grappling, and competition training'. The 10th Planet instructor has MMA coaching experience (Eris / New World MMA). | M22: http://erismartialarts.com/
A23: Nomad Martial Arts & Fitness | B23: Kingston (~2h30 drive) | C23: No-gi BJJ, wrestling, kickboxing & MMA, strength & conditioning | D23: unknown | E23: alimo@nomadma.net; 613-519-2588; The Bunker, 1300 Bath Rd, Kingston | F23: https://nomadma.net/ | G23: Not contacted | K23: =IF(OR(A23="",J23="",G23="Sending fighters",G23="Not this time"),"",IF(J23<=TODAY(),"DUE","")) | L23: Competition: Lists 'Kickboxing & MMA' and wrestling programs; head coach Ali is a BJJ black belt. No fight team named. | M23: https://nomadma.net/
A24: Infinite Martial Arts & Fitness | B24: Belleville (~1h45 drive) | C24: BJJ, Muay Thai, boxing (amateur boxing program), wrestling, women's kickboxing, kids Muay Thai/boxing, powerlifting | D24: unknown | E24: Info@Infinite-MMA.com; (613) 969-7653; 315 Bell Blvd, Belleville | F24: https://infinite-mma.com/ | G24: Not contacted | K24: =IF(OR(A24="",J24="",G24="Sending fighters",G24="Not this time"),"",IF(J24<=TODAY(),"DUE","")) | L24: The best MMA-style gym found in the Quinte area. Contact it for any Marmora or Madoc show. Competition: Its site pitches its 'Muay Thai, Grappling & Boxing programs' to people interested in MMA and runs 'a complete amateur boxing program'. Coach records include Nolan Brant ('12 MMA battles'), Jace Rennie-Millar ('4 fights') and Mario Gibbs (Muay Thai/K1). No named fight team. | M24: https://infinite-mma.com/
A25: Limitless Martial Arts Trenton | B25: Trenton (Quinte West) (~2h drive) | C25: BJJ, Muay Thai kickboxing, wrestling, MMA grappling, women's kickboxing, kids | D25: unknown | E25: limitlessbjjtrenton@gmail.com; (613) 827-7401 / 613-955-0343; 99 Dufferin Ave, Trenton | F25: https://www.limitlessbjjtrenton.com/ | G25: Not contacted | K25: =IF(OR(A25="",J25="",G25="Sending fighters",G25="Not this time"),"",IF(J25<=TODAY(),"DUE","")) | L25: Competition: Head coach Jordan Preisinger is described as an 'MMA champion'; the Muay Thai and wrestling coach has a pro MMA background. The site advertises 'Highly decorated competitors'. | M25: https://www.limitlessbjjtrenton.com/
A26: Mamute Martial Arts | B26: Oshawa (~2h40 drive) | C26: MMA, BJJ, Muay Thai, boxing, kids wrestling, strength & conditioning | D26: unknown | E26: info@mamutemaa.com; (647) 648-1662; 907 Simcoe St N, Oshawa | F26: https://mamutemaa.com/ | G26: Not contacted | K26: =IF(OR(A26="",J26="",G26="Sending fighters",G26="Not this time"),"",IF(J26<=TODAY(),"DUE","")) | L26: Competition: Offers a dedicated MMA program. The head instructor coaches MMA, Muay Thai, wrestling, boxing and BJJ (a reviewer says he is an ex-pro MMA fighter). There is an 'Achievements' page, but no team is named. | M26: https://mamutemaa.com/
A27: Legacy Fight Club | B27: Barrie (~2h45 drive) | C27: Muay Thai, BJJ gi/no-gi, MMA, wrestling, boxing | D27: unknown | E27: teamlegacy.assistance@gmail.com; text (249) 501-9937; 351 King St Unit 7, Barrie | F27: https://www.legacyfightclub.com/ | G27: Not contacted | K27: =IF(OR(A27="",J27="",G27="Sending fighters",G27="Not this time"),"",IF(J27<=TODAY(),"DUE","")) | L27: At the edge of the 3 h radius. Barrie has its own shows (MM-Eh lists 'Fight Night Barrie', Nov 20 2026). Competition: Its curriculum runs 'through to competitive athletes', and a member is preparing for a debut fight in Thailand. No named fight team. | M27: https://www.legacyfightclub.com/
A28: World Championship Martial Arts | B28: Peterborough (~1h45 drive) | C28: Muay Thai kickboxing, BJJ, MMA, karate, youth kickboxing | D28: unknown | E28: 705-304-9084; 'Email Us' link on its site (address masked); 871 Chemong Rd Unit 6 & 7 (Brookdale Plaza) | F28: https://worldchampionship.ca/ | G28: Not contacted | K28: =IF(OR(A28="",J28="",G28="Sending fighters",G28="Not this time"),"",IF(J28<=TODAY(),"DUE","")) | L28: Competition: Its site lists MMA and youth BJJ/kickboxing but names no fight team. | M28: https://worldchampionship.ca/
A29: Hayabusa Academy | B29: Kingston (~2h30 drive) | C29: BJJ, Muay Thai, fitness kickboxing, kids (billed as 'Mixed Martial Arts & Fitness') | D29: unknown | E29: info@Hayabusa-Academy.com; 613-484-5455; 677 Innovation Dr Unit 7, Kingston | F29: https://www.hayabusa-academy.com/ | G29: Not contacted | K29: =IF(OR(A29="",J29="",G29="Sending fighters",G29="Not this time"),"",IF(J29<=TODAY(),"DUE","")) | L29: Confirm the current owners and whether it is still operating. The Chop Shop's owners can introduce you. Competition: Was a 370-member gym that GSP trained at a few times (per The Highlander). Its founders moved to Haliburton in 2026, but the site still advertises a 2026 kids camp. No fight team is named. | M29: https://www.hayabusa-academy.com/
... A33: Surge MMA | B33: Orléans (Ottawa) (~3h drive) | C33: BJJ, Muay Thai & boxing, kids MMA, women's grappling | D33: unknown | E33: SMS (343) 600-3066; email masked on site; 180 Vanguard Dr, Orléans | F33: https://www.surgemma.com/ | G33: Not contacted | K33: =IF(OR(A33="",J33="",G33="Sending fighters",G33="Not this time"),"",IF(J33<=TODAY(),"DUE","")) | L33: RUNS ITS OWN PROMOTION: - organizer of 'Next Wave Combat' (amateur MMA and Muay Thai in a cage, Lois Kemp Arena, Ottawa, Aug 1 2026). A competing promoter on the eastern edge of the range. Possible fighter-exchange partner, but expect it to prioritise its own cards. Competition: Its site lists 'Upcoming Competitions' under Events but names no fight team. | M33: https://www.eventbrite.ca/e/next-wave-combat-tickets-1990798629291
A34: Eastside Boxing & Wellness | B34: Peterborough (~1h45 drive) | C34: Boxing, wellness/fitness, youth boxing | D34: unknown | E34: 311 George St N, Peterborough (no public email or phone found) | G34: Not contacted | K34: =IF(OR(A34="",J34="",G34="Sending fighters",G34="Not this time"),"",IF(J34<=TODAY(),"DUE","")) | L34: Boxing only. Low value as a source of MMA fighters. Competition: Boxing Ontario says the club 'carries on the legacy of the Peterborough Boxing Club' (founded 1977) and has hosted provincial championships. It opened in its current form in Nov 2024, with a grand opening in Jul 2026; owner and head coach is Marsha Gaulton. Low confidence: check the contact first. | M34: https://www.ptbotoday.ca/?p=102471
A35: TRACK2 Brazilian Jiu-Jitsu | B35: Kingston (~2h30 drive) | C35: BJJ | D35: unknown | E35: hello@track2.ca (Let's Roll directory, not confirmed on the gym's site); 559 Bagot St, Kingston | F35: https://track2.ca/ | G35: Not contacted | K35: =IF(OR(A35="",J35="",G35="Sending fighters",G35="Not this time"),"",IF(J35<=TODAY(),"DUE","")) | L35: Competition: No information found on its own site. Low confidence: check the contact first. | M35: https://letsroll.co/gym/track2-brazilian-jiu-jitsu-kingston-on
A36: Four-Eleven Brazilian Jiu Jitsu | B36: Whitby (~2h45 drive) | C36: BJJ (kids, teens, adults, women's) | D36: unknown | E36: info@fourelevenbjj.ca; 905-665-7998; 277 Michael Blvd Unit 6, Whitby (Let's Roll directory) | F36: https://fourelevenbjj.ca/ | G36: Not contacted | K36: =IF(OR(A36="",J36="",G36="Sending fighters",G36="Not this time"),"",IF(J36<=TODAY(),"DUE","")) | L36: Competition: No information found. Low confidence: check the contact first. | M36: https://letsroll.co/gym/four-eleven-brazilian-jiu-jitsu-whitby-on
A37: Team DNA BJJ | B37: Whitby (~2h45 drive) | C37: BJJ, no-gi | D37: unknown | E37: info@dnabjj.com; 416-988-6548; 2001 Thickson Rd S Unit 15, Whitby (Let's Roll directory) | F37: https://www.dnabjj.com/ | G37: Not contacted | K37: =IF(OR(A37="",J37="",G37="Sending fighters",G37="Not this time"),"",IF(J37<=TODAY(),"DUE","")) | L37: Competition: No information found. Low confidence: check the contact first. | M37: https://letsroll.co/gym/team-dna-bjj-whitby-on
A38: Empire Mixed Martial Arts & Fitness | B38: Barrie (~2h45 drive) | C38: Boxing, Muay Thai/kickboxing, BJJ | D38: unknown | E38: info@empiremma.ca; 705-728-8885; 100 Caplan Ave Unit 8, Barrie (Let's Roll directory) | F38: https://empiremma.ca/ | G38: Not contacted | K38: =IF(OR(A38="",J38="",G38="Sending fighters",G38="Not this time"),"",IF(J38<=TODAY(),"DUE","")) | L38: Competition: No information found. Low confidence: check the contact first. | M38: https://letsroll.co/gym/empire-mixed-martial-arts-fitness-barrie-on
K39: =IF(OR(A39="",J39="",G39="Sending fighters",G39="Not this time"),"",IF(J39<=TODAY(),"DUE",""))
K40: =IF(OR(A40="",J40="",G40="Sending fighters",G40="Not this time"),"",IF(J40<=TODAY(),"DUE",""))
K41: =IF(OR(A41="",J41="",G41="Sending fighters",G41="Not this time"),"",IF(J41<=TODAY(),"DUE",""))
K42: =IF(OR(A42="",J42="",G42="Sending fighters",G42="Not this time"),"",IF(J42<=TODAY(),"DUE",""))
K43: =IF(OR(A43="",J43="",G43="Sending fighters",G43="Not this time"),"",IF(J43<=TODAY(),"DUE",""))
K44: =IF(OR(A44="",J44="",G44="Sending fighters",G44="Not this time"),"",IF(J44<=TODAY(),"DUE",""))
...

Sheet Fighters
A1: FIGHTERS
A2: One row per fighter who applies. Medical: Yes/No only, never details. Under 18: first name and last initial, a parent's consent, and the parent signs the day-of forms. No personal phone numbers: contact fighters through their gym or coach. Anyone with pro fights or a prize worth $300+ isn't an amateur.
A4: Fighter (name on the card) | B4: Under 18? | C4: Gym / team | D4: Coach (first name) | E4: Contact via (gym email or page) | F4: Discipline | G4: Age division | H4: Fight weight (lb) | I4: MMA wins | J4: MMA losses | K4: Other amateur contests (any combat sport) | L4: Contests | M4: Experience class | N4: Grappling level | O4: Annual medical done | P4: Codes & rules declaration signed | Q4: CCCL waiver signed | R4: Parent consent (under 18) | S4: Concussion confirmation (Rowan's Law) | T4: Status | U4: Show | V4: Ready to fight? | W4: Notes
A5: (Example) Jordan Smith | B5: No | C5: Big Country Lindsay | D5: Mike | E5: Through the gym's page | F5: Amateur MMA | G5: Senior (19+) | H5: 154 | I5: 2 | J5: 1 | K5: 2 | L5: =IF(A5="","",N(I5)+N(J5)+N(K5)) -> 5 | M5: =IF(A5="","",IF(L5<=5,"Pre-Novice",IF(L5<=10,"Novice","Open"))) -> Pre-Novice | O5: Pending | P5: No | Q5: Yes | R5: N/A | S5: N/A | T5: Available | V5: =IF(A5="","",IF(((O5<>"Yes")+(P5<>"Yes")+(Q5<>"Yes")+AND(B5="Yes",R5<>"Yes")+AND(OR(B5="Yes",ISNUMBER(SEARCH("grappling",F5))),S5<>"Yes"))=0,"READY",((O5<>"Yes")+(P5<>"Yes")+(Q5<>"Yes")+AND(B5="Yes",R5<>"Yes")+AND(OR(B5="Yes",ISNUMBER(SEARCH("grappling",F5))),S5<>"Yes"))&" to do")) -> 2 to do | W5: Example row. Replace it with a real fighter.
L6: =IF(A6="","",N(I6)+N(J6)+N(K6)) | M6: =IF(A6="","",IF(L6<=5,"Pre-Novice",IF(L6<=10,"Novice","Open"))) | V6: =IF(A6="","",IF(((O6<>"Yes")+(P6<>"Yes")+(Q6<>"Yes")+AND(B6="Yes",R6<>"Yes")+AND(OR(B6="Yes",ISNUMBER(SEARCH("grappling",F6))),S6<>"Yes"))=0,"READY",((O6<>"Yes")+(P6<>"Yes")+(Q6<>"Yes")+AND(B6="Yes",R6<>"Yes")+AND(OR(B6="Yes",ISNUMBER(SEARCH("grappling",F6))),S6<>"Yes"))&" to do"))
L7: =IF(A7="","",N(I7)+N(J7)+N(K7)) | M7: =IF(A7="","",IF(L7<=5,"Pre-Novice",IF(L7<=10,"Novice","Open"))) | V7: =IF(A7="","",IF(((O7<>"Yes")+(P7<>"Yes")+(Q7<>"Yes")+AND(B7="Yes",R7<>"Yes")+AND(OR(B7="Yes",ISNUMBER(SEARCH("grappling",F7))),S7<>"Yes"))=0,"READY",((O7<>"Yes")+(P7<>"Yes")+(Q7<>"Yes")+AND(B7="Yes",R7<>"Yes")+AND(OR(B7="Yes",ISNUMBER(SEARCH("grappling",F7))),S7<>"Yes"))&" to do"))
L8: =IF(A8="","",N(I8)+N(J8)+N(K8)) | M8: =IF(A8="","",IF(L8<=5,"Pre-Novice",IF(L8<=10,"Novice","Open"))) | V8: =IF(A8="","",IF(((O8<>"Yes")+(P8<>"Yes")+(Q8<>"Yes")+AND(B8="Yes",R8<>"Yes")+AND(OR(B8="Yes",ISNUMBER(SEARCH("grappling",F8))),S8<>"Yes"))=0,"READY",((O8<>"Yes")+(P8<>"Yes")+(Q8<>"Yes")+AND(B8="Yes",R8<>"Yes")+AND(OR(B8="Yes",ISNUMBER(SEARCH("grappling",F8))),S8<>"Yes"))&" to do"))
L9: =IF(A9="","",N(I9)+N(J9)+N(K9)) | M9: =IF(A9="","",IF(L9<=5,"Pre-Novice",IF(L9<=10,"Novice","Open"))) | V9: =IF(A9="","",IF(((O9<>"Yes")+(P9<>"Yes")+(Q9<>"Yes")+AND(B9="Yes",R9<>"Yes")+AND(OR(B9="Yes",ISNUMBER(SEARCH("grappling",F9))),S9<>"Yes"))=0,"READY",((O9<>"Yes")+(P9<>"Yes")+(Q9<>"Yes")+AND(B9="Yes",R9<>"Yes")+AND(OR(B9="Yes",ISNUMBER(SEARCH("grappling",F9))),S9<>"Yes"))&" to do"))
L10: =IF(A10="","",N(I10)+N(J10)+N(K10)) | M10: =IF(A10="","",IF(L10<=5,"Pre-Novice",IF(L10<=10,"Novice","Open"))) | V10: =IF(A10="","",IF(((O10<>"Yes")+(P10<>"Yes")+(Q10<>"Yes")+AND(B10="Yes",R10<>"Yes")+AND(OR(B10="Yes",ISNUMBER(SEARCH("grappling",F10))),S10<>"Yes"))=0,"READY",((O10<>"Yes")+(P10<>"Yes")+(Q10<>"Yes")+AND(B10="Yes",R10<>"Yes")+AND(OR(B10="Yes",ISNUMBER(SEARCH("grappling",F10))),S10<>"Yes"))&" to do"))
L11: =IF(A11="","",N(I11)+N(J11)+N(K11)) | M11: =IF(A11="","",IF(L11<=5,"Pre-Novice",IF(L11<=10,"Novice","Open"))) | V11: =IF(A11="","",IF(((O11<>"Yes")+(P11<>"Yes")+(Q11<>"Yes")+AND(B11="Yes",R11<>"Yes")+AND(OR(B11="Yes",ISNUMBER(SEARCH("grappling",F11))),S11<>"Yes"))=0,"READY",((O11<>"Yes")+(P11<>"Yes")+(Q11<>"Yes")+AND(B11="Yes",R11<>"Yes")+AND(OR(B11="Yes",ISNUMBER(SEARCH("grappling",F11))),S11<>"Yes"))&" to do"))
L12: =IF(A12="","",N(I12)+N(J12)+N(K12)) | M12: =IF(A12="","",IF(L12<=5,"Pre-Novice",IF(L12<=10,"Novice","Open"))) | V12: =IF(A12="","",IF(((O12<>"Yes")+(P12<>"Yes")+(Q12<>"Yes")+AND(B12="Yes",R12<>"Yes")+AND(OR(B12="Yes",ISNUMBER(SEARCH("grappling",F12))),S12<>"Yes"))=0,"READY",((O12<>"Yes")+(P12<>"Yes")+(Q12<>"Yes")+AND(B12="Yes",R12<>"Yes")+AND(OR(B12="Yes",ISNUMBER(SEARCH("grappling",F12))),S12<>"Yes"))&" to do"))
L13: =IF(A13="","",N(I13)+N(J13)+N(K13)) | M13: =IF(A13="","",IF(L13<=5,"Pre-Novice",IF(L13<=10,"Novice","Open"))) | V13: =IF(A13="","",IF(((O13<>"Yes")+(P13<>"Yes")+(Q13<>"Yes")+AND(B13="Yes",R13<>"Yes")+AND(OR(B13="Yes",ISNUMBER(SEARCH("grappling",F13))),S13<>"Yes"))=0,"READY",((O13<>"Yes")+(P13<>"Yes")+(Q13<>"Yes")+AND(B13="Yes",R13<>"Yes")+AND(OR(B13="Yes",ISNUMBER(SEARCH("grappling",F13))),S13<>"Yes"))&" to do"))
L14: =IF(A14="","",N(I14)+N(J14)+N(K14)) | M14: =IF(A14="","",IF(L14<=5,"Pre-Novice",IF(L14<=10,"Novice","Open"))) | V14: =IF(A14="","",IF(((O14<>"Yes")+(P14<>"Yes")+(Q14<>"Yes")+AND(B14="Yes",R14<>"Yes")+AND(OR(B14="Yes",ISNUMBER(SEARCH("grappling",F14))),S14<>"Yes"))=0,"READY",((O14<>"Yes")+(P14<>"Yes")+(Q14<>"Yes")+AND(B14="Yes",R14<>"Yes")+AND(OR(B14="Yes",ISNUMBER(SEARCH("grappling",F14))),S14<>"Yes"))&" to do"))
L15: =IF(A15="","",N(I15)+N(J15)+N(K15)) | M15: =IF(A15="","",IF(L15<=5,"Pre-Novice",IF(L15<=10,"Novice","Open"))) | V15: =IF(A15="","",IF(((O15<>"Yes")+(P15<>"Yes")+(Q15<>"Yes")+AND(B15="Yes",R15<>"Yes")+AND(OR(B15="Yes",ISNUMBER(SEARCH("grappling",F15))),S15<>"Yes"))=0,"READY",((O15<>"Yes")+(P15<>"Yes")+(Q15<>"Yes")+AND(B15="Yes",R15<>"Yes")+AND(OR(B15="Yes",ISNUMBER(SEARCH("grappling",F15))),S15<>"Yes"))&" to do"))
L16: =IF(A16="","",N(I16)+N(J16)+N(K16)) | M16: =IF(A16="","",IF(L16<=5,"Pre-Novice",IF(L16<=10,"Novice","Open"))) | V16: =IF(A16="","",IF(((O16<>"Yes")+(P16<>"Yes")+(Q16<>"Yes")+AND(B16="Yes",R16<>"Yes")+AND(OR(B16="Yes",ISNUMBER(SEARCH("grappling",F16))),S16<>"Yes"))=0,"READY",((O16<>"Yes")+(P16<>"Yes")+(Q16<>"Yes")+AND(B16="Yes",R16<>"Yes")+AND(OR(B16="Yes",ISNUMBER(SEARCH("grappling",F16))),S16<>"Yes"))&" to do"))
L17: =IF(A17="","",N(I17)+N(J17)+N(K17)) | M17: =IF(A17="","",IF(L17<=5,"Pre-Novice",IF(L17<=10,"Novice","Open"))) | V17: =IF(A17="","",IF(((O17<>"Yes")+(P17<>"Yes")+(Q17<>"Yes")+AND(B17="Yes",R17<>"Yes")+AND(OR(B17="Yes",ISNUMBER(SEARCH("grappling",F17))),S17<>"Yes"))=0,"READY",((O17<>"Yes")+(P17<>"Yes")+(Q17<>"Yes")+AND(B17="Yes",R17<>"Yes")+AND(OR(B17="Yes",ISNUMBER(SEARCH("grappling",F17))),S17<>"Yes"))&" to do"))
... L204: =IF(A204="","",N(I204)+N(J204)+N(K204)) | M204: =IF(A204="","",IF(L204<=5,"Pre-Novice",IF(L204<=10,"Novice","Open"))) | V204: =IF(A204="","",IF(((O204<>"Yes")+(P204<>"Yes")+(Q204<>"Yes")+AND(B204="Yes",R204<>"Yes")+AND(OR(B204="Yes",ISNUMBER(SEARCH("grappling",F204))),S204<>"Yes"))=0,"READY",((O204<>"Yes")+(P204<>"Yes")+(Q204<>"Yes")+AND(B204="Yes",R204<>"Yes")+AND(OR(B204="Yes",ISNUMBER(SEARCH("grappling",F204))),S204<>"Yes"))&" to do"))

Sheet Bout Card
A1: BOUT CARD
A2: Pick both corners from the Fighters list, in the order the bouts will happen (main event last). It checks the Ontario weight-gap table, experience classes, age divisions, double bookings and paperwork. Flags are a prompt to look again: Cody and the officials decide. Results only once official.
A4: Bouts on the card | F4: Approved by Cody and the officials | M4: Bouts with a flag to look at
A5: =COUNTIF(D8:D37,"?*") -> 0 | F5: =COUNTIFS(D8:D37,"?*",N8:N37,"Yes",O8:O37,"Yes") -> 0 | M5: =COUNTIF(M8:M37,"?*")-COUNTIF(M8:M37,"OK") -> 0
A7: Bout # | B7: Card position | C7: Rules | D7: Red corner | E7: Blue corner | F7: Red weight | G7: Blue weight | H7: Weight gap (lb) | I7: Allowed gap (lb) | J7: Red class | K7: Blue class | L7: Both ready? | M7: Checks | N7: Cody approved | O7: Officials OK | P7: Winner | Q7: Method | R7: Round | S7: Time | T7: Notes
A8: 1 | F8: =IF(D8="","",IFERROR(INDEX(Fighters!$H$5:$H$204,MATCH(D8,Fighters!$A$5:$A$204,0)),"")) | G8: =IF(E8="","",IFERROR(INDEX(Fighters!$H$5:$H$204,MATCH(E8,Fighters!$A$5:$A$204,0)),"")) | H8: =IF(OR(F8="",G8=""),"",ABS(F8-G8)) | I8: =IF(OR(F8="",G8=""),"",IF(LEFT(C8,11)="Amateur MMA",INDEX(Lists!$K$2:$K$6,MATCH(MIN(F8,G8),Lists!$J$2:$J$6,1)),'Show Setup'!$B$23)) | J8: =IF(D8="","",IFERROR(INDEX(Fighters!$M$5:$M$204,MATCH(D8,Fighters!$A$5:$A$204,0)),"")) | K8: =IF(E8="","",IFERROR(INDEX(Fighters!$M$5:$M$204,MATCH(E8,Fighters!$A$5:$A$204,0)),"")) | L8: =IF(OR(D8="",E8=""),"",IF(AND(IFERROR(INDEX(Fighters!$V$5:$V$204,MATCH(D8,Fighters!$A$5:$A$204,0)),"")="READY",IFERROR(INDEX(Fighters!$V$5:$V$204,MATCH(E8,Fighters!$A$5:$A$204,0)),"")="READY"),"Yes","Not yet")) | M8: =IF(OR(D8="",E8=""),"",IF((IF(OR(H8="",I8=""),"",IF(H8>I8,"Weight gap over the limit. ",""))&IF(AND(LEFT(C8,11)="Amateur MMA",J8<>"",K8<>"",J8<>K8),"Different experience classes (needs the Commissioner's OK). ","")&IF(IFERROR(INDEX(Fighters!$G$5:$G$204,MATCH(D8,Fighters!$A$5:$A$204,0)),"")<>IFERROR(INDEX(Fighters!$G$5:$G$204,MATCH(E8,Fighters!$A$5:$A$204,0)),""),"Different age divisions. ","")&IF(AND(LEFT(C8,11)="Amateur MMA",OR(LEFT(IFERROR(INDEX(Fighters!$G$5:$G$204,MATCH(D8,Fighters!$A$5:$A$204,0)),""),5)="Under",LEFT(IFERROR(INDEX(Fighters!$G$5:$G$204,MATCH(E8,Fighters!$A$5:$A$204,0)),""),5)="Under")),"Under 12 can't do MMA. ","")&IF(AND(C8="Amateur MMA (Senior)",OR(LEFT(IFERROR(INDEX(Fighters!$G$5:$G$204,MATCH(D8,Fighters!$A$5:$A$204,0)),""),5)="Youth",LEFT(IFERROR(INDEX(Fighters!$G$5:$G$204,MATCH(E8,Fighters!$A$5:$A$204,0)),""),5)="Youth")),"Youth on Senior rules. ","")&IF(D8=E8,"Same fighter twice. ","")&IF(COUNTIF($D$8:$E$37,D8)+COUNTIF($D$8:$E$37,E8)>2,"A fighter is in two bouts. ","")&IF(L8="Not yet","Paperwork not done. ","")&IF(C8="","Pick the rules. ",""))="","OK",IF(OR(H8="",I8=""),"",IF(H8>I8,"Weight gap over the limit. ",""))&IF(AND(LEFT(C8,11)="Amateur MMA",J8<>"",K8<>"",J8<>K8),"Different experience classes (needs the Commissioner's OK). ","")&IF(IFERROR(INDEX(Fighters!$G$5:$G$204,MATCH(D8,Fighters!$A$5:$A$204,0)),"")<>IFERROR(INDEX(Fighters!$G$5:$G$204,MATCH(E8,Fighters!$A$5:$A$204,0)),""),"Different age divisions. ","")&IF(AND(LEFT(C8,11)="Amateur MMA",OR(LEFT(IFERROR(INDEX(Fighters!$G$5:$G$204,MATCH(D8,Fighters!$A$5:$A$204,0)),""),5)="Under",LEFT(IFERROR(INDEX(Fighters!$G$5:$G$204,MATCH(E8,Fighters!$A$5:$A$204,0)),""),5)="Under")),"Under 12 can't do MMA. ","")&IF(AND(C8="Amateur MMA (Senior)",OR(LEFT(IFERROR(INDEX(Fighters!$G$5:$G$204,MATCH(D8,Fighters!$A$5:$A$204,0)),""),5)="Youth",LEFT(IFERROR(INDEX(Fighters!$G$5:$G$204,MATCH(E8,Fighters!$A$5:$A$204,0)),""),5)="Youth")),"Youth on Senior rules. ","")&IF(D8=E8,"Same fighter twice. ","")&IF(COUNTIF($D$8:$E$37,D8)+COUNTIF($D$8:$E$37,E8)>2,"A fighter is in two bouts. ","")&IF(L8="Not yet","Paperwork not done. ","")&IF(C8="","Pick the rules. ","")))
A9: 2 | F9: =IF(D9="","",IFERROR(INDEX(Fighters!$H$5:$H$204,MATCH(D9,Fighters!$A$5:$A$204,0)),"")) | G9: =IF(E9="","",IFERROR(INDEX(Fighters!$H$5:$H$204,MATCH(E9,Fighters!$A$5:$A$204,0)),"")) | H9: =IF(OR(F9="",G9=""),"",ABS(F9-G9)) | I9: =IF(OR(F9="",G9=""),"",IF(LEFT(C9,11)="Amateur MMA",INDEX(Lists!$K$2:$K$6,MATCH(MIN(F9,G9),Lists!$J$2:$J$6,1)),'Show Setup'!$B$23)) | J9: =IF(D9="","",IFERROR(INDEX(Fighters!$M$5:$M$204,MATCH(D9,Fighters!$A$5:$A$204,0)),"")) | K9: =IF(E9="","",IFERROR(INDEX(Fighters!$M$5:$M$204,MATCH(E9,Fighters!$A$5:$A$204,0)),"")) | L9: =IF(OR(D9="",E9=""),"",IF(AND(IFERROR(INDEX(Fighters!$V$5:$V$204,MATCH(D9,Fighters!$A$5:$A$204,0)),"")="READY",IFERROR(INDEX(Fighters!$V$5:$V$204,MATCH(E9,Fighters!$A$5:$A$204,0)),"")="READY"),"Yes","Not yet")) | M9: =IF(OR(D9="",E9=""),"",IF((IF(OR(H9="",I9=""),"",IF(H9>I9,"Weight gap over the limit. ",""))&IF(AND(LEFT(C9,11)="Amateur MMA",J9<>"",K9<>"",J9<>K9),"Different experience classes (needs the Commissioner's OK). ","")&IF(IFERROR(INDEX(Fighters!$G$5:$G$204,MATCH(D9,Fighters!$A$5:$A$204,0)),"")<>IFERROR(INDEX(Fighters!$G$5:$G$204,MATCH(E9,Fighters!$A$5:$A$204,0)),""),"Different age divisions. ","")&IF(AND(LEFT(C9,11)="Amateur MMA",OR(LEFT(IFERROR(INDEX(Fighters!$G$5:$G$204,MATCH(D9,Fighters!$A$5:$A$204,0)),""),5)="Under",LEFT(IFERROR(INDEX(Fighters!$G$5:$G$204,MATCH(E9,Fighters!$A$5:$A$204,0)),""),5)="Under")),"Under 12 can't do MMA. ","")&IF(AND(C9="Amateur MMA (Senior)",OR(LEFT(IFERROR(INDEX(Fighters!$G$5:$G$204,MATCH(D9,Fighters!$A$5:$A$204,0)),""),5)="Youth",LEFT(IFERROR(INDEX(Fighters!$G$5:$G$204,MATCH(E9,Fighters!$A$5:$A$204,0)),""),5)="Youth")),"Youth on Senior rules. ","")&IF(D9=E9,"Same fighter twice. ","")&IF(COUNTIF($D$8:$E$37,D9)+COUNTIF($D$8:$E$37,E9)>2,"A fighter is in two bouts. ","")&IF(L9="Not yet","Paperwork not done. ","")&IF(C9="","Pick the rules. ",""))="","OK",IF(OR(H9="",I9=""),"",IF(H9>I9,"Weight gap over the limit. ",""))&IF(AND(LEFT(C9,11)="Amateur MMA",J9<>"",K9<>"",J9<>K9),"Different experience classes (needs the Commissioner's OK). ","")&IF(IFERROR(INDEX(Fighters!$G$5:$G$204,MATCH(D9,Fighters!$A$5:$A$204,0)),"")<>IFERROR(INDEX(Fighters!$G$5:$G$204,MATCH(E9,Fighters!$A$5:$A$204,0)),""),"Different age divisions. ","")&IF(AND(LEFT(C9,11)="Amateur MMA",OR(LEFT(IFERROR(INDEX(Fighters!$G$5:$G$204,MATCH(D9,Fighters!$A$5:$A$204,0)),""),5)="Under",LEFT(IFERROR(INDEX(Fighters!$G$5:$G$204,MATCH(E9,Fighters!$A$5:$A$204,0)),""),5)="Under")),"Under 12 can't do MMA. ","")&IF(AND(C9="Amateur MMA (Senior)",OR(LEFT(IFERROR(INDEX(Fighters!$G$5:$G$204,MATCH(D9,Fighters!$A$5:$A$204,0)),""),5)="Youth",LEFT(IFERROR(INDEX(Fighters!$G$5:$G$204,MATCH(E9,Fighters!$A$5:$A$204,0)),""),5)="Youth")),"Youth on Senior rules. ","")&IF(D9=E9,"Same fighter twice. ","")&IF(COUNTIF($D$8:$E$37,D9)+COUNTIF($D$8:$E$37,E9)>2,"A fighter is in two bouts. ","")&IF(L9="Not yet","Paperwork not done. ","")&IF(C9="","Pick the rules. ","")))
A10: 3 | F10: =IF(D10="","",IFERROR(INDEX(Fighters!$H$5:$H$204,MATCH(D10,Fighters!$A$5:$A$204,0)),"")) | G10: =IF(E10="","",IFERROR(INDEX(Fighters!$H$5:$H$204,MATCH(E10,Fighters!$A$5:$A$204,0)),"")) | H10: =IF(OR(F10="",G10=""),"",ABS(F10-G10)) | I10: =IF(OR(F10="",G10=""),"",IF(LEFT(C10,11)="Amateur MMA",INDEX(Lists!$K$2:$K$6,MATCH(MIN(F10,G10),Lists!$J$2:$J$6,1)),'Show Setup'!$B$23)) | J10: =IF(D10="","",IFERROR(INDEX(Fighters!$M$5:$M$204,MATCH(D10,Fighters!$A$5:$A$204,0)),"")) | K10: =IF(E10="","",IFERROR(INDEX(Fighters!$M$5:$M$204,MATCH(E10,Fighters!$A$5:$A$204,0)),"")) | L10: =IF(OR(D10="",E10=""),"",IF(AND(IFERROR(INDEX(Fighters!$V$5:$V$204,MATCH(D10,Fighters!$A$5:$A$204,0)),"")="READY",IFERROR(INDEX(Fighters!$V$5:$V$204,MATCH(E10,Fighters!$A$5:$A$204,0)),"")="READY"),"Yes","Not yet")) | M10: =IF(OR(D10="",E10=""),"",IF((IF(OR(H10="",I10=""),"",IF(H10>I10,"Weight gap over the limit. ",""))&IF(AND(LEFT(C10,11)="Amateur MMA",J10<>"",K10<>"",J10<>K10),"Different experience classes (needs the Commissioner's OK). ","")&IF(IFERROR(INDEX(Fighters!$G$5:$G$204,MATCH(D10,Fighters!$A$5:$A$204,0)),"")<>IFERROR(INDEX(Fighters!$G$5:$G$204,MATCH(E10,Fighters!$A$5:$A$204,0)),""),"Different age divisions. ","")&IF(AND(LEFT(C10,11)="Amateur MMA",OR(LEFT(IFERROR(INDEX(Fighters!$G$5:$G$204,MATCH(D10,Fighters!$A$5:$A$204,0)),""),5)="Under",LEFT(IFERROR(INDEX(Fighters!$G$5:$G$204,MATCH(E10,Fighters!$A$5:$A$204,0)),""),5)="Under")),"Under 12 can't do MMA. ","")&IF(AND(C10="Amateur MMA (Senior)",OR(LEFT(IFERROR(INDEX(Fighters!$G$5:$G$204,MATCH(D10,Fighters!$A$5:$A$204,0)),""),5)="Youth",LEFT(IFERROR(INDEX(Fighters!$G$5:$G$204,MATCH(E10,Fighters!$A$5:$A$204,0)),""),5)="Youth")),"Youth on Senior rules. ","")&IF(D10=E10,"Same fighter twice. ","")&IF(COUNTIF($D$8:$E$37,D10)+COUNTIF($D$8:$E$37,E10)>2,"A fighter is in two bouts. ","")&IF(L10="Not yet","Paperwork not done. ","")&IF(C10="","Pick the rules. ",""))="","OK",IF(OR(H10="",I10=""),"",IF(H10>I10,"Weight gap over the limit. ",""))&IF(AND(LEFT(C10,11)="Amateur MMA",J10<>"",K10<>"",J10<>K10),"Different experience classes (needs the Commissioner's OK). ","")&IF(IFERROR(INDEX(Fighters!$G$5:$G$204,MATCH(D10,Fighters!$A$5:$A$204,0)),"")<>IFERROR(INDEX(Fighters!$G$5:$G$204,MATCH(E10,Fighters!$A$5:$A$204,0)),""),"Different age divisions. ","")&IF(AND(LEFT(C10,11)="Amateur MMA",OR(LEFT(IFERROR(INDEX(Fighters!$G$5:$G$204,MATCH(D10,Fighters!$A$5:$A$204,0)),""),5)="Under",LEFT(IFERROR(INDEX(Fighters!$G$5:$G$204,MATCH(E10,Fighters!$A$5:$A$204,0)),""),5)="Under")),"Under 12 can't do MMA. ","")&IF(AND(C10="Amateur MMA (Senior)",OR(LEFT(IFERROR(INDEX(Fighters!$G$5:$G$204,MATCH(D10,Fighters!$A$5:$A$204,0)),""),5)="Youth",LEFT(IFERROR(INDEX(Fighters!$G$5:$G$204,MATCH(E10,Fighters!$A$5:$A$204,0)),""),5)="Youth")),"Youth on Senior rules. ","")&IF(D10=E10,"Same fighter twice. ","")&IF(COUNTIF($D$8:$E$37,D10)+COUNTIF($D$8:$E$37,E10)>2,"A fighter is in two bouts. ","")&IF(L10="Not yet","Paperwork not done. ","")&IF(C10="","Pick the rules. ","")))
A11: 4 | F11: =IF(D11="","",IFERROR(INDEX(Fighters!$H$5:$H$204,MATCH(D11,Fighters!$A$5:$A$204,0)),"")) | G11: =IF(E11="","",IFERROR(INDEX(Fighters!$H$5:$H$204,MATCH(E11,Fighters!$A$5:$A$204,0)),"")) | H11: =IF(OR(F11="",G11=""),"",ABS(F11-G11)) | I11: =IF(OR(F11="",G11=""),"",IF(LEFT(C11,11)="Amateur MMA",INDEX(Lists!$K$2:$K$6,MATCH(MIN(F11,G11),Lists!$J$2:$J$6,1)),'Show Setup'!$B$23)) | J11: =IF(D11="","",IFERROR(INDEX(Fighters!$M$5:$M$204,MATCH(D11,Fighters!$A$5:$A$204,0)),"")) | K11: =IF(E11="","",IFERROR(INDEX(Fighters!$M$5:$M$204,MATCH(E11,Fighters!$A$5:$A$204,0)),"")) | L11: =IF(OR(D11="",E11=""),"",IF(AND(IFERROR(INDEX(Fighters!$V$5:$V$204,MATCH(D11,Fighters!$A$5:$A$204,0)),"")="READY",IFERROR(INDEX(Fighters!$V$5:$V$204,MATCH(E11,Fighters!$A$5:$A$204,0)),"")="READY"),"Yes","Not yet")) | M11: =IF(OR(D11="",E11=""),"",IF((IF(OR(H11="",I11=""),"",IF(H11>I11,"Weight gap over the limit. ",""))&IF(AND(LEFT(C11,11)="Amateur MMA",J11<>"",K11<>"",J11<>K11),"Different experience classes (needs the Commissioner's OK). ","")&IF(IFERROR(INDEX(Fighters!$G$5:$G$204,MATCH(D11,Fighters!$A$5:$A$204,0)),"")<>IFERROR(INDEX(Fighters!$G$5:$G$204,MATCH(E11,Fighters!$A$5:$A$204,0)),""),"Different age divisions. ","")&IF(AND(LEFT(C11,11)="Amateur MMA",OR(LEFT(IFERROR(INDEX(Fighters!$G$5:$G$204,MATCH(D11,Fighters!$A$5:$A$204,0)),""),5)="Under",LEFT(IFERROR(INDEX(Fighters!$G$5:$G$204,MATCH(E11,Fighters!$A$5:$A$204,0)),""),5)="Under")),"Under 12 can't do MMA. ","")&IF(AND(C11="Amateur MMA (Senior)",OR(LEFT(IFERROR(INDEX(Fighters!$G$5:$G$204,MATCH(D11,Fighters!$A$5:$A$204,0)),""),5)="Youth",LEFT(IFERROR(INDEX(Fighters!$G$5:$G$204,MATCH(E11,Fighters!$A$5:$A$204,0)),""),5)="Youth")),"Youth on Senior rules. ","")&IF(D11=E11,"Same fighter twice. ","")&IF(COUNTIF($D$8:$E$37,D11)+COUNTIF($D$8:$E$37,E11)>2,"A fighter is in two bouts. ","")&IF(L11="Not yet","Paperwork not done. ","")&IF(C11="","Pick the rules. ",""))="","OK",IF(OR(H11="",I11=""),"",IF(H11>I11,"Weight gap over the limit. ",""))&IF(AND(LEFT(C11,11)="Amateur MMA",J11<>"",K11<>"",J11<>K11),"Different experience classes (needs the Commissioner's OK). ","")&IF(IFERROR(INDEX(Fighters!$G$5:$G$204,MATCH(D11,Fighters!$A$5:$A$204,0)),"")<>IFERROR(INDEX(Fighters!$G$5:$G$204,MATCH(E11,Fighters!$A$5:$A$204,0)),""),"Different age divisions. ","")&IF(AND(LEFT(C11,11)="Amateur MMA",OR(LEFT(IFERROR(INDEX(Fighters!$G$5:$G$204,MATCH(D11,Fighters!$A$5:$A$204,0)),""),5)="Under",LEFT(IFERROR(INDEX(Fighters!$G$5:$G$204,MATCH(E11,Fighters!$A$5:$A$204,0)),""),5)="Under")),"Under 12 can't do MMA. ","")&IF(AND(C11="Amateur MMA (Senior)",OR(LEFT(IFERROR(INDEX(Fighters!$G$5:$G$204,MATCH(D11,Fighters!$A$5:$A$204,0)),""),5)="Youth",LEFT(IFERROR(INDEX(Fighters!$G$5:$G$204,MATCH(E11,Fighters!$A$5:$A$204,0)),""),5)="Youth")),"Youth on Senior rules. ","")&IF(D11=E11,"Same fighter twice. ","")&IF(COUNTIF($D$8:$E$37,D11)+COUNTIF($D$8:$E$37,E11)>2,"A fighter is in two bouts. ","")&IF(L11="Not yet","Paperwork not done. ","")&IF(C11="","Pick the rules. ","")))
A12: 5 | F12: =IF(D12="","",IFERROR(INDEX(Fighters!$H$5:$H$204,MATCH(D12,Fighters!$A$5:$A$204,0)),"")) | G12: =IF(E12="","",IFERROR(INDEX(Fighters!$H$5:$H$204,MATCH(E12,Fighters!$A$5:$A$204,0)),"")) | H12: =IF(OR(F12="",G12=""),"",ABS(F12-G12)) | I12: =IF(OR(F12="",G12=""),"",IF(LEFT(C12,11)="Amateur MMA",INDEX(Lists!$K$2:$K$6,MATCH(MIN(F12,G12),Lists!$J$2:$J$6,1)),'Show Setup'!$B$23)) | J12: =IF(D12="","",IFERROR(INDEX(Fighters!$M$5:$M$204,MATCH(D12,Fighters!$A$5:$A$204,0)),"")) | K12: =IF(E12="","",IFERROR(INDEX(Fighters!$M$5:$M$204,MATCH(E12,Fighters!$A$5:$A$204,0)),"")) | L12: =IF(OR(D12="",E12=""),"",IF(AND(IFERROR(INDEX(Fighters!$V$5:$V$204,MATCH(D12,Fighters!$A$5:$A$204,0)),"")="READY",IFERROR(INDEX(Fighters!$V$5:$V$204,MATCH(E12,Fighters!$A$5:$A$204,0)),"")="READY"),"Yes","Not yet")) | M12: =IF(OR(D12="",E12=""),"",IF((IF(OR(H12="",I12=""),"",IF(H12>I12,"Weight gap over the limit. ",""))&IF(AND(LEFT(C12,11)="Amateur MMA",J12<>"",K12<>"",J12<>K12),"Different experience classes (needs the Commissioner's OK). ","")&IF(IFERROR(INDEX(Fighters!$G$5:$G$204,MATCH(D12,Fighters!$A$5:$A$204,0)),"")<>IFERROR(INDEX(Fighters!$G$5:$G$204,MATCH(E12,Fighters!$A$5:$A$204,0)),""),"Different age divisions. ","")&IF(AND(LEFT(C12,11)="Amateur MMA",OR(LEFT(IFERROR(INDEX(Fighters!$G$5:$G$204,MATCH(D12,Fighters!$A$5:$A$204,0)),""),5)="Under",LEFT(IFERROR(INDEX(Fighters!$G$5:$G$204,MATCH(E12,Fighters!$A$5:$A$204,0)),""),5)="Under")),"Under 12 can't do MMA. ","")&IF(AND(C12="Amateur MMA (Senior)",OR(LEFT(IFERROR(INDEX(Fighters!$G$5:$G$204,MATCH(D12,Fighters!$A$5:$A$204,0)),""),5)="Youth",LEFT(IFERROR(INDEX(Fighters!$G$5:$G$204,MATCH(E12,Fighters!$A$5:$A$204,0)),""),5)="Youth")),"Youth on Senior rules. ","")&IF(D12=E12,"Same fighter twice. ","")&IF(COUNTIF($D$8:$E$37,D12)+COUNTIF($D$8:$E$37,E12)>2,"A fighter is in two bouts. ","")&IF(L12="Not yet","Paperwork not done. ","")&IF(C12="","Pick the rules. ",""))="","OK",IF(OR(H12="",I12=""),"",IF(H12>I12,"Weight gap over the limit. ",""))&IF(AND(LEFT(C12,11)="Amateur MMA",J12<>"",K12<>"",J12<>K12),"Different experience classes (needs the Commissioner's OK). ","")&IF(IFERROR(INDEX(Fighters!$G$5:$G$204,MATCH(D12,Fighters!$A$5:$A$204,0)),"")<>IFERROR(INDEX(Fighters!$G$5:$G$204,MATCH(E12,Fighters!$A$5:$A$204,0)),""),"Different age divisions. ","")&IF(AND(LEFT(C12,11)="Amateur MMA",OR(LEFT(IFERROR(INDEX(Fighters!$G$5:$G$204,MATCH(D12,Fighters!$A$5:$A$204,0)),""),5)="Under",LEFT(IFERROR(INDEX(Fighters!$G$5:$G$204,MATCH(E12,Fighters!$A$5:$A$204,0)),""),5)="Under")),"Under 12 can't do MMA. ","")&IF(AND(C12="Amateur MMA (Senior)",OR(LEFT(IFERROR(INDEX(Fighters!$G$5:$G$204,MATCH(D12,Fighters!$A$5:$A$204,0)),""),5)="Youth",LEFT(IFERROR(INDEX(Fighters!$G$5:$G$204,MATCH(E12,Fighters!$A$5:$A$204,0)),""),5)="Youth")),"Youth on Senior rules. ","")&IF(D12=E12,"Same fighter twice. ","")&IF(COUNTIF($D$8:$E$37,D12)+COUNTIF($D$8:$E$37,E12)>2,"A fighter is in two bouts. ","")&IF(L12="Not yet","Paperwork not done. ","")&IF(C12="","Pick the rules. ","")))
A13: 6 | F13: =IF(D13="","",IFERROR(INDEX(Fighters!$H$5:$H$204,MATCH(D13,Fighters!$A$5:$A$204,0)),"")) | G13: =IF(E13="","",IFERROR(INDEX(Fighters!$H$5:$H$204,MATCH(E13,Fighters!$A$5:$A$204,0)),"")) | H13: =IF(OR(F13="",G13=""),"",ABS(F13-G13)) | I13: =IF(OR(F13="",G13=""),"",IF(LEFT(C13,11)="Amateur MMA",INDEX(Lists!$K$2:$K$6,MATCH(MIN(F13,G13),Lists!$J$2:$J$6,1)),'Show Setup'!$B$23)) | J13: =IF(D13="","",IFERROR(INDEX(Fighters!$M$5:$M$204,MATCH(D13,Fighters!$A$5:$A$204,0)),"")) | K13: =IF(E13="","",IFERROR(INDEX(Fighters!$M$5:$M$204,MATCH(E13,Fighters!$A$5:$A$204,0)),"")) | L13: =IF(OR(D13="",E13=""),"",IF(AND(IFERROR(INDEX(Fighters!$V$5:$V$204,MATCH(D13,Fighters!$A$5:$A$204,0)),"")="READY",IFERROR(INDEX(Fighters!$V$5:$V$204,MATCH(E13,Fighters!$A$5:$A$204,0)),"")="READY"),"Yes","Not yet")) | M13: =IF(OR(D13="",E13=""),"",IF((IF(OR(H13="",I13=""),"",IF(H13>I13,"Weight gap over the limit. ",""))&IF(AND(LEFT(C13,11)="Amateur MMA",J13<>"",K13<>"",J13<>K13),"Different experience classes (needs the Commissioner's OK). ","")&IF(IFERROR(INDEX(Fighters!$G$5:$G$204,MATCH(D13,Fighters!$A$5:$A$204,0)),"")<>IFERROR(INDEX(Fighters!$G$5:$G$204,MATCH(E13,Fighters!$A$5:$A$204,0)),""),"Different age divisions. ","")&IF(AND(LEFT(C13,11)="Amateur MMA",OR(LEFT(IFERROR(INDEX(Fighters!$G$5:$G$204,MATCH(D13,Fighters!$A$5:$A$204,0)),""),5)="Under",LEFT(IFERROR(INDEX(Fighters!$G$5:$G$204,MATCH(E13,Fighters!$A$5:$A$204,0)),""),5)="Under")),"Under 12 can't do MMA. ","")&IF(AND(C13="Amateur MMA (Senior)",OR(LEFT(IFERROR(INDEX(Fighters!$G$5:$G$204,MATCH(D13,Fighters!$A$5:$A$204,0)),""),5)="Youth",LEFT(IFERROR(INDEX(Fighters!$G$5:$G$204,MATCH(E13,Fighters!$A$5:$A$204,0)),""),5)="Youth")),"Youth on Senior rules. ","")&IF(D13=E13,"Same fighter twice. ","")&IF(COUNTIF($D$8:$E$37,D13)+COUNTIF($D$8:$E$37,E13)>2,"A fighter is in two bouts. ","")&IF(L13="Not yet","Paperwork not done. ","")&IF(C13="","Pick the rules. ",""))="","OK",IF(OR(H13="",I13=""),"",IF(H13>I13,"Weight gap over the limit. ",""))&IF(AND(LEFT(C13,11)="Amateur MMA",J13<>"",K13<>"",J13<>K13),"Different experience classes (needs the Commissioner's OK). ","")&IF(IFERROR(INDEX(Fighters!$G$5:$G$204,MATCH(D13,Fighters!$A$5:$A$204,0)),"")<>IFERROR(INDEX(Fighters!$G$5:$G$204,MATCH(E13,Fighters!$A$5:$A$204,0)),""),"Different age divisions. ","")&IF(AND(LEFT(C13,11)="Amateur MMA",OR(LEFT(IFERROR(INDEX(Fighters!$G$5:$G$204,MATCH(D13,Fighters!$A$5:$A$204,0)),""),5)="Under",LEFT(IFERROR(INDEX(Fighters!$G$5:$G$204,MATCH(E13,Fighters!$A$5:$A$204,0)),""),5)="Under")),"Under 12 can't do MMA. ","")&IF(AND(C13="Amateur MMA (Senior)",OR(LEFT(IFERROR(INDEX(Fighters!$G$5:$G$204,MATCH(D13,Fighters!$A$5:$A$204,0)),""),5)="Youth",LEFT(IFERROR(INDEX(Fighters!$G$5:$G$204,MATCH(E13,Fighters!$A$5:$A$204,0)),""),5)="Youth")),"Youth on Senior rules. ","")&IF(D13=E13,"Same fighter twice. ","")&IF(COUNTIF($D$8:$E$37,D13)+COUNTIF($D$8:$E$37,E13)>2,"A fighter is in two bouts. ","")&IF(L13="Not yet","Paperwork not done. ","")&IF(C13="","Pick the rules. ","")))
