Workbook

Sheet Start Here
A1: CCCL SPONSORSHIP PIPELINE
A2: Find sponsors, pitch them, follow up, collect, and deliver what was promised. Built for Cody Purtell by Kyle. Opens in Google Sheets or Excel.
B4: THE STAGES
B5: Prospect | C5: Researched, not contacted yet.
B6: Contacted | C6: Pitch sent or a conversation started. Set a next follow-up date.
B7: Interested | C7: They replied and want to hear more.
B8: Proposal sent | C8: They have the package and price.
B9: Signed | C9: They said yes and agreed an amount. Not money yet.
B10: Paid | C10: The money is in the account. Only this counts as revenue.
B11: Not now | C11: Said no or not this year. Leave a note and try again next season.
B13: EVERY WEEK (15 MINUTES)
A14: 1 | B14: Monday | C14: Open Summary. Anyone marked DUE gets a follow-up today. Claude can draft them.
A15: 2 | B15: New sponsor signed | C15: Set Stage to Signed, fill in the package and amount, and add them to the Fulfilment tab.
A16: 3 | B16: Money arrives | C16: Set Stage to Paid and fill in Amount paid.
A17: 4 | B17: Before the show | C17: Check Fulfilment: banners hung, posts done, tickets sent.
A18: 5 | B18: After the show | C18: Send every sponsor a photo and a thank-you. Mark it on Fulfilment. That's how they come back next year.
B20: TABS
B21: Summary | C21: Money agreed vs paid, follow-ups due, packages sold.
B22: Pipeline | C22: Every business, one row each. Yellow columns are yours. Grey columns came from research.
B23: Packages | C23: Cody's sponsor packages (Title $7,500 down to Community $300-500, plus VIP tables).
B24: Fulfilment | C24: What each sponsor was promised and whether it's done.
B26: ABOUT THE LIST
B27: Where it came from | C27: The 2026 Title Sponsor, 70 local businesses and 24 national and Ontario brands (rows marked 'Brand:' in the Area column), researched by Claude from public websites in October 2026. Phone numbers and emails are each business's public contact details. Check them before reaching out.
B28: Existing supporters | C28: 2026 sponsors (Cody, Oct 20, 2026): Dillabough Millwrighting & Welding (Title, $7,500), Dixie Lee, Pinestone Resort, IT STIX Signs & Graphics and ICO; most were Bronze. Businesses marked 'Yes (logo on gym wall)' support the gym but weren't May 2 sponsors. Start with both groups: thank them first, then pitch 2027. Cody has promised some sponsors spots at future Apsley, Bancroft and Haliburton shows: check with him before pitching for those towns. Add the other 2026 sponsors when Cody lists them.
B29: Brands | C29: Start with Hayabusa (Kingston fight gear), BioSteel / Canadian Protein and MuscleTech / Six Star. Ask for product first (fighter bags, a sampling table, prize packs), then cash once there are 2027 crowd numbers. Anything a fighter receives must be worth under $300 in total (amateur rule); no raffle without a lottery licence. Alcohol and energy drinks stay away from youth bouts and kids' content; Proper No. Twelve only for a 19+ show or area, and only after checking with the AGCO and the venue.
B30: Show column | C30: No 2027 show is booked yet, so every row says 'Not booked yet'. Change it once Cody confirms a town and date. Never name a town or date in a pitch until then.
B31: Colour key | C31: Yellow cells with blue text are yours to fill in. Black text is calculated. Don't type over it.

Sheet Summary
A1: SPONSORSHIP SUMMARY
A2: Updates by itself from the Pipeline tab. Nothing to type here except the goals in yellow.
A4: GOALS
A5: Sponsorship goal for the next show ($) | B5: 18000 | F5: The first show raised $18,000 from 15 sponsors (Cody). With 4+ shows in 2027, set a goal for each show. The Event Profit Predictor shows how much each venue needs to break even on a low night.
A6: Number of sponsors wanted | B6: 15 | F6: Same as 2026.
A8: WHERE THE MONEY IS
A9: Stage | B9: Businesses | C9: Dollars agreed | D9: Dollars paid
A10: Prospect | B10: =COUNTIFS(Pipeline!$H$5:$H$304,"Prospect",Pipeline!$B$5:$B$304,"<>") -> 95 | C10: =SUMIFS(Pipeline!$J$5:$J$304,Pipeline!$H$5:$H$304,"Prospect") -> 0 | D10: =SUMIFS(Pipeline!$K$5:$K$304,Pipeline!$H$5:$H$304,"Prospect") -> 0
A11: Contacted | B11: =COUNTIFS(Pipeline!$H$5:$H$304,"Contacted",Pipeline!$B$5:$B$304,"<>") -> 0 | C11: =SUMIFS(Pipeline!$J$5:$J$304,Pipeline!$H$5:$H$304,"Contacted") -> 0 | D11: =SUMIFS(Pipeline!$K$5:$K$304,Pipeline!$H$5:$H$304,"Contacted") -> 0
A12: Interested | B12: =COUNTIFS(Pipeline!$H$5:$H$304,"Interested",Pipeline!$B$5:$B$304,"<>") -> 0 | C12: =SUMIFS(Pipeline!$J$5:$J$304,Pipeline!$H$5:$H$304,"Interested") -> 0 | D12: =SUMIFS(Pipeline!$K$5:$K$304,Pipeline!$H$5:$H$304,"Interested") -> 0
A13: Proposal sent | B13: =COUNTIFS(Pipeline!$H$5:$H$304,"Proposal sent",Pipeline!$B$5:$B$304,"<>") -> 0 | C13: =SUMIFS(Pipeline!$J$5:$J$304,Pipeline!$H$5:$H$304,"Proposal sent") -> 0 | D13: =SUMIFS(Pipeline!$K$5:$K$304,Pipeline!$H$5:$H$304,"Proposal sent") -> 0
A14: Signed | B14: =COUNTIFS(Pipeline!$H$5:$H$304,"Signed",Pipeline!$B$5:$B$304,"<>") -> 0 | C14: =SUMIFS(Pipeline!$J$5:$J$304,Pipeline!$H$5:$H$304,"Signed") -> 0 | D14: =SUMIFS(Pipeline!$K$5:$K$304,Pipeline!$H$5:$H$304,"Signed") -> 0
A15: Paid | B15: =COUNTIFS(Pipeline!$H$5:$H$304,"Paid",Pipeline!$B$5:$B$304,"<>") -> 0 | C15: =SUMIFS(Pipeline!$J$5:$J$304,Pipeline!$H$5:$H$304,"Paid") -> 0 | D15: =SUMIFS(Pipeline!$K$5:$K$304,Pipeline!$H$5:$H$304,"Paid") -> 0
A16: Not now | B16: =COUNTIFS(Pipeline!$H$5:$H$304,"Not now",Pipeline!$B$5:$B$304,"<>") -> 0 | C16: =SUMIFS(Pipeline!$J$5:$J$304,Pipeline!$H$5:$H$304,"Not now") -> 0 | D16: =SUMIFS(Pipeline!$K$5:$K$304,Pipeline!$H$5:$H$304,"Not now") -> 0
A17: Total | B17: =SUM(B10:B16) -> 95 | C17: =SUM(C10:C16) -> 0 | D17: =SUM(D10:D16) -> 0
A19: SCOREBOARD
A20: Signed or paid ($ agreed) | B20: =SUMIFS(Pipeline!$J$5:$J$304,Pipeline!$H$5:$H$304,"Signed")+SUMIFS(Pipeline!$J$5:$J$304,Pipeline!$H$5:$H$304,"Paid") -> 0
A21: Money actually received | B21: =SUM(Pipeline!$K$5:$K$304) -> 0
A22: Still to collect from signed sponsors | B22: =MAX(0,B20-B21) -> 0
A23: % of goal received | B23: =IF($B$5=0,0,B21/$B$5) -> 0
A24: Sponsors signed or paid | B24: =COUNTIFS(Pipeline!$H$5:$H$304,"Signed",Pipeline!$B$5:$B$304,"<>")+COUNTIFS(Pipeline!$H$5:$H$304,"Paid",Pipeline!$B$5:$B$304,"<>") -> 0
A25: Follow-ups due today or overdue | B25: =COUNTIF(Pipeline!$T$5:$T$304,"DUE") -> 0
A26: Businesses not contacted yet | B26: =COUNTIFS(Pipeline!$H$5:$H$304,"Prospect",Pipeline!$B$5:$B$304,"<>") -> 95
A28: PACKAGES SOLD
A29: Package | B29: Price ($) | C29: Sold (signed or paid) | D29: Slots | E29: Left
A30: Title Sponsor | B30: =Packages!B5 -> 7500 | C30: =COUNTIFS(Pipeline!$I$5:$I$304,"Title Sponsor",Pipeline!$H$5:$H$304,"Signed")+COUNTIFS(Pipeline!$I$5:$I$304,"Title Sponsor",Pipeline!$H$5:$H$304,"Paid") -> 0 | D30: =Packages!D5 -> 1 | E30: =MAX(0,D30-C30) -> 1
A31: Gold Sponsor | B31: =Packages!B6 -> 4000 | C31: =COUNTIFS(Pipeline!$I$5:$I$304,"Gold Sponsor",Pipeline!$H$5:$H$304,"Signed")+COUNTIFS(Pipeline!$I$5:$I$304,"Gold Sponsor",Pipeline!$H$5:$H$304,"Paid") -> 0 | D31: =Packages!D6 -> 2 | E31: =MAX(0,D31-C31) -> 2
A32: Silver Sponsor | B32: =Packages!B7 -> 2000 | C32: =COUNTIFS(Pipeline!$I$5:$I$304,"Silver Sponsor",Pipeline!$H$5:$H$304,"Signed")+COUNTIFS(Pipeline!$I$5:$I$304,"Silver Sponsor",Pipeline!$H$5:$H$304,"Paid") -> 0 | D32: =Packages!D7 -> 4 | E32: =MAX(0,D32-C32) -> 4
A33: Bronze Sponsor | B33: =Packages!B8 -> 1000 | C33: =COUNTIFS(Pipeline!$I$5:$I$304,"Bronze Sponsor",Pipeline!$H$5:$H$304,"Signed")+COUNTIFS(Pipeline!$I$5:$I$304,"Bronze Sponsor",Pipeline!$H$5:$H$304,"Paid") -> 0 | D33: =Packages!D8 -> 10 | E33: =MAX(0,D33-C33) -> 10
A34: Community Sponsor | B34: =Packages!B9 -> 300 | C34: =COUNTIFS(Pipeline!$I$5:$I$304,"Community Sponsor",Pipeline!$H$5:$H$304,"Signed")+COUNTIFS(Pipeline!$I$5:$I$304,"Community Sponsor",Pipeline!$H$5:$H$304,"Paid") -> 0 | D34: =Packages!D9 -> 20 | E34: =MAX(0,D34-C34) -> 20
A35: In-kind Partner | B35: =Packages!B10 -> 0 | C35: =COUNTIFS(Pipeline!$I$5:$I$304,"In-kind Partner",Pipeline!$H$5:$H$304,"Signed")+COUNTIFS(Pipeline!$I$5:$I$304,"In-kind Partner",Pipeline!$H$5:$H$304,"Paid") -> 0 | D35: =Packages!D10 -> 6 | E35: =MAX(0,D35-C35) -> 6
A36: VIP Corporate Table | B36: =Packages!B11 -> 1500 | C36: =COUNTIFS(Pipeline!$I$5:$I$304,"VIP Corporate Table",Pipeline!$H$5:$H$304,"Signed")+COUNTIFS(Pipeline!$I$5:$I$304,"VIP Corporate Table",Pipeline!$H$5:$H$304,"Paid") -> 0 | D36: =Packages!D11 -> 6 | E36: =MAX(0,D36-C36) -> 6

Sheet Pipeline
A1: CCCL SPONSORSHIP PIPELINE
A2: One row per business. Move the Stage as things happen. Only 'Paid' counts as money in the bank. Yellow columns are yours to fill in; grey ones come from research.
A4: # | B4: Business | C4: Town | D4: Area | E4: Category | F4: Existing supporter? | G4: Suggested package | H4: Stage | I4: Package agreed | J4: Amount agreed ($) | K4: Amount paid ($) | L4: Show | M4: Owner | N4: Contact person | O4: Phone | P4: Email | Q4: Website | R4: Last contact | S4: Next follow-up | T4: Follow-up due? | U4: Why they fit | V4: Notes | W4: Source
A5: 1 | B5: Dillabough Millwrighting & Welding | C5: Bancroft | D5: North Hastings | E5: Millwright & welding shop | F5: Yes (2026 Title Sponsor) | G5: Title Sponsor | H5: Prospect | L5: Not booked yet | M5: Cody | T5: =IF(OR(B5="",H5="Paid",H5="Not now",S5=""),"",IF(S5<=TODAY(),"DUE","")) | U5: 2026 Title Sponsor ($7,500). Thank them first, then offer Title again for 2027 before anyone else. | W5: https://www.canpages.ca/page/ON/bancroft/dillabough-millwrighting-welding/7238519
A6: 2 | B6: Pinestone Resort & Conference Centre | C6: Haliburton | D6: Haliburton County | E6: Resort / golf / conference centre | F6: Yes (2026 sponsor) | G6: Bronze Sponsor | H6: Prospect | L6: Not booked yet | M6: Cody | O6: 705-457-1800 | P6: reservations@pinestone-resort.com | Q6: https://pinestone-resort.com/ | T6: =IF(OR(B6="",H6="Paid",H6="Not now",S6=""),"",IF(S6<=TODAY(),"DUE","")) | U6: Haliburton resort with 18-hole golf, Stone 21 dining and event space a few minutes from A.J. LaRue Arena; natural fit for fighter/out-of-town guest rooms or a weigh-in/after-party venue. | W6: https://kawarthanow.com/venue/1511/pinestone-resort-conference-centre
A7: 3 | B7: Dixie Lee Fried Chicken (Bancroft) | C7: Bancroft | D7: North Hastings | E7: Restaurant (fast food) | F7: Yes (2026 sponsor) | G7: Bronze Sponsor | H7: Prospect | L7: Not booked yet | M7: Cody | O7: 613-703-7178 | Q7: https://www.dixieleefriedchicken.com/ | T7: =IF(OR(B7="",H7="Paid",H7="Not now",S7=""),"",IF(S7<=TODAY(),"DUE","")) | U7: Bancroft fried-chicken franchise at 121 Hastings St N; easy fit for fight-night food tie-ins or a fighter-meal promo. | W7: https://www.circulaire-en-ligne.ca/annuaire/ON/dixie-lee-fried-chicken/bancroft-121-hastings-st-n
A8: 4 | B8: IT STIX Signs & Graphics Inc. | C8: Bancroft | D8: North Hastings | E8: Sign shop / graphics / web design | F8: Yes (2026 sponsor) | G8: Bronze Sponsor | H8: Prospect | L8: Not booked yet | M8: Cody | O8: 613-334-5344 | P8: itstix@itstix.ca | Q8: https://itstix.ca/ | T8: =IF(OR(B8="",H8="Paid",H8="Not now",S8=""),"",IF(S8<=TODAY(),"DUE","")) | U8: Bancroft sign, banner and web-design shop; ideal in-kind partner for event banners and sponsor signage in exchange for logo placement. | W8: https://itstix.ca/contact/
A9: 5 | B9: Quality Cedar Products | C9: Bancroft | D9: North Hastings | E9: Building supply / lumber (western red cedar) | F9: Yes (logo on gym wall) | G9: Bronze Sponsor | H9: Prospect | L9: Not booked yet | M9: Cody | O9: 289-633-3335 | P9: sales@qualitycedarproducts.ca | Q9: https://www.qualitycedarproducts.ca/ | T9: =IF(OR(B9="",H9="Paid",H9="Not now",S9=""),"",IF(S9<=TODAY(),"DUE","")) | U9: Family-owned Bancroft cedar lumber supplier (decking, siding, sauna) selling to contractors across Ontario; already on the gym wall and sells to the trades crowd. | W9: https://www.qualitycedarproducts.ca/about
A10: 6 | B10: USG Fight Gear (probable match for 'USG' logo) | C10: Brampton | D10: other | E10: Combat sports gear maker | F10: Yes (logo on gym wall) | G10: Community Sponsor | H10: Prospect | L10: Not booked yet | M10: Cody | O10: 647-573-5433 | Q10: https://usgfightgear.com/ | T10: =IF(OR(B10="",H10="Paid",H10="Not now",S10=""),"",IF(S10<=TODAY(),"DUE","")) | U10: Ontario-made boxing/MMA gloves, shin guards and walkout gear, partnered with the Canadian Boxing Federation; most likely the stylized USG logo on the wall. Good for in-kind gear, prizes or fighter kits. | W10: https://usgfightgear.com/
A11: 7 | B11: Bryan Fraser Mechanical Services (not found; closest match Bryan Fraser Contracting Inc.) | C11: Golden Lake (unconfirmed match) | D11: other | E11: Contractor / trades | F11: Yes (logo on gym wall) | G11: Bronze Sponsor | H11: Prospect | L11: Not booked yet | M11: Cody | O11: 613-639-5569 | P11: bryanfraserinc@gmail.com | Q11: https://bryanfrasercontracting.com/ | T11: =IF(OR(B11="",H11="Paid",H11="Not now",S11=""),"",IF(S11<=TODAY(),"DUE","")) | U11: No 'Bryan Fraser Mechanical' found online. Bryan Fraser Contracting Inc. in Golden Lake (custom homes, renos, ICF, decks) exists but may be a different business; confirm with Cody. | V11: Unconfirmed: check the business name and details before contacting. | W11: https://bryanfrasercontracting.com/
A12: 8 | B12: ICO - International Combat Organisation | C12: UK-based (ICO Canada listed as 'TBA') | D12: other | E12: Combat sports sanctioning organization | F12: Yes (2026 sponsor) | G12: Community Sponsor | H12: Prospect | L12: Not booked yet | M12: Cody | O12: +44 7875 138526 | Q12: https://icokickboxing.org/ | T12: =IF(OR(B12="",H12="Paid",H12="Not now",S12=""),"",IF(S12<=TODAY(),"DUE","")) | U12: Amateur kickboxing/MMA/Muay Thai sanctioning body active in 45+ countries; its Canada branch is listed as 'TBA', so the wall logo is likely an affiliation. Treat as a credibility/affiliation partner, not a cash sponsor. | V12: Cody confirmed 'ICO' sponsored May 2, 2026. Which ICO is a guess from the logo: confirm the full name with Cody before contacting. | W12: https://icokickboxing.org/international-members/
A13: 9 | B13: Unidentified '...'s Daughter' boutique (possibly 'Barber's Daughter') | C13: Unverified | D13: other | E13: Clothing boutique | F13: Yes (logo on gym wall) | G13: Community Sponsor | H13: Prospect | L13: Not booked yet | M13: Cody | T13: =IF(OR(B13="",H13="Paid",H13="Not now",S13=""),"",IF(S13<=TODAY(),"DUE","")) | U13: No boutique ending in 'Daughter' found in the Bancroft chamber shopping list, Yellow Pages Haliburton-area clothing stores or My Haliburton Highlands; Facebook pages called 'The Barbers Daughter' exist but none confirmed local. Check the logo or ask Cody. | V13: Unconfirmed: check the business name and details before contacting. | W13: https://bancroftontario.com/single-category/shopping-lifestyle/
A14: 10 | B14: Lockhart Bros. (Contracting) | C14: Unverified (likely Bancroft area) | D14: other | E14: Contractor / trades | F14: Yes (logo on gym wall) | G14: Bronze Sponsor | H14: Prospect | L14: Not booked yet | M14: Cody | Q14: https://www.facebook.com/lockhartbros/ | T14: =IF(OR(B14="",H14="Paid",H14="Not now",S14=""),"",IF(S14<=TODAY(),"DUE","")) | U14: Logo is on the BBG gym wall; a Facebook page 'Lockhart Bros.' exists, but no directory or website confirming town or services was found. Ask Cody for the contact. | V14: Unconfirmed: check the business name and details before contacting. | W14: https://www.facebook.com/lockhartbros/
A15: 11 | B15: R & R Property Services | C15: Unverified (likely Bancroft area) | D15: other | E15: Property services / contractor | F15: Yes (logo on gym wall) | G15: Bronze Sponsor | H15: Prospect | L15: Not booked yet | M15: Cody | Q15: https://www.facebook.com/RR.PR0PERTYSERVICES/ | T15: =IF(OR(B15="",H15="Paid",H15="Not now",S15=""),"",IF(S15<=TODAY(),"DUE","")) | U15: Logo is on the BBG gym wall; a Facebook page named 'R & R Property Services' exists, but its town and services could not be confirmed online. Ask Cody for the contact. | V15: Unconfirmed: check the business name and details before contacting. | W15: https://www.facebook.com/RR.PR0PERTYSERVICES/
A16: 12 | B16: Thomas Contracting | C16: Algonquin Highlands | D16: Haliburton County | E16: Excavation / construction | G16: Community Sponsor | H16: Prospect | L16: Not booked yet | M16: Cody | O16: 705-489-2711 | P16: excavate@thomascontracting.ca | T16: =IF(OR(B16="",H16="Paid",H16="Not now",S16=""),"",IF(S16<=TODAY(),"DUE","")) | U16: Excavation and construction contractor on Hwy 35; local trades business reaching homeowners and cottagers. | W16: https://marketplace.thehighlander.ca/?p=405
A17: 13 | B17: Total Site Services | C17: Dysart et al (Haliburton) | D17: Haliburton County | E17: Excavation / septic / wells | G17: Bronze Sponsor | H17: Prospect | L17: Not booked yet | M17: Cody | O17: 705-457-9558 | P17: info@totalsiteservices.ca | T17: =IF(OR(B17="",H17="Paid",H17="Not now",S17=""),"",IF(S17<=TODAY(),"DUE","")) | U17: Site clearing, excavation, septic and wells on Gelert Rd; heavy-equipment crews match the fight-night audience. | W17: https://marketplace.thehighlander.ca/?p=405
A18: 14 | B18: Sir Sam's Inn & Spa | C18: Eagle Lake (Haliburton) | D18: Haliburton County | E18: Resort / lodge | G18: Bronze Sponsor | H18: Prospect | L18: Not booked yet | M18: Cody | O18: 800-361-2188 | P18: info@sirsamsinn.com | Q18: https://www.sirsamsinn.com | T18: =IF(OR(B18="",H18="Paid",H18="Not now",S18=""),"",IF(S18<=TODAY(),"DUE","")) | U18: Upscale Haliburton resort that hosts weddings and group events; good for fighter/VIP rooms in exchange for a sponsor package. | W18: https://www.sirsamsinn.com
A19: 15 | B19: CARSTAR Haliburton | C19: Haliburton | D19: Haliburton County | E19: Auto repair / body shop | G19: Community Sponsor | H19: Prospect | L19: Not booked yet | M19: Cody | T19: =IF(OR(B19="",H19="Paid",H19="Not now",S19=""),"",IF(S19<=TODAY(),"DUE","")) | U19: 6,500 sq ft collision shop at 154 Industrial Park Dr (sister to CARSTAR Lindsay); local shop wanting name recognition with drivers. | W19: https://www.bodyshopbusiness.com/?p=179383
A20: 16 | B20: Canoe FM 100.9 (CKHA) | C20: Haliburton | D20: Haliburton County | E20: Media partner | G20: Bronze Sponsor | H20: Prospect | L20: Not booked yet | M20: Cody | O20: 705-457-1009 | P20: info@canoefm.com | Q20: https://canoefm.com | T20: =IF(OR(B20="",H20="Paid",H20="Not now",S20=""),"",IF(S20<=TODAY(),"DUE","")) | U20: MEDIA PARTNER: Haliburton community radio, and a proven local sponsor (sponsors the Haliburton Land Trust); propose on-air promo trade. | W20: https://www.canoefm.com
A21: 17 | B21: Country Pickin's | C21: Haliburton | D21: Haliburton County | E21: Clothing / footwear retailer | G21: Community Sponsor | H21: Prospect | L21: Not booked yet | M21: Cody | O21: 705-457-2726 | P21: info@countrypickinshaliburton.ca | T21: =IF(OR(B21="",H21="Paid",H21="Not now",S21=""),"",IF(S21<=TODAY(),"DUE","")) | U21: Haliburton footwear and fashion shop on Highland St; a local retailer reaching event-going shoppers. | W21: https://marketplace.thehighlander.ca/?p=405
A22: 18 | B22: Curry Chevrolet Buick GMC Ltd | C22: Haliburton | D22: Haliburton County | E22: Auto dealer | G22: Silver Sponsor | H22: Prospect | L22: Not booked yet | M22: Cody | O22: 705-457-2100 | Q22: https://currymotors.ca | T22: =IF(OR(B22="",H22="Paid",H22="Not now",S22=""),"",IF(S22<=TODAY(),"DUE","")) | U22: Haliburton's GM truck dealer on County Rd 21; pickups and trucks sell to the same 25-45 crowd that buys fight tickets. | W22: https://www.yellowpages.ca/search/si/1/Car+Dealers/Haliburton+ON
A23: 19 | B23: Emmerson Lumber | C23: Haliburton | D23: Haliburton County | E23: Building supply / lumber | G23: Bronze Sponsor | H23: Prospect | L23: Not booked yet | M23: Cody | O23: 705-457-1550 | P23: information@emmersonlumber.com | Q23: https://emmersonlumber.com | T23: =IF(OR(B23="",H23="Paid",H23="Not now",S23=""),"",IF(S23<=TODAY(),"DUE","")) | U23: Haliburton lumber and design centre that advertises heavily in The Highlander; contractors and trades customers are core fight-night ticket buyers. | W23: https://marketplace.thehighlander.ca/?p=405
A24: 20 | B24: Haliburton RPM (RPM Marinas) | C24: Haliburton | D24: Haliburton County | E24: Powersports / marine dealer | G24: Bronze Sponsor | H24: Prospect | L24: Not booked yet | M24: Cody | O24: 705-457-1473 | P24: info@haliburtonrpm.com | T24: =IF(OR(B24="",H24="Paid",H24="Not now",S24=""),"",IF(S24<=TODAY(),"DUE","")) | U24: Yamaha and Kawasaki boat and powersports showroom on County Rd 21 serving about 3,000 customers; good audience overlap for sleds and ATVs. | W24: https://marketplace.thehighlander.ca/?p=405
A25: 21 | B25: Haliburton Timber Mart | C25: Haliburton | D25: Haliburton County | E25: Building supply / hardware | G25: Bronze Sponsor | H25: Prospect | L25: Not booked yet | M25: Cody | O25: 705-457-2510 | Q25: https://timbermart.ca/en/ | T25: =IF(OR(B25="",H25="Paid",H25="Not now",S25=""),"",IF(S25<=TODAY(),"DUE","")) | U25: Proven local sponsor: listed as a 'Shooting Stars' business sponsor of the Haliburton Highlands Land Trust; serves local trades. | W25: https://www.haliburtonlandtrust.ca/landtruststar/
A26: 22 | B26: Hawk River Construction | C26: Haliburton | D26: Haliburton County | E26: Excavation / site prep / septic | G26: Bronze Sponsor | H26: Prospect | L26: Not booked yet | M26: Cody | O26: 705-457-1386 | P26: info@hawkriver.ca | T26: =IF(OR(B26="",H26="Paid",H26="Not now",S26=""),"",IF(S26<=TODAY(),"DUE","")) | U26: Haliburton site prep, roads, septic and excavation contractor; trades employers like seeing their name in front of local crowds. | W26: https://marketplace.thehighlander.ca/?p=405
A27: 23 | B27: The Highlander (newspaper) | C27: Haliburton | D27: Haliburton County | E27: Media partner | G27: Bronze Sponsor | H27: Prospect | L27: Not booked yet | M27: Cody | O27: 705-457-2900 | P27: Sales@TheHighlander.ca | Q27: https://thehighlander.ca | T27: =IF(OR(B27="",H27="Paid",H27="Not now",S27=""),"",IF(S27<=TODAY(),"DUE","")) | U27: MEDIA PARTNER: Haliburton County weekly that already covered CCCL ('Fight night coming to Haliburton County'); propose ad and coverage trade for logo placement. | W27: https://thehighlander.ca/advertise/
A28: 24 | B28: Haliburton Highlands Brewing | C28: Haliburton (Abbey Gardens) | D28: Haliburton County | E28: Brewery (ALCOHOL) | G28: Community Sponsor | H28: Prospect | L28: Not booked yet | M28: Cody | Q28: https://haliburtonhighlandsbrewing.ca | T28: =IF(OR(B28="",H28="Paid",H28="Not now",S28=""),"",IF(S28<=TODAY(),"DUE","")) | U28: Local craft brewery that champions Highlands events, artists and musicians. Alcohol sponsor: check venue and AGCO rules. | V28: ALCOHOL: Cody decides. Keep their logo off youth bouts and kids' content. | W28: https://haliburtonhighlandsbrewing.ca/aboutus
A29: 25 | B29: Haliburton Forest & Wild Life Reserve | C29: Haliburton (Dysart et al) | D29: Haliburton County | E29: Large regional employer / outdoor tourism | G29: Bronze Sponsor | H29: Prospect | L29: Not booked yet | M29: Cody | O29: 800-631-2198 | P29: reservations@haliburtonforest.com | T29: =IF(OR(B29="",H29="Paid",H29="Not now",S29=""),"",IF(S29<=TODAY(),"DUE","")) | U29: Major outdoor recreation, logging and tourism employer north of Haliburton; reaches outdoorsy locals and visitors. | W29: https://marketplace.thehighlander.ca/?p=405
A30: 26 | B30: Fowler Construction | C30: Haliburton (head office Bracebridge) | D30: Haliburton County | E30: Large regional employer / aggregate & paving | G30: Silver Sponsor | H30: Prospect | L30: Not booked yet | M30: Cody | O30: 705-457-9900 | Q30: https://fowler.ca | T30: =IF(OR(B30="",H30="Paid",H30="Not now",S30=""),"",IF(S30<=TODAY(),"DUE","")) | U30: Big road-building, aggregate and paving company with a Haliburton yard on Gelert Rd; large employer of exactly the crowd that fills arena seats. | W30: https://www.yellowpages.ca/search/si/1/Contractors/Haliburton+ON
A31: 27 | B31: Foodland Haliburton and Foodland Minden | C31: Haliburton / Minden | D31: Haliburton County | E31: Grocery | G31: Community Sponsor | H31: Prospect | L31: Not booked yet | M31: Cody | O31: 705-286-1121 | T31: =IF(OR(B31="",H31="Paid",H31="Not now",S31=""),"",IF(S31<=TODAY(),"DUE","")) | U31: Proven local supporter: the two area Foodland stores sold Haliburton County Huskies merchandise (400 hats, 300 shirts), per Minden Times. Haliburton 705-457-2242. | W31: https://mindentimes.ca/news/huskies-return-bolstered-by-community-support/
A32: 28 | B32: Hudson Henderson Insurance | C32: Haliburton / Minden / Bancroft / Lindsay | D32: Haliburton County | E32: Insurance broker | G32: Bronze Sponsor | H32: Prospect | L32: Not booked yet | M32: Cody | O32: 888-522-4999 | P32: info@hudsonhenderson.com | Q32: https://www.hudsonhenderson.com/ | T32: =IF(OR(B32="",H32="Paid",H32="Not now",S32=""),"",IF(S32<=TODAY(),"DUE","")) | U32: Cottage-country broker with offices in Haliburton, Minden, Bancroft and Lindsay, so one sponsorship covers every 2027 host town. | W32: https://www.hudsonhenderson.com/
A33: 29 | B33: Nomi Resort | C33: Harcourt | D33: Haliburton County | E33: Resort / restaurant / lounge | G33: Bronze Sponsor | H33: Prospect | L33: Not booked yet | M33: Cody | O33: 1-888-765-9951 | P33: stay@nomiresort.com | Q33: https://nomiresort.com | T33: =IF(OR(B33="",H33="Paid",H33="Not now",S33=""),"",IF(S33<=TODAY(),"DUE","")) | U33: Luxury resort with 8fifty restaurant and lounge in Harcourt, Cody's hometown; strong hometown story for a VIP table or presenting package. | W33: https://nomiresort.com
A34: 30 | B34: Boshkung Brewing | C34: Minden | D34: Haliburton County | E34: Brewery / restaurant (ALCOHOL) | G34: Bronze Sponsor | H34: Prospect | L34: Not booked yet | M34: Cody | O34: 705-286-2711 | Q34: https://boshkungbrewing.com | T34: =IF(OR(B34="",H34="Paid",H34="Not now",S34=""),"",IF(S34<=TODAY(),"DUE","")) | U34: Minden brewery and taproom now expanding into a full restaurant; a natural after-party or beer-garden partner. Alcohol sponsor: check venue and AGCO rules. | V34: ALCOHOL: Cody decides. Keep their logo off youth bouts and kids' content. | W34: https://www.boshkungbrewing.com
A35: 31 | B35: Floyd Hall Limited (insurance) | C35: Minden | D35: Haliburton County | E35: Insurance broker | G35: Community Sponsor | H35: Prospect | L35: Not booked yet | M35: Cody | O35: 705-286-1270 | T35: =IF(OR(B35="",H35="Paid",H35="Not now",S35=""),"",IF(S35<=TODAY(),"DUE","")) | U35: Proven local sponsor: listed as a 'Star Gazers' business sponsor of the Haliburton Highlands Land Trust. | W35: https://www.haliburtonlandtrust.ca/landtruststar/
A36: 32 | B36: RE/MAX Professionals North | C36: Minden | D36: Haliburton County | E36: Real estate brokerage | G36: Bronze Sponsor | H36: Prospect | L36: Not booked yet | M36: Cody | T36: =IF(OR(B36="",H36="Paid",H36="Not now",S36=""),"",IF(S36<=TODAY(),"DUE","")) | U36: Proven local sponsor: its Terry Carr team sponsors the Haliburton Land Trust, and at its Minden office opening the owners said they want to be involved in local events. | W36: https://thehighlander.ca/2020/08/25/re-max-professionals-celebrate-grand-opening/
A37: 33 | B37: Ridgewood Ford Sales Ltd | C37: Minden | D37: Haliburton County | E37: Auto dealer | G37: Bronze Sponsor | H37: Prospect | L37: Not booked yet | M37: Cody | O37: 705-286-2890 | Q37: https://ridgewoodford.com | T37: =IF(OR(B37="",H37="Paid",H37="Not now",S37=""),"",IF(S37<=TODAY(),"DUE","")) | U37: Minden Ford dealer on Hwy 35; F-series trucks and a Haliburton County customer base fit a ringside banner. | W37: https://www.yellowpages.ca/search/si/1/Car+Dealers/Haliburton+ON
A38: 34 | B38: The Rockcliffe - Moore Falls | C38: Minden | D38: Haliburton County | E38: Restaurant / bar (ALCOHOL) | G38: Community Sponsor | H38: Prospect | L38: Not booked yet | M38: Cody | P38: info@therockcliffe.ca | T38: =IF(OR(B38="",H38="Paid",H38="Not now",S38=""),"",IF(S38<=TODAY(),"DUE","")) | U38: Minden-area restaurant and bar that could host a viewing party or the after-party. Alcohol sponsor. | V38: ALCOHOL: Cody decides. Keep their logo off youth bouts and kids' content. | W38: https://marketplace.thehighlander.ca/?p=405
A39: 35 | B39: Harper Powersports & Marine | C39: Minden / Haliburton | D39: Haliburton County | E39: Powersports / marine dealer | G39: Silver Sponsor | H39: Prospect | L39: Not booked yet | M39: Cody | O39: 705-286-2750 | Q39: https://www.harper-marine.com | T39: =IF(OR(B39="",H39="Paid",H39="Not now",S39=""),"",IF(S39<=TODAY(),"DUE","")) | U39: Authorized BRP dealer (Ski-Doo, Can-Am, Sea-Doo) with Minden and Haliburton stores; sells sleds and side-by-sides to the same young rural crowd that buys fight tickets. | W39: https://www.harper-marine.com
A40: 36 | B40: Harcourt TIM-BR Mart | C40: Wilberforce (Harcourt area) | D40: Haliburton County | E40: Building supply / hardware | G40: Community Sponsor | H40: Prospect | L40: Not booked yet | M40: Cody | O40: 705-448-2268 | T40: =IF(OR(B40="",H40="Paid",H40="Not now",S40=""),"",IF(S40<=TODAY(),"DUE","")) | U40: Small Highlands East building centre near Harcourt, Cody's hometown; a hometown angle for a small banner. | W40: https://www.yellowpages.ca/search/si/1/Hardware+Stores/Bancroft+ON
A41: 37 | B41: 97.7 Moose FM / My Bancroft Now | C41: Bancroft | D41: North Hastings | E41: Media partner | G41: Bronze Sponsor | H41: Prospect | L41: Not booked yet | M41: Cody | O41: 613-332-1423 | Q41: https://www.mybancroftnow.com | T41: =IF(OR(B41="",H41="Paid",H41="Not now",S41=""),"",IF(S41<=TODAY(),"DUE","")) | U41: MEDIA PARTNER: Bancroft's commercial radio station and news site; propose on-air ticket giveaways and promo trade. | W41: https://www.mybancroftnow.com/contact-us/
...

Sheet Packages
A1: SPONSOR PACKAGES
A2: Cody's 2026 packages, used again for 2027 until he changes them. Prices, perks and slots in yellow can be changed. Slots per show are a suggestion.
A4: Package | B4: Price ($) | C4: What the sponsor gets | D4: Slots | E4: Status
A5: Title Sponsor | B5: 7500 | C5: Naming rights ("presented by"), top logo on the cage and banners, featured on posters, ads and social media, named at fighter introductions, own posts before and after, VIP seating, a booth or display, recognised as the leading partner. Biggest logo on the event shirt and "presented by" on the livestream. | D5: 1 | E5: 2026 package (Cody). Same for 2027 unless Cody changes it. 2026: Dillabough Millwrighting & Welding. Cody calls this level Platinum.
A6: Gold Sponsor | B6: 4000 | C6: Priority logo around the cage, featured on posters and ads, social media posts, several announcer mentions, VIP tickets, room for their banner and display. Large logo on the event shirt and the livestream. | D6: 2 | E6: 2026 package (Cody). Same for 2027 unless Cody changes it. Shirt and livestream sizes by level: confirmed by Cody (Oct 20, 2026).
A7: Silver Sponsor | B7: 2000 | C7: Logo on selected posters and promos, CCCL social media mention, shared banner space at the venue, announcer mention, free tickets, listed as an official sponsor. Logo on the event shirt and the livestream. | D7: 4 | E7: 2026 package (Cody). Same for 2027 unless Cody changes it. Quote $2,000 (the 2026 price) until Cody confirms. He listed Silver at $2,500 in Oct 2026.
A8: Bronze Sponsor | B8: 1000 | C8: Logo on selected ads, social media sponsor announcement, named in sponsor thank-yous, announcer mention, free admission tickets. Small logo on the event shirt and the livestream sponsor slide. | D8: 10 | E8: 2026 package (Cody). Same for 2027 unless Cody changes it.
A9: Community Sponsor | B9: 300 | C9: CCCL social media mention, name or logo in selected sponsor promos, listed as an official community supporter. Name on the event shirt and the livestream sponsor slide. $300-$500. | D9: 20 | E9: 2026 package (Cody). Same for 2027 unless Cody changes it. Price is the minimum of the $300-$500 range.
A10: In-kind Partner | B10: 0 | C10: Product, prizes or services instead of cash: fighter bags, a sampling table, gear, prize packs. Perks agreed one-on-one, roughly matching the cash level of the same value. | D10: 6 | E10: For brands that give product. Agreed by Cody case by case. Only cash counts toward the sponsorship goal. Anything a fighter receives must be worth under $300 in total, or they lose amateur status; belts, medals and trophies are fine. No raffle without a lottery licence.
A11: VIP Corporate Table | B11: 1500 | C11: Cage-side table for 8-10 guests (depends on the venue's tables) for a business to host staff or clients. | D11: 6 | E11: $1,500 a table (Cody); 6 sold in 2026. Seats 8-10 depending on the venue's tables (Kyle, Oct 2026).

Sheet Fulfilment
A1: SPONSOR DELIVERY CHECKLIST
A2: When a sponsor signs, add them here (pick from the list) and tick off each promise as it's done. Every sponsor should get everything they paid for.
A4: Business | B4: Package | C4: Show | D4: Logo file received | E4: Banner ordered | F4: Banner hung at show | G4: Own thank-you post | H4: Tagged in fight-week posts | I4: On poster | J4: On the livestream | K4: On the shirts | L4: Tickets / VIP seats sent | M4: Announcer shout-out | N4: Photo + thank-you sent after | O4: All done? | P4: Notes
A5: (Example) Lockhart Bros Contracting | B5: Bronze Sponsor | C5: Show 1 · 2027 | D5: Yes | E5: N/A | F5: N/A | G5: Yes | H5: No | I5: Yes | J5: No | K5: No | L5: No | M5: No | N5: No | O5: =IF(A5="","",IF(COUNTIF(D5:N5,"Yes")+COUNTIF(D5:N5,"N/A")=11,"DONE",11-COUNTIF(D5:N5,"Yes")-COUNTIF(D5:N5,"N/A")&" left")) -> 6 left | P5: Example row showing the format. Bronze gets a logo on ads and the shirt, not its own banner, so the two banner columns are N/A. Replace it with a real sponsor.
O6: =IF(A6="","",IF(COUNTIF(D6:N6,"Yes")+COUNTIF(D6:N6,"N/A")=11,"DONE",11-COUNTIF(D6:N6,"Yes")-COUNTIF(D6:N6,"N/A")&" left"))
O7: =IF(A7="","",IF(COUNTIF(D7:N7,"Yes")+COUNTIF(D7:N7,"N/A")=11,"DONE",11-COUNTIF(D7:N7,"Yes")-COUNTIF(D7:N7,"N/A")&" left"))
O8: =IF(A8="","",IF(COUNTIF(D8:N8,"Yes")+COUNTIF(D8:N8,"N/A")=11,"DONE",11-COUNTIF(D8:N8,"Yes")-COUNTIF(D8:N8,"N/A")&" left"))
O9: =IF(A9="","",IF(COUNTIF(D9:N9,"Yes")+COUNTIF(D9:N9,"N/A")=11,"DONE",11-COUNTIF(D9:N9,"Yes")-COUNTIF(D9:N9,"N/A")&" left"))
O10: =IF(A10="","",IF(COUNTIF(D10:N10,"Yes")+COUNTIF(D10:N10,"N/A")=11,"DONE",11-COUNTIF(D10:N10,"Yes")-COUNTIF(D10:N10,"N/A")&" left"))
O11: =IF(A11="","",IF(COUNTIF(D11:N11,"Yes")+COUNTIF(D11:N11,"N/A")=11,"DONE",11-COUNTIF(D11:N11,"Yes")-COUNTIF(D11:N11,"N/A")&" left"))
O12: =IF(A12="","",IF(COUNTIF(D12:N12,"Yes")+COUNTIF(D12:N12,"N/A")=11,"DONE",11-COUNTIF(D12:N12,"Yes")-COUNTIF(D12:N12,"N/A")&" left"))
O13: =IF(A13="","",IF(COUNTIF(D13:N13,"Yes")+COUNTIF(D13:N13,"N/A")=11,"DONE",11-COUNTIF(D13:N13,"Yes")-COUNTIF(D13:N13,"N/A")&" left"))
O14: =IF(A14="","",IF(COUNTIF(D14:N14,"Yes")+COUNTIF(D14:N14,"N/A")=11,"DONE",11-COUNTIF(D14:N14,"Yes")-COUNTIF(D14:N14,"N/A")&" left"))
O15: =IF(A15="","",IF(COUNTIF(D15:N15,"Yes")+COUNTIF(D15:N15,"N/A")=11,"DONE",11-COUNTIF(D15:N15,"Yes")-COUNTIF(D15:N15,"N/A")&" left"))
O16: =IF(A16="","",IF(COUNTIF(D16:N16,"Yes")+COUNTIF(D16:N16,"N/A")=11,"DONE",11-COUNTIF(D16:N16,"Yes")-COUNTIF(D16:N16,"N/A")&" left"))
O17: =IF(A17="","",IF(COUNTIF(D17:N17,"Yes")+COUNTIF(D17:N17,"N/A")=11,"DONE",11-COUNTIF(D17:N17,"Yes")-COUNTIF(D17:N17,"N/A")&" left"))
... O64: =IF(A64="","",IF(COUNTIF(D64:N64,"Yes")+COUNTIF(D64:N64,"N/A")=11,"DONE",11-COUNTIF(D64:N64,"Yes")-COUNTIF(D64:N64,"N/A")&" left"))
