Workbook

Sheet Start Here
A1: BBG & CCCL CONTACTS
A2: Everyone we work with, in one place: venues, gyms, media, suppliers, officials and partners. It stays the same from show to show.
A4: 1 | B4: What it's for | C4: The permanent address book. The Fight Night Kit's Recruitment and Press tabs are per-show working lists (you copy the Kit for each show); this sheet keeps the relationship from one show to the next.
A5: 2 | B5: Sponsors live elsewhere | C5: Sponsors and prospects stay in the CCCL Sponsorship Pipeline (stages, money, follow-ups). Only add a sponsor here if they're also a supplier or partner.
A6: 3 | B6: Log every contact | C6: On the Log tab, add one row each time someone calls, emails or meets a contact. 'Last contact' on the Contacts tab fills in by itself.
A7: 4 | B7: Next step and date | C7: Put the next step and its date on the Contacts tab. 'Due?' turns red when it's overdue, and Claude's morning report lists what's due.
A8: 5 | B8: Starting data | C8: 110 contacts from Kyle's research (Oct 2026): venues, gyms, media and the Athletics Commission. Public business contact details only. Check a number before relying on it.
A9: 6 | B9: Privacy | C9: Public business contacts only: no personal cell numbers, home addresses or anything about health. Members, kids and Second Chance participants never go in this sheet.
B11: Relationship
B12: Not contacted | C12: From research; nobody has reached out yet
B13: Cold | C13: Contacted, no real conversation yet
B14: Warm | C14: Talking, or worked together once
B15: Strong | C15: Worked together more than once; picks up when Cody calls
B16: Partner | C16: Formal or ongoing arrangement (e.g. a venue or gym we always use)
B17: Not a fit | C17: Keep for reference; don't chase
B19: Colours
B20: Yellow, blue text | C20: You type here
B21: Black, bold | C21: Calculated: don't type over it

Sheet Summary
A1: SUMMARY
A2: Who we know and how well, and what's due. Updates by itself.
A4: Type | B4: Not contacted | C4: Cold | D4: Warm | E4: Strong | F4: Partner | G4: Not a fit | H4: Total | I4: Due this week
A5: Venue | B5: =COUNTIFS(Contacts!$B$5:$B$264,$A5,Contacts!$G$5:$G$264,"Not contacted") -> 45 | C5: =COUNTIFS(Contacts!$B$5:$B$264,$A5,Contacts!$G$5:$G$264,"Cold") -> 0 | D5: =COUNTIFS(Contacts!$B$5:$B$264,$A5,Contacts!$G$5:$G$264,"Warm") -> 0 | E5: =COUNTIFS(Contacts!$B$5:$B$264,$A5,Contacts!$G$5:$G$264,"Strong") -> 1 | F5: =COUNTIFS(Contacts!$B$5:$B$264,$A5,Contacts!$G$5:$G$264,"Partner") -> 0 | G5: =COUNTIFS(Contacts!$B$5:$B$264,$A5,Contacts!$G$5:$G$264,"Not a fit") -> 0 | H5: =COUNTIFS(Contacts!$B$5:$B$264,$A5) -> 46 | I5: =COUNTIFS(Contacts!$B$5:$B$264,$A5,Contacts!$L$5:$L$264,"OVERDUE")+COUNTIFS(Contacts!$B$5:$B$264,$A5,Contacts!$L$5:$L$264,"TODAY")+COUNTIFS(Contacts!$B$5:$B$264,$A5,Contacts!$L$5:$L$264,"THIS WEEK") -> 0
A6: Gym | B6: =COUNTIFS(Contacts!$B$5:$B$264,$A6,Contacts!$G$5:$G$264,"Not contacted") -> 32 | C6: =COUNTIFS(Contacts!$B$5:$B$264,$A6,Contacts!$G$5:$G$264,"Cold") -> 0 | D6: =COUNTIFS(Contacts!$B$5:$B$264,$A6,Contacts!$G$5:$G$264,"Warm") -> 2 | E6: =COUNTIFS(Contacts!$B$5:$B$264,$A6,Contacts!$G$5:$G$264,"Strong") -> 0 | F6: =COUNTIFS(Contacts!$B$5:$B$264,$A6,Contacts!$G$5:$G$264,"Partner") -> 0 | G6: =COUNTIFS(Contacts!$B$5:$B$264,$A6,Contacts!$G$5:$G$264,"Not a fit") -> 0 | H6: =COUNTIFS(Contacts!$B$5:$B$264,$A6) -> 34 | I6: =COUNTIFS(Contacts!$B$5:$B$264,$A6,Contacts!$L$5:$L$264,"OVERDUE")+COUNTIFS(Contacts!$B$5:$B$264,$A6,Contacts!$L$5:$L$264,"TODAY")+COUNTIFS(Contacts!$B$5:$B$264,$A6,Contacts!$L$5:$L$264,"THIS WEEK") -> 0
A7: Media | B7: =COUNTIFS(Contacts!$B$5:$B$264,$A7,Contacts!$G$5:$G$264,"Not contacted") -> 27 | C7: =COUNTIFS(Contacts!$B$5:$B$264,$A7,Contacts!$G$5:$G$264,"Cold") -> 0 | D7: =COUNTIFS(Contacts!$B$5:$B$264,$A7,Contacts!$G$5:$G$264,"Warm") -> 2 | E7: =COUNTIFS(Contacts!$B$5:$B$264,$A7,Contacts!$G$5:$G$264,"Strong") -> 0 | F7: =COUNTIFS(Contacts!$B$5:$B$264,$A7,Contacts!$G$5:$G$264,"Partner") -> 0 | G7: =COUNTIFS(Contacts!$B$5:$B$264,$A7,Contacts!$G$5:$G$264,"Not a fit") -> 0 | H7: =COUNTIFS(Contacts!$B$5:$B$264,$A7) -> 29 | I7: =COUNTIFS(Contacts!$B$5:$B$264,$A7,Contacts!$L$5:$L$264,"OVERDUE")+COUNTIFS(Contacts!$B$5:$B$264,$A7,Contacts!$L$5:$L$264,"TODAY")+COUNTIFS(Contacts!$B$5:$B$264,$A7,Contacts!$L$5:$L$264,"THIS WEEK") -> 0
A8: Supplier | B8: =COUNTIFS(Contacts!$B$5:$B$264,$A8,Contacts!$G$5:$G$264,"Not contacted") -> 0 | C8: =COUNTIFS(Contacts!$B$5:$B$264,$A8,Contacts!$G$5:$G$264,"Cold") -> 0 | D8: =COUNTIFS(Contacts!$B$5:$B$264,$A8,Contacts!$G$5:$G$264,"Warm") -> 0 | E8: =COUNTIFS(Contacts!$B$5:$B$264,$A8,Contacts!$G$5:$G$264,"Strong") -> 0 | F8: =COUNTIFS(Contacts!$B$5:$B$264,$A8,Contacts!$G$5:$G$264,"Partner") -> 0 | G8: =COUNTIFS(Contacts!$B$5:$B$264,$A8,Contacts!$G$5:$G$264,"Not a fit") -> 0 | H8: =COUNTIFS(Contacts!$B$5:$B$264,$A8) -> 0 | I8: =COUNTIFS(Contacts!$B$5:$B$264,$A8,Contacts!$L$5:$L$264,"OVERDUE")+COUNTIFS(Contacts!$B$5:$B$264,$A8,Contacts!$L$5:$L$264,"TODAY")+COUNTIFS(Contacts!$B$5:$B$264,$A8,Contacts!$L$5:$L$264,"THIS WEEK") -> 0
A9: Official | B9: =COUNTIFS(Contacts!$B$5:$B$264,$A9,Contacts!$G$5:$G$264,"Not contacted") -> 0 | C9: =COUNTIFS(Contacts!$B$5:$B$264,$A9,Contacts!$G$5:$G$264,"Cold") -> 0 | D9: =COUNTIFS(Contacts!$B$5:$B$264,$A9,Contacts!$G$5:$G$264,"Warm") -> 1 | E9: =COUNTIFS(Contacts!$B$5:$B$264,$A9,Contacts!$G$5:$G$264,"Strong") -> 0 | F9: =COUNTIFS(Contacts!$B$5:$B$264,$A9,Contacts!$G$5:$G$264,"Partner") -> 0 | G9: =COUNTIFS(Contacts!$B$5:$B$264,$A9,Contacts!$G$5:$G$264,"Not a fit") -> 0 | H9: =COUNTIFS(Contacts!$B$5:$B$264,$A9) -> 1 | I9: =COUNTIFS(Contacts!$B$5:$B$264,$A9,Contacts!$L$5:$L$264,"OVERDUE")+COUNTIFS(Contacts!$B$5:$B$264,$A9,Contacts!$L$5:$L$264,"TODAY")+COUNTIFS(Contacts!$B$5:$B$264,$A9,Contacts!$L$5:$L$264,"THIS WEEK") -> 0
A10: Sponsor | B10: =COUNTIFS(Contacts!$B$5:$B$264,$A10,Contacts!$G$5:$G$264,"Not contacted") -> 0 | C10: =COUNTIFS(Contacts!$B$5:$B$264,$A10,Contacts!$G$5:$G$264,"Cold") -> 0 | D10: =COUNTIFS(Contacts!$B$5:$B$264,$A10,Contacts!$G$5:$G$264,"Warm") -> 0 | E10: =COUNTIFS(Contacts!$B$5:$B$264,$A10,Contacts!$G$5:$G$264,"Strong") -> 0 | F10: =COUNTIFS(Contacts!$B$5:$B$264,$A10,Contacts!$G$5:$G$264,"Partner") -> 0 | G10: =COUNTIFS(Contacts!$B$5:$B$264,$A10,Contacts!$G$5:$G$264,"Not a fit") -> 0 | H10: =COUNTIFS(Contacts!$B$5:$B$264,$A10) -> 0 | I10: =COUNTIFS(Contacts!$B$5:$B$264,$A10,Contacts!$L$5:$L$264,"OVERDUE")+COUNTIFS(Contacts!$B$5:$B$264,$A10,Contacts!$L$5:$L$264,"TODAY")+COUNTIFS(Contacts!$B$5:$B$264,$A10,Contacts!$L$5:$L$264,"THIS WEEK") -> 0
A11: Partner | B11: =COUNTIFS(Contacts!$B$5:$B$264,$A11,Contacts!$G$5:$G$264,"Not contacted") -> 0 | C11: =COUNTIFS(Contacts!$B$5:$B$264,$A11,Contacts!$G$5:$G$264,"Cold") -> 0 | D11: =COUNTIFS(Contacts!$B$5:$B$264,$A11,Contacts!$G$5:$G$264,"Warm") -> 0 | E11: =COUNTIFS(Contacts!$B$5:$B$264,$A11,Contacts!$G$5:$G$264,"Strong") -> 0 | F11: =COUNTIFS(Contacts!$B$5:$B$264,$A11,Contacts!$G$5:$G$264,"Partner") -> 0 | G11: =COUNTIFS(Contacts!$B$5:$B$264,$A11,Contacts!$G$5:$G$264,"Not a fit") -> 0 | H11: =COUNTIFS(Contacts!$B$5:$B$264,$A11) -> 0 | I11: =COUNTIFS(Contacts!$B$5:$B$264,$A11,Contacts!$L$5:$L$264,"OVERDUE")+COUNTIFS(Contacts!$B$5:$B$264,$A11,Contacts!$L$5:$L$264,"TODAY")+COUNTIFS(Contacts!$B$5:$B$264,$A11,Contacts!$L$5:$L$264,"THIS WEEK") -> 0
A12: Other | B12: =COUNTIFS(Contacts!$B$5:$B$264,$A12,Contacts!$G$5:$G$264,"Not contacted") -> 0 | C12: =COUNTIFS(Contacts!$B$5:$B$264,$A12,Contacts!$G$5:$G$264,"Cold") -> 0 | D12: =COUNTIFS(Contacts!$B$5:$B$264,$A12,Contacts!$G$5:$G$264,"Warm") -> 0 | E12: =COUNTIFS(Contacts!$B$5:$B$264,$A12,Contacts!$G$5:$G$264,"Strong") -> 0 | F12: =COUNTIFS(Contacts!$B$5:$B$264,$A12,Contacts!$G$5:$G$264,"Partner") -> 0 | G12: =COUNTIFS(Contacts!$B$5:$B$264,$A12,Contacts!$G$5:$G$264,"Not a fit") -> 0 | H12: =COUNTIFS(Contacts!$B$5:$B$264,$A12) -> 0 | I12: =COUNTIFS(Contacts!$B$5:$B$264,$A12,Contacts!$L$5:$L$264,"OVERDUE")+COUNTIFS(Contacts!$B$5:$B$264,$A12,Contacts!$L$5:$L$264,"TODAY")+COUNTIFS(Contacts!$B$5:$B$264,$A12,Contacts!$L$5:$L$264,"THIS WEEK") -> 0
A13: All | B13: =SUM(B5:B12) -> 104 | C13: =SUM(C5:C12) -> 0 | D13: =SUM(D5:D12) -> 5 | E13: =SUM(E5:E12) -> 1 | F13: =SUM(F5:F12) -> 0 | G13: =SUM(G5:G12) -> 0 | H13: =SUM(H5:H12) -> 110 | I13: =SUM(I5:I12) -> 0
A15: Follow-ups
A16: Overdue | B16: =COUNTIFS(Contacts!$L$5:$L$264,"OVERDUE") -> 0
A17: Due today | B17: =COUNTIFS(Contacts!$L$5:$L$264,"TODAY") -> 0
A18: Due in the next 7 days | B18: =COUNTIFS(Contacts!$L$5:$L$264,"THIS WEEK") -> 0
A19: Gone quiet | B19: =COUNTIFS(Contacts!$G$5:$G$264,"Strong",Contacts!$O$5:$O$264,">90")+COUNTIFS(Contacts!$G$5:$G$264,"Partner",Contacts!$O$5:$O$264,">90") -> 0 | C19: Strong or Partner contacts with no logged contact in 90+ days: worth a quick call.
A20: Contacts logged | B20: =COUNTA(Log!$B$5:$B$2000) -> 0

Sheet Contacts
A1: CONTACTS
A2: One row per organization. Type the next step and date; 'Last contact' comes from the Log tab. Filter by Type or Due?.
A4: Organization | B4: Type | C4: Town / area | D4: Contact (public business details) | E4: Website | F4: For | G4: Relationship | H4: Last contact | I4: Next step | J4: Next date | K4: Owner | L4: Due? | M4: Notes | N4: Source | O4: Days since
A5: New Tecumseth Recreation Centre (main arena) | B5: Venue | C5: Alliston (New Tecumseth) | D5: Town of New Tecumseth | F5: CCCL | G5: Not contacted | H5: =IF(A5="","",IF(COUNTIFS(Log!$B$5:$B$2000,A5)=0,"",SUMPRODUCT(MAX((Log!$B$5:$B$2000=A5)*Log!$A$5:$A$2000)))) | K5: Cody | L5: =IF(OR(A5="",J5=""),"",IF(J5<TODAY(),"OVERDUE",IF(J5=TODAY(),"TODAY",IF(J5<=TODAY()+7,"THIS WEEK","")))) | M5: Capacity: Main arena seats 750 (2021) Rate: Not published | N5: https://newtectimes.com/new-tecumseth-recreation-centre-getting-a-new-roof/ | O5: =IF(H5="","",TODAY()-H5)
A6: Nottawasaga Inn Resort - Trade Centre | B6: Venue | C6: Alliston (New Tecumseth) | D6: Nottawasaga Resort sales | F6: CCCL | G6: Not contacted | H6: =IF(A6="","",IF(COUNTIFS(Log!$B$5:$B$2000,A6)=0,"",SUMPRODUCT(MAX((Log!$B$5:$B$2000=A6)*Log!$A$5:$A$2000)))) | K6: Cody | L6: =IF(OR(A6="",J6=""),"",IF(J6<TODAY(),"OVERDUE",IF(J6=TODAY(),"TODAY",IF(J6<=TODAY()+7,"THIS WEEK","")))) | M6: Capacity: Trade Centre 20,358 sq ft: 1,000 theatre / 1,000 banquet Rate: Not published | N6: https://www.successfulmeetings.com/Meeting-Event-Venues/Alliston-ON/Convention-Hotel/Nottawasaga-Inn-Resort-Conference-Ctr-p5578841 | O6: =IF(H6="","",TODAY()-H6)
A7: North Kawartha Community Centre (NKCC) | B7: Venue | C7: Apsley | D7: 705-656-4445; Shawn Tucker, Parks & Rec Supervisor, s.tucker@northkawartha.ca | F7: CCCL | G7: Not contacted | H7: =IF(A7="","",IF(COUNTIFS(Log!$B$5:$B$2000,A7)=0,"",SUMPRODUCT(MAX((Log!$B$5:$B$2000=A7)*Log!$A$5:$A$2000)))) | K7: Cody | L7: =IF(OR(A7="",J7=""),"",IF(J7<TODAY(),"OVERDUE",IF(J7=TODAY(),"TODAY",IF(J7<=TODAY()+7,"THIS WEEK","")))) | M7: Capacity: Arena floor not published; banquet hall up to 325 Rate: 2026, plus HST: arena special-event flat rate $600.00/day; hall $300/day + $50 kitchen/bar | N7: https://northkawartha.ca/living-here/facility-rentals | O7: =IF(H7="","",TODAY()-H7)
A8: North Hastings Community Centre (NHCC) arena | B8: Venue | C8: Bancroft | D8: 613-332-2062; communitycentre@bancroft.ca (2023) | F8: CCCL | G8: Not contacted | H8: =IF(A8="","",IF(COUNTIFS(Log!$B$5:$B$2000,A8)=0,"",SUMPRODUCT(MAX((Log!$B$5:$B$2000=A8)*Log!$A$5:$A$2000)))) | K8: Cody | L8: =IF(OR(A8="",J8=""),"",IF(J8<TODAY(),"OVERDUE",IF(J8=TODAY(),"TODAY",IF(J8<=TODAY()+7,"THIS WEEK","")))) | M8: Capacity: Not published Rate: Not published. The Town has said it wants year-round rentals; the arena ran a $207,350 deficit in 2023. | N8: https://bancroft.hosted.civiclive.com/living/recreation___leisure/north_hastings_community_centre | O8: =IF(H8="","",TODAY()-H8)
A9: Paul J. Yakabuski Community Centre (PJYCC) | B9: Venue | C9: Barry's Bay | D9: Hannah Gutoskie, 613-756-2747 ext. 220, recreation@madawaskavalley.ca | F9: CCCL | G9: Not contacted | H9: =IF(A9="","",IF(COUNTIFS(Log!$B$5:$B$2000,A9)=0,"",SUMPRODUCT(MAX((Log!$B$5:$B$2000=A9)*Log!$A$5:$A$2000)))) | K9: Cody | L9: =IF(OR(A9="",J9=""),"",IF(J9<TODAY(),"OVERDUE",IF(J9=TODAY(),"TODAY",IF(J9<=TODAY()+7,"THIS WEEK","")))) | M9: Capacity: Ice surface 800; upstairs Community Hall 285 Rate: 2026 Schedule of Fees: "PJYCC Renter Run Bar: downstairs ice surface" $1224; Municipal Run Bar downstairs $81… | N9: https://www.madawaskavalley.ca/recreation-tourism/facilities-rentals/paul-j-yakabuski-community-centre/ | O9: =IF(H9="","",TODAY()-H9)
A10: Belleville Armouries | B10: Venue | C10: Belleville | D10: Not found | F10: CCCL | G10: Not contacted | H10: =IF(A10="","",IF(COUNTIFS(Log!$B$5:$B$2000,A10)=0,"",SUMPRODUCT(MAX((Log!$B$5:$B$2000=A10)*Log!$A$5:$A$2000)))) | K10: Cody | L10: =IF(OR(A10="",J10=""),"",IF(J10<TODAY(),"OVERDUE",IF(J10=TODAY(),"TODAY",IF(J10<=TODAY()+7,"THIS WEEK","")))) | M10: Capacity: Not published Rate: Not published | N10: https://anishinabeknews.ca/2025/01/historic-mixed-martial-arts-event-will-be-staged-in-belleville/ | O10: =IF(H10="","",TODAY()-H10)
A11: Quinte Sports & Wellness Centre - main bowl (City lists 'CIBC Place'; Wikipedia: CAA Arena) | B11: Venue | C11: Belleville | D11: rentals@belleville.ca, 613-966-4632 | F11: CCCL | G11: Not contacted | H11: =IF(A11="","",IF(COUNTIFS(Log!$B$5:$B$2000,A11)=0,"",SUMPRODUCT(MAX((Log!$B$5:$B$2000=A11)*Log!$A$5:$A$2000)))) | K11: Cody | L11: =IF(OR(A11="",J11=""),"",IF(J11<TODAY(),"OVERDUE",IF(J11=TODAY(),"TODAY",IF(J11<=TODAY()+7,"THIS WEEK","")))) | M11: Capacity: Over 4,400 (City) / 4,365 hockey (Wikipedia); other pads 300, 200, 400 seats Rate: City page (excl. HST, year not stated): adult ball hockey/floor $119.75/hr, minor $81.75/hr; "Benefit Exhibit… | N11: https://www.belleville.ca/learn-and-play/facilities-and-rentals/arenas/ | O11: =IF(H11="","",TODAY()-H11)
A12: Bobcaygeon/Verulam Community Centre | B12: Venue | C12: Bobcaygeon | D12: 705-738-3331 | F12: CCCL | G12: Not contacted | H12: =IF(A12="","",IF(COUNTIFS(Log!$B$5:$B$2000,A12)=0,"",SUMPRODUCT(MAX((Log!$B$5:$B$2000=A12)*Log!$A$5:$A$2000)))) | K12: Cody | L12: =IF(OR(A12="",J12=""),"",IF(J12<TODAY(),"OVERDUE",IF(J12=TODAY(),"TODAY",IF(J12<=TODAY()+7,"THIS WEEK","")))) | M12: Capacity: Hall 200 Rate: Not published | N12: https://www.kawarthalakes.ca/explore-play/facility-and-park-rentals/community-hall-rentals/ | O12: =IF(H12="","",TODAY()-H12)
A13: Bracebridge Sportsplex | B13: Venue | C13: Bracebridge | D13: Town of Bracebridge 705-645-5264 | F13: CCCL | G13: Not contacted | H13: =IF(A13="","",IF(COUNTIFS(Log!$B$5:$B$2000,A13)=0,"",SUMPRODUCT(MAX((Log!$B$5:$B$2000=A13)*Log!$A$5:$A$2000)))) | K13: Cody | L13: =IF(OR(A13="",J13=""),"",IF(J13<TODAY(),"OVERDUE",IF(J13=TODAY(),"TODAY",IF(J13<=TODAY()+7,"THIS WEEK","")))) | M13: Capacity: Not published Rate: Not published | N13: https://www.bracebridge.ca/be-active/recreation-facilities-and-rentals/ | O13: =IF(H13="","",TODAY()-H13)
A14: Muskoka Lumber Arena (Muskoka Lumber Community Centre) | B14: Venue | C14: Bracebridge | D14: Josh Taylor, Bookings, 705-645-3037 ext. 3763, jtaylor@bracebridge.ca | F14: CCCL | G14: Not contacted | H14: =IF(A14="","",IF(COUNTIFS(Log!$B$5:$B$2000,A14)=0,"",SUMPRODUCT(MAX((Log!$B$5:$B$2000=A14)*Log!$A$5:$A$2000)))) | K14: Cody | L14: =IF(OR(A14="",J14=""),"",IF(J14<TODAY(),"OVERDUE",IF(J14=TODAY(),"TODAY",IF(J14<=TODAY()+7,"THIS WEEK","")))) | M14: Capacity: Not published Rate: Not published | N14: https://www.bracebridge.ca/be-active/recreation-facilities-and-rentals/ | O14: =IF(H14="","",TODAY()-H14)
A15: Sunny Life Recreation & Wellness Centre | B15: Venue | C15: Campbellford | D15: bookings@trenthills.ca; 705-653-1900 | F15: CCCL | G15: Not contacted | H15: =IF(A15="","",IF(COUNTIFS(Log!$B$5:$B$2000,A15)=0,"",SUMPRODUCT(MAX((Log!$B$5:$B$2000=A15)*Log!$A$5:$A$2000)))) | K15: Cody | L15: =IF(OR(A15="",J15=""),"",IF(J15<TODAY(),"OVERDUE",IF(J15=TODAY(),"TODAY",IF(J15<=TODAY()+7,"THIS WEEK","")))) | M15: Capacity: Not published Rate: Not published | N15: https://trenthills.ca/parks-recreation-community/sunny-life-recreation-wellness-centre | O15: =IF(H15="","",TODAY()-H15)
A16: Coboconk Community Centre (hall) | B16: Venue | C16: Coboconk | D16: City Facility Booking 705-324-9411 ext. 1226 | F16: CCCL | G16: Not contacted | H16: =IF(A16="","",IF(COUNTIFS(Log!$B$5:$B$2000,A16)=0,"",SUMPRODUCT(MAX((Log!$B$5:$B$2000=A16)*Log!$A$5:$A$2000)))) | K16: Cody | L16: =IF(OR(A16="",J16=""),"",IF(J16<TODAY(),"OVERDUE",IF(J16=TODAY(),"TODAY",IF(J16<=TODAY()+7,"THIS WEEK","")))) | M16: Capacity: 175 Rate: Not published | N16: https://www.kawarthalakes.ca/explore-play/facility-and-park-rentals/community-hall-rentals/ | O16: =IF(H16="","",TODAY()-H16)
... A50: Keith Tallman Memorial Arena | B50: Venue | C50: Wilberforce | D50: Highlands East municipal office | F50: CCCL | G50: Not contacted | H50: =IF(A50="","",IF(COUNTIFS(Log!$B$5:$B$2000,A50)=0,"",SUMPRODUCT(MAX((Log!$B$5:$B$2000=A50)*Log!$A$5:$A$2000)))) | K50: Cody | L50: =IF(OR(A50="",J50=""),"",IF(J50<TODAY(),"OVERDUE",IF(J50=TODAY(),"TODAY",IF(J50<=TODAY()+7,"THIS WEEK","")))) | M50: Capacity: Not published Rate: Highlands East page (year not stated): "Summer Prime Time ... $40 plus HST" per hour, "Summer Non-Prime ... $… | N50: https://www.highlandseast.ca/municipal-services/fees/facility-fees/ | O50: =IF(H50="","",TODAY()-H50)
A51: Ontario Athletics Commission | B51: Official | C51: Toronto (province-wide) | D51: AthleticsComm@ontario.ca; 416-326-0416 | E51: https://www.ontario.ca/page/amateur-combative-sports | F51: CCCL | G51: Warm | H51: =IF(A51="","",IF(COUNTIFS(Log!$B$5:$B$2000,A51)=0,"",SUMPRODUCT(MAX((Log!$B$5:$B$2000=A51)*Log!$A$5:$A$2000)))) | K51: Cody | L51: =IF(OR(A51="",J51=""),"",IF(J51<TODAY(),"OVERDUE",IF(J51=TODAY(),"TODAY",IF(J51<=TODAY()+7,"THIS WEEK","")))) | M51: Event permit ($600 per show), officials, rules questions, post-event report within 14 days. | N51: https://www.ontario.ca/page/amateur-combative-sports | O51: =IF(H51="","",TODAY()-H51)
A52: Empire Mixed Martial Arts & Fitness | B52: Gym | C52: Barrie | D52: info@empiremma.ca; 705-728-8885; 100 Caplan Ave Unit 8, Barrie (Let's Roll directory) | E52: https://empiremma.ca/ | F52: CCCL | G52: Not contacted | H52: =IF(A52="","",IF(COUNTIFS(Log!$B$5:$B$2000,A52)=0,"",SUMPRODUCT(MAX((Log!$B$5:$B$2000=A52)*Log!$A$5:$A$2000)))) | K52: Cody | L52: =IF(OR(A52="",J52=""),"",IF(J52<TODAY(),"OVERDUE",IF(J52=TODAY(),"TODAY",IF(J52<=TODAY()+7,"THIS WEEK","")))) | N52: https://letsroll.co/gym/empire-mixed-martial-arts-fitness-barrie-on | O52: =IF(H52="","",TODAY()-H52)
A53: Legacy Fight Club | B53: Gym | C53: Barrie | D53: teamlegacy.assistance@gmail.com; text (249) 501-9937; 351 King St Unit 7, Barrie | E53: https://www.legacyfightclub.com/ | F53: CCCL | G53: Not contacted | H53: =IF(A53="","",IF(COUNTIFS(Log!$B$5:$B$2000,A53)=0,"",SUMPRODUCT(MAX((Log!$B$5:$B$2000=A53)*Log!$A$5:$A$2000)))) | K53: Cody | L53: =IF(OR(A53="",J53=""),"",IF(J53<TODAY(),"OVERDUE",IF(J53=TODAY(),"TODAY",IF(J53<=TODAY()+7,"THIS WEEK","")))) | M53: At the edge of the 3 h radius. Barrie has its own shows (MM-Eh lists 'Fight Night Barrie', Nov 20 2026). | N53: https://www.legacyfightclub.com/ | O53: =IF(H53="","",TODAY()-H53)
A54: Infinite Martial Arts & Fitness | B54: Gym | C54: Belleville | D54: Info@Infinite-MMA.com; (613) 969-7653; 315 Bell Blvd, Belleville | E54: https://infinite-mma.com/ | F54: CCCL | G54: Not contacted | H54: =IF(A54="","",IF(COUNTIFS(Log!$B$5:$B$2000,A54)=0,"",SUMPRODUCT(MAX((Log!$B$5:$B$2000=A54)*Log!$A$5:$A$2000)))) | K54: Cody | L54: =IF(OR(A54="",J54=""),"",IF(J54<TODAY(),"OVERDUE",IF(J54=TODAY(),"TODAY",IF(J54<=TODAY()+7,"THIS WEEK","")))) | M54: The best MMA-style gym found in the Quinte area. Contact it for any Marmora or Madoc show. | N54: https://infinite-mma.com/ | O54: =IF(H54="","",TODAY()-H54)
A55: Pinnacle Boxing Academy | B55: Gym | C55: Belleville | D55: No official contact found. Ask Boxing Ontario or check the club's social pages. | F55: CCCL | G55: Not contacted | H55: =IF(A55="","",IF(COUNTIFS(Log!$B$5:$B$2000,A55)=0,"",SUMPRODUCT(MAX((Log!$B$5:$B$2000=A55)*Log!$A$5:$A$2000)))) | K55: Cody | L55: =IF(OR(A55="",J55=""),"",IF(J55<TODAY(),"OVERDUE",IF(J55=TODAY(),"TODAY",IF(J55<=TODAY()+7,"THIS WEEK","")))) | M55: Boxing only. Runs its own boxing club shows. | N55: https://www.inquinte.ca/2025/10/local-boxers-fight-their-way-to-medals-at-provincial-championships/ | O55: =IF(H55="","",TODAY()-H55)
A56: Big Country - Muskoka | B56: Gym | C56: Bracebridge | D56: bigcountrymuskoka@gmail.com; 705-706-1631; 75 Manitoba St, Bracebridge | E56: https://bigcountrymuskoka.gymdesk.com/ | F56: CCCL | G56: Not contacted | H56: =IF(A56="","",IF(COUNTIFS(Log!$B$5:$B$2000,A56)=0,"",SUMPRODUCT(MAX((Log!$B$5:$B$2000=A56)*Log!$A$5:$A$2000)))) | K56: Cody | L56: =IF(OR(A56="",J56=""),"",IF(J56<TODAY(),"OVERDUE",IF(J56=TODAY(),"TODAY",IF(J56<=TODAY()+7,"THIS WEEK","")))) | N56: https://bigcountrymuskoka.gymdesk.com/ | O56: =IF(H56="","",TODAY()-H56)
A57: United Brazilian Jiu-Jitsu & Muay Thai | B57: Gym | C57: Cobourg | D57: (905) 375-3113 (own site; email masked); 1040 Division St, Cobourg (directory) | E57: http://unitedbjj.ca/ | F57: CCCL | G57: Not contacted | H57: =IF(A57="","",IF(COUNTIFS(Log!$B$5:$B$2000,A57)=0,"",SUMPRODUCT(MAX((Log!$B$5:$B$2000=A57)*Log!$A$5:$A$2000)))) | K57: Cody | L57: =IF(OR(A57="",J57=""),"",IF(J57<TODAY(),"OVERDUE",IF(J57=TODAY(),"TODAY",IF(J57<=TODAY()+7,"THIS WEEK","")))) | N57: http://unitedbjj.ca/ | O57: =IF(H57="","",TODAY()-H57)
A58: The Chop Shop MMA | B58: Gym | C58: Haliburton | D58: 705-854-3773; 175 Industrial Park Rd Unit A, Haliburton; Facebook /TheChopShopHaliburton; Instagram @thechopshophaliburton | E58: https://www.thechopshop.ca/ | F58: CCCL | G58: Not contacted | H58: =IF(A58="","",IF(COUNTIFS(Log!$B$5:$B$2000,A58)=0,"",SUMPRODUCT(MAX((Log!$B$5:$B$2000=A58)*Log!$A$5:$A$2000)))) | K58: Cody | L58: =IF(OR(A58="",J58=""),"",IF(J58<TODAY(),"OVERDUE",IF(J58=TODAY(),"TODAY",IF(J58<=TODAY()+7,"THIS WEEK","")))) | M58: Closest gym to CCCL's Haliburton venue. Good for youth grappling bouts and as a local co-host. | N58: https://www.thechopshop.ca/ | O58: =IF(H58="","",TODAY()-H58)
A59: Grizzly Gym | B59: Gym | C59: Kingston | D59: mike@grizzlygym.com (decoded from its site); 613-483-7522; 541 Days Rd, Kingston | E59: https://www.grizzlygym.com/ | F59: CCCL | G59: Warm | H59: =IF(A59="","",IF(COUNTIFS(Log!$B$5:$B$2000,A59)=0,"",SUMPRODUCT(MAX((Log!$B$5:$B$2000=A59)*Log!$A$5:$A$2000)))) | K59: Cody | L59: =IF(OR(A59="",J59=""),"",IF(J59<TODAY(),"OVERDUE",IF(J59=TODAY(),"TODAY",IF(J59<=TODAY()+7,"THIS WEEK","")))) | M59: Has already sent a fighter to CCCL. Strong partner for a Kingston show. | N59: https://www.sherdog.com/fighter/Joshua-Henshaw-355453 | O59: =IF(H59="","",TODAY()-H59)
A60: Hayabusa Academy | B60: Gym | C60: Kingston | D60: info@Hayabusa-Academy.com; 613-484-5455; 677 Innovation Dr Unit 7, Kingston | E60: https://www.hayabusa-academy.com/ | F60: CCCL | G60: Not contacted | H60: =IF(A60="","",IF(COUNTIFS(Log!$B$5:$B$2000,A60)=0,"",SUMPRODUCT(MAX((Log!$B$5:$B$2000=A60)*Log!$A$5:$A$2000)))) | K60: Cody | L60: =IF(OR(A60="",J60=""),"",IF(J60<TODAY(),"OVERDUE",IF(J60=TODAY(),"TODAY",IF(J60<=TODAY()+7,"THIS WEEK","")))) | M60: Confirm the current owners and whether it is still operating. The Chop Shop's owners can introduce you. | N60: https://www.hayabusa-academy.com/ | O60: =IF(H60="","",TODAY()-H60)
A61: Jiu-Jitsu Kingston | B61: Gym | C61: Kingston | D61: Contact form on its site; (613) 449-8616 / 343-321-5852; 654 Norris Ct, Kingston | E61: https://jiu-jitsukingston.com/ | F61: CCCL | G61: Not contacted | H61: =IF(A61="","",IF(COUNTIFS(Log!$B$5:$B$2000,A61)=0,"",SUMPRODUCT(MAX((Log!$B$5:$B$2000=A61)*Log!$A$5:$A$2000)))) | K61: Cody | L61: =IF(OR(A61="",J61=""),"",IF(J61<TODAY(),"OVERDUE",IF(J61=TODAY(),"TODAY",IF(J61<=TODAY()+7,"THIS WEEK","")))) | M61: CORRECTION: earlier research listed 'Kingston Jiu Jitsu'. kingstonjiujitsu.com is a UK academy in Kingston upon Thames. The Kingston, Ontario gym is Jiu-Jitsu Kingston (jiu-jitsukingston.co… | N61: https://jiu-jitsukingston.com/ | O61: =IF(H61="","",TODAY()-H61)
A62: Kingston Combat Wrestling Club | B62: Gym | C62: Kingston | D62: Club contact on the OAWA club listing (https://www.oawa.ca/oawa-club-listing); the listed email is a personal address, so it isn't copied here | F62: CCCL | G62: Not contacted | H62: =IF(A62="","",IF(COUNTIFS(Log!$B$5:$B$2000,A62)=0,"",SUMPRODUCT(MAX((Log!$B$5:$B$2000=A62)*Log!$A$5:$A$2000)))) | K62: Cody | L62: =IF(OR(A62="",J62=""),"",IF(J62<TODAY(),"OVERDUE",IF(J62=TODAY(),"TODAY",IF(J62<=TODAY()+7,"THIS WEEK","")))) | N62: https://www.oawa.ca/oawa-club-listing | O62: =IF(H62="","",TODAY()-H62)
A63: Kingston Wrestling Club | B63: Gym | C63: Kingston | D63: Marcus Niemann: kingstonwrestling@hotmail.com (OAWA club listing) | F63: CCCL | G63: Not contacted | H63: =IF(A63="","",IF(COUNTIFS(Log!$B$5:$B$2000,A63)=0,"",SUMPRODUCT(MAX((Log!$B$5:$B$2000=A63)*Log!$A$5:$A$2000)))) | K63: Cody | L63: =IF(OR(A63="",J63=""),"",IF(J63<TODAY(),"OVERDUE",IF(J63=TODAY(),"TODAY",IF(J63<=TODAY()+7,"THIS WEEK","")))) | N63: https://www.oawa.ca/oawa-club-listing | O63: =IF(H63="","",TODAY()-H63)
A64: Nomad Martial Arts & Fitness | B64: Gym | C64: Kingston | D64: alimo@nomadma.net; 613-519-2588; The Bunker, 1300 Bath Rd, Kingston | E64: https://nomadma.net/ | F64: CCCL | G64: Not contacted | H64: =IF(A64="","",IF(COUNTIFS(Log!$B$5:$B$2000,A64)=0,"",SUMPRODUCT(MAX((Log!$B$5:$B$2000=A64)*Log!$A$5:$A$2000)))) | K64: Cody | L64: =IF(OR(A64="",J64=""),"",IF(J64<TODAY(),"OVERDUE",IF(J64=TODAY(),"TODAY",IF(J64<=TODAY()+7,"THIS WEEK","")))) | N64: https://nomadma.net/ | O64: =IF(H64="","",TODAY()-H64)
A65: TRACK2 Brazilian Jiu-Jitsu | B65: Gym | C65: Kingston | D65: hello@track2.ca (Let's Roll directory, not confirmed on the gym's site); 559 Bagot St, Kingston | E65: https://track2.ca/ | F65: CCCL | G65: Not contacted | H65: =IF(A65="","",IF(COUNTIFS(Log!$B$5:$B$2000,A65)=0,"",SUMPRODUCT(MAX((Log!$B$5:$B$2000=A65)*Log!$A$5:$A$2000)))) | K65: Cody | L65: =IF(OR(A65="",J65=""),"",IF(J65<TODAY(),"OVERDUE",IF(J65=TODAY(),"TODAY",IF(J65<=TODAY()+7,"THIS WEEK","")))) | N65: https://letsroll.co/gym/track2-brazilian-jiu-jitsu-kingston-on | O65: =IF(H65="","",TODAY()-H65)
A66: YGK Combatives Group | B66: Gym | C66: Kingston | D66: Contact page on its site (email masked); 613-389-7378 (directory listing); 745 Development Dr, Kingston | E66: https://www.ygkcombativesgroup.com/ | F66: CCCL | G66: Not contacted | H66: =IF(A66="","",IF(COUNTIFS(Log!$B$5:$B$2000,A66)=0,"",SUMPRODUCT(MAX((Log!$B$5:$B$2000=A66)*Log!$A$5:$A$2000)))) | K66: Cody | L66: =IF(OR(A66="",J66=""),"",IF(J66<TODAY(),"OVERDUE",IF(J66=TODAY(),"TODAY",IF(J66<=TODAY()+7,"THIS WEEK","")))) | N66: https://www.ygkcombativesgroup.com/ | O66: =IF(H66="","",TODAY()-H66)
A67: van Jango Studio of Martial Arts | B67: Gym | C67: Kingston | D67: manager@vanjango.com; 343-333-8433; 629 Division St (lower level), Kingston | E67: https://www.vanjango.com/ | F67: CCCL | G67: Not contacted | H67: =IF(A67="","",IF(COUNTIFS(Log!$B$5:$B$2000,A67)=0,"",SUMPRODUCT(MAX((Log!$B$5:$B$2000=A67)*Log!$A$5:$A$2000)))) | K67: Cody | L67: =IF(OR(A67="",J67=""),"",IF(J67<TODAY(),"OVERDUE",IF(J67=TODAY(),"TODAY",IF(J67<=TODAY()+7,"THIS WEEK","")))) | N67: https://www.sherdog.com/fighter/Jesse-Van-Vlack-464451 | O67: =IF(H67="","",TODAY()-H67)
A68: Big Country MMA - Lindsay | B68: Gym | C68: Lindsay | D68: bigcountrymma1@gmail.com; 705-344-2662; 50 Mary St W, Lindsay | E68: https://bigcountrylindsay.gymdesk.com/ | F68: CCCL | G68: Warm | H68: =IF(A68="","",IF(COUNTIFS(Log!$B$5:$B$2000,A68)=0,"",SUMPRODUCT(MAX((Log!$B$5:$B$2000=A68)*Log!$A$5:$A$2000)))) | K68: Cody | L68: =IF(OR(A68="",J68=""),"",IF(J68<TODAY(),"OVERDUE",IF(J68=TODAY(),"TODAY",IF(J68<=TODAY()+7,"THIS WEEK","")))) | M68: The best partner gym: it already sends several fighters per card. Head coach Joe Elliott (BJJ black, Muay Thai red) teaches across all three Big Country locations. | N68: https://bigcountrylindsay.gymdesk.com/page/home | O68: =IF(H68="","",TODAY()-H68)
A69: Big Country - Orillia | B69: Gym | C69: Orillia | D69: orilliabigcountry@gmail.com; 27 West St S, Orillia | E69: https://bigcountryorillia.gymdesk.com | F69: CCCL | G69: Not contacted | H69: =IF(A69="","",IF(COUNTIFS(Log!$B$5:$B$2000,A69)=0,"",SUMPRODUCT(MAX((Log!$B$5:$B$2000=A69)*Log!$A$5:$A$2000)))) | K69: Cody | L69: =IF(OR(A69="",J69=""),"",IF(J69<TODAY(),"OVERDUE",IF(J69=TODAY(),"TODAY",IF(J69<=TODAY()+7,"THIS WEEK","")))) | N69: https://bigcountryorillia.gymdesk.com | O69: =IF(H69="","",TODAY()-H69)
A70: Mariposa Wrestling Club | B70: Gym | C70: Orillia | D70: Club contact on the OAWA club listing (https://www.oawa.ca/oawa-club-listing); the listed email is a personal address, so it isn't copied here | F70: CCCL | G70: Not contacted | H70: =IF(A70="","",IF(COUNTIFS(Log!$B$5:$B$2000,A70)=0,"",SUMPRODUCT(MAX((Log!$B$5:$B$2000=A70)*Log!$A$5:$A$2000)))) | K70: Cody | L70: =IF(OR(A70="",J70=""),"",IF(J70<TODAY(),"OVERDUE",IF(J70=TODAY(),"TODAY",IF(J70<=TODAY()+7,"THIS WEEK","")))) | N70: https://www.oawa.ca/oawa-club-listing | O70: =IF(H70="","",TODAY()-H70)
A71: Surge MMA | B71: Gym | C71: Orléans (Ottawa) | D71: SMS (343) 600-3066; email masked on site; 180 Vanguard Dr, Orléans | E71: https://www.surgemma.com/ | F71: CCCL | G71: Not contacted | H71: =IF(A71="","",IF(COUNTIFS(Log!$B$5:$B$2000,A71)=0,"",SUMPRODUCT(MAX((Log!$B$5:$B$2000=A71)*Log!$A$5:$A$2000)))) | K71: Cody | L71: =IF(OR(A71="",J71=""),"",IF(J71<TODAY(),"OVERDUE",IF(J71=TODAY(),"TODAY",IF(J71<=TODAY()+7,"THIS WEEK","")))) | M71: A competing promoter on the eastern edge of the range. Possible fighter-exchange partner, but expect it to prioritise its own cards. | N71: https://www.eventbrite.ca/e/next-wave-combat-tickets-1990798629291 | O71: =IF(H71="","",TODAY()-H71)
A72: Mamute Martial Arts | B72: Gym | C72: Oshawa | D72: info@mamutemaa.com; (647) 648-1662; 907 Simcoe St N, Oshawa | E72: https://mamutemaa.com/ | F72: CCCL | G72: Not contacted | H72: =IF(A72="","",IF(COUNTIFS(Log!$B$5:$B$2000,A72)=0,"",SUMPRODUCT(MAX((Log!$B$5:$B$2000=A72)*Log!$A$5:$A$2000)))) | K72: Cody | L72: =IF(OR(A72="",J72=""),"",IF(J72<TODAY(),"OVERDUE",IF(J72=TODAY(),"TODAY",IF(J72<=TODAY()+7,"THIS WEEK","")))) | N72: https://mamutemaa.com/ | O72: =IF(H72="","",TODAY()-H72)
A73: Oshawa BJJ & Fitness | B73: Gym | C73: Oshawa | D73: mocaiberbjj@gmail.com; 289-980-0484; 350 Wentworth St E Unit 4-5, Oshawa (waiver lists 1160 Simcoe St S) | E73: https://oshawabjj.com/ | F73: CCCL | G73: Not contacted | H73: =IF(A73="","",IF(COUNTIFS(Log!$B$5:$B$2000,A73)=0,"",SUMPRODUCT(MAX((Log!$B$5:$B$2000=A73)*Log!$A$5:$A$2000)))) | K73: Cody | L73: =IF(OR(A73="",J73=""),"",IF(J73<TODAY(),"OVERDUE",IF(J73=TODAY(),"TODAY",IF(J73<=TODAY()+7,"THIS WEEK","")))) | M73: Good source of youth grapplers. A BBG 12-year-old won gold at the Durham Classic BJJ event in Oshawa (Feb 2026). | N73: https://oshawabjj.com/ | O73: =IF(H73="","",TODAY()-H73)
A74: Evolution Jiu Jitsu (Petawawa) | B74: Gym | C74: Petawawa | D74: evolutionbjjpetawawa@hotmail.com; 613-687-2833; Army Fitness Centre, 3 Festubert Blvd Bldg Q-103, Petawawa | F74: CCCL | G74: Not contacted | H74: =IF(A74="","",IF(COUNTIFS(Log!$B$5:$B$2000,A74)=0,"",SUMPRODUCT(MAX((Log!$B$5:$B$2000=A74)*Log!$A$5:$A$2000)))) | K74: Cody | L74: =IF(OR(A74="",J74=""),"",IF(J74<TODAY(),"OVERDUE",IF(J74=TODAY(),"TODAY",IF(J74<=TODAY()+7,"THIS WEEK","")))) | M74: On CFB Petawawa, with a military athlete pool. About as close to Bancroft as Peterborough, via Barry's Bay. | N74: https://cfmws.ca/petawawa/evolution-jiu-jitsu-club | O74: =IF(H74="","",TODAY()-H74)
...

Sheet Log
A1: CONTACT LOG
A2: One row every time someone calls, emails, texts or meets a contact. Newest at the bottom. Copy the next step and date onto the Contacts tab.
A4: Date | B4: Organization (pick from Contacts) | C4: Who (staff) | D4: How | E4: What happened | F4: Next step | G4: Next date
