Workbook

Sheet Start Here
A1: THE CONSTRICTOR FUNDING TRACKER
A2: Grants and programs that fit BBG, CCCL, Second Chance and gym families: who can apply, when, and where each application stands.
A4: 1 | B4: What's here | C4: 35 programs researched on 2026-10-18: 18 BBG, CCCL or families can use now, 13 that open up once Second Chance is a nonprofit or charity, and the rest for reference. The Not Eligible tab lists ones that don't fit and why.
A5: 2 | B5: Check before relying | C5: Programs change every year. Before planning around a date or amount, open the source link and check the current intake. The Confidence column says how sure the research was.
A6: 3 | B6: Track it | C6: For each program you go after, set Our status, the Next deadline and the Owner. 'Days left' counts down and the Summary tab shows what's due in the next 60 days.
A7: 4 | B7: Apply | C7: Ask Claude: "draft the Canada Summer Jobs application". It drafts from real facts only and marks the gaps for you. You review and submit. The Application Kit tab lists what funders usually ask for.
A8: 5 | B8: Money | C8: A grant counts on the Money Summary only when it's paid into the bank. Approved grants usually come with reports and receipts: put the report date in 'Report due'.
A9: 6 | B9: Second Chance | C9: Most nonprofit funding needs an incorporated nonprofit (some need a registered charity). Keep Second Chance's applications and money separate from BBG and CCCL.
B11: Colours
B12: Yellow, blue text | C12: You type or pick here
B13: Black, bold | C13: Calculated: don't type over it

Sheet Summary
A1: SUMMARY
A2: What's open to us, where each application stands, and what's due.
A4: For | B4: Programs | C4: Yes, now | D4: After nonprofit or charity | E4: Applied (submitted) | F4: Approved | G4: Approved $
A5: BBG | B5: =COUNTIFS(Programs!$D$5:$D$79,"*BBG*") -> 16 | C5: =COUNTIFS(Programs!$D$5:$D$79,"*BBG*",Programs!$E$5:$E$79,"Yes, now") -> 13 | D5: =COUNTIFS(Programs!$D$5:$D$79,"*BBG*",Programs!$E$5:$E$79,"After*") -> 1 | E5: =COUNTIFS(Programs!$D$5:$D$79,"*BBG*",Programs!$O$5:$O$79,"Submitted") -> 0 | F5: =COUNTIFS(Programs!$D$5:$D$79,"*BBG*",Programs!$O$5:$O$79,"Approved") -> 0 | G5: =SUMIFS(Programs!$T$5:$T$79,Programs!$D$5:$D$79,"*BBG*",Programs!$O$5:$O$79,"Approved") -> 0
A6: CCCL | B6: =COUNTIFS(Programs!$D$5:$D$79,"*CCCL*") -> 13 | C6: =COUNTIFS(Programs!$D$5:$D$79,"*CCCL*",Programs!$E$5:$E$79,"Yes, now") -> 11 | D6: =COUNTIFS(Programs!$D$5:$D$79,"*CCCL*",Programs!$E$5:$E$79,"After*") -> 0 | E6: =COUNTIFS(Programs!$D$5:$D$79,"*CCCL*",Programs!$O$5:$O$79,"Submitted") -> 0 | F6: =COUNTIFS(Programs!$D$5:$D$79,"*CCCL*",Programs!$O$5:$O$79,"Approved") -> 0 | G6: =SUMIFS(Programs!$T$5:$T$79,Programs!$D$5:$D$79,"*CCCL*",Programs!$O$5:$O$79,"Approved") -> 0
A7: Second Chance | B7: =COUNTIFS(Programs!$D$5:$D$79,"*Second Chance*") -> 17 | C7: =COUNTIFS(Programs!$D$5:$D$79,"*Second Chance*",Programs!$E$5:$E$79,"Yes, now") -> 2 | D7: =COUNTIFS(Programs!$D$5:$D$79,"*Second Chance*",Programs!$E$5:$E$79,"After*") -> 13 | E7: =COUNTIFS(Programs!$D$5:$D$79,"*Second Chance*",Programs!$O$5:$O$79,"Submitted") -> 0 | F7: =COUNTIFS(Programs!$D$5:$D$79,"*Second Chance*",Programs!$O$5:$O$79,"Approved") -> 0 | G7: =SUMIFS(Programs!$T$5:$T$79,Programs!$D$5:$D$79,"*Second Chance*",Programs!$O$5:$O$79,"Approved") -> 0
A8: Families | B8: =COUNTIFS(Programs!$D$5:$D$79,"*Families*") -> 2 | C8: =COUNTIFS(Programs!$D$5:$D$79,"*Families*",Programs!$E$5:$E$79,"Yes, now") -> 1 | D8: =COUNTIFS(Programs!$D$5:$D$79,"*Families*",Programs!$E$5:$E$79,"After*") -> 0 | E8: =COUNTIFS(Programs!$D$5:$D$79,"*Families*",Programs!$O$5:$O$79,"Submitted") -> 0 | F8: =COUNTIFS(Programs!$D$5:$D$79,"*Families*",Programs!$O$5:$O$79,"Approved") -> 0 | G8: =SUMIFS(Programs!$T$5:$T$79,Programs!$D$5:$D$79,"*Families*",Programs!$O$5:$O$79,"Approved") -> 0
A10: Deadlines
A11: Due in the next 14 days | B11: =COUNTIFS(Programs!$Q$5:$Q$79,">=0",Programs!$Q$5:$Q$79,"<=14",Programs!$O$5:$O$79,"<>Submitted",Programs!$O$5:$O$79,"<>Approved",Programs!$O$5:$O$79,"<>Declined") -> 0
A12: Due in the next 60 days | B12: =COUNTIFS(Programs!$Q$5:$Q$79,">=0",Programs!$Q$5:$Q$79,"<=60",Programs!$O$5:$O$79,"<>Submitted",Programs!$O$5:$O$79,"<>Approved",Programs!$O$5:$O$79,"<>Declined") -> 2
A13: Deadline passed, not applied | B13: =COUNTIFS(Programs!$Q$5:$Q$79,"<0",Programs!$O$5:$O$79,"<>Submitted",Programs!$O$5:$O$79,"<>Approved",Programs!$O$5:$O$79,"<>Declined",Programs!$O$5:$O$79,"<>Not eligible",Programs!$O$5:$O$79,"<>Not now") -> 0
A14: Reports due in the next 30 days | B14: =COUNTIFS(Programs!$U$5:$U$79,">="&TODAY(),Programs!$U$5:$U$79,"<="&(TODAY()+30)) -> 0
A16: Programs can count under more than one 'For'.

Sheet Programs
A1: PROGRAMS
A2: Researched programs (left) and where we stand with each (right, in yellow). Check the source before relying on a date or amount.
A4: Program | B4: Funder | C4: Level | D4: For | E4: Can we apply? | F4: Who can apply | G4: What it funds | H4: Amount | I4: Intake / deadline | J4: Program status | K4: Matching money | L4: How to apply | M4: Source | N4: Confidence | O4: Our status | P4: Next deadline | Q4: Days left | R4: Owner | S4: Amount asked | T4: Amount approved | U4: Report due | V4: Notes
A5: CFDC Young Entrepreneur Loan Fund | B5: CFDC North & Central Hastings and South Algonquin | C5: Regional | D5: BBG, CCCL | E5: Yes, now | F5: Business owners aged 18 to 39 in North & Central Hastings and South Algonquin | G5: Business start-up or growth | H5: Up to $30,000; no fees, no payments for the first year, prime + 2.5%, term up to 5 years | I5: Continuous | J5: Rolling | K5: Loan | L5: Contact Carolyn Barker Brown at 613-332-5564 ext. 203 | M5: https://community-futures.ca/services-programs/business-loans/ | N5: High | O5: Not started | Q5: =IF(P5="","",P5-TODAY()) | V5: Cody is 18-39 (Cody, Oct 20, 2026), so he qualifies on age. Only if Cody (or a co-owner) is 39 or younger.
A6: Canada Small Business Financing Program (CSBFP) | B6: Innovation, Science and Economic Development Canada (delivered by banks and credit unions) | C6: Federal | D6: BBG, CCCL | E6: Yes, now | F6: Small businesses or start-ups operating in Canada with gross annual revenues of $10 million or less (farming excluded) | G6: Government-backed loans for equipment, leasehold improvements, real property, intangible assets and working capital; lines of credit | H6: Up to $1.15M per borrower: term loans up to $1M (max $500K for leasehold improvements and equipment, of which up to $15… | I6: Continuous | J6: Rolling | K6: Loan, not a grant. 2% registration fee; interest capped (floating term loans at lender prime + 3%; lines of credit prim… | L6: Ask a financial officer at your bank or credit union for a CSBFP loan; the lender approves and registers it | M6: https://ised-isde.canada.ca/site/canada-small-business-financing-program/en/find-loan-your-small-business/about-program/helping-small-businesses-get-loans | N6: High | O6: Not started | Q6: =IF(P6="","",P6-TODAY()) | V6: Cody is thinking about a new or bigger space (Cody, Oct 20, 2026): CSBFP loans can cover leasehold improvements and equipment as well as gear. Good route for gym equipment (mats, ring, bags) or a cag…
A7: Canada Summer Jobs 2027 (private-sector employer rate) | B7: Employment and Social Development Canada (ESDC) | C7: Federal | D7: BBG, CCCL | E7: Yes, now | F7: Not-for-profits, public-sector employers, and private-sector (for-profit) employers with 50 or fewer full-time employees | G7: Wage subsidy for summer jobs for youth aged 15 to 30 (e.g., youth program assistant coaches, camp staff, event and marketing assistants) | H7: Private sector: up to 50% of the provincial adult minimum hourly wage; mandatory employment-related costs (MERCs) are n… | I7: CSJ 2027 call opens October 27, 2026 at 9:00 am ET (canada.ca, modified Sept 29, 2026). Closing date not yet posted (the 2026 call ran Nov… | J7: Open since Oct 27, 2026 (close date not posted yet) | K7: Employer pays the remaining ~50% of wages plus all MERCs | L7: Apply online through the CSJ applicant guide's 'Apply now' section once the call opens Oct 27, 2026 | M7: https://www.canada.ca/en/employment-social-development/services/funding/canada-summer-jobs/applicant-guide.html | N7: High | O7: Drafting | Q7: =IF(P7="","",P7-TODAY()) | V7: Opens Oct 27, 2026 at 9 am ET. Open BBG's CRA payroll (RP) account first: the form asks for it. Draft application ready for Cody. Cody wants a funded summer student (Cody, Oct 20, 2026). The form's first question asks for the payroll (RP) number, and BBG only has a business number: open the CRA payroll account now (CSJ opened O…
A8: Canadian Tire Jumpstart Individual Child Grants | B8: Canadian Tire Jumpstart Charities | C8: Private | D8: Families | E8: Yes, now | F8: Parents or guardians of children aged 4 to 18 meeting Low-Income Cut-Off (LICO) criteria; funds go to the program provider, which must be a registered business… | G8: Registration (and equipment) costs for sustained sport or physical activity programs: at least 5 weeks with one session per week, or camps of 5+ consecutive days | H8: Up to $300 per child per year (2026), subject to chapter discretion and local demand | I8: 2026 program is open; apply before the program starts; payment takes 6-8 weeks | J8: Open | K8: None | L8: Parent creates an account on the Jumpstart Individual Child Grant page and applies with a Canada Child Benefit statement and program details | M8: https://jumpstart.canadiantire.ca/pages/individual-child-grants | N8: High | O8: Tell families | Q8: =IF(P8="","",P8-TODAY()) | V8: BBG is already signed up to take Jumpstart grants (Cody, Oct 20, 2026). FAQ (https://jumpstart.canadiantire.ca/pages/faq) confirms the payee can be a 'registered business', so a for-profit gym like B…
A9: Community Futures (CFDC of North & Central Hastings and South Algonquin) Business Loans | B9: CFDC North & Central Hastings and South Algonquin (Bancroft; FedDev-supported Community Futures) | C9: Regional | D9: BBG, CCCL, Second Chance | E9: Yes, now | F9: Businesses and social enterprises in its service area (Town of Bancroft, Hastings Highlands, Centre Hastings, Tweed, Marmora and Lake, Madoc, Faraday, Limerick… | G9: Operating costs, equipment, inventory, leasehold improvements, commercial real estate | H9: Up to $300,000 (Ready Money microloans up to $10,000); CANtrade Opportunity Fund up to $150,000 for tariff-affected bus… | I9: Continuous | J9: Rolling | K9: Loan; rates, terms and security set by risk; no prepayment penalties | L9: Call 613-332-5564, meet a loan officer, then submit the Loan Application (or Ready Money form) with a cash flow projection | M9: https://community-futures.ca/services-programs/business-loans/ | N9: High | O9: Not started | Q9: =IF(P9="","",P9-TODAY()) | V9: BBG is in the CFDC area (Bancroft). Free business advice is a good first stop for the bigger-space plans (Cody, Oct 20, 2026). Office at 26 Chemaushgon Rd, Bancroft. Second Chance fits only if it run…
A10: Futurpreneur Core Startup Program (with BDC) | B10: Futurpreneur Canada (national non-profit) with Business Development Bank of Canada | C10: Federal | D10: CCCL | E10: Yes, now | F10: Entrepreneurs aged 18 to 39 (Canadian citizen or PR) whose business is pre-startup or has less than a year of significant sales | G10: Start-up loans plus up to two years of 1:1 mentorship | H10: Up to $75,000 total: up to $25,000 from Futurpreneur (RBC prime + 3%, capped at 9%) and up to $50,000 from BDC (BDC flo… | I10: Continuous | J10: Rolling | K10: Loan, not a grant; 1% loan management fee on the Futurpreneur portion | L10: Sign up on futurpreneur.ca to be contacted, or submit a business plan and 24-month cash flow through the MyFP portal | M10: https://futurpreneur.ca/en/offering/core-startup/ | N10: High | O10: Not started | Q10: =IF(P10="","",P10-TODAY()) | V10: Cody is 18-39 and runs BBG and CCCL as two businesses (Cody, Oct 20, 2026). CCCL's first show was May 2, 2026, so CCCL has under a year of sales and may qualify; BBG opened in 2025, so it probably do…
A11: Starter Company Plus (Hastings County delivery) | B11: Government of Ontario, delivered by the Small Business Centre at the Quinte Business Development Centre (Belleville) | C11: Provincial | D11: BBG, CCCL | E11: Yes, now | F11: Ontario residents 18+, not in school full-time, starting, expanding or buying a business; the Belleville centre serves businesses registered in Hastings County… | G11: Business training, mentoring and a start-up/expansion grant | H11: Grant up to $5,000 | I11: 2026 local intake ran Apr 13 to May 22, 2026. 2027 dates not posted (expect spring 2027) | J11: Closed (2027 intake unknown) | K11: Applicant contributes cash or in-kind equal to at least 25% of the grant | L11: Apply through the Small Business Centre (info@smallbusinessctr.com, 613-961-0590) | M11: https://ontario.ca/page/starter-company-plus | N11: High | O11: Not started | Q11: =IF(P11="","",P11-TODAY()) | V11: Local intake details: https://www.smallbusinessctr.com/services/. Ask the centre whether one owner can enter two businesses (BBG and CCCL).
A12: CFDC Youth Business Marketing Grant | B12: CFDC North & Central Hastings and South Algonquin | C12: Regional | D12: BBG, CCCL | E12: Yes, now | F12: Business owners aged 18 to 39 in the CFDC area | G12: One-on-one digital marketing consultation | H12: Approx. $500 | I12: Not stated (contact office) | J12: Unknown | K12: None stated | L12: Contact Melanie Wright at 613-332-5564 ext. 210 | M12: https://community-futures.ca/services-programs/economic-development/ | N12: Medium | O12: Not started | Q12: =IF(P12="","",P12-TODAY()) | V12: Cody is 18-39 (Cody, Oct 20, 2026), so he qualifies on age. A quick win for CCCL or BBG marketing. Small, but quick to get; age 18-39 only.
A13: Community Coaching Grant (Coaches Association of Ontario and Hydro One) | B13: Coaches Association of Ontario with Hydro One | C13: Private | D13: BBG | E13: Yes, now | F13: Individual sport coaches in Ontario at any level; organizations may apply for a group of coaches if the coaches directly benefit | G13: Safety training (NCCP or other safety-focused courses), replacing outdated or unsafe equipment (mats, protective gear), other safe-sport costs | H13: Up to $1,000 per recipient (at least 40 grants in 2026) | I13: 2026 applications closed June 5, 2026 (opened in May); 2027 dates not posted | J13: Closed (2027 intake likely spring 2027) | K13: None; expenses before acceptance are ineligible | L13: Online application on the CAO Safe Sport 101 grant page when it reopens | M13: https://safesport101.coachesontario.ca/grant/ | N13: Medium | O13: Not started | Q13: =IF(P13="","",P13-TODAY()) | V13: Because individual coaches can apply, for-profit status is not a barrier here. Scoring rewards specific items and quantities, how they improve safety or access (with data), and a detailed budget. 202…
A14: Community Sport and Recreation Infrastructure Fund: Stream 2 (New Builds / Signature New Builds) | B14: Ontario Ministry of Sport | C14: Provincial | D14: BBG | E14: Yes, now | F14: Municipalities, Indigenous communities, local services boards, not-for-profits, and for-profit organizations that operate or manage a space offering sport or r… | G14: New sport and recreation infrastructure, including repurposing or expanding existing structures to create net-new facilities | H14: Up to $10 million (more for Signature New Builds); no minimum stated | I14: Applications due Tuesday, December 22, 2026, 4 pm ET | J14: Open | K14: For-profit provincial share capped at 25%; applicant covers the rest. Cannot stack with other Ontario funding for the s… | L14: Apply per the CSRIF guidelines on ontario.ca (contact csrif@ontario.ca) | M14: https://www.ontario.ca/document/community-sport-and-recreation-infrastructure-fund/stream-2-new-buildssignature-new-builds | N14: Medium | O14: Not started | P14: 46378 | Q14: =IF(P14="","",P14-TODAY()) -> 56 | V14: Only for new or expanded facilities; the province pays at most 25%. Cody is thinking about a new or bigger gym space (Cody, Oct 20, 2026). Stream 2 only funds new builds and asks for audited financial statements, which is a big cost for a small sole proprietorship (B…
A15: Ontario's Highlands Tourism Organization (RTO 11) membership and Come Wander marketing partnerships | B15: Ontario's Highlands Tourism Organization (OHTO) | C15: Regional | D15: CCCL, BBG | E15: Yes, now | F15: Businesses, organizations or individuals that operate in Ontario's Highlands and/or deliver services to visitors (membership is free for tourism participants) | G15: Free marketing exposure: Come Wander content features, social posts, website features, newsletters, influencer and photo-shoot partnerships; early notice of grants; free member training | H15: No cash funding currently ('None at this time' for funding opportunities) | I15: Membership year-round | J15: Rolling (no funding open) | K15: None stated | L15: Register through the OHTO member portal (ohto.ca/become-a-member) and contact the marketing department or book a Discovery Call | M15: https://ohto.ca/programs-resources/funding-partnership-opportunities | N15: Medium | O15: Not started | Q15: =IF(P15="","",P15-TODAY()) | V15: Joining lets OHTO flag funding to CCCL when it appears (members were previously eligible for a 'TRIP' skills development funding program). Marketing programs: https://ohto.ca/programs-resources/marke…
A16: CFDC Façade Improvement Grant Program | B16: CFDC North & Central Hastings and South Algonquin | C16: Regional | D16: BBG | E16: Yes, now | F16: Legally registered small or medium-sized businesses in the CFDC service area, on commercially zoned property | G16: Façade improvements under a Green (environmental) or Accessibility component | H16: Up to $3,000 non-repayable | I16: Page still shows costs must be incurred before March 31, 2025; current round unconfirmed | J16: Unknown | K16: Reimburses 50% of eligible costs | L16: Contact CFDC to confirm whether a current round is open | M16: https://community-futures.ca/services-programs/economic-development/ | N16: Low | O16: Not started | Q16: =IF(P16="","",P16-TODAY()) | V16: BBG leases its building (Cody, Oct 20, 2026): ask CFDC whether a tenant can apply (usually with the landlord's written OK). Only if BBG's building needs accessible entrances or green upgrades. Costs…
A17: Canadian Women & Sport Spotlight Grant | B17: Canadian Women & Sport | C17: Private | D17: BBG | E17: Yes, now | F17: Community sport and physical activity organizations (for-profit eligibility not stated) | G17: Projects removing barriers for girls from priority communities (2SLGBTQIA+, Black, Indigenous, racialized, low-income, disability, newcomer) | H17: $5,000 or $15,000 | I17: Not stated | J17: Unknown | K17: None stated | L17: Check the program page or email spotlight@womenandsport.ca | M17: https://womenandsport.ca/program/spotlight-grant | N17: Low | O17: Not started | Q17: =IF(P17="","",P17-TODAY()) | V17: Low-income girls in North Hastings could be the priority group; confirm eligibility of for-profit clubs.
A18: RTO8 (Kawarthas Northumberland) Partnership Funding Program | B18: Regional Tourism Organization 8 | C18: Regional | D18: CCCL | E18: Yes, now | F18: Established for-profit tourism businesses (incorporated or with an active CRA business number, selling directly to consumers) in Kawartha Lakes, Northumberland… | G18: Matched digital marketing campaigns for bookable experiences with an overnight stay (visitors travelling 40+ km), signage, studies, visual assets | H18: Partner contributions of $1,500 to $14,000, matched by RTO8 (not a grant) | I18: 2026-27 single intake closed Apr 6, 2026; 2027-28 not posted | J18: Closed (next intake unknown, likely spring 2027) | K18: Matched funding (partner pays its share) | L18: Download and submit the Partnership Funding Program application PDF during the intake | M18: https://rto8.com/2026-27-partnership-funding-program/ | N18: Low | O18: Not started | Q18: =IF(P18="","",P18-TODAY()) | V18: CCCL is based in RTO 11 territory, so it likely only qualifies if it runs a recurring show in Peterborough or Lindsay with a local partner (e.g., a venue or DMO applicant). Pair the show with hotel p…
A19: The Next Play (Canadian Women & Sport, funded by Ontario) | B19: Canadian Women & Sport with the Government of Ontario | C19: Private | D19: BBG | E19: Yes, now | F19: Ontario-based sport, physical activity and recreation organizations (for-profit eligibility not stated) | G19: Training on gender-inclusive program design plus a grant to run programs that engage and retain girls and gender-diverse youth | H19: Earlier rounds: $1,000 honorarium for completing training plus a $4,500 project grant (2024 details); 65 organizations… | I19: Annual spring intake (2025 opened late April); 2026 recipients already announced; 2027 not posted | J19: Closed (2027 intake unknown) | K19: None stated | L19: Apply through Canadian Women & Sport when the next round opens | M19: https://womenandsport.ca/resource/ontario-government-invests-in-the-next-play-for-20 | N19: Low | O19: Not started | Q19: =IF(P19="","",P19-TODAY()) | V19: Ask info@womenandsport.ca whether for-profit gyms qualify before investing time. Fits BBG's women's boxing and girls' programs.
A20: Tourism Kingston sport event funding | B20: Tourism Kingston | C20: Local | D20: CCCL | E20: Yes, now | F20: Organizers bringing sport events to Kingston; eligibility depends on event type, expected impact, length of stay and time of year | G20: Offsetting event hosting costs, including accommodation support | H20: Not stated | I20: Not stated | J20: Rolling (assumed; apply-now link on page) | K20: Not stated | L20: Use the 'apply now' form on Tourism Kingston's tournament and event hosting page | M20: https://www.visitkingston.ca/sport-tourism/tournament-event-hosting | N20: Low | O20: Not started | Q20: =IF(P20="","",P20-TODAY()) | V20: The page does not say whether for-profit promoters qualify; ask before planning a Kingston-area show. Room nights booked by fighters, teams and fans are the likely selling point.
A21: Town of Bancroft Community Improvement Plan (incl. Tax Increment Equivalent Grant) | B21: Town of Bancroft | C21: Local | D21: BBG | E21: Yes, now | F21: Property owners and businesses within the CIP area (details in the CIP document) | G21: Revitalization and redevelopment incentives for commercial properties; Tax Increment Equivalent Grant for improvements that raise assessed value | H21: Not stated on web pages; see CIP document | I21: Not stated | J21: Unknown | K21: Unknown | L21: Download the CIP and application form from the Town's CIP page or contact Bancroft Economic Development | M21: https://www.bancroft.ca/business/community_improvement_plan_and_application | N21: Low | O21: Not started | Q21: =IF(P21="","",P21-TODAY()) | V21: BBG is inside Bancroft's CIP area and leases its building (Cody, Oct 20, 2026). Worth asking the Town what a tenant can apply for, especially if BBG renovates or moves to a bigger space. CIP document…
A22: Town of Bancroft council grants and in-kind event support | B22: Town of Bancroft | C22: Local | D22: CCCL, Second Chance | E22: Yes, now | F22: Community organizations and events that request support from council (no formal published program found) | G22: Cash grants and in-kind municipal services for community events | H22: Historic example (2016): Rally of the Tall Pines got $5,000 cash plus $7,500 in services; Wheels/Water/Wings got $3,000… | I22: Requests reviewed in the annual budget process (2016 review was late March) | J22: Unknown | K22: Unknown | L22: Send a written request to council or Economic Development ahead of budget deliberations | M22: https://www.bancroftthisweek.com/bancroft-council-assesses-local-grants/ | N22: Low | O22: Not started | Q22: =IF(P22="","",P22-TODAY()) | V22: Source is a 2016 news article, not a current policy. For-profit status of CCCL may limit cash support; in-kind support (venue, arena, promotion) is the more realistic ask. Ask the Town if a current g…
A23: CFDC Local Initiatives Program | B23: CFDC North & Central Hastings and South Algonquin | C23: Regional | D23: Second Chance | E23: After nonprofit | F23: Incorporated not-for-profit organizations, municipalities and other incorporated community organizations in the catchment; unincorporated groups only if an inc… | G23: Incremental community economic development projects (capital or non-capital); not core operations, staff wages, basic websites, yearly festivals or construction | H23: Non-repayable, normally up to $3,000 | I23: One project per organization per fiscal year (Apr 1 to Mar 31); projects cannot run past March 31 | J23: Rolling (funding limited) | K23: None stated | L23: Contact the CFDC office before applying | M23: https://community-futures.ca/services-programs/economic-development/ | N23: High | O23: Not now | Q23: =IF(P23="","",P23-TODAY()) | V23: Good small first grant for Second Chance (e.g., an employer-partnership launch or resume workshop series). Hastings County's resource page lists this at up to $3,500; CFDC's own page says normally up…
A24: Canada Summer Jobs 2027 (not-for-profit employer rate) | B24: Employment and Social Development Canada (ESDC) | C24: Federal | D24: Second Chance | E24: After nonprofit | F24: Not-for-profit organizations (also public and small private employers at the lower rate) | G24: Summer jobs for youth aged 15 to 30, e.g., youth employment outreach or program assistant roles | H24: Up to 100% of the provincial adult minimum hourly wage plus eligible MERCs | I24: 2027 call opens October 27, 2026 at 9:00 am ET; close date not yet posted | J24: Open since Oct 27, 2026 (close date not posted yet) | K24: None required at the not-for-profit rate (up to 100%) | L24: Apply online via the CSJ applicant guide once the call opens | M24: https://www.canada.ca/en/employment-social-development/services/funding/canada-summer-jobs/applicant-guide/about.html | N24: High | O24: Not now | Q24: =IF(P24="","",P24-TODAY()) | V24: Second Chance would need to be an established not-for-profit employer at application time; the 2027 call likely closes in early-to-mid December 2026, which is probably too soon unless incorporation i…
A25: Jumpstart Community Development Grants (Access and Youth Development streams) | B25: Canadian Tire Jumpstart Charities | C25: Private | D25: Second Chance | E25: After nonprofit | F25: Registered charities, registered nonprofits or societies, registered Canadian amateur athletic associations (RCAAAs), municipalities and other qualified donees… | G25: Access: programs that remove barriers to sport for kids and youth. Youth Development: programs using sport to build life, leadership and employment-related skills where mentorship, coaching or employment is core (ages u… | H25: Access up to $25,000; Youth Development up to $75,000 | I25: Intake 1 (programs starting in 2027) closes October 20, 2026, 11:59 pm ET. Intake 2 (programs starting Sep 1 to Dec 31, 2027) opens Mar 10,… | J25: Open (closes Oct 20, 2026); next intake Mar 10 to Apr 7, 2027 | K25: None stated; paid 70% on acceptance, 30% after impact report | L25: Book a call with the regional Relationship Manager, then apply on the jumpstartgrants.smartsimple.ca portal | M25: https://jumpstart.canadiantire.ca/pages/community-development-grants | N25: High | O25: Not now | Q25: =IF(P25="","",P25-TODAY()) | V25: Weak fit: Second Chance serves adults, and Jumpstart funds kids' and youth sport. Strong fit for a combined idea: a nonprofit Second Chance running a sport-based youth employment/mentorship program w…
A26: Ontario Trillium Foundation Capital Grant | B26: Ontario Trillium Foundation (OTF) | C26: Provincial | D26: Second Chance | E26: After nonprofit | F26: Registered or incorporated non-profits actively operating 12+ months, delivering programs in sports and recreation, arts and culture, environment, or human and… | G26: Equipment (fixed and non-fixed), renovations and retrofits, outdoor space improvements | H26: $10,000 to $200,000, for 6 or 12 months | I26: Most recent window Feb 4 to Mar 4, 2026 (closed); watch for the next window | J26: Closed (next deadline not posted) | K26: None stated; quotes required for items over $5,000 | L26: Apply through the OTF portal when the next window opens | M26: https://otf.ca/our-grants/community-investments-grants/capital-grant | N26: High | O26: Not now | Q26: =IF(P26="","",P26-TODAY()) | V26: Needs 3+ board members (50% arm's length). Fixed equipment or renovations need ownership or a lease with 5+ years remaining. If Cody ever set up a separate nonprofit youth sport club, this is the mai…
... A35: TELUS Friendly Future Foundation Community Boards (Ottawa and Eastern Ontario) | B35: TELUS Friendly Future Foundation | C35: Private | D35: Second Chance | E35: After charity | F35: Canadian registered charities and qualified donees | G35: Programs supporting youth up to age 29 facing obstacles, with health and education focus | H35: Up to $20,000, single year | I35: No Canadian community board deadlines listed | J35: Unknown | K35: None stated | L35: Apply through the TELUS community grants portal when the board's intake opens | M35: https://www.telus.com/en/social-impact/giving-back/community-grants | N35: Medium | O35: Not now | Q35: =IF(P35="","",P35-TODAY()) | V35: Weak fit unless Second Chance adds a youth program: it serves adults leaving the justice system. Fits if Second Chance serves youth (e.g., youth job readiness).
A36: KidSport Ontario: Provincial Fund (individual child grants) | B36: KidSport Ontario | C36: Private | D36: Families | E36: No | F36: Families (individual children) whose income is within federal low-income guidelines plus about 30%; communities without a local chapter apply to the Provincial… | G36: Sport registration fees (not travel or competitions) | H36: Up to $250 per eligible child per calendar year | I36: Rolling by program season; apply by Friday, December 4, 2026 for eligible programs running January-February 2027; processed within 30 days | J36: Open (rolling) | K36: None | L36: Parent registers the child, tells the club they will apply, then applies online, by paper, mail or email with proof of income (Canada Child Benefit notice preferred) | M36: https://kidsportcanada.ca/ontario/provincial-fund/ | N36: High | O36: Not eligible | P36: 46360 | Q36: =IF(P36="","",P36-TODAY()) -> 38 | V36: Families apply by Dec 4 for Jan-Feb programs. BBG isn't registered with Boxing Ontario (Cody, Oct 2026), so KidSport can't cover BBG classes until it is. BBG isn't registered with Boxing Ontario or any provincial sport body (Cody, Oct 20, 2026), so KidSport can't cover BBG classes. It would if BBG registered. Key condition: 'Sport clubs must be member…
A37: Ontario Job Grant (formerly Canada-Ontario Job Grant) | B37: Ontario Ministry of Labour, Immigration, Training and Skills Development (Employment Ontario) | C37: Provincial | D37: BBG, CCCL, Second Chance | E37: No | F37: Private-sector (for-profit) and non-profit employers with a physical Ontario location that have operated in Ontario for at least one year | G37: Third-party training for existing staff or new hires (e.g., coaching, first aid, safe sport, business or marketing courses delivered by an eligible training provider) | H37: Up to $10,000 per trainee; up to $15,000 per previously unemployed new hire with no minimum employer contribution | I37: Year-round; ministry currently accepting applications involving 25 or fewer participants | J37: Rolling | K37: Employers with under 100 employees pay at least one-sixth of training costs (no contribution for unemployed new hires) | L37: Apply online through the Employment Ontario Ontario Job Grant portal (one application at a time) | M37: https://www.ontario.ca/page/ontario-job-grant | N37: High | O37: Not eligible | Q37: =IF(P37="","",P37-TODAY()) | V37: Not now: BBG has no payroll employees and its coaches are volunteers (Cody, Oct 20, 2026), so there's no one for the grant to train. Look again once BBG has staff on payroll. Training must come from…
A38: OTF Youth Opportunities Fund: Youth Innovations (Test / Scale) grants | B38: Ontario Trillium Foundation (OTF) | C38: Provincial | D38: Second Chance | E38: No | F38: Grassroots groups (not registered charities and not incorporated, or small non-profits with gross revenue of $50,000 or less) with an Organizational Mentor; yo… | G38: Projects benefiting young people aged 12-25 (12-29 for youth with disabilities, mental health or addiction needs), including justice/care well-being outcomes | H38: Up to $100,000 per year for 1 to 3 years (15% of budget goes to the Organizational Mentor) | I38: 2026 cycle closed (EOI Apr 15, 2026; application Jul 8, 2026). 2027 cycle not posted | J38: Closed (next cycle unknown) | K38: None | L38: Submit an Expression of Interest when OTF opens the next YOF cycle, with an Organizational Mentor lined up | M38: https://otf.ca/og-grants/youth-innovations-test-grant | N38: Medium | O38: Not eligible | Q38: =IF(P38="","",P38-TODAY()) | V38: Doesn't fit: Second Chance serves adults leaving the justice system (Cody, Oct 20, 2026), not a youth-led group. This is the one sizeable grant that does not require Second Chance to incorporate firs…
A39: Rural Ontario Development (ROD) Program: Business Development stream | B39: Government of Ontario (rural affairs ministry) | C39: Provincial | D39: BBG, CCCL | E39: No | F39: Small brick-and-mortar businesses in rural Ontario with 1 to 20 employees on payroll (excluding owners); incorporated, partnership, sole proprietorship or co-o… | G39: Project types: market development, cyber security, succession planning, accessibility improvements. Eligible costs: professional fees, technology, marketing and promotion, minor capital for accessibility, training | H39: 35% of project costs, up to $10,000 (minimum request $1,000) | I39: Third period closed Oct 1, 2026. Fourth period: Jan 18 to Feb 25, 2027, 5 pm ET (subject to change) | J39: Closed (next window Jan 18 to Feb 25, 2027) | K39: Applicant pays 65% of project costs | L39: Complete the PDF application in Adobe Acrobat and email it to RODProgram@ontario.ca; be registered on Transfer Payment Ontario | M39: https://www.ontario.ca/page/rural-ontario-development-program | N39: Medium | O39: Not eligible | P39: 46443 | Q39: =IF(P39="","",P39-TODAY()) -> 121 | V39: Fourth window Jan 18 to Feb 25, 2027. Not now: BBG has no payroll employees (Cody, Oct 20, 2026), and ROD needs 1 to 20 (owners don't count). If BBG puts someone on payroll before the Jan 18 to Feb 25, 2027 window, check again; it would…
Q40: =IF(P40="","",P40-TODAY())
Q41: =IF(P41="","",P41-TODAY())
Q42: =IF(P42="","",P42-TODAY())
Q43: =IF(P43="","",P43-TODAY())
Q44: =IF(P44="","",P44-TODAY())
Q45: =IF(P45="","",P45-TODAY())
Q46: =IF(P46="","",P46-TODAY())
Q47: =IF(P47="","",P47-TODAY())
Q48: =IF(P48="","",P48-TODAY())
Q49: =IF(P49="","",P49-TODAY())
...

Sheet Not Eligible
A1: NOT ELIGIBLE (FOR NOW)
A2: Programs that came up but don't fit, and why. Worth a second look if something changes (e.g. Second Chance becomes a charity).
A4: Program | B4: Why not | C4: Source
A5: Experience Ontario 2026/2027 (Established Events and Capacity Building streams) | B5: CCCL shows don't qualify: events must run at least two consecutive days with 5+ hours of programming each day. The program also excludes sporting competitions not marketed to tourists, events of a primarily commercial nature, and sole proprietorships and partnerships as applicants. The 2026 intake closed Dec 16, 2025. Note: Experience Ontario is the province's current festival/event program. | C5: https://forms.mgcs.gov.on.ca/dataset/8b8e8f60-9d1c-4ad7-843a-144ef54a105c/resource/f7351091-7cba-4d7a-93e2-dbc9e5cdb146/download/eo26_application_guidlines_2025_11_21_final.pdf
A6: Reconnect Festival and Event Program (Ontario) | B6: No current Reconnect intake found. It was a pandemic-recovery program, and Ontario's current festival/event funding is Experience Ontario (see above). Not available to CCCL. | C6: https://forms.mgcs.gov.on.ca/dataset/8b8e8f60-9d1c-4ad7-843a-144ef54a105c/resource/f7351091-7cba-4d7a-93e2-dbc9e5cdb146/download/eo26_application_guidlines_2025_11_21_final.pdf
A7: Ontario Sport Hosting Program 2026-27 | B7: For-profit applicants are ineligible, and events must be national or international, sanctioned by listed national sport organizations or international federations (no MMA body is listed). CCCL can't apply. | C7: https://forms.mgcs.gov.on.ca/en/dataset/2a497778-0458-4d72-b19f-422fa3ecc066/resource/70e9c426-0ad2-449b-a449-aa5bdd0da7f7/download/2026-27-sport-hosting-guidelines_part-1-program-guide_en.pdf
A8: Eastern Ontario Development Fund (EODF) | B8: Business projects need 3+ years of operation, at least 5 employees in rural areas, $200,000+ investment and 5 new jobs (or a 30% increase). Personal services are excluded. Community projects must be led by municipalities, economic development or sector organizations. Not realistic for BBG or CCCL. (Hastings is in the program area; next deadline Jan 21, 2027.) | C8: https://www.ontario.ca/page/eastern-ontario-development-fund
A9: FedDev Ontario Tourism Growth Program (southern Ontario) | B9: Closed and no longer accepting applications. It covered 2023-24 to 2025-26. Watch for a successor program; incorporated tourism SMEs were eligible (repayable contributions). | C9: https://feddev-ontario.canada.ca/en/funding-southern-ontario/tourism-growth-program-southern-ontario
A10: FedDev Ontario funding for businesses (e.g., Business Scale-up and Productivity) | B10: Businesses must be for-profit, incorporated for at least 3 years, and have at least 5 full-time employees. BBG and CCCL likely fall short. | C10: https://feddev-ontario.canada.ca/en/funding-southern-ontario/funding-businesses-southern-ontario-who-can-apply
A11: FedDev Build Communities Strong Fund - Local Impact Stream | B11: Intake is paused. It is for community infrastructure projects, not small businesses. | C11: https://feddev-ontario.canada.ca/en/funding-southern-ontario/build-communities-strong-fund-local-impact-stream-southern-ontario
A12: Sport Canada Community Sport for All Initiative | B12: Closed. Only national-level incorporated not-for-profits could apply. Community groups get this money indirectly through funded national organizations such as Jumpstart. | C12: https://www.canada.ca/en/canadian-heritage/services/funding/sport-support/community-sport-initiative.html
A13: ESDC Youth Employment and Skills Strategy - Strategic Collaboration | B13: Closed (May-July 2024) and by invitation only. | C13: https://www.canada.ca/en/employment-social-development/services/funding/yess-strategic-collaboration.html
A14: ESDC Team Canada Strong Youth Placements | B14: The expression of interest closes Oct 23, 2026. It funds large trades and construction placement projects (up to $15M/year), and for-profits are allowed only for non-commercial activity. Second Chance is not yet incorporated and the project scale doesn't fit. | C14: https://www.canada.ca/en/employment-social-development/services/funding/team-canada-strong-youth-placements.html
A15: Community Sport and Recreation Infrastructure Fund - Stream 1 (Repair and Rehabilitation) | B15: For-profit organizations are not listed as eligible (only municipalities, Indigenous organizations, local services boards and not-for-profits). BBG can only use Stream 2 (new builds). | C15: https://www.ontario.ca/document/community-sport-and-recreation-infrastructure-fund/stream-1-repair-and-rehabilitation
... A23: Public Safety Canada Grants and Contributions Program to Voluntary Organizations (community reintegration) | B23: Only for incorporated not-for-profits offering corrections, conditional release or reintegration programming. The 2025-26 call closed Jan 23, 2026. Second Chance can consider a future call only once incorporated and if it serves justice-involved people. | C23: https://www.canada.ca/en/public-safety-canada/news/2025/12/government-of-canada-announces-funding-for-community-reintegration-programs.html

Sheet Application Kit
A1: APPLICATION KIT
A2: What funders usually ask for, and the facts we can use. Get these ready once and most applications go faster.
A4: Item | B4: Where it comes from / notes | C4: Ready?
A5: Business or organization legal name and address | B5: BBG: 17 Snow Road, Bancroft ON. BBG and CCCL are two separate businesses (Cody, Oct 20, 2026): use the right one's legal name.
A6: Business Number (CRA) and structure | B6: Sole proprietorship (Cody, Oct 20, 2026). BBG has a business number; open the payroll (RP) account before hiring. Your accountant can confirm anything else a form asks.
A7: Number of employees | B7: Canada Summer Jobs and others depend on it (e.g. 50 or fewer for private-sector employers).
A8: Last year's financial statements or a budget | B8: Your accountant; the Money Summary helps for a simple budget.
A9: Project description and timeline | B9: What the money will do, by when, and who it helps. Claude drafts it from real facts.
A10: Project budget with quotes | B10: Each cost marked as a quote, estimate or known cost.
A11: Letters of support | B11: From partners, the town or a sponsor. Ask early; never draft one for someone to sign as if it were theirs.
A12: Proof of insurance | B12: Gym and event policies.
A13: Results so far (real numbers only) | B13: 400 tickets and 15 sponsors at the first show; about 90 gym members by March 2026 (The Highlander). No invented numbers.
A14: Photos | B14: Only adults who agreed, or kids with a parent's written OK. Never kids in funder marketing without it.
A15: Banking details for payment | B15: Entered on the funder's portal by Cody. Never put them in a sheet or a draft.
A17: Tips from the funders
A18: • | B18: Canada Summer Jobs 2027 opens Oct 27, 2026 at 9:00 am ET. Have the CRA business number and payroll deductions account ready. Jobs must be 30-40 hours/week for 6-16 consecutive weeks. Private employers get up to 50% of minimum wage with no MERCs; not-for-profits get up to 100% plus MERCs. Write the application to the riding's local priorities (2026 priorities for Hastings-Lennox and Addington-Tyendinaga included community events and local/regional tourism development). (canada.ca CSJ applicant guide; CFIB CSJ page; CSJ local priorities page)
A19: • | B19: KidSport only pays for clubs that are members of their Provincial Sport Organization. Boxing Ontario club registration needs at least one NCCP Level 1 Instruction Beginner coach, a safety inspection, and staff registered with Boxing Ontario; registration runs to Dec 31 each year. BBG isn't registered (Cody, Oct 20, 2026). Decide whether to register: it's the only way families could use KidSport at BBG (Dec 4, 2026 deadline for Jan-Feb 2027 programs). (kidsportcanada.ca/ontario/provincial-fund; boxingontario.com becoming a registered club)
A20: • | B20: Structure kids' programs as sessions of at least 5 weeks (one or more classes per week) or camps of at least 5 consecutive days so they qualify for Jumpstart individual grants. BBG is already a Jumpstart payee (Cody, Oct 2026); cheques go to the provider, not the family. Families should apply before the program starts. (jumpstart.canadiantire.ca individual-child-grants and FAQ)
A21: • | B21: OTF requires nonprofits to have 12 months of incorporation, operating and financial history, at least 3 board members, and Board-approved financial statements. Incorporate Second Chance as early as possible so the 12-month clock starts. Seed applications are scored Strategy 50%, Process 25%, People 25%. (otf.ca eligibility policy and Seed grant page)
A22: • | B22: Several funders (MLSE Foundation, RBC, TELUS, United Way, 100 Women Who Care) require qualified-donee status: a registered charity, or a registered Canadian amateur athletic association for sport. MLSE lets non-qualified groups apply through a qualified-donee trustee. Partnering with an existing local charity as lead or trustee is the fastest route for youth or employment projects. (mlsefoundation.org community grants; rbc.com apply for funding; telus.com community grants; unitedwayhpe.ca/funding)
A23: • | B23: Jumpstart Community Development Grants recommend booking a call with your regional Relationship Manager before applying. Its Youth Development stream (up to $75,000) funds sport programs where coaching, mentorship or employment is core, which matches a Second Chance + BBG youth employment program. Next intake opens Mar 10, 2027. (jumpstart.canadiantire.ca/pages/community-development-grants)
A24: • | B24: Rural Ontario Development business funding is first-come, first-served, and each business gets only one successful application. Costs incurred before the project's effective date are ineligible. Fill the form in Adobe Acrobat (not a browser), email it to RODProgram@ontario.ca, and register on Transfer Payment Ontario first. The next window is Jan 18 to Feb 25, 2027. (ontario.ca ROD page and business development application form)
A25: • | B25: Starter Company Plus requires a cash or in-kind contribution of at least 25% of the grant. Hastings County businesses apply through the Small Business Centre in Belleville (2026 intake was Apr 13 to May 22), so plan a business plan and cash flow for a spring 2027 intake. (ontario.ca/page/starter-company-plus; smallbusinessctr.com/services)
A26: • | B26: CFDC loan applications need the amount, its purpose and how it helps the business, a meeting with staff, the Loan Application (or Ready Money form under $10,000), and a cash flow projection. Owners aged 18-39 can get the Young Entrepreneur Loan with no payments in year one. (community-futures.ca business loans)
A27: • | B27: Ontario Job Grant: employers with under 100 employees pay at least one-sixth of training costs. Training must be from an eligible third-party provider with 2+ years of experience delivering it, and the employer must have operated in Ontario for at least a year. Up to $15,000 with no employer share is possible when training an unemployed new hire, which could pair well with Second Chance clients hired by partner employers. (ontario.ca/page/ontario-job-grant)
A28: • | B28: The Coaches Association of Ontario Community Coaching Grant lets individual coaches apply (up to $1,000 for mats, protective gear or safety training). Each BBG coach could apply separately when it reopens (2026 window closed June 5). Purchases made before acceptance are not reimbursed. (safesport101.coachesontario.ca/grant)
A29: • | B29: The Community Sport and Recreation Infrastructure Fund caps for-profit applicants at 25% provincial cost share, requires audited financial statements and a corporate structure document, and closes Dec 22, 2026. Only pursue it if a new or expanded BBG facility is planned. (ontario.ca CSRIF Stream 2)
... A33: • | B33: MLSE Foundation Community Action Grant: expression of interest opens Nov 3, 2026, info webinar Nov 17, closes Dec 15, 2026. Women- and girl-identified youth programming is a primary focus, which suits BBG's women's boxing if delivered with a qualified-donee lead. (mlsefoundation.org)

Sheet Open Questions
A1: QUESTIONS FOR CODY
A2: Eligibility hangs on these. Cody answered most of them on October 20, 2026; the rest are at the bottom.
A4: Question | B4: Answer
A5: CODY'S ANSWERS (OCTOBER 20, 2026)
A6: Legal structure of BBG and CCCL; one entity or two? | B6: Sole proprietorship. BBG and CCCL are two businesses.
A7: Employees on payroll (excluding owners); coaches employees or contractors? | B7: None on payroll. Coaches are volunteers.
A8: CRA business number and payroll account; Transfer Payment Ontario? | B8: Business number only, no payroll account. Not sure about Transfer Payment Ontario.
A9: How long operating; annual sales? | B9: BBG opened in 2025; sales under $50,000 a year. CCCL's first show was May 2, 2026.
A10: Cody's age (youth programs need 18 to 39) | B10: 18 to 39.
A11: Registered with Boxing Ontario or another sport body? NCCP? | B11: Not registered with any sport body. Some coaches have NCCP certification.
A12: Own or lease; commercially zoned; in Bancroft's CIP area? | B12: Leases. Inside the CIP area.
A13: New or expanded facility being considered? | B13: Yes.
A14: Where is CCCL based? | B14: At the gym's address in Bancroft; it runs events across Ontario.
A15: Second Chance: incorporation, board, charity plans? | B15: Incorporation in progress. Plans to become a registered charity. Five possible board members named. No bank account yet.
A16: Second Chance: who it serves? | B16: Adults leaving the justice system and anyone who needs a fresh start: job skills, work experience and volunteer roles at fight nights.
A17: Jumpstart payee? | B17: Yes, BBG is already signed up.
A18: Which federal riding is Bancroft in for CSJ local priorities? Hastings-Lennox and Addington-Tyendinaga appears likely (see the CSJ draft). | B18: Hastings—Lennox and Addington—Tyendinaga: Elections Canada lists the Town of Bancroft in it (checked Oct 2026; see the CSJ draft).
A20: STILL TO CONFIRM
A21: Is BBG registered on Transfer Payment Ontario? (Needed for most Ontario grants, including ROD.)
A22: Second Chance: incorporating federally (CNCA) or in Ontario (ONCA)? Are the board members at arm's length (not related to each other or to Cody, and not his employees)?
A23: Is there a local registered charity that could act as lead applicant or trustee for Second Chance projects while it gets established?
A24: Would the NCCP courses BBG's coaches want count as eligible third-party training (only matters once BBG has payroll staff)?
A25: Does the Town of Bancroft have a current community grant or event-support policy that CCCL could use?
A27: BUSINESS PROFILE FOR APPLICATIONS
A28: BBG is a sole proprietorship owned by Cody Purtell. BBG and CCCL are run as two businesses (Cody, Oct 20, 2026).
A29: Payroll: none besides Cody. Coaches are volunteers. Cody runs and coaches every class.
A30: CRA: BBG has a business number but no payroll program account yet.
A31: Transfer Payment Ontario: not sure whether BBG is registered.
A32: BBG's yearly sales: under $50,000.
... A38: Coaches: all have a vulnerable sector check; some hold NCCP certification. Rowan's Law paperwork is in place.
