Workbook

Sheet Start Here
A1: BBG COACHING LIBRARY
A2: Class profiles, a drill library and 4-week lesson plans for every class on the schedule, with the safety rules every coach follows.
A4: 1 | B4: Classes | C4: Every class on the Gymdesk schedule: length, ages, the contact allowed and the focus. Cody sets the contact rules; the lesson plans check against them.
A5: 2 | B5: Drills | C5: 63 drills: how to run each one, coaching points, safety, ages, contact level, equipment and minutes. Add your own at the bottom.
A6: 3 | B6: Lesson Plans | C6: A 4-week block for each class, six slots per class: warm-up, two skills, a pad or partner drill, a game or live round, and a finisher. Pick drills from the dropdowns; the Check column flags a plan that runs over time, uses a drill for older ages, or uses more contact than the class allows. In an all-ages class it says 'split by age' when some drills are for older athletes, so younger kids do their own version.
A7: 4 | B7: Safety | C7: The rules every coach follows (Rowan's Law, the Rule of Two, youth contact limits, what to do after a hit to the head), with sources. Read it before coaching kids.
A8: 5 | B8: With Claude | C8: The bbg-coach skill uses this sheet: "plan Wednesday's kids boxing", "a 4-week wrestling block on takedowns", "a sub-coach sheet for Thursday", "a parent update for the kids class".
A9: 6 | B9: Who decides | C9: Cody, the head coach at every class, decides what's taught and who spars. These plans are starting points, not rules from a sport body: check the Safety tab and your coaching certification.
B11: Contact levels
B12: None | C12: Solo work: shadowboxing, footwork, movement
B13: Pads/bag | C13: Hitting pads, shields or bags held by a coach or partner
B14: Partner drilling | C14: Cooperative partner work with no strikes: drilling a takedown, a sweep, glove-tap games
B15: Live grappling | C15: Live wrestling or grappling, matched by size, coach watching
B16: Light touch (body) | C16: Light touches to the body only, coach watching every pair
B17: Controlled sparring | C17: Sparring with head contact: Competition Class only, Cody's OK, full gear
B19: Colours
B20: Yellow, blue text | C20: You type or pick here
B21: Black, bold | C21: Calculated: don't type over it

Sheet Classes
A1: CLASSES
A2: From the Gymdesk schedule and Cody's answers (October 2026). Change the contact allowed, youngest age or age groups here and every lesson plan re-checks.
A4: Class | B4: Day and time | C4: Minutes | D4: Ages | E4: Youngest age | F4: Contact allowed (separate with ;) | G4: Focus | H4: Coach (first name) | I4: Splits into age groups?
A5: Kids Boxing | B5: Wed 5:15-6:15 PM | C5: 60 | D5: Kids 4-10 | E5: 4 | F5: None;Pads/bag;Partner drilling | G5: Stance, guard, footwork, straight punches on pads, fun games. No partner punching. Kids from about 4: short, play-based drills for the youngest. | H5: Cody | I5: No
A6: Wrestling | B6: Mon 3:20-4:00 PM | C6: 40 | D6: Kids and youth | E6: 6 | F6: None;Partner drilling;Live grappling | G6: Stance and motion, safe falling, takedowns, pins, games. | H6: Cody (Sean and Jordan help) | I6: No
A7: Boxing 11-14 | B7: Thu 4:00-5:00 PM | C7: 60 | D7: Youth 11-14 | E7: 11 | F7: None;Pads/bag;Light touch (body) | G7: Technique and combinations on pads and bags; body-only touch drills with a coach watching. | H7: Cody | I7: No
A8: Boxing | B8: Mon and Wed 4:00-5:00 PM | C8: 60 | D8: All ages, from about 4 | E8: 4 | F8: None;Pads/bag;Light touch (body) | G8: Fitness and technique for every age: footwork, combinations, defence, bag rounds. Kids work in their own group for anything above their age. | H8: Cody | I8: Yes
A9: Women's Boxing | B9: Wed 7:00-7:45 PM, Thu 6:00-6:45 PM | C9: 45 | D9: Women and girls 16+ | E9: 16 | F9: None;Pads/bag;Light touch (body) | G9: A welcoming, women-only class: technique, pads, bag circuits, confidence. | H9: Cody | I9: No
A10: Kickboxing | B10: Thu 7:00-8:00 PM | C10: 60 | D10: Teens and adults | E10: 15 | F10: None;Pads/bag;Light touch (body) | G10: Punches and kicks on pads and shields, combinations, conditioning. | H10: Cody | I10: No
A11: Jiu-Jitsu (no-gi) | B11: Tue 4:00-6:00 PM | C11: 120 | D11: Ages 12+ | E11: 12 | F11: None;Partner drilling;Live grappling | G11: Escapes, guard, passing, submissions with the tap rule, positional sparring. Under-16s only do the submissions Ontario allows at their age. | H11: Cody | I11: No
A12: MMA | B12: Fri 4:00-5:00 PM | C12: 60 | D12: Ages 12+ | E12: 12 | F12: None;Pads/bag;Partner drilling;Live grappling;Light touch (body) | G12: Putting striking and grappling together: level changes, clinch, get-ups. No strikes to the head or face for anyone under 19. | H12: Cody | I12: No
A13: Competition Class | B13: Fri 5:00-6:00 PM | C13: 60 | D13: Invited by Cody (adults; under 18 only with Cody's and a parent's OK) | E13: 18 | F13: None;Pads/bag;Partner drilling;Live grappling;Light touch (body);Controlled sparring | G13: Fight preparation for athletes Cody picks. Sparring only with his OK. | H13: Cody | I13: No
A25: Yoga (Tue 6:15-7:00 PM) is run by its own instructor and isn't covered here.
A26: Splits into age groups? Yes = an all-ages class. Drills above the youngest age are fine, but younger kids do a drill for their age at the same time (the Check says 'split by age').
A27: Gym equipment (Cody, Oct 2026): Heavy bags, Focus mitts, Thai pads and kick shields, Wrestling mats, Gloves to lend, Headgear, Agility ladders and cones, Medicine balls, Battle ropes. Not at BBG: boxing ring, cage, skipping ropes. Plans only use this gear.

Sheet Lesson Plans
A1: LESSON PLANS
A2: Pick a drill for each slot. Minutes fill in from the drill (type over to change). Check flags plans that run long, use a drill meant for older athletes, or use more contact than the class allows. Amber split by age means an all-ages class runs that drill in age groups.
A4: Class | B4: Week | C4: Theme | D4: Warm-up | E4: Min | F4: Skill 1 | G4: Min | H4: Skill 2 | I4: Min | J4: Pads or partner | K4: Min | L4: Game or live | M4: Min | N4: Finish / cool-down | O4: Min | P4: Total | Q4: Class min | R4: Check | S4: Notes | T4: Youngest | U4: Allowed | V4: Code 1 | W4: Code 2 | X4: Code 3 | Y4: Code 4 | Z4: Code 5 | AA4: Code 6 | AB4: Splits
A5: Kids Boxing | B5: 1 | C5: Stance and guard | D5: Animal walks | E5: 8 | F5: Stance and guard | G5: 8 | H5: Step-drag footwork | I5: 10 | J5: Pad target game | K5: 10 | L5: Follow the leader footwork | M5: 8 | N5: Cool-down stretch and breathing | O5: 6 | P5: =IF(A5="","",SUM(E5,G5,I5,K5,M5,O5)) -> 50 | Q5: =IF(A5="","",IFERROR(INDEX(Classes!$C$5:$C$23,MATCH(A5,Classes!$A$5:$A$23,0)),"")) -> 60 | R5: =IF(A5="","",IF(TRIM(IF(AND(N(Q5)>0,N(P5)>N(Q5)),"Over by "&(P5-Q5)&" min. ","")&IF(AND(COUNTIF(V5:AA5,"*A*")>0,AB5<>"Yes"),"Age check. ","")&IF(COUNTIF(V5:AA5,"*C*")>0,"Contact check. ","")&IF(COUNTIF(V5:AA5,"~?")>0,"Drill not in library. ",""))="","OK"&IF(AND(COUNTIF(V5:AA5,"*A*")>0,AB5="Yes")," · split by age","")&IF(N(Q5)>N(P5)," ("&(Q5-P5)&" min spare)",""),TRIM(IF(AND(N(Q5)>0,N(P5)>N(Q5)),"Over by "&(P5-Q5)&" min. ","")&IF(AND(COUNTIF(V5:AA5,"*A*")>0,AB5<>"Yes"),"Age check. ","")&IF(COUNTIF(V5:AA5,"*C*")>0,"Contact check. ","")&IF(COUNTIF(V5:AA5,"~?")>0,"Drill not in library. ",""))&IF(AND(COUNTIF(V5:AA5,"*A*")>0,AB5="Yes")," · split by age",""))) -> OK (10 min spare) | T5: =IF(A5="","",IFERROR(INDEX(Classes!$E$5:$E$23,MATCH(A5,Classes!$A$5:$A$23,0)),"")) -> 4 | U5: =IF(A5="","",IFERROR(INDEX(Classes!$F$5:$F$23,MATCH(A5,Classes!$A$5:$A$23,0)),"")) -> None;Pads/bag;Partner drilling | V5: =IF(OR(D5="",$A5=""),"",IF(ISNA(MATCH(D5,Drills!$A$5:$A$127,0)),"?",IF(N(INDEX(Drills!$K$5:$K$127,MATCH(D5,Drills!$A$5:$A$127,0)))>N($T5),"A","")&IF(ISNUMBER(SEARCH(INDEX(Drills!$E$5:$E$127,MATCH(D5,Drills!$A$5:$A$127,0)),$U5)),"","C"))) | W5: =IF(OR(F5="",$A5=""),"",IF(ISNA(MATCH(F5,Drills!$A$5:$A$127,0)),"?",IF(N(INDEX(Drills!$K$5:$K$127,MATCH(F5,Drills!$A$5:$A$127,0)))>N($T5),"A","")&IF(ISNUMBER(SEARCH(INDEX(Drills!$E$5:$E$127,MATCH(F5,Drills!$A$5:$A$127,0)),$U5)),"","C"))) | X5: =IF(OR(H5="",$A5=""),"",IF(ISNA(MATCH(H5,Drills!$A$5:$A$127,0)),"?",IF(N(INDEX(Drills!$K$5:$K$127,MATCH(H5,Drills!$A$5:$A$127,0)))>N($T5),"A","")&IF(ISNUMBER(SEARCH(INDEX(Drills!$E$5:$E$127,MATCH(H5,Drills!$A$5:$A$127,0)),$U5)),"","C"))) | Y5: =IF(OR(J5="",$A5=""),"",IF(ISNA(MATCH(J5,Drills!$A$5:$A$127,0)),"?",IF(N(INDEX(Drills!$K$5:$K$127,MATCH(J5,Drills!$A$5:$A$127,0)))>N($T5),"A","")&IF(ISNUMBER(SEARCH(INDEX(Drills!$E$5:$E$127,MATCH(J5,Drills!$A$5:$A$127,0)),$U5)),"","C"))) | Z5: =IF(OR(L5="",$A5=""),"",IF(ISNA(MATCH(L5,Drills!$A$5:$A$127,0)),"?",IF(N(INDEX(Drills!$K$5:$K$127,MATCH(L5,Drills!$A$5:$A$127,0)))>N($T5),"A","")&IF(ISNUMBER(SEARCH(INDEX(Drills!$E$5:$E$127,MATCH(L5,Drills!$A$5:$A$127,0)),$U5)),"","C"))) | AA5: =IF(OR(N5="",$A5=""),"",IF(ISNA(MATCH(N5,Drills!$A$5:$A$127,0)),"?",IF(N(INDEX(Drills!$K$5:$K$127,MATCH(N5,Drills!$A$5:$A$127,0)))>N($T5),"A","")&IF(ISNUMBER(SEARCH(INDEX(Drills!$E$5:$E$127,MATCH(N5,Drills!$A$5:$A$127,0)),$U5)),"","C"))) | AB5: =IF(A5="","",IFERROR(INDEX(Classes!$I$5:$I$23,MATCH(A5,Classes!$A$5:$A$23,0)),"")) -> No
A6: Kids Boxing | B6: 2 | C6: The jab | D6: Dynamic warm-up | E6: 10 | F6: Jab on pads | G6: 10 | H6: Footwork ladder and cones | I6: 8 | J6: Heavy bag rounds | K6: 10 | L6: Relay races | M6: 8 | N6: Cool-down stretch and breathing | O6: 6 | P6: =IF(A6="","",SUM(E6,G6,I6,K6,M6,O6)) -> 52 | Q6: =IF(A6="","",IFERROR(INDEX(Classes!$C$5:$C$23,MATCH(A6,Classes!$A$5:$A$23,0)),"")) -> 60 | R6: =IF(A6="","",IF(TRIM(IF(AND(N(Q6)>0,N(P6)>N(Q6)),"Over by "&(P6-Q6)&" min. ","")&IF(AND(COUNTIF(V6:AA6,"*A*")>0,AB6<>"Yes"),"Age check. ","")&IF(COUNTIF(V6:AA6,"*C*")>0,"Contact check. ","")&IF(COUNTIF(V6:AA6,"~?")>0,"Drill not in library. ",""))="","OK"&IF(AND(COUNTIF(V6:AA6,"*A*")>0,AB6="Yes")," · split by age","")&IF(N(Q6)>N(P6)," ("&(Q6-P6)&" min spare)",""),TRIM(IF(AND(N(Q6)>0,N(P6)>N(Q6)),"Over by "&(P6-Q6)&" min. ","")&IF(AND(COUNTIF(V6:AA6,"*A*")>0,AB6<>"Yes"),"Age check. ","")&IF(COUNTIF(V6:AA6,"*C*")>0,"Contact check. ","")&IF(COUNTIF(V6:AA6,"~?")>0,"Drill not in library. ",""))&IF(AND(COUNTIF(V6:AA6,"*A*")>0,AB6="Yes")," · split by age",""))) -> OK (8 min spare) | T6: =IF(A6="","",IFERROR(INDEX(Classes!$E$5:$E$23,MATCH(A6,Classes!$A$5:$A$23,0)),"")) -> 4 | U6: =IF(A6="","",IFERROR(INDEX(Classes!$F$5:$F$23,MATCH(A6,Classes!$A$5:$A$23,0)),"")) -> None;Pads/bag;Partner drilling | V6: =IF(OR(D6="",$A6=""),"",IF(ISNA(MATCH(D6,Drills!$A$5:$A$127,0)),"?",IF(N(INDEX(Drills!$K$5:$K$127,MATCH(D6,Drills!$A$5:$A$127,0)))>N($T6),"A","")&IF(ISNUMBER(SEARCH(INDEX(Drills!$E$5:$E$127,MATCH(D6,Drills!$A$5:$A$127,0)),$U6)),"","C"))) | W6: =IF(OR(F6="",$A6=""),"",IF(ISNA(MATCH(F6,Drills!$A$5:$A$127,0)),"?",IF(N(INDEX(Drills!$K$5:$K$127,MATCH(F6,Drills!$A$5:$A$127,0)))>N($T6),"A","")&IF(ISNUMBER(SEARCH(INDEX(Drills!$E$5:$E$127,MATCH(F6,Drills!$A$5:$A$127,0)),$U6)),"","C"))) | X6: =IF(OR(H6="",$A6=""),"",IF(ISNA(MATCH(H6,Drills!$A$5:$A$127,0)),"?",IF(N(INDEX(Drills!$K$5:$K$127,MATCH(H6,Drills!$A$5:$A$127,0)))>N($T6),"A","")&IF(ISNUMBER(SEARCH(INDEX(Drills!$E$5:$E$127,MATCH(H6,Drills!$A$5:$A$127,0)),$U6)),"","C"))) | Y6: =IF(OR(J6="",$A6=""),"",IF(ISNA(MATCH(J6,Drills!$A$5:$A$127,0)),"?",IF(N(INDEX(Drills!$K$5:$K$127,MATCH(J6,Drills!$A$5:$A$127,0)))>N($T6),"A","")&IF(ISNUMBER(SEARCH(INDEX(Drills!$E$5:$E$127,MATCH(J6,Drills!$A$5:$A$127,0)),$U6)),"","C"))) | Z6: =IF(OR(L6="",$A6=""),"",IF(ISNA(MATCH(L6,Drills!$A$5:$A$127,0)),"?",IF(N(INDEX(Drills!$K$5:$K$127,MATCH(L6,Drills!$A$5:$A$127,0)))>N($T6),"A","")&IF(ISNUMBER(SEARCH(INDEX(Drills!$E$5:$E$127,MATCH(L6,Drills!$A$5:$A$127,0)),$U6)),"","C"))) | AA6: =IF(OR(N6="",$A6=""),"",IF(ISNA(MATCH(N6,Drills!$A$5:$A$127,0)),"?",IF(N(INDEX(Drills!$K$5:$K$127,MATCH(N6,Drills!$A$5:$A$127,0)))>N($T6),"A","")&IF(ISNUMBER(SEARCH(INDEX(Drills!$E$5:$E$127,MATCH(N6,Drills!$A$5:$A$127,0)),$U6)),"","C"))) | AB6: =IF(A6="","",IFERROR(INDEX(Classes!$I$5:$I$23,MATCH(A6,Classes!$A$5:$A$23,0)),"")) -> No
A7: Kids Boxing | B7: 3 | C7: Jab and cross | D7: Jump rope | E7: 6 | F7: 1-2 on pads | G7: 10 | H7: Step-drag footwork | I7: 8 | J7: Heavy bag rounds | K7: 10 | L7: Pad target game | M7: 10 | N7: Cool-down stretch and breathing | O7: 6 | P7: =IF(A7="","",SUM(E7,G7,I7,K7,M7,O7)) -> 50 | Q7: =IF(A7="","",IFERROR(INDEX(Classes!$C$5:$C$23,MATCH(A7,Classes!$A$5:$A$23,0)),"")) -> 60 | R7: =IF(A7="","",IF(TRIM(IF(AND(N(Q7)>0,N(P7)>N(Q7)),"Over by "&(P7-Q7)&" min. ","")&IF(AND(COUNTIF(V7:AA7,"*A*")>0,AB7<>"Yes"),"Age check. ","")&IF(COUNTIF(V7:AA7,"*C*")>0,"Contact check. ","")&IF(COUNTIF(V7:AA7,"~?")>0,"Drill not in library. ",""))="","OK"&IF(AND(COUNTIF(V7:AA7,"*A*")>0,AB7="Yes")," · split by age","")&IF(N(Q7)>N(P7)," ("&(Q7-P7)&" min spare)",""),TRIM(IF(AND(N(Q7)>0,N(P7)>N(Q7)),"Over by "&(P7-Q7)&" min. ","")&IF(AND(COUNTIF(V7:AA7,"*A*")>0,AB7<>"Yes"),"Age check. ","")&IF(COUNTIF(V7:AA7,"*C*")>0,"Contact check. ","")&IF(COUNTIF(V7:AA7,"~?")>0,"Drill not in library. ",""))&IF(AND(COUNTIF(V7:AA7,"*A*")>0,AB7="Yes")," · split by age",""))) -> OK (10 min spare) | T7: =IF(A7="","",IFERROR(INDEX(Classes!$E$5:$E$23,MATCH(A7,Classes!$A$5:$A$23,0)),"")) -> 4 | U7: =IF(A7="","",IFERROR(INDEX(Classes!$F$5:$F$23,MATCH(A7,Classes!$A$5:$A$23,0)),"")) -> None;Pads/bag;Partner drilling | V7: =IF(OR(D7="",$A7=""),"",IF(ISNA(MATCH(D7,Drills!$A$5:$A$127,0)),"?",IF(N(INDEX(Drills!$K$5:$K$127,MATCH(D7,Drills!$A$5:$A$127,0)))>N($T7),"A","")&IF(ISNUMBER(SEARCH(INDEX(Drills!$E$5:$E$127,MATCH(D7,Drills!$A$5:$A$127,0)),$U7)),"","C"))) | W7: =IF(OR(F7="",$A7=""),"",IF(ISNA(MATCH(F7,Drills!$A$5:$A$127,0)),"?",IF(N(INDEX(Drills!$K$5:$K$127,MATCH(F7,Drills!$A$5:$A$127,0)))>N($T7),"A","")&IF(ISNUMBER(SEARCH(INDEX(Drills!$E$5:$E$127,MATCH(F7,Drills!$A$5:$A$127,0)),$U7)),"","C"))) | X7: =IF(OR(H7="",$A7=""),"",IF(ISNA(MATCH(H7,Drills!$A$5:$A$127,0)),"?",IF(N(INDEX(Drills!$K$5:$K$127,MATCH(H7,Drills!$A$5:$A$127,0)))>N($T7),"A","")&IF(ISNUMBER(SEARCH(INDEX(Drills!$E$5:$E$127,MATCH(H7,Drills!$A$5:$A$127,0)),$U7)),"","C"))) | Y7: =IF(OR(J7="",$A7=""),"",IF(ISNA(MATCH(J7,Drills!$A$5:$A$127,0)),"?",IF(N(INDEX(Drills!$K$5:$K$127,MATCH(J7,Drills!$A$5:$A$127,0)))>N($T7),"A","")&IF(ISNUMBER(SEARCH(INDEX(Drills!$E$5:$E$127,MATCH(J7,Drills!$A$5:$A$127,0)),$U7)),"","C"))) | Z7: =IF(OR(L7="",$A7=""),"",IF(ISNA(MATCH(L7,Drills!$A$5:$A$127,0)),"?",IF(N(INDEX(Drills!$K$5:$K$127,MATCH(L7,Drills!$A$5:$A$127,0)))>N($T7),"A","")&IF(ISNUMBER(SEARCH(INDEX(Drills!$E$5:$E$127,MATCH(L7,Drills!$A$5:$A$127,0)),$U7)),"","C"))) | AA7: =IF(OR(N7="",$A7=""),"",IF(ISNA(MATCH(N7,Drills!$A$5:$A$127,0)),"?",IF(N(INDEX(Drills!$K$5:$K$127,MATCH(N7,Drills!$A$5:$A$127,0)))>N($T7),"A","")&IF(ISNUMBER(SEARCH(INDEX(Drills!$E$5:$E$127,MATCH(N7,Drills!$A$5:$A$127,0)),$U7)),"","C"))) | AB7: =IF(A7="","",IFERROR(INDEX(Classes!$I$5:$I$23,MATCH(A7,Classes!$A$5:$A$23,0)),"")) -> No
A8: Kids Boxing | B8: 4 | C8: Slips and review | D8: Animal walks | E8: 8 | F8: Slip line | G8: 8 | H8: 1-2 on pads | I8: 10 | J8: Heavy bag rounds | K8: 10 | L8: Follow the leader footwork | M8: 8 | N8: Cool-down stretch and breathing | O8: 6 | P8: =IF(A8="","",SUM(E8,G8,I8,K8,M8,O8)) -> 50 | Q8: =IF(A8="","",IFERROR(INDEX(Classes!$C$5:$C$23,MATCH(A8,Classes!$A$5:$A$23,0)),"")) -> 60 | R8: =IF(A8="","",IF(TRIM(IF(AND(N(Q8)>0,N(P8)>N(Q8)),"Over by "&(P8-Q8)&" min. ","")&IF(AND(COUNTIF(V8:AA8,"*A*")>0,AB8<>"Yes"),"Age check. ","")&IF(COUNTIF(V8:AA8,"*C*")>0,"Contact check. ","")&IF(COUNTIF(V8:AA8,"~?")>0,"Drill not in library. ",""))="","OK"&IF(AND(COUNTIF(V8:AA8,"*A*")>0,AB8="Yes")," · split by age","")&IF(N(Q8)>N(P8)," ("&(Q8-P8)&" min spare)",""),TRIM(IF(AND(N(Q8)>0,N(P8)>N(Q8)),"Over by "&(P8-Q8)&" min. ","")&IF(AND(COUNTIF(V8:AA8,"*A*")>0,AB8<>"Yes"),"Age check. ","")&IF(COUNTIF(V8:AA8,"*C*")>0,"Contact check. ","")&IF(COUNTIF(V8:AA8,"~?")>0,"Drill not in library. ",""))&IF(AND(COUNTIF(V8:AA8,"*A*")>0,AB8="Yes")," · split by age",""))) -> OK (10 min spare) | T8: =IF(A8="","",IFERROR(INDEX(Classes!$E$5:$E$23,MATCH(A8,Classes!$A$5:$A$23,0)),"")) -> 4 | U8: =IF(A8="","",IFERROR(INDEX(Classes!$F$5:$F$23,MATCH(A8,Classes!$A$5:$A$23,0)),"")) -> None;Pads/bag;Partner drilling | V8: =IF(OR(D8="",$A8=""),"",IF(ISNA(MATCH(D8,Drills!$A$5:$A$127,0)),"?",IF(N(INDEX(Drills!$K$5:$K$127,MATCH(D8,Drills!$A$5:$A$127,0)))>N($T8),"A","")&IF(ISNUMBER(SEARCH(INDEX(Drills!$E$5:$E$127,MATCH(D8,Drills!$A$5:$A$127,0)),$U8)),"","C"))) | W8: =IF(OR(F8="",$A8=""),"",IF(ISNA(MATCH(F8,Drills!$A$5:$A$127,0)),"?",IF(N(INDEX(Drills!$K$5:$K$127,MATCH(F8,Drills!$A$5:$A$127,0)))>N($T8),"A","")&IF(ISNUMBER(SEARCH(INDEX(Drills!$E$5:$E$127,MATCH(F8,Drills!$A$5:$A$127,0)),$U8)),"","C"))) | X8: =IF(OR(H8="",$A8=""),"",IF(ISNA(MATCH(H8,Drills!$A$5:$A$127,0)),"?",IF(N(INDEX(Drills!$K$5:$K$127,MATCH(H8,Drills!$A$5:$A$127,0)))>N($T8),"A","")&IF(ISNUMBER(SEARCH(INDEX(Drills!$E$5:$E$127,MATCH(H8,Drills!$A$5:$A$127,0)),$U8)),"","C"))) | Y8: =IF(OR(J8="",$A8=""),"",IF(ISNA(MATCH(J8,Drills!$A$5:$A$127,0)),"?",IF(N(INDEX(Drills!$K$5:$K$127,MATCH(J8,Drills!$A$5:$A$127,0)))>N($T8),"A","")&IF(ISNUMBER(SEARCH(INDEX(Drills!$E$5:$E$127,MATCH(J8,Drills!$A$5:$A$127,0)),$U8)),"","C"))) | Z8: =IF(OR(L8="",$A8=""),"",IF(ISNA(MATCH(L8,Drills!$A$5:$A$127,0)),"?",IF(N(INDEX(Drills!$K$5:$K$127,MATCH(L8,Drills!$A$5:$A$127,0)))>N($T8),"A","")&IF(ISNUMBER(SEARCH(INDEX(Drills!$E$5:$E$127,MATCH(L8,Drills!$A$5:$A$127,0)),$U8)),"","C"))) | AA8: =IF(OR(N8="",$A8=""),"",IF(ISNA(MATCH(N8,Drills!$A$5:$A$127,0)),"?",IF(N(INDEX(Drills!$K$5:$K$127,MATCH(N8,Drills!$A$5:$A$127,0)))>N($T8),"A","")&IF(ISNUMBER(SEARCH(INDEX(Drills!$E$5:$E$127,MATCH(N8,Drills!$A$5:$A$127,0)),$U8)),"","C"))) | AB8: =IF(A8="","",IFERROR(INDEX(Classes!$I$5:$I$23,MATCH(A8,Classes!$A$5:$A$23,0)),"")) -> No
A9: Wrestling | B9: 1 | C9: Stance and safe falling | D9: Grappling movement warm-up | E9: 10 | F9: Breakfalls | G9: 6 | H9: Stance and motion | I9: 6 | J9: Sprawl drill | K9: 5 | L9: Knee tag | M9: 6 | N9: Cool-down stretch and breathing | O9: 5 | P9: =IF(A9="","",SUM(E9,G9,I9,K9,M9,O9)) -> 38 | Q9: =IF(A9="","",IFERROR(INDEX(Classes!$C$5:$C$23,MATCH(A9,Classes!$A$5:$A$23,0)),"")) -> 40 | R9: =IF(A9="","",IF(TRIM(IF(AND(N(Q9)>0,N(P9)>N(Q9)),"Over by "&(P9-Q9)&" min. ","")&IF(AND(COUNTIF(V9:AA9,"*A*")>0,AB9<>"Yes"),"Age check. ","")&IF(COUNTIF(V9:AA9,"*C*")>0,"Contact check. ","")&IF(COUNTIF(V9:AA9,"~?")>0,"Drill not in library. ",""))="","OK"&IF(AND(COUNTIF(V9:AA9,"*A*")>0,AB9="Yes")," · split by age","")&IF(N(Q9)>N(P9)," ("&(Q9-P9)&" min spare)",""),TRIM(IF(AND(N(Q9)>0,N(P9)>N(Q9)),"Over by "&(P9-Q9)&" min. ","")&IF(AND(COUNTIF(V9:AA9,"*A*")>0,AB9<>"Yes"),"Age check. ","")&IF(COUNTIF(V9:AA9,"*C*")>0,"Contact check. ","")&IF(COUNTIF(V9:AA9,"~?")>0,"Drill not in library. ",""))&IF(AND(COUNTIF(V9:AA9,"*A*")>0,AB9="Yes")," · split by age",""))) -> OK (2 min spare) | T9: =IF(A9="","",IFERROR(INDEX(Classes!$E$5:$E$23,MATCH(A9,Classes!$A$5:$A$23,0)),"")) -> 6 | U9: =IF(A9="","",IFERROR(INDEX(Classes!$F$5:$F$23,MATCH(A9,Classes!$A$5:$A$23,0)),"")) -> None;Partner drilling;Live grappling | V9: =IF(OR(D9="",$A9=""),"",IF(ISNA(MATCH(D9,Drills!$A$5:$A$127,0)),"?",IF(N(INDEX(Drills!$K$5:$K$127,MATCH(D9,Drills!$A$5:$A$127,0)))>N($T9),"A","")&IF(ISNUMBER(SEARCH(INDEX(Drills!$E$5:$E$127,MATCH(D9,Drills!$A$5:$A$127,0)),$U9)),"","C"))) | W9: =IF(OR(F9="",$A9=""),"",IF(ISNA(MATCH(F9,Drills!$A$5:$A$127,0)),"?",IF(N(INDEX(Drills!$K$5:$K$127,MATCH(F9,Drills!$A$5:$A$127,0)))>N($T9),"A","")&IF(ISNUMBER(SEARCH(INDEX(Drills!$E$5:$E$127,MATCH(F9,Drills!$A$5:$A$127,0)),$U9)),"","C"))) | X9: =IF(OR(H9="",$A9=""),"",IF(ISNA(MATCH(H9,Drills!$A$5:$A$127,0)),"?",IF(N(INDEX(Drills!$K$5:$K$127,MATCH(H9,Drills!$A$5:$A$127,0)))>N($T9),"A","")&IF(ISNUMBER(SEARCH(INDEX(Drills!$E$5:$E$127,MATCH(H9,Drills!$A$5:$A$127,0)),$U9)),"","C"))) | Y9: =IF(OR(J9="",$A9=""),"",IF(ISNA(MATCH(J9,Drills!$A$5:$A$127,0)),"?",IF(N(INDEX(Drills!$K$5:$K$127,MATCH(J9,Drills!$A$5:$A$127,0)))>N($T9),"A","")&IF(ISNUMBER(SEARCH(INDEX(Drills!$E$5:$E$127,MATCH(J9,Drills!$A$5:$A$127,0)),$U9)),"","C"))) | Z9: =IF(OR(L9="",$A9=""),"",IF(ISNA(MATCH(L9,Drills!$A$5:$A$127,0)),"?",IF(N(INDEX(Drills!$K$5:$K$127,MATCH(L9,Drills!$A$5:$A$127,0)))>N($T9),"A","")&IF(ISNUMBER(SEARCH(INDEX(Drills!$E$5:$E$127,MATCH(L9,Drills!$A$5:$A$127,0)),$U9)),"","C"))) | AA9: =IF(OR(N9="",$A9=""),"",IF(ISNA(MATCH(N9,Drills!$A$5:$A$127,0)),"?",IF(N(INDEX(Drills!$K$5:$K$127,MATCH(N9,Drills!$A$5:$A$127,0)))>N($T9),"A","")&IF(ISNUMBER(SEARCH(INDEX(Drills!$E$5:$E$127,MATCH(N9,Drills!$A$5:$A$127,0)),$U9)),"","C"))) | AB9: =IF(A9="","",IFERROR(INDEX(Classes!$I$5:$I$23,MATCH(A9,Classes!$A$5:$A$23,0)),"")) -> No
A10: Wrestling | B10: 2 | C10: Penetration step | D10: Breakfalls | E10: 6 | F10: Penetration step | G10: 8 | H10: Sprawl drill | I10: 5 | J10: Sumo push | K10: 6 | L10: Live wrestling from the knees | M10: 10 | N10: Cool-down stretch and breathing | O10: 5 | P10: =IF(A10="","",SUM(E10,G10,I10,K10,M10,O10)) -> 40 | Q10: =IF(A10="","",IFERROR(INDEX(Classes!$C$5:$C$23,MATCH(A10,Classes!$A$5:$A$23,0)),"")) -> 40 | R10: =IF(A10="","",IF(TRIM(IF(AND(N(Q10)>0,N(P10)>N(Q10)),"Over by "&(P10-Q10)&" min. ","")&IF(AND(COUNTIF(V10:AA10,"*A*")>0,AB10<>"Yes"),"Age check. ","")&IF(COUNTIF(V10:AA10,"*C*")>0,"Contact check. ","")&IF(COUNTIF(V10:AA10,"~?")>0,"Drill not in library. ",""))="","OK"&IF(AND(COUNTIF(V10:AA10,"*A*")>0,AB10="Yes")," · split by age","")&IF(N(Q10)>N(P10)," ("&(Q10-P10)&" min spare)",""),TRIM(IF(AND(N(Q10)>0,N(P10)>N(Q10)),"Over by "&(P10-Q10)&" min. ","")&IF(AND(COUNTIF(V10:AA10,"*A*")>0,AB10<>"Yes"),"Age check. ","")&IF(COUNTIF(V10:AA10,"*C*")>0,"Contact check. ","")&IF(COUNTIF(V10:AA10,"~?")>0,"Drill not in library. ",""))&IF(AND(COUNTIF(V10:AA10,"*A*")>0,AB10="Yes")," · split by age",""))) -> OK | T10: =IF(A10="","",IFERROR(INDEX(Classes!$E$5:$E$23,MATCH(A10,Classes!$A$5:$A$23,0)),"")) -> 6 | U10: =IF(A10="","",IFERROR(INDEX(Classes!$F$5:$F$23,MATCH(A10,Classes!$A$5:$A$23,0)),"")) -> None;Partner drilling;Live grappling | V10: =IF(OR(D10="",$A10=""),"",IF(ISNA(MATCH(D10,Drills!$A$5:$A$127,0)),"?",IF(N(INDEX(Drills!$K$5:$K$127,MATCH(D10,Drills!$A$5:$A$127,0)))>N($T10),"A","")&IF(ISNUMBER(SEARCH(INDEX(Drills!$E$5:$E$127,MATCH(D10,Drills!$A$5:$A$127,0)),$U10)),"","C"))) | W10: =IF(OR(F10="",$A10=""),"",IF(ISNA(MATCH(F10,Drills!$A$5:$A$127,0)),"?",IF(N(INDEX(Drills!$K$5:$K$127,MATCH(F10,Drills!$A$5:$A$127,0)))>N($T10),"A","")&IF(ISNUMBER(SEARCH(INDEX(Drills!$E$5:$E$127,MATCH(F10,Drills!$A$5:$A$127,0)),$U10)),"","C"))) | X10: =IF(OR(H10="",$A10=""),"",IF(ISNA(MATCH(H10,Drills!$A$5:$A$127,0)),"?",IF(N(INDEX(Drills!$K$5:$K$127,MATCH(H10,Drills!$A$5:$A$127,0)))>N($T10),"A","")&IF(ISNUMBER(SEARCH(INDEX(Drills!$E$5:$E$127,MATCH(H10,Drills!$A$5:$A$127,0)),$U10)),"","C"))) | Y10: =IF(OR(J10="",$A10=""),"",IF(ISNA(MATCH(J10,Drills!$A$5:$A$127,0)),"?",IF(N(INDEX(Drills!$K$5:$K$127,MATCH(J10,Drills!$A$5:$A$127,0)))>N($T10),"A","")&IF(ISNUMBER(SEARCH(INDEX(Drills!$E$5:$E$127,MATCH(J10,Drills!$A$5:$A$127,0)),$U10)),"","C"))) | Z10: =IF(OR(L10="",$A10=""),"",IF(ISNA(MATCH(L10,Drills!$A$5:$A$127,0)),"?",IF(N(INDEX(Drills!$K$5:$K$127,MATCH(L10,Drills!$A$5:$A$127,0)))>N($T10),"A","")&IF(ISNUMBER(SEARCH(INDEX(Drills!$E$5:$E$127,MATCH(L10,Drills!$A$5:$A$127,0)),$U10)),"","C"))) | AA10: =IF(OR(N10="",$A10=""),"",IF(ISNA(MATCH(N10,Drills!$A$5:$A$127,0)),"?",IF(N(INDEX(Drills!$K$5:$K$127,MATCH(N10,Drills!$A$5:$A$127,0)))>N($T10),"A","")&IF(ISNUMBER(SEARCH(INDEX(Drills!$E$5:$E$127,MATCH(N10,Drills!$A$5:$A$127,0)),$U10)),"","C"))) | AB10: =IF(A10="","",IFERROR(INDEX(Classes!$I$5:$I$23,MATCH(A10,Classes!$A$5:$A$23,0)),"")) -> No
A11: Wrestling | B11: 3 | C11: Pins | D11: Animal walks | E11: 6 | F11: Half nelson turn | G11: 8 | H11: Turtle flip | I11: 6 | J11: Sprawl drill | K11: 5 | L11: Live wrestling from the knees | M11: 10 | N11: Cool-down stretch and breathing | O11: 5 | P11: =IF(A11="","",SUM(E11,G11,I11,K11,M11,O11)) -> 40 | Q11: =IF(A11="","",IFERROR(INDEX(Classes!$C$5:$C$23,MATCH(A11,Classes!$A$5:$A$23,0)),"")) -> 40 | R11: =IF(A11="","",IF(TRIM(IF(AND(N(Q11)>0,N(P11)>N(Q11)),"Over by "&(P11-Q11)&" min. ","")&IF(AND(COUNTIF(V11:AA11,"*A*")>0,AB11<>"Yes"),"Age check. ","")&IF(COUNTIF(V11:AA11,"*C*")>0,"Contact check. ","")&IF(COUNTIF(V11:AA11,"~?")>0,"Drill not in library. ",""))="","OK"&IF(AND(COUNTIF(V11:AA11,"*A*")>0,AB11="Yes")," · split by age","")&IF(N(Q11)>N(P11)," ("&(Q11-P11)&" min spare)",""),TRIM(IF(AND(N(Q11)>0,N(P11)>N(Q11)),"Over by "&(P11-Q11)&" min. ","")&IF(AND(COUNTIF(V11:AA11,"*A*")>0,AB11<>"Yes"),"Age check. ","")&IF(COUNTIF(V11:AA11,"*C*")>0,"Contact check. ","")&IF(COUNTIF(V11:AA11,"~?")>0,"Drill not in library. ",""))&IF(AND(COUNTIF(V11:AA11,"*A*")>0,AB11="Yes")," · split by age",""))) -> OK | T11: =IF(A11="","",IFERROR(INDEX(Classes!$E$5:$E$23,MATCH(A11,Classes!$A$5:$A$23,0)),"")) -> 6 | U11: =IF(A11="","",IFERROR(INDEX(Classes!$F$5:$F$23,MATCH(A11,Classes!$A$5:$A$23,0)),"")) -> None;Partner drilling;Live grappling | V11: =IF(OR(D11="",$A11=""),"",IF(ISNA(MATCH(D11,Drills!$A$5:$A$127,0)),"?",IF(N(INDEX(Drills!$K$5:$K$127,MATCH(D11,Drills!$A$5:$A$127,0)))>N($T11),"A","")&IF(ISNUMBER(SEARCH(INDEX(Drills!$E$5:$E$127,MATCH(D11,Drills!$A$5:$A$127,0)),$U11)),"","C"))) | W11: =IF(OR(F11="",$A11=""),"",IF(ISNA(MATCH(F11,Drills!$A$5:$A$127,0)),"?",IF(N(INDEX(Drills!$K$5:$K$127,MATCH(F11,Drills!$A$5:$A$127,0)))>N($T11),"A","")&IF(ISNUMBER(SEARCH(INDEX(Drills!$E$5:$E$127,MATCH(F11,Drills!$A$5:$A$127,0)),$U11)),"","C"))) | X11: =IF(OR(H11="",$A11=""),"",IF(ISNA(MATCH(H11,Drills!$A$5:$A$127,0)),"?",IF(N(INDEX(Drills!$K$5:$K$127,MATCH(H11,Drills!$A$5:$A$127,0)))>N($T11),"A","")&IF(ISNUMBER(SEARCH(INDEX(Drills!$E$5:$E$127,MATCH(H11,Drills!$A$5:$A$127,0)),$U11)),"","C"))) | Y11: =IF(OR(J11="",$A11=""),"",IF(ISNA(MATCH(J11,Drills!$A$5:$A$127,0)),"?",IF(N(INDEX(Drills!$K$5:$K$127,MATCH(J11,Drills!$A$5:$A$127,0)))>N($T11),"A","")&IF(ISNUMBER(SEARCH(INDEX(Drills!$E$5:$E$127,MATCH(J11,Drills!$A$5:$A$127,0)),$U11)),"","C"))) | Z11: =IF(OR(L11="",$A11=""),"",IF(ISNA(MATCH(L11,Drills!$A$5:$A$127,0)),"?",IF(N(INDEX(Drills!$K$5:$K$127,MATCH(L11,Drills!$A$5:$A$127,0)))>N($T11),"A","")&IF(ISNUMBER(SEARCH(INDEX(Drills!$E$5:$E$127,MATCH(L11,Drills!$A$5:$A$127,0)),$U11)),"","C"))) | AA11: =IF(OR(N11="",$A11=""),"",IF(ISNA(MATCH(N11,Drills!$A$5:$A$127,0)),"?",IF(N(INDEX(Drills!$K$5:$K$127,MATCH(N11,Drills!$A$5:$A$127,0)))>N($T11),"A","")&IF(ISNUMBER(SEARCH(INDEX(Drills!$E$5:$E$127,MATCH(N11,Drills!$A$5:$A$127,0)),$U11)),"","C"))) | AB11: =IF(A11="","",IFERROR(INDEX(Classes!$I$5:$I$23,MATCH(A11,Classes!$A$5:$A$23,0)),"")) -> No
A12: Wrestling | B12: 4 | C12: Review and games | D12: Breakfalls | E12: 6 | F12: Penetration step | G12: 8 | H12: Knee tag | I12: 6 | J12: Sprawl drill | K12: 5 | L12: Live wrestling from the knees | M12: 10 | N12: Cool-down stretch and breathing | O12: 5 | P12: =IF(A12="","",SUM(E12,G12,I12,K12,M12,O12)) -> 40 | Q12: =IF(A12="","",IFERROR(INDEX(Classes!$C$5:$C$23,MATCH(A12,Classes!$A$5:$A$23,0)),"")) -> 40 | R12: =IF(A12="","",IF(TRIM(IF(AND(N(Q12)>0,N(P12)>N(Q12)),"Over by "&(P12-Q12)&" min. ","")&IF(AND(COUNTIF(V12:AA12,"*A*")>0,AB12<>"Yes"),"Age check. ","")&IF(COUNTIF(V12:AA12,"*C*")>0,"Contact check. ","")&IF(COUNTIF(V12:AA12,"~?")>0,"Drill not in library. ",""))="","OK"&IF(AND(COUNTIF(V12:AA12,"*A*")>0,AB12="Yes")," · split by age","")&IF(N(Q12)>N(P12)," ("&(Q12-P12)&" min spare)",""),TRIM(IF(AND(N(Q12)>0,N(P12)>N(Q12)),"Over by "&(P12-Q12)&" min. ","")&IF(AND(COUNTIF(V12:AA12,"*A*")>0,AB12<>"Yes"),"Age check. ","")&IF(COUNTIF(V12:AA12,"*C*")>0,"Contact check. ","")&IF(COUNTIF(V12:AA12,"~?")>0,"Drill not in library. ",""))&IF(AND(COUNTIF(V12:AA12,"*A*")>0,AB12="Yes")," · split by age",""))) -> OK | T12: =IF(A12="","",IFERROR(INDEX(Classes!$E$5:$E$23,MATCH(A12,Classes!$A$5:$A$23,0)),"")) -> 6 | U12: =IF(A12="","",IFERROR(INDEX(Classes!$F$5:$F$23,MATCH(A12,Classes!$A$5:$A$23,0)),"")) -> None;Partner drilling;Live grappling | V12: =IF(OR(D12="",$A12=""),"",IF(ISNA(MATCH(D12,Drills!$A$5:$A$127,0)),"?",IF(N(INDEX(Drills!$K$5:$K$127,MATCH(D12,Drills!$A$5:$A$127,0)))>N($T12),"A","")&IF(ISNUMBER(SEARCH(INDEX(Drills!$E$5:$E$127,MATCH(D12,Drills!$A$5:$A$127,0)),$U12)),"","C"))) | W12: =IF(OR(F12="",$A12=""),"",IF(ISNA(MATCH(F12,Drills!$A$5:$A$127,0)),"?",IF(N(INDEX(Drills!$K$5:$K$127,MATCH(F12,Drills!$A$5:$A$127,0)))>N($T12),"A","")&IF(ISNUMBER(SEARCH(INDEX(Drills!$E$5:$E$127,MATCH(F12,Drills!$A$5:$A$127,0)),$U12)),"","C"))) | X12: =IF(OR(H12="",$A12=""),"",IF(ISNA(MATCH(H12,Drills!$A$5:$A$127,0)),"?",IF(N(INDEX(Drills!$K$5:$K$127,MATCH(H12,Drills!$A$5:$A$127,0)))>N($T12),"A","")&IF(ISNUMBER(SEARCH(INDEX(Drills!$E$5:$E$127,MATCH(H12,Drills!$A$5:$A$127,0)),$U12)),"","C"))) | Y12: =IF(OR(J12="",$A12=""),"",IF(ISNA(MATCH(J12,Drills!$A$5:$A$127,0)),"?",IF(N(INDEX(Drills!$K$5:$K$127,MATCH(J12,Drills!$A$5:$A$127,0)))>N($T12),"A","")&IF(ISNUMBER(SEARCH(INDEX(Drills!$E$5:$E$127,MATCH(J12,Drills!$A$5:$A$127,0)),$U12)),"","C"))) | Z12: =IF(OR(L12="",$A12=""),"",IF(ISNA(MATCH(L12,Drills!$A$5:$A$127,0)),"?",IF(N(INDEX(Drills!$K$5:$K$127,MATCH(L12,Drills!$A$5:$A$127,0)))>N($T12),"A","")&IF(ISNUMBER(SEARCH(INDEX(Drills!$E$5:$E$127,MATCH(L12,Drills!$A$5:$A$127,0)),$U12)),"","C"))) | AA12: =IF(OR(N12="",$A12=""),"",IF(ISNA(MATCH(N12,Drills!$A$5:$A$127,0)),"?",IF(N(INDEX(Drills!$K$5:$K$127,MATCH(N12,Drills!$A$5:$A$127,0)))>N($T12),"A","")&IF(ISNUMBER(SEARCH(INDEX(Drills!$E$5:$E$127,MATCH(N12,Drills!$A$5:$A$127,0)),$U12)),"","C"))) | AB12: =IF(A12="","",IFERROR(INDEX(Classes!$I$5:$I$23,MATCH(A12,Classes!$A$5:$A$23,0)),"")) -> No
A13: Boxing 11-14 | B13: 1 | C13: Fundamentals | D13: Jump rope | E13: 6 | F13: Stance and guard | G13: 8 | H13: Step-drag footwork | I13: 8 | J13: 1-2 on pads | K13: 10 | L13: Heavy bag rounds | M13: 12 | N13: Cool-down stretch and breathing | O13: 6 | P13: =IF(A13="","",SUM(E13,G13,I13,K13,M13,O13)) -> 50 | Q13: =IF(A13="","",IFERROR(INDEX(Classes!$C$5:$C$23,MATCH(A13,Classes!$A$5:$A$23,0)),"")) -> 60 | R13: =IF(A13="","",IF(TRIM(IF(AND(N(Q13)>0,N(P13)>N(Q13)),"Over by "&(P13-Q13)&" min. ","")&IF(AND(COUNTIF(V13:AA13,"*A*")>0,AB13<>"Yes"),"Age check. ","")&IF(COUNTIF(V13:AA13,"*C*")>0,"Contact check. ","")&IF(COUNTIF(V13:AA13,"~?")>0,"Drill not in library. ",""))="","OK"&IF(AND(COUNTIF(V13:AA13,"*A*")>0,AB13="Yes")," · split by age","")&IF(N(Q13)>N(P13)," ("&(Q13-P13)&" min spare)",""),TRIM(IF(AND(N(Q13)>0,N(P13)>N(Q13)),"Over by "&(P13-Q13)&" min. ","")&IF(AND(COUNTIF(V13:AA13,"*A*")>0,AB13<>"Yes"),"Age check. ","")&IF(COUNTIF(V13:AA13,"*C*")>0,"Contact check. ","")&IF(COUNTIF(V13:AA13,"~?")>0,"Drill not in library. ",""))&IF(AND(COUNTIF(V13:AA13,"*A*")>0,AB13="Yes")," · split by age",""))) -> OK (10 min spare) | T13: =IF(A13="","",IFERROR(INDEX(Classes!$E$5:$E$23,MATCH(A13,Classes!$A$5:$A$23,0)),"")) -> 11 | U13: =IF(A13="","",IFERROR(INDEX(Classes!$F$5:$F$23,MATCH(A13,Classes!$A$5:$A$23,0)),"")) -> None;Pads/bag;Light touch (body) | V13: =IF(OR(D13="",$A13=""),"",IF(ISNA(MATCH(D13,Drills!$A$5:$A$127,0)),"?",IF(N(INDEX(Drills!$K$5:$K$127,MATCH(D13,Drills!$A$5:$A$127,0)))>N($T13),"A","")&IF(ISNUMBER(SEARCH(INDEX(Drills!$E$5:$E$127,MATCH(D13,Drills!$A$5:$A$127,0)),$U13)),"","C"))) | W13: =IF(OR(F13="",$A13=""),"",IF(ISNA(MATCH(F13,Drills!$A$5:$A$127,0)),"?",IF(N(INDEX(Drills!$K$5:$K$127,MATCH(F13,Drills!$A$5:$A$127,0)))>N($T13),"A","")&IF(ISNUMBER(SEARCH(INDEX(Drills!$E$5:$E$127,MATCH(F13,Drills!$A$5:$A$127,0)),$U13)),"","C"))) | X13: =IF(OR(H13="",$A13=""),"",IF(ISNA(MATCH(H13,Drills!$A$5:$A$127,0)),"?",IF(N(INDEX(Drills!$K$5:$K$127,MATCH(H13,Drills!$A$5:$A$127,0)))>N($T13),"A","")&IF(ISNUMBER(SEARCH(INDEX(Drills!$E$5:$E$127,MATCH(H13,Drills!$A$5:$A$127,0)),$U13)),"","C"))) | Y13: =IF(OR(J13="",$A13=""),"",IF(ISNA(MATCH(J13,Drills!$A$5:$A$127,0)),"?",IF(N(INDEX(Drills!$K$5:$K$127,MATCH(J13,Drills!$A$5:$A$127,0)))>N($T13),"A","")&IF(ISNUMBER(SEARCH(INDEX(Drills!$E$5:$E$127,MATCH(J13,Drills!$A$5:$A$127,0)),$U13)),"","C"))) | Z13: =IF(OR(L13="",$A13=""),"",IF(ISNA(MATCH(L13,Drills!$A$5:$A$127,0)),"?",IF(N(INDEX(Drills!$K$5:$K$127,MATCH(L13,Drills!$A$5:$A$127,0)))>N($T13),"A","")&IF(ISNUMBER(SEARCH(INDEX(Drills!$E$5:$E$127,MATCH(L13,Drills!$A$5:$A$127,0)),$U13)),"","C"))) | AA13: =IF(OR(N13="",$A13=""),"",IF(ISNA(MATCH(N13,Drills!$A$5:$A$127,0)),"?",IF(N(INDEX(Drills!$K$5:$K$127,MATCH(N13,Drills!$A$5:$A$127,0)))>N($T13),"A","")&IF(ISNUMBER(SEARCH(INDEX(Drills!$E$5:$E$127,MATCH(N13,Drills!$A$5:$A$127,0)),$U13)),"","C"))) | AB13: =IF(A13="","",IFERROR(INDEX(Classes!$I$5:$I$23,MATCH(A13,Classes!$A$5:$A$23,0)),"")) -> No
A14: Boxing 11-14 | B14: 2 | C14: Combinations | D14: Dynamic warm-up | E14: 10 | F14: 1-2-3 on pads | G14: 10 | H14: Coach-called combinations | I14: 8 | J14: Heavy bag rounds | K14: 12 | L14: Bob and weave under the rope | M14: 6 | N14: Cool-down stretch and breathing | O14: 6 | P14: =IF(A14="","",SUM(E14,G14,I14,K14,M14,O14)) -> 52 | Q14: =IF(A14="","",IFERROR(INDEX(Classes!$C$5:$C$23,MATCH(A14,Classes!$A$5:$A$23,0)),"")) -> 60 | R14: =IF(A14="","",IF(TRIM(IF(AND(N(Q14)>0,N(P14)>N(Q14)),"Over by "&(P14-Q14)&" min. ","")&IF(AND(COUNTIF(V14:AA14,"*A*")>0,AB14<>"Yes"),"Age check. ","")&IF(COUNTIF(V14:AA14,"*C*")>0,"Contact check. ","")&IF(COUNTIF(V14:AA14,"~?")>0,"Drill not in library. ",""))="","OK"&IF(AND(COUNTIF(V14:AA14,"*A*")>0,AB14="Yes")," · split by age","")&IF(N(Q14)>N(P14)," ("&(Q14-P14)&" min spare)",""),TRIM(IF(AND(N(Q14)>0,N(P14)>N(Q14)),"Over by "&(P14-Q14)&" min. ","")&IF(AND(COUNTIF(V14:AA14,"*A*")>0,AB14<>"Yes"),"Age check. ","")&IF(COUNTIF(V14:AA14,"*C*")>0,"Contact check. ","")&IF(COUNTIF(V14:AA14,"~?")>0,"Drill not in library. ",""))&IF(AND(COUNTIF(V14:AA14,"*A*")>0,AB14="Yes")," · split by age",""))) -> OK (8 min spare) | T14: =IF(A14="","",IFERROR(INDEX(Classes!$E$5:$E$23,MATCH(A14,Classes!$A$5:$A$23,0)),"")) -> 11 | U14: =IF(A14="","",IFERROR(INDEX(Classes!$F$5:$F$23,MATCH(A14,Classes!$A$5:$A$23,0)),"")) -> None;Pads/bag;Light touch (body) | V14: =IF(OR(D14="",$A14=""),"",IF(ISNA(MATCH(D14,Drills!$A$5:$A$127,0)),"?",IF(N(INDEX(Drills!$K$5:$K$127,MATCH(D14,Drills!$A$5:$A$127,0)))>N($T14),"A","")&IF(ISNUMBER(SEARCH(INDEX(Drills!$E$5:$E$127,MATCH(D14,Drills!$A$5:$A$127,0)),$U14)),"","C"))) | W14: =IF(OR(F14="",$A14=""),"",IF(ISNA(MATCH(F14,Drills!$A$5:$A$127,0)),"?",IF(N(INDEX(Drills!$K$5:$K$127,MATCH(F14,Drills!$A$5:$A$127,0)))>N($T14),"A","")&IF(ISNUMBER(SEARCH(INDEX(Drills!$E$5:$E$127,MATCH(F14,Drills!$A$5:$A$127,0)),$U14)),"","C"))) | X14: =IF(OR(H14="",$A14=""),"",IF(ISNA(MATCH(H14,Drills!$A$5:$A$127,0)),"?",IF(N(INDEX(Drills!$K$5:$K$127,MATCH(H14,Drills!$A$5:$A$127,0)))>N($T14),"A","")&IF(ISNUMBER(SEARCH(INDEX(Drills!$E$5:$E$127,MATCH(H14,Drills!$A$5:$A$127,0)),$U14)),"","C"))) | Y14: =IF(OR(J14="",$A14=""),"",IF(ISNA(MATCH(J14,Drills!$A$5:$A$127,0)),"?",IF(N(INDEX(Drills!$K$5:$K$127,MATCH(J14,Drills!$A$5:$A$127,0)))>N($T14),"A","")&IF(ISNUMBER(SEARCH(INDEX(Drills!$E$5:$E$127,MATCH(J14,Drills!$A$5:$A$127,0)),$U14)),"","C"))) | Z14: =IF(OR(L14="",$A14=""),"",IF(ISNA(MATCH(L14,Drills!$A$5:$A$127,0)),"?",IF(N(INDEX(Drills!$K$5:$K$127,MATCH(L14,Drills!$A$5:$A$127,0)))>N($T14),"A","")&IF(ISNUMBER(SEARCH(INDEX(Drills!$E$5:$E$127,MATCH(L14,Drills!$A$5:$A$127,0)),$U14)),"","C"))) | AA14: =IF(OR(N14="",$A14=""),"",IF(ISNA(MATCH(N14,Drills!$A$5:$A$127,0)),"?",IF(N(INDEX(Drills!$K$5:$K$127,MATCH(N14,Drills!$A$5:$A$127,0)))>N($T14),"A","")&IF(ISNUMBER(SEARCH(INDEX(Drills!$E$5:$E$127,MATCH(N14,Drills!$A$5:$A$127,0)),$U14)),"","C"))) | AB14: =IF(A14="","",IFERROR(INDEX(Classes!$I$5:$I$23,MATCH(A14,Classes!$A$5:$A$23,0)),"")) -> No
A15: Boxing 11-14 | B15: 3 | C15: Defence | D15: Jump rope | E15: 6 | F15: Slip line | G15: 8 | H15: Bob and weave under the rope | I15: 8 | J15: Heavy bag rounds | K15: 12 | L15: Body-only partner touch | M15: 8 | N15: Cool-down stretch and breathing | O15: 6 | P15: =IF(A15="","",SUM(E15,G15,I15,K15,M15,O15)) -> 48 | Q15: =IF(A15="","",IFERROR(INDEX(Classes!$C$5:$C$23,MATCH(A15,Classes!$A$5:$A$23,0)),"")) -> 60 | R15: =IF(A15="","",IF(TRIM(IF(AND(N(Q15)>0,N(P15)>N(Q15)),"Over by "&(P15-Q15)&" min. ","")&IF(AND(COUNTIF(V15:AA15,"*A*")>0,AB15<>"Yes"),"Age check. ","")&IF(COUNTIF(V15:AA15,"*C*")>0,"Contact check. ","")&IF(COUNTIF(V15:AA15,"~?")>0,"Drill not in library. ",""))="","OK"&IF(AND(COUNTIF(V15:AA15,"*A*")>0,AB15="Yes")," · split by age","")&IF(N(Q15)>N(P15)," ("&(Q15-P15)&" min spare)",""),TRIM(IF(AND(N(Q15)>0,N(P15)>N(Q15)),"Over by "&(P15-Q15)&" min. ","")&IF(AND(COUNTIF(V15:AA15,"*A*")>0,AB15<>"Yes"),"Age check. ","")&IF(COUNTIF(V15:AA15,"*C*")>0,"Contact check. ","")&IF(COUNTIF(V15:AA15,"~?")>0,"Drill not in library. ",""))&IF(AND(COUNTIF(V15:AA15,"*A*")>0,AB15="Yes")," · split by age",""))) -> OK (12 min spare) | T15: =IF(A15="","",IFERROR(INDEX(Classes!$E$5:$E$23,MATCH(A15,Classes!$A$5:$A$23,0)),"")) -> 11 | U15: =IF(A15="","",IFERROR(INDEX(Classes!$F$5:$F$23,MATCH(A15,Classes!$A$5:$A$23,0)),"")) -> None;Pads/bag;Light touch (body) | V15: =IF(OR(D15="",$A15=""),"",IF(ISNA(MATCH(D15,Drills!$A$5:$A$127,0)),"?",IF(N(INDEX(Drills!$K$5:$K$127,MATCH(D15,Drills!$A$5:$A$127,0)))>N($T15),"A","")&IF(ISNUMBER(SEARCH(INDEX(Drills!$E$5:$E$127,MATCH(D15,Drills!$A$5:$A$127,0)),$U15)),"","C"))) | W15: =IF(OR(F15="",$A15=""),"",IF(ISNA(MATCH(F15,Drills!$A$5:$A$127,0)),"?",IF(N(INDEX(Drills!$K$5:$K$127,MATCH(F15,Drills!$A$5:$A$127,0)))>N($T15),"A","")&IF(ISNUMBER(SEARCH(INDEX(Drills!$E$5:$E$127,MATCH(F15,Drills!$A$5:$A$127,0)),$U15)),"","C"))) | X15: =IF(OR(H15="",$A15=""),"",IF(ISNA(MATCH(H15,Drills!$A$5:$A$127,0)),"?",IF(N(INDEX(Drills!$K$5:$K$127,MATCH(H15,Drills!$A$5:$A$127,0)))>N($T15),"A","")&IF(ISNUMBER(SEARCH(INDEX(Drills!$E$5:$E$127,MATCH(H15,Drills!$A$5:$A$127,0)),$U15)),"","C"))) | Y15: =IF(OR(J15="",$A15=""),"",IF(ISNA(MATCH(J15,Drills!$A$5:$A$127,0)),"?",IF(N(INDEX(Drills!$K$5:$K$127,MATCH(J15,Drills!$A$5:$A$127,0)))>N($T15),"A","")&IF(ISNUMBER(SEARCH(INDEX(Drills!$E$5:$E$127,MATCH(J15,Drills!$A$5:$A$127,0)),$U15)),"","C"))) | Z15: =IF(OR(L15="",$A15=""),"",IF(ISNA(MATCH(L15,Drills!$A$5:$A$127,0)),"?",IF(N(INDEX(Drills!$K$5:$K$127,MATCH(L15,Drills!$A$5:$A$127,0)))>N($T15),"A","")&IF(ISNUMBER(SEARCH(INDEX(Drills!$E$5:$E$127,MATCH(L15,Drills!$A$5:$A$127,0)),$U15)),"","C"))) | AA15: =IF(OR(N15="",$A15=""),"",IF(ISNA(MATCH(N15,Drills!$A$5:$A$127,0)),"?",IF(N(INDEX(Drills!$K$5:$K$127,MATCH(N15,Drills!$A$5:$A$127,0)))>N($T15),"A","")&IF(ISNUMBER(SEARCH(INDEX(Drills!$E$5:$E$127,MATCH(N15,Drills!$A$5:$A$127,0)),$U15)),"","C"))) | AB15: =IF(A15="","",IFERROR(INDEX(Classes!$I$5:$I$23,MATCH(A15,Classes!$A$5:$A$23,0)),"")) -> No
A16: Boxing 11-14 | B16: 4 | C16: Putting it together | D16: Dynamic warm-up | E16: 10 | F16: Footwork ladder and cones | G16: 8 | H16: 1-2-3 on pads | I16: 10 | J16: Heavy bag rounds | K16: 12 | L16: Body-only partner touch | M16: 8 | N16: Cool-down stretch and breathing | O16: 6 | P16: =IF(A16="","",SUM(E16,G16,I16,K16,M16,O16)) -> 54 | Q16: =IF(A16="","",IFERROR(INDEX(Classes!$C$5:$C$23,MATCH(A16,Classes!$A$5:$A$23,0)),"")) -> 60 | R16: =IF(A16="","",IF(TRIM(IF(AND(N(Q16)>0,N(P16)>N(Q16)),"Over by "&(P16-Q16)&" min. ","")&IF(AND(COUNTIF(V16:AA16,"*A*")>0,AB16<>"Yes"),"Age check. ","")&IF(COUNTIF(V16:AA16,"*C*")>0,"Contact check. ","")&IF(COUNTIF(V16:AA16,"~?")>0,"Drill not in library. ",""))="","OK"&IF(AND(COUNTIF(V16:AA16,"*A*")>0,AB16="Yes")," · split by age","")&IF(N(Q16)>N(P16)," ("&(Q16-P16)&" min spare)",""),TRIM(IF(AND(N(Q16)>0,N(P16)>N(Q16)),"Over by "&(P16-Q16)&" min. ","")&IF(AND(COUNTIF(V16:AA16,"*A*")>0,AB16<>"Yes"),"Age check. ","")&IF(COUNTIF(V16:AA16,"*C*")>0,"Contact check. ","")&IF(COUNTIF(V16:AA16,"~?")>0,"Drill not in library. ",""))&IF(AND(COUNTIF(V16:AA16,"*A*")>0,AB16="Yes")," · split by age",""))) -> OK (6 min spare) | T16: =IF(A16="","",IFERROR(INDEX(Classes!$E$5:$E$23,MATCH(A16,Classes!$A$5:$A$23,0)),"")) -> 11 | U16: =IF(A16="","",IFERROR(INDEX(Classes!$F$5:$F$23,MATCH(A16,Classes!$A$5:$A$23,0)),"")) -> None;Pads/bag;Light touch (body) | V16: =IF(OR(D16="",$A16=""),"",IF(ISNA(MATCH(D16,Drills!$A$5:$A$127,0)),"?",IF(N(INDEX(Drills!$K$5:$K$127,MATCH(D16,Drills!$A$5:$A$127,0)))>N($T16),"A","")&IF(ISNUMBER(SEARCH(INDEX(Drills!$E$5:$E$127,MATCH(D16,Drills!$A$5:$A$127,0)),$U16)),"","C"))) | W16: =IF(OR(F16="",$A16=""),"",IF(ISNA(MATCH(F16,Drills!$A$5:$A$127,0)),"?",IF(N(INDEX(Drills!$K$5:$K$127,MATCH(F16,Drills!$A$5:$A$127,0)))>N($T16),"A","")&IF(ISNUMBER(SEARCH(INDEX(Drills!$E$5:$E$127,MATCH(F16,Drills!$A$5:$A$127,0)),$U16)),"","C"))) | X16: =IF(OR(H16="",$A16=""),"",IF(ISNA(MATCH(H16,Drills!$A$5:$A$127,0)),"?",IF(N(INDEX(Drills!$K$5:$K$127,MATCH(H16,Drills!$A$5:$A$127,0)))>N($T16),"A","")&IF(ISNUMBER(SEARCH(INDEX(Drills!$E$5:$E$127,MATCH(H16,Drills!$A$5:$A$127,0)),$U16)),"","C"))) | Y16: =IF(OR(J16="",$A16=""),"",IF(ISNA(MATCH(J16,Drills!$A$5:$A$127,0)),"?",IF(N(INDEX(Drills!$K$5:$K$127,MATCH(J16,Drills!$A$5:$A$127,0)))>N($T16),"A","")&IF(ISNUMBER(SEARCH(INDEX(Drills!$E$5:$E$127,MATCH(J16,Drills!$A$5:$A$127,0)),$U16)),"","C"))) | Z16: =IF(OR(L16="",$A16=""),"",IF(ISNA(MATCH(L16,Drills!$A$5:$A$127,0)),"?",IF(N(INDEX(Drills!$K$5:$K$127,MATCH(L16,Drills!$A$5:$A$127,0)))>N($T16),"A","")&IF(ISNUMBER(SEARCH(INDEX(Drills!$E$5:$E$127,MATCH(L16,Drills!$A$5:$A$127,0)),$U16)),"","C"))) | AA16: =IF(OR(N16="",$A16=""),"",IF(ISNA(MATCH(N16,Drills!$A$5:$A$127,0)),"?",IF(N(INDEX(Drills!$K$5:$K$127,MATCH(N16,Drills!$A$5:$A$127,0)))>N($T16),"A","")&IF(ISNUMBER(SEARCH(INDEX(Drills!$E$5:$E$127,MATCH(N16,Drills!$A$5:$A$127,0)),$U16)),"","C"))) | AB16: =IF(A16="","",IFERROR(INDEX(Classes!$I$5:$I$23,MATCH(A16,Classes!$A$5:$A$23,0)),"")) -> No
... A40: Competition Class | B40: 4 | C40: Fight week | D40: Shadowboxing round | E40: 6 | F40: Coach-called combinations | G40: 8 | H40: Heavy bag rounds | I40: 10 | J40: Controlled technical sparring | K40: 12 | L40: Bag and body-weight circuit | M40: 12 | N40: Cool-down stretch and breathing | O40: 5 | P40: =IF(A40="","",SUM(E40,G40,I40,K40,M40,O40)) -> 53 | Q40: =IF(A40="","",IFERROR(INDEX(Classes!$C$5:$C$23,MATCH(A40,Classes!$A$5:$A$23,0)),"")) -> 60 | R40: =IF(A40="","",IF(TRIM(IF(AND(N(Q40)>0,N(P40)>N(Q40)),"Over by "&(P40-Q40)&" min. ","")&IF(AND(COUNTIF(V40:AA40,"*A*")>0,AB40<>"Yes"),"Age check. ","")&IF(COUNTIF(V40:AA40,"*C*")>0,"Contact check. ","")&IF(COUNTIF(V40:AA40,"~?")>0,"Drill not in library. ",""))="","OK"&IF(AND(COUNTIF(V40:AA40,"*A*")>0,AB40="Yes")," · split by age","")&IF(N(Q40)>N(P40)," ("&(Q40-P40)&" min spare)",""),TRIM(IF(AND(N(Q40)>0,N(P40)>N(Q40)),"Over by "&(P40-Q40)&" min. ","")&IF(AND(COUNTIF(V40:AA40,"*A*")>0,AB40<>"Yes"),"Age check. ","")&IF(COUNTIF(V40:AA40,"*C*")>0,"Contact check. ","")&IF(COUNTIF(V40:AA40,"~?")>0,"Drill not in library. ",""))&IF(AND(COUNTIF(V40:AA40,"*A*")>0,AB40="Yes")," · split by age",""))) -> OK (7 min spare) | T40: =IF(A40="","",IFERROR(INDEX(Classes!$E$5:$E$23,MATCH(A40,Classes!$A$5:$A$23,0)),"")) -> 18 | U40: =IF(A40="","",IFERROR(INDEX(Classes!$F$5:$F$23,MATCH(A40,Classes!$A$5:$A$23,0)),"")) -> None;Pads/bag;Partner drilling;Live grappling;Light touch (body);Controlled sparring | V40: =IF(OR(D40="",$A40=""),"",IF(ISNA(MATCH(D40,Drills!$A$5:$A$127,0)),"?",IF(N(INDEX(Drills!$K$5:$K$127,MATCH(D40,Drills!$A$5:$A$127,0)))>N($T40),"A","")&IF(ISNUMBER(SEARCH(INDEX(Drills!$E$5:$E$127,MATCH(D40,Drills!$A$5:$A$127,0)),$U40)),"","C"))) | W40: =IF(OR(F40="",$A40=""),"",IF(ISNA(MATCH(F40,Drills!$A$5:$A$127,0)),"?",IF(N(INDEX(Drills!$K$5:$K$127,MATCH(F40,Drills!$A$5:$A$127,0)))>N($T40),"A","")&IF(ISNUMBER(SEARCH(INDEX(Drills!$E$5:$E$127,MATCH(F40,Drills!$A$5:$A$127,0)),$U40)),"","C"))) | X40: =IF(OR(H40="",$A40=""),"",IF(ISNA(MATCH(H40,Drills!$A$5:$A$127,0)),"?",IF(N(INDEX(Drills!$K$5:$K$127,MATCH(H40,Drills!$A$5:$A$127,0)))>N($T40),"A","")&IF(ISNUMBER(SEARCH(INDEX(Drills!$E$5:$E$127,MATCH(H40,Drills!$A$5:$A$127,0)),$U40)),"","C"))) | Y40: =IF(OR(J40="",$A40=""),"",IF(ISNA(MATCH(J40,Drills!$A$5:$A$127,0)),"?",IF(N(INDEX(Drills!$K$5:$K$127,MATCH(J40,Drills!$A$5:$A$127,0)))>N($T40),"A","")&IF(ISNUMBER(SEARCH(INDEX(Drills!$E$5:$E$127,MATCH(J40,Drills!$A$5:$A$127,0)),$U40)),"","C"))) | Z40: =IF(OR(L40="",$A40=""),"",IF(ISNA(MATCH(L40,Drills!$A$5:$A$127,0)),"?",IF(N(INDEX(Drills!$K$5:$K$127,MATCH(L40,Drills!$A$5:$A$127,0)))>N($T40),"A","")&IF(ISNUMBER(SEARCH(INDEX(Drills!$E$5:$E$127,MATCH(L40,Drills!$A$5:$A$127,0)),$U40)),"","C"))) | AA40: =IF(OR(N40="",$A40=""),"",IF(ISNA(MATCH(N40,Drills!$A$5:$A$127,0)),"?",IF(N(INDEX(Drills!$K$5:$K$127,MATCH(N40,Drills!$A$5:$A$127,0)))>N($T40),"A","")&IF(ISNUMBER(SEARCH(INDEX(Drills!$E$5:$E$127,MATCH(N40,Drills!$A$5:$A$127,0)),$U40)),"","C"))) | AB40: =IF(A40="","",IFERROR(INDEX(Classes!$I$5:$I$23,MATCH(A40,Classes!$A$5:$A$23,0)),"")) -> No
E41: =IF(D41="","",IFERROR(INDEX(Drills!$G$5:$G$127,MATCH(D41,Drills!$A$5:$A$127,0)),"")) | G41: =IF(F41="","",IFERROR(INDEX(Drills!$G$5:$G$127,MATCH(F41,Drills!$A$5:$A$127,0)),"")) | I41: =IF(H41="","",IFERROR(INDEX(Drills!$G$5:$G$127,MATCH(H41,Drills!$A$5:$A$127,0)),"")) | K41: =IF(J41="","",IFERROR(INDEX(Drills!$G$5:$G$127,MATCH(J41,Drills!$A$5:$A$127,0)),"")) | M41: =IF(L41="","",IFERROR(INDEX(Drills!$G$5:$G$127,MATCH(L41,Drills!$A$5:$A$127,0)),"")) | O41: =IF(N41="","",IFERROR(INDEX(Drills!$G$5:$G$127,MATCH(N41,Drills!$A$5:$A$127,0)),"")) | P41: =IF(A41="","",SUM(E41,G41,I41,K41,M41,O41)) | Q41: =IF(A41="","",IFERROR(INDEX(Classes!$C$5:$C$23,MATCH(A41,Classes!$A$5:$A$23,0)),"")) | R41: =IF(A41="","",IF(TRIM(IF(AND(N(Q41)>0,N(P41)>N(Q41)),"Over by "&(P41-Q41)&" min. ","")&IF(AND(COUNTIF(V41:AA41,"*A*")>0,AB41<>"Yes"),"Age check. ","")&IF(COUNTIF(V41:AA41,"*C*")>0,"Contact check. ","")&IF(COUNTIF(V41:AA41,"~?")>0,"Drill not in library. ",""))="","OK"&IF(AND(COUNTIF(V41:AA41,"*A*")>0,AB41="Yes")," · split by age","")&IF(N(Q41)>N(P41)," ("&(Q41-P41)&" min spare)",""),TRIM(IF(AND(N(Q41)>0,N(P41)>N(Q41)),"Over by "&(P41-Q41)&" min. ","")&IF(AND(COUNTIF(V41:AA41,"*A*")>0,AB41<>"Yes"),"Age check. ","")&IF(COUNTIF(V41:AA41,"*C*")>0,"Contact check. ","")&IF(COUNTIF(V41:AA41,"~?")>0,"Drill not in library. ",""))&IF(AND(COUNTIF(V41:AA41,"*A*")>0,AB41="Yes")," · split by age",""))) | T41: =IF(A41="","",IFERROR(INDEX(Classes!$E$5:$E$23,MATCH(A41,Classes!$A$5:$A$23,0)),"")) | U41: =IF(A41="","",IFERROR(INDEX(Classes!$F$5:$F$23,MATCH(A41,Classes!$A$5:$A$23,0)),"")) | V41: =IF(OR(D41="",$A41=""),"",IF(ISNA(MATCH(D41,Drills!$A$5:$A$127,0)),"?",IF(N(INDEX(Drills!$K$5:$K$127,MATCH(D41,Drills!$A$5:$A$127,0)))>N($T41),"A","")&IF(ISNUMBER(SEARCH(INDEX(Drills!$E$5:$E$127,MATCH(D41,Drills!$A$5:$A$127,0)),$U41)),"","C"))) | W41: =IF(OR(F41="",$A41=""),"",IF(ISNA(MATCH(F41,Drills!$A$5:$A$127,0)),"?",IF(N(INDEX(Drills!$K$5:$K$127,MATCH(F41,Drills!$A$5:$A$127,0)))>N($T41),"A","")&IF(ISNUMBER(SEARCH(INDEX(Drills!$E$5:$E$127,MATCH(F41,Drills!$A$5:$A$127,0)),$U41)),"","C"))) | X41: =IF(OR(H41="",$A41=""),"",IF(ISNA(MATCH(H41,Drills!$A$5:$A$127,0)),"?",IF(N(INDEX(Drills!$K$5:$K$127,MATCH(H41,Drills!$A$5:$A$127,0)))>N($T41),"A","")&IF(ISNUMBER(SEARCH(INDEX(Drills!$E$5:$E$127,MATCH(H41,Drills!$A$5:$A$127,0)),$U41)),"","C"))) | Y41: =IF(OR(J41="",$A41=""),"",IF(ISNA(MATCH(J41,Drills!$A$5:$A$127,0)),"?",IF(N(INDEX(Drills!$K$5:$K$127,MATCH(J41,Drills!$A$5:$A$127,0)))>N($T41),"A","")&IF(ISNUMBER(SEARCH(INDEX(Drills!$E$5:$E$127,MATCH(J41,Drills!$A$5:$A$127,0)),$U41)),"","C"))) | Z41: =IF(OR(L41="",$A41=""),"",IF(ISNA(MATCH(L41,Drills!$A$5:$A$127,0)),"?",IF(N(INDEX(Drills!$K$5:$K$127,MATCH(L41,Drills!$A$5:$A$127,0)))>N($T41),"A","")&IF(ISNUMBER(SEARCH(INDEX(Drills!$E$5:$E$127,MATCH(L41,Drills!$A$5:$A$127,0)),$U41)),"","C"))) | AA41: =IF(OR(N41="",$A41=""),"",IF(ISNA(MATCH(N41,Drills!$A$5:$A$127,0)),"?",IF(N(INDEX(Drills!$K$5:$K$127,MATCH(N41,Drills!$A$5:$A$127,0)))>N($T41),"A","")&IF(ISNUMBER(SEARCH(INDEX(Drills!$E$5:$E$127,MATCH(N41,Drills!$A$5:$A$127,0)),$U41)),"","C"))) | AB41: =IF(A41="","",IFERROR(INDEX(Classes!$I$5:$I$23,MATCH(A41,Classes!$A$5:$A$23,0)),""))
E42: =IF(D42="","",IFERROR(INDEX(Drills!$G$5:$G$127,MATCH(D42,Drills!$A$5:$A$127,0)),"")) | G42: =IF(F42="","",IFERROR(INDEX(Drills!$G$5:$G$127,MATCH(F42,Drills!$A$5:$A$127,0)),"")) | I42: =IF(H42="","",IFERROR(INDEX(Drills!$G$5:$G$127,MATCH(H42,Drills!$A$5:$A$127,0)),"")) | K42: =IF(J42="","",IFERROR(INDEX(Drills!$G$5:$G$127,MATCH(J42,Drills!$A$5:$A$127,0)),"")) | M42: =IF(L42="","",IFERROR(INDEX(Drills!$G$5:$G$127,MATCH(L42,Drills!$A$5:$A$127,0)),"")) | O42: =IF(N42="","",IFERROR(INDEX(Drills!$G$5:$G$127,MATCH(N42,Drills!$A$5:$A$127,0)),"")) | P42: =IF(A42="","",SUM(E42,G42,I42,K42,M42,O42)) | Q42: =IF(A42="","",IFERROR(INDEX(Classes!$C$5:$C$23,MATCH(A42,Classes!$A$5:$A$23,0)),"")) | R42: =IF(A42="","",IF(TRIM(IF(AND(N(Q42)>0,N(P42)>N(Q42)),"Over by "&(P42-Q42)&" min. ","")&IF(AND(COUNTIF(V42:AA42,"*A*")>0,AB42<>"Yes"),"Age check. ","")&IF(COUNTIF(V42:AA42,"*C*")>0,"Contact check. ","")&IF(COUNTIF(V42:AA42,"~?")>0,"Drill not in library. ",""))="","OK"&IF(AND(COUNTIF(V42:AA42,"*A*")>0,AB42="Yes")," · split by age","")&IF(N(Q42)>N(P42)," ("&(Q42-P42)&" min spare)",""),TRIM(IF(AND(N(Q42)>0,N(P42)>N(Q42)),"Over by "&(P42-Q42)&" min. ","")&IF(AND(COUNTIF(V42:AA42,"*A*")>0,AB42<>"Yes"),"Age check. ","")&IF(COUNTIF(V42:AA42,"*C*")>0,"Contact check. ","")&IF(COUNTIF(V42:AA42,"~?")>0,"Drill not in library. ",""))&IF(AND(COUNTIF(V42:AA42,"*A*")>0,AB42="Yes")," · split by age",""))) | T42: =IF(A42="","",IFERROR(INDEX(Classes!$E$5:$E$23,MATCH(A42,Classes!$A$5:$A$23,0)),"")) | U42: =IF(A42="","",IFERROR(INDEX(Classes!$F$5:$F$23,MATCH(A42,Classes!$A$5:$A$23,0)),"")) | V42: =IF(OR(D42="",$A42=""),"",IF(ISNA(MATCH(D42,Drills!$A$5:$A$127,0)),"?",IF(N(INDEX(Drills!$K$5:$K$127,MATCH(D42,Drills!$A$5:$A$127,0)))>N($T42),"A","")&IF(ISNUMBER(SEARCH(INDEX(Drills!$E$5:$E$127,MATCH(D42,Drills!$A$5:$A$127,0)),$U42)),"","C"))) | W42: =IF(OR(F42="",$A42=""),"",IF(ISNA(MATCH(F42,Drills!$A$5:$A$127,0)),"?",IF(N(INDEX(Drills!$K$5:$K$127,MATCH(F42,Drills!$A$5:$A$127,0)))>N($T42),"A","")&IF(ISNUMBER(SEARCH(INDEX(Drills!$E$5:$E$127,MATCH(F42,Drills!$A$5:$A$127,0)),$U42)),"","C"))) | X42: =IF(OR(H42="",$A42=""),"",IF(ISNA(MATCH(H42,Drills!$A$5:$A$127,0)),"?",IF(N(INDEX(Drills!$K$5:$K$127,MATCH(H42,Drills!$A$5:$A$127,0)))>N($T42),"A","")&IF(ISNUMBER(SEARCH(INDEX(Drills!$E$5:$E$127,MATCH(H42,Drills!$A$5:$A$127,0)),$U42)),"","C"))) | Y42: =IF(OR(J42="",$A42=""),"",IF(ISNA(MATCH(J42,Drills!$A$5:$A$127,0)),"?",IF(N(INDEX(Drills!$K$5:$K$127,MATCH(J42,Drills!$A$5:$A$127,0)))>N($T42),"A","")&IF(ISNUMBER(SEARCH(INDEX(Drills!$E$5:$E$127,MATCH(J42,Drills!$A$5:$A$127,0)),$U42)),"","C"))) | Z42: =IF(OR(L42="",$A42=""),"",IF(ISNA(MATCH(L42,Drills!$A$5:$A$127,0)),"?",IF(N(INDEX(Drills!$K$5:$K$127,MATCH(L42,Drills!$A$5:$A$127,0)))>N($T42),"A","")&IF(ISNUMBER(SEARCH(INDEX(Drills!$E$5:$E$127,MATCH(L42,Drills!$A$5:$A$127,0)),$U42)),"","C"))) | AA42: =IF(OR(N42="",$A42=""),"",IF(ISNA(MATCH(N42,Drills!$A$5:$A$127,0)),"?",IF(N(INDEX(Drills!$K$5:$K$127,MATCH(N42,Drills!$A$5:$A$127,0)))>N($T42),"A","")&IF(ISNUMBER(SEARCH(INDEX(Drills!$E$5:$E$127,MATCH(N42,Drills!$A$5:$A$127,0)),$U42)),"","C"))) | AB42: =IF(A42="","",IFERROR(INDEX(Classes!$I$5:$I$23,MATCH(A42,Classes!$A$5:$A$23,0)),""))
E43: =IF(D43="","",IFERROR(INDEX(Drills!$G$5:$G$127,MATCH(D43,Drills!$A$5:$A$127,0)),"")) | G43: =IF(F43="","",IFERROR(INDEX(Drills!$G$5:$G$127,MATCH(F43,Drills!$A$5:$A$127,0)),"")) | I43: =IF(H43="","",IFERROR(INDEX(Drills!$G$5:$G$127,MATCH(H43,Drills!$A$5:$A$127,0)),"")) | K43: =IF(J43="","",IFERROR(INDEX(Drills!$G$5:$G$127,MATCH(J43,Drills!$A$5:$A$127,0)),"")) | M43: =IF(L43="","",IFERROR(INDEX(Drills!$G$5:$G$127,MATCH(L43,Drills!$A$5:$A$127,0)),"")) | O43: =IF(N43="","",IFERROR(INDEX(Drills!$G$5:$G$127,MATCH(N43,Drills!$A$5:$A$127,0)),"")) | P43: =IF(A43="","",SUM(E43,G43,I43,K43,M43,O43)) | Q43: =IF(A43="","",IFERROR(INDEX(Classes!$C$5:$C$23,MATCH(A43,Classes!$A$5:$A$23,0)),"")) | R43: =IF(A43="","",IF(TRIM(IF(AND(N(Q43)>0,N(P43)>N(Q43)),"Over by "&(P43-Q43)&" min. ","")&IF(AND(COUNTIF(V43:AA43,"*A*")>0,AB43<>"Yes"),"Age check. ","")&IF(COUNTIF(V43:AA43,"*C*")>0,"Contact check. ","")&IF(COUNTIF(V43:AA43,"~?")>0,"Drill not in library. ",""))="","OK"&IF(AND(COUNTIF(V43:AA43,"*A*")>0,AB43="Yes")," · split by age","")&IF(N(Q43)>N(P43)," ("&(Q43-P43)&" min spare)",""),TRIM(IF(AND(N(Q43)>0,N(P43)>N(Q43)),"Over by "&(P43-Q43)&" min. ","")&IF(AND(COUNTIF(V43:AA43,"*A*")>0,AB43<>"Yes"),"Age check. ","")&IF(COUNTIF(V43:AA43,"*C*")>0,"Contact check. ","")&IF(COUNTIF(V43:AA43,"~?")>0,"Drill not in library. ",""))&IF(AND(COUNTIF(V43:AA43,"*A*")>0,AB43="Yes")," · split by age",""))) | T43: =IF(A43="","",IFERROR(INDEX(Classes!$E$5:$E$23,MATCH(A43,Classes!$A$5:$A$23,0)),"")) | U43: =IF(A43="","",IFERROR(INDEX(Classes!$F$5:$F$23,MATCH(A43,Classes!$A$5:$A$23,0)),"")) | V43: =IF(OR(D43="",$A43=""),"",IF(ISNA(MATCH(D43,Drills!$A$5:$A$127,0)),"?",IF(N(INDEX(Drills!$K$5:$K$127,MATCH(D43,Drills!$A$5:$A$127,0)))>N($T43),"A","")&IF(ISNUMBER(SEARCH(INDEX(Drills!$E$5:$E$127,MATCH(D43,Drills!$A$5:$A$127,0)),$U43)),"","C"))) | W43: =IF(OR(F43="",$A43=""),"",IF(ISNA(MATCH(F43,Drills!$A$5:$A$127,0)),"?",IF(N(INDEX(Drills!$K$5:$K$127,MATCH(F43,Drills!$A$5:$A$127,0)))>N($T43),"A","")&IF(ISNUMBER(SEARCH(INDEX(Drills!$E$5:$E$127,MATCH(F43,Drills!$A$5:$A$127,0)),$U43)),"","C"))) | X43: =IF(OR(H43="",$A43=""),"",IF(ISNA(MATCH(H43,Drills!$A$5:$A$127,0)),"?",IF(N(INDEX(Drills!$K$5:$K$127,MATCH(H43,Drills!$A$5:$A$127,0)))>N($T43),"A","")&IF(ISNUMBER(SEARCH(INDEX(Drills!$E$5:$E$127,MATCH(H43,Drills!$A$5:$A$127,0)),$U43)),"","C"))) | Y43: =IF(OR(J43="",$A43=""),"",IF(ISNA(MATCH(J43,Drills!$A$5:$A$127,0)),"?",IF(N(INDEX(Drills!$K$5:$K$127,MATCH(J43,Drills!$A$5:$A$127,0)))>N($T43),"A","")&IF(ISNUMBER(SEARCH(INDEX(Drills!$E$5:$E$127,MATCH(J43,Drills!$A$5:$A$127,0)),$U43)),"","C"))) | Z43: =IF(OR(L43="",$A43=""),"",IF(ISNA(MATCH(L43,Drills!$A$5:$A$127,0)),"?",IF(N(INDEX(Drills!$K$5:$K$127,MATCH(L43,Drills!$A$5:$A$127,0)))>N($T43),"A","")&IF(ISNUMBER(SEARCH(INDEX(Drills!$E$5:$E$127,MATCH(L43,Drills!$A$5:$A$127,0)),$U43)),"","C"))) | AA43: =IF(OR(N43="",$A43=""),"",IF(ISNA(MATCH(N43,Drills!$A$5:$A$127,0)),"?",IF(N(INDEX(Drills!$K$5:$K$127,MATCH(N43,Drills!$A$5:$A$127,0)))>N($T43),"A","")&IF(ISNUMBER(SEARCH(INDEX(Drills!$E$5:$E$127,MATCH(N43,Drills!$A$5:$A$127,0)),$U43)),"","C"))) | AB43: =IF(A43="","",IFERROR(INDEX(Classes!$I$5:$I$23,MATCH(A43,Classes!$A$5:$A$23,0)),""))
E44: =IF(D44="","",IFERROR(INDEX(Drills!$G$5:$G$127,MATCH(D44,Drills!$A$5:$A$127,0)),"")) | G44: =IF(F44="","",IFERROR(INDEX(Drills!$G$5:$G$127,MATCH(F44,Drills!$A$5:$A$127,0)),"")) | I44: =IF(H44="","",IFERROR(INDEX(Drills!$G$5:$G$127,MATCH(H44,Drills!$A$5:$A$127,0)),"")) | K44: =IF(J44="","",IFERROR(INDEX(Drills!$G$5:$G$127,MATCH(J44,Drills!$A$5:$A$127,0)),"")) | M44: =IF(L44="","",IFERROR(INDEX(Drills!$G$5:$G$127,MATCH(L44,Drills!$A$5:$A$127,0)),"")) | O44: =IF(N44="","",IFERROR(INDEX(Drills!$G$5:$G$127,MATCH(N44,Drills!$A$5:$A$127,0)),"")) | P44: =IF(A44="","",SUM(E44,G44,I44,K44,M44,O44)) | Q44: =IF(A44="","",IFERROR(INDEX(Classes!$C$5:$C$23,MATCH(A44,Classes!$A$5:$A$23,0)),"")) | R44: =IF(A44="","",IF(TRIM(IF(AND(N(Q44)>0,N(P44)>N(Q44)),"Over by "&(P44-Q44)&" min. ","")&IF(AND(COUNTIF(V44:AA44,"*A*")>0,AB44<>"Yes"),"Age check. ","")&IF(COUNTIF(V44:AA44,"*C*")>0,"Contact check. ","")&IF(COUNTIF(V44:AA44,"~?")>0,"Drill not in library. ",""))="","OK"&IF(AND(COUNTIF(V44:AA44,"*A*")>0,AB44="Yes")," · split by age","")&IF(N(Q44)>N(P44)," ("&(Q44-P44)&" min spare)",""),TRIM(IF(AND(N(Q44)>0,N(P44)>N(Q44)),"Over by "&(P44-Q44)&" min. ","")&IF(AND(COUNTIF(V44:AA44,"*A*")>0,AB44<>"Yes"),"Age check. ","")&IF(COUNTIF(V44:AA44,"*C*")>0,"Contact check. ","")&IF(COUNTIF(V44:AA44,"~?")>0,"Drill not in library. ",""))&IF(AND(COUNTIF(V44:AA44,"*A*")>0,AB44="Yes")," · split by age",""))) | T44: =IF(A44="","",IFERROR(INDEX(Classes!$E$5:$E$23,MATCH(A44,Classes!$A$5:$A$23,0)),"")) | U44: =IF(A44="","",IFERROR(INDEX(Classes!$F$5:$F$23,MATCH(A44,Classes!$A$5:$A$23,0)),"")) | V44: =IF(OR(D44="",$A44=""),"",IF(ISNA(MATCH(D44,Drills!$A$5:$A$127,0)),"?",IF(N(INDEX(Drills!$K$5:$K$127,MATCH(D44,Drills!$A$5:$A$127,0)))>N($T44),"A","")&IF(ISNUMBER(SEARCH(INDEX(Drills!$E$5:$E$127,MATCH(D44,Drills!$A$5:$A$127,0)),$U44)),"","C"))) | W44: =IF(OR(F44="",$A44=""),"",IF(ISNA(MATCH(F44,Drills!$A$5:$A$127,0)),"?",IF(N(INDEX(Drills!$K$5:$K$127,MATCH(F44,Drills!$A$5:$A$127,0)))>N($T44),"A","")&IF(ISNUMBER(SEARCH(INDEX(Drills!$E$5:$E$127,MATCH(F44,Drills!$A$5:$A$127,0)),$U44)),"","C"))) | X44: =IF(OR(H44="",$A44=""),"",IF(ISNA(MATCH(H44,Drills!$A$5:$A$127,0)),"?",IF(N(INDEX(Drills!$K$5:$K$127,MATCH(H44,Drills!$A$5:$A$127,0)))>N($T44),"A","")&IF(ISNUMBER(SEARCH(INDEX(Drills!$E$5:$E$127,MATCH(H44,Drills!$A$5:$A$127,0)),$U44)),"","C"))) | Y44: =IF(OR(J44="",$A44=""),"",IF(ISNA(MATCH(J44,Drills!$A$5:$A$127,0)),"?",IF(N(INDEX(Drills!$K$5:$K$127,MATCH(J44,Drills!$A$5:$A$127,0)))>N($T44),"A","")&IF(ISNUMBER(SEARCH(INDEX(Drills!$E$5:$E$127,MATCH(J44,Drills!$A$5:$A$127,0)),$U44)),"","C"))) | Z44: =IF(OR(L44="",$A44=""),"",IF(ISNA(MATCH(L44,Drills!$A$5:$A$127,0)),"?",IF(N(INDEX(Drills!$K$5:$K$127,MATCH(L44,Drills!$A$5:$A$127,0)))>N($T44),"A","")&IF(ISNUMBER(SEARCH(INDEX(Drills!$E$5:$E$127,MATCH(L44,Drills!$A$5:$A$127,0)),$U44)),"","C"))) | AA44: =IF(OR(N44="",$A44=""),"",IF(ISNA(MATCH(N44,Drills!$A$5:$A$127,0)),"?",IF(N(INDEX(Drills!$K$5:$K$127,MATCH(N44,Drills!$A$5:$A$127,0)))>N($T44),"A","")&IF(ISNUMBER(SEARCH(INDEX(Drills!$E$5:$E$127,MATCH(N44,Drills!$A$5:$A$127,0)),$U44)),"","C"))) | AB44: =IF(A44="","",IFERROR(INDEX(Classes!$I$5:$I$23,MATCH(A44,Classes!$A$5:$A$23,0)),""))
