Workbook

Sheet Start Here
A1: BBG SKILLS PASSPORT
A2: Four levels for each kids' and youth class (Rookie, Contender, Challenger, Champion). Coaches tick off skills; parents get a progress card.
A4: 1 | B4: Levels | C4: Kids Boxing, Wrestling and Boxing 11-14 each have four levels of five skills. Most skills match a drill in the Coaching Library, so they're taught before they're checked. A few (gym rules, sportsmanship, helping newer athletes) are learned in every class. None of them involve hitting to the head.
A5: 2 | B5: Roster | C5: One row per athlete: first name only (add a number if two kids share a name, e.g. Liam 2), their class and the date they started. No last names, birthdays, phone numbers or health details.
A6: 3 | B6: Log a skill | C6: When a coach sees a skill done well, add a row on the Progress tab: date, athlete, skill, coach. Log each skill once. The Roster shows each athlete's level and how many skills are left.
A7: 4 | B7: Progress card | C7: On the Card tab, pick an athlete: it shows their level, what they've passed and what's next. Screenshot it or ask Claude for a parent message to go with it. Share it with the parent, never post it publicly.
A8: 5 | B8: Levelling up | C8: When all five skills of a level are passed, the athlete moves up. A small moment in class (a shout-out, a sticker) is plenty. No prizes or money.
B10: Colours
B11: Yellow, blue text | C11: You type or pick here
B12: Black, bold | C12: Calculated: don't type over it

Sheet Card
G1: first | H1: count
B2: BBG SKILLS PASSPORT | G2: =IF($C$7="","",MATCH($C$7,Levels!$A$5:$A$94,0)) | H2: =IF($C$7="","",COUNTIF(Levels!$A$5:$A$94,$C$7))
B3: Bancroft Boxing & Grappling
B6: Athlete | D6: ← pick a name
B7: Class | C7: =IF($C$6="","",IFERROR(INDEX(Roster!$B$5:$B$154,MATCH($C$6,Roster!$A$5:$A$154,0)),""))
B8: Level now | C8: =IF($C$6="","",IFERROR(INDEX(Roster!$I$5:$I$154,MATCH($C$6,Roster!$A$5:$A$154,0)),""))
B10: Level | C10: Skill | D10: Done
B11: =IF(OR($C$7="",0>=N($H$2)),"",INDEX(Levels!$B$5:$B$94,($G$2+0))&" "&INDEX(Levels!$C$5:$C$94,($G$2+0))) | C11: =IF(OR($C$7="",0>=N($H$2)),"",INDEX(Levels!$D$5:$D$94,($G$2+0))&": "&INDEX(Levels!$E$5:$E$94,($G$2+0))) | D11: =IF(OR($C$7="",0>=N($H$2)),"",IF(COUNTIFS(Progress!$B$5:$B$3000,$C$6,Progress!$G$5:$G$3000,INDEX(Levels!$G$5:$G$94,($G$2+0)))>0,"✓ Passed",IF(IFERROR(INDEX(Levels!$B$5:$B$94,($G$2+0))=VALUE(LEFT($C$8,1)),FALSE()),"Next up","Later")))
B12: =IF(OR($C$7="",1>=N($H$2)),"",INDEX(Levels!$B$5:$B$94,($G$2+1))&" "&INDEX(Levels!$C$5:$C$94,($G$2+1))) | C12: =IF(OR($C$7="",1>=N($H$2)),"",INDEX(Levels!$D$5:$D$94,($G$2+1))&": "&INDEX(Levels!$E$5:$E$94,($G$2+1))) | D12: =IF(OR($C$7="",1>=N($H$2)),"",IF(COUNTIFS(Progress!$B$5:$B$3000,$C$6,Progress!$G$5:$G$3000,INDEX(Levels!$G$5:$G$94,($G$2+1)))>0,"✓ Passed",IF(IFERROR(INDEX(Levels!$B$5:$B$94,($G$2+1))=VALUE(LEFT($C$8,1)),FALSE()),"Next up","Later")))
B13: =IF(OR($C$7="",2>=N($H$2)),"",INDEX(Levels!$B$5:$B$94,($G$2+2))&" "&INDEX(Levels!$C$5:$C$94,($G$2+2))) | C13: =IF(OR($C$7="",2>=N($H$2)),"",INDEX(Levels!$D$5:$D$94,($G$2+2))&": "&INDEX(Levels!$E$5:$E$94,($G$2+2))) | D13: =IF(OR($C$7="",2>=N($H$2)),"",IF(COUNTIFS(Progress!$B$5:$B$3000,$C$6,Progress!$G$5:$G$3000,INDEX(Levels!$G$5:$G$94,($G$2+2)))>0,"✓ Passed",IF(IFERROR(INDEX(Levels!$B$5:$B$94,($G$2+2))=VALUE(LEFT($C$8,1)),FALSE()),"Next up","Later")))
B14: =IF(OR($C$7="",3>=N($H$2)),"",INDEX(Levels!$B$5:$B$94,($G$2+3))&" "&INDEX(Levels!$C$5:$C$94,($G$2+3))) | C14: =IF(OR($C$7="",3>=N($H$2)),"",INDEX(Levels!$D$5:$D$94,($G$2+3))&": "&INDEX(Levels!$E$5:$E$94,($G$2+3))) | D14: =IF(OR($C$7="",3>=N($H$2)),"",IF(COUNTIFS(Progress!$B$5:$B$3000,$C$6,Progress!$G$5:$G$3000,INDEX(Levels!$G$5:$G$94,($G$2+3)))>0,"✓ Passed",IF(IFERROR(INDEX(Levels!$B$5:$B$94,($G$2+3))=VALUE(LEFT($C$8,1)),FALSE()),"Next up","Later")))
B15: =IF(OR($C$7="",4>=N($H$2)),"",INDEX(Levels!$B$5:$B$94,($G$2+4))&" "&INDEX(Levels!$C$5:$C$94,($G$2+4))) | C15: =IF(OR($C$7="",4>=N($H$2)),"",INDEX(Levels!$D$5:$D$94,($G$2+4))&": "&INDEX(Levels!$E$5:$E$94,($G$2+4))) | D15: =IF(OR($C$7="",4>=N($H$2)),"",IF(COUNTIFS(Progress!$B$5:$B$3000,$C$6,Progress!$G$5:$G$3000,INDEX(Levels!$G$5:$G$94,($G$2+4)))>0,"✓ Passed",IF(IFERROR(INDEX(Levels!$B$5:$B$94,($G$2+4))=VALUE(LEFT($C$8,1)),FALSE()),"Next up","Later")))
B16: =IF(OR($C$7="",5>=N($H$2)),"",INDEX(Levels!$B$5:$B$94,($G$2+5))&" "&INDEX(Levels!$C$5:$C$94,($G$2+5))) | C16: =IF(OR($C$7="",5>=N($H$2)),"",INDEX(Levels!$D$5:$D$94,($G$2+5))&": "&INDEX(Levels!$E$5:$E$94,($G$2+5))) | D16: =IF(OR($C$7="",5>=N($H$2)),"",IF(COUNTIFS(Progress!$B$5:$B$3000,$C$6,Progress!$G$5:$G$3000,INDEX(Levels!$G$5:$G$94,($G$2+5)))>0,"✓ Passed",IF(IFERROR(INDEX(Levels!$B$5:$B$94,($G$2+5))=VALUE(LEFT($C$8,1)),FALSE()),"Next up","Later")))
B17: =IF(OR($C$7="",6>=N($H$2)),"",INDEX(Levels!$B$5:$B$94,($G$2+6))&" "&INDEX(Levels!$C$5:$C$94,($G$2+6))) | C17: =IF(OR($C$7="",6>=N($H$2)),"",INDEX(Levels!$D$5:$D$94,($G$2+6))&": "&INDEX(Levels!$E$5:$E$94,($G$2+6))) | D17: =IF(OR($C$7="",6>=N($H$2)),"",IF(COUNTIFS(Progress!$B$5:$B$3000,$C$6,Progress!$G$5:$G$3000,INDEX(Levels!$G$5:$G$94,($G$2+6)))>0,"✓ Passed",IF(IFERROR(INDEX(Levels!$B$5:$B$94,($G$2+6))=VALUE(LEFT($C$8,1)),FALSE()),"Next up","Later")))
B18: =IF(OR($C$7="",7>=N($H$2)),"",INDEX(Levels!$B$5:$B$94,($G$2+7))&" "&INDEX(Levels!$C$5:$C$94,($G$2+7))) | C18: =IF(OR($C$7="",7>=N($H$2)),"",INDEX(Levels!$D$5:$D$94,($G$2+7))&": "&INDEX(Levels!$E$5:$E$94,($G$2+7))) | D18: =IF(OR($C$7="",7>=N($H$2)),"",IF(COUNTIFS(Progress!$B$5:$B$3000,$C$6,Progress!$G$5:$G$3000,INDEX(Levels!$G$5:$G$94,($G$2+7)))>0,"✓ Passed",IF(IFERROR(INDEX(Levels!$B$5:$B$94,($G$2+7))=VALUE(LEFT($C$8,1)),FALSE()),"Next up","Later")))
B19: =IF(OR($C$7="",8>=N($H$2)),"",INDEX(Levels!$B$5:$B$94,($G$2+8))&" "&INDEX(Levels!$C$5:$C$94,($G$2+8))) | C19: =IF(OR($C$7="",8>=N($H$2)),"",INDEX(Levels!$D$5:$D$94,($G$2+8))&": "&INDEX(Levels!$E$5:$E$94,($G$2+8))) | D19: =IF(OR($C$7="",8>=N($H$2)),"",IF(COUNTIFS(Progress!$B$5:$B$3000,$C$6,Progress!$G$5:$G$3000,INDEX(Levels!$G$5:$G$94,($G$2+8)))>0,"✓ Passed",IF(IFERROR(INDEX(Levels!$B$5:$B$94,($G$2+8))=VALUE(LEFT($C$8,1)),FALSE()),"Next up","Later")))
B20: =IF(OR($C$7="",9>=N($H$2)),"",INDEX(Levels!$B$5:$B$94,($G$2+9))&" "&INDEX(Levels!$C$5:$C$94,($G$2+9))) | C20: =IF(OR($C$7="",9>=N($H$2)),"",INDEX(Levels!$D$5:$D$94,($G$2+9))&": "&INDEX(Levels!$E$5:$E$94,($G$2+9))) | D20: =IF(OR($C$7="",9>=N($H$2)),"",IF(COUNTIFS(Progress!$B$5:$B$3000,$C$6,Progress!$G$5:$G$3000,INDEX(Levels!$G$5:$G$94,($G$2+9)))>0,"✓ Passed",IF(IFERROR(INDEX(Levels!$B$5:$B$94,($G$2+9))=VALUE(LEFT($C$8,1)),FALSE()),"Next up","Later")))
B21: =IF(OR($C$7="",10>=N($H$2)),"",INDEX(Levels!$B$5:$B$94,($G$2+10))&" "&INDEX(Levels!$C$5:$C$94,($G$2+10))) | C21: =IF(OR($C$7="",10>=N($H$2)),"",INDEX(Levels!$D$5:$D$94,($G$2+10))&": "&INDEX(Levels!$E$5:$E$94,($G$2+10))) | D21: =IF(OR($C$7="",10>=N($H$2)),"",IF(COUNTIFS(Progress!$B$5:$B$3000,$C$6,Progress!$G$5:$G$3000,INDEX(Levels!$G$5:$G$94,($G$2+10)))>0,"✓ Passed",IF(IFERROR(INDEX(Levels!$B$5:$B$94,($G$2+10))=VALUE(LEFT($C$8,1)),FALSE()),"Next up","Later")))
B22: =IF(OR($C$7="",11>=N($H$2)),"",INDEX(Levels!$B$5:$B$94,($G$2+11))&" "&INDEX(Levels!$C$5:$C$94,($G$2+11))) | C22: =IF(OR($C$7="",11>=N($H$2)),"",INDEX(Levels!$D$5:$D$94,($G$2+11))&": "&INDEX(Levels!$E$5:$E$94,($G$2+11))) | D22: =IF(OR($C$7="",11>=N($H$2)),"",IF(COUNTIFS(Progress!$B$5:$B$3000,$C$6,Progress!$G$5:$G$3000,INDEX(Levels!$G$5:$G$94,($G$2+11)))>0,"✓ Passed",IF(IFERROR(INDEX(Levels!$B$5:$B$94,($G$2+11))=VALUE(LEFT($C$8,1)),FALSE()),"Next up","Later")))
B23: =IF(OR($C$7="",12>=N($H$2)),"",INDEX(Levels!$B$5:$B$94,($G$2+12))&" "&INDEX(Levels!$C$5:$C$94,($G$2+12))) | C23: =IF(OR($C$7="",12>=N($H$2)),"",INDEX(Levels!$D$5:$D$94,($G$2+12))&": "&INDEX(Levels!$E$5:$E$94,($G$2+12))) | D23: =IF(OR($C$7="",12>=N($H$2)),"",IF(COUNTIFS(Progress!$B$5:$B$3000,$C$6,Progress!$G$5:$G$3000,INDEX(Levels!$G$5:$G$94,($G$2+12)))>0,"✓ Passed",IF(IFERROR(INDEX(Levels!$B$5:$B$94,($G$2+12))=VALUE(LEFT($C$8,1)),FALSE()),"Next up","Later")))
B24: =IF(OR($C$7="",13>=N($H$2)),"",INDEX(Levels!$B$5:$B$94,($G$2+13))&" "&INDEX(Levels!$C$5:$C$94,($G$2+13))) | C24: =IF(OR($C$7="",13>=N($H$2)),"",INDEX(Levels!$D$5:$D$94,($G$2+13))&": "&INDEX(Levels!$E$5:$E$94,($G$2+13))) | D24: =IF(OR($C$7="",13>=N($H$2)),"",IF(COUNTIFS(Progress!$B$5:$B$3000,$C$6,Progress!$G$5:$G$3000,INDEX(Levels!$G$5:$G$94,($G$2+13)))>0,"✓ Passed",IF(IFERROR(INDEX(Levels!$B$5:$B$94,($G$2+13))=VALUE(LEFT($C$8,1)),FALSE()),"Next up","Later")))
B25: =IF(OR($C$7="",14>=N($H$2)),"",INDEX(Levels!$B$5:$B$94,($G$2+14))&" "&INDEX(Levels!$C$5:$C$94,($G$2+14))) | C25: =IF(OR($C$7="",14>=N($H$2)),"",INDEX(Levels!$D$5:$D$94,($G$2+14))&": "&INDEX(Levels!$E$5:$E$94,($G$2+14))) | D25: =IF(OR($C$7="",14>=N($H$2)),"",IF(COUNTIFS(Progress!$B$5:$B$3000,$C$6,Progress!$G$5:$G$3000,INDEX(Levels!$G$5:$G$94,($G$2+14)))>0,"✓ Passed",IF(IFERROR(INDEX(Levels!$B$5:$B$94,($G$2+14))=VALUE(LEFT($C$8,1)),FALSE()),"Next up","Later")))
B26: =IF(OR($C$7="",15>=N($H$2)),"",INDEX(Levels!$B$5:$B$94,($G$2+15))&" "&INDEX(Levels!$C$5:$C$94,($G$2+15))) | C26: =IF(OR($C$7="",15>=N($H$2)),"",INDEX(Levels!$D$5:$D$94,($G$2+15))&": "&INDEX(Levels!$E$5:$E$94,($G$2+15))) | D26: =IF(OR($C$7="",15>=N($H$2)),"",IF(COUNTIFS(Progress!$B$5:$B$3000,$C$6,Progress!$G$5:$G$3000,INDEX(Levels!$G$5:$G$94,($G$2+15)))>0,"✓ Passed",IF(IFERROR(INDEX(Levels!$B$5:$B$94,($G$2+15))=VALUE(LEFT($C$8,1)),FALSE()),"Next up","Later")))
B27: =IF(OR($C$7="",16>=N($H$2)),"",INDEX(Levels!$B$5:$B$94,($G$2+16))&" "&INDEX(Levels!$C$5:$C$94,($G$2+16))) | C27: =IF(OR($C$7="",16>=N($H$2)),"",INDEX(Levels!$D$5:$D$94,($G$2+16))&": "&INDEX(Levels!$E$5:$E$94,($G$2+16))) | D27: =IF(OR($C$7="",16>=N($H$2)),"",IF(COUNTIFS(Progress!$B$5:$B$3000,$C$6,Progress!$G$5:$G$3000,INDEX(Levels!$G$5:$G$94,($G$2+16)))>0,"✓ Passed",IF(IFERROR(INDEX(Levels!$B$5:$B$94,($G$2+16))=VALUE(LEFT($C$8,1)),FALSE()),"Next up","Later")))
B28: =IF(OR($C$7="",17>=N($H$2)),"",INDEX(Levels!$B$5:$B$94,($G$2+17))&" "&INDEX(Levels!$C$5:$C$94,($G$2+17))) | C28: =IF(OR($C$7="",17>=N($H$2)),"",INDEX(Levels!$D$5:$D$94,($G$2+17))&": "&INDEX(Levels!$E$5:$E$94,($G$2+17))) | D28: =IF(OR($C$7="",17>=N($H$2)),"",IF(COUNTIFS(Progress!$B$5:$B$3000,$C$6,Progress!$G$5:$G$3000,INDEX(Levels!$G$5:$G$94,($G$2+17)))>0,"✓ Passed",IF(IFERROR(INDEX(Levels!$B$5:$B$94,($G$2+17))=VALUE(LEFT($C$8,1)),FALSE()),"Next up","Later")))
B29: =IF(OR($C$7="",18>=N($H$2)),"",INDEX(Levels!$B$5:$B$94,($G$2+18))&" "&INDEX(Levels!$C$5:$C$94,($G$2+18))) | C29: =IF(OR($C$7="",18>=N($H$2)),"",INDEX(Levels!$D$5:$D$94,($G$2+18))&": "&INDEX(Levels!$E$5:$E$94,($G$2+18))) | D29: =IF(OR($C$7="",18>=N($H$2)),"",IF(COUNTIFS(Progress!$B$5:$B$3000,$C$6,Progress!$G$5:$G$3000,INDEX(Levels!$G$5:$G$94,($G$2+18)))>0,"✓ Passed",IF(IFERROR(INDEX(Levels!$B$5:$B$94,($G$2+18))=VALUE(LEFT($C$8,1)),FALSE()),"Next up","Later")))
B30: =IF(OR($C$7="",19>=N($H$2)),"",INDEX(Levels!$B$5:$B$94,($G$2+19))&" "&INDEX(Levels!$C$5:$C$94,($G$2+19))) | C30: =IF(OR($C$7="",19>=N($H$2)),"",INDEX(Levels!$D$5:$D$94,($G$2+19))&": "&INDEX(Levels!$E$5:$E$94,($G$2+19))) | D30: =IF(OR($C$7="",19>=N($H$2)),"",IF(COUNTIFS(Progress!$B$5:$B$3000,$C$6,Progress!$G$5:$G$3000,INDEX(Levels!$G$5:$G$94,($G$2+19)))>0,"✓ Passed",IF(IFERROR(INDEX(Levels!$B$5:$B$94,($G$2+19))=VALUE(LEFT($C$8,1)),FALSE()),"Next up","Later")))
B32: Share with the parent only. First names only; never post a child's card publicly.

Sheet Roster
A1: ROSTER
A2: First names only. Level counts and the current level fill in from the Progress tab.
A4: Athlete (first name) | B4: Class | C4: Started | D4: Coach | E4: Rookie | F4: Contender | G4: Challenger | H4: Champion | I4: Current level | J4: Skills left in level | K4: Last skill passed | L4: Notes (no health details)
E5: =IF(OR($A5="",$B5=""),"",SUMPRODUCT((Levels!$A$5:$A$94=$B5)*(Levels!$B$5:$B$94=1)*(COUNTIFS(Progress!$B$5:$B$3000,$A5,Progress!$G$5:$G$3000,Levels!$G$5:$G$94)>0))&" / "&COUNTIFS(Levels!$A$5:$A$94,$B5,Levels!$B$5:$B$94,1)) | F5: =IF(OR($A5="",$B5=""),"",SUMPRODUCT((Levels!$A$5:$A$94=$B5)*(Levels!$B$5:$B$94=2)*(COUNTIFS(Progress!$B$5:$B$3000,$A5,Progress!$G$5:$G$3000,Levels!$G$5:$G$94)>0))&" / "&COUNTIFS(Levels!$A$5:$A$94,$B5,Levels!$B$5:$B$94,2)) | G5: =IF(OR($A5="",$B5=""),"",SUMPRODUCT((Levels!$A$5:$A$94=$B5)*(Levels!$B$5:$B$94=3)*(COUNTIFS(Progress!$B$5:$B$3000,$A5,Progress!$G$5:$G$3000,Levels!$G$5:$G$94)>0))&" / "&COUNTIFS(Levels!$A$5:$A$94,$B5,Levels!$B$5:$B$94,3)) | H5: =IF(OR($A5="",$B5=""),"",SUMPRODUCT((Levels!$A$5:$A$94=$B5)*(Levels!$B$5:$B$94=4)*(COUNTIFS(Progress!$B$5:$B$3000,$A5,Progress!$G$5:$G$3000,Levels!$G$5:$G$94)>0))&" / "&COUNTIFS(Levels!$A$5:$A$94,$B5,Levels!$B$5:$B$94,4)) | I5: =IF(OR($A5="",$B5=""),"",IF(SUMPRODUCT((Levels!$A$5:$A$94=$B5)*(Levels!$B$5:$B$94=1)*(COUNTIFS(Progress!$B$5:$B$3000,$A5,Progress!$G$5:$G$3000,Levels!$G$5:$G$94)>0))<COUNTIFS(Levels!$A$5:$A$94,$B5,Levels!$B$5:$B$94,1),"1 Rookie",IF(SUMPRODUCT((Levels!$A$5:$A$94=$B5)*(Levels!$B$5:$B$94=2)*(COUNTIFS(Progress!$B$5:$B$3000,$A5,Progress!$G$5:$G$3000,Levels!$G$5:$G$94)>0))<COUNTIFS(Levels!$A$5:$A$94,$B5,Levels!$B$5:$B$94,2),"2 Contender",IF(SUMPRODUCT((Levels!$A$5:$A$94=$B5)*(Levels!$B$5:$B$94=3)*(COUNTIFS(Progress!$B$5:$B$3000,$A5,Progress!$G$5:$G$3000,Levels!$G$5:$G$94)>0))<COUNTIFS(Levels!$A$5:$A$94,$B5,Levels!$B$5:$B$94,3),"3 Challenger",IF(SUMPRODUCT((Levels!$A$5:$A$94=$B5)*(Levels!$B$5:$B$94=4)*(COUNTIFS(Progress!$B$5:$B$3000,$A5,Progress!$G$5:$G$3000,Levels!$G$5:$G$94)>0))<COUNTIFS(Levels!$A$5:$A$94,$B5,Levels!$B$5:$B$94,4),"4 Champion","All done"))))) | J5: =IF(OR(I5="",I5="All done"),"",COUNTIFS(Levels!$A$5:$A$94,$B5,Levels!$B$5:$B$94,1)*(LEFT(I5,1)="1")+COUNTIFS(Levels!$A$5:$A$94,$B5,Levels!$B$5:$B$94,2)*(LEFT(I5,1)="2")+COUNTIFS(Levels!$A$5:$A$94,$B5,Levels!$B$5:$B$94,3)*(LEFT(I5,1)="3")+COUNTIFS(Levels!$A$5:$A$94,$B5,Levels!$B$5:$B$94,4)*(LEFT(I5,1)="4")-(SUMPRODUCT((Levels!$A$5:$A$94=$B5)*(Levels!$B$5:$B$94=1)*(COUNTIFS(Progress!$B$5:$B$3000,$A5,Progress!$G$5:$G$3000,Levels!$G$5:$G$94)>0))*(LEFT(I5,1)="1")+SUMPRODUCT((Levels!$A$5:$A$94=$B5)*(Levels!$B$5:$B$94=2)*(COUNTIFS(Progress!$B$5:$B$3000,$A5,Progress!$G$5:$G$3000,Levels!$G$5:$G$94)>0))*(LEFT(I5,1)="2")+SUMPRODUCT((Levels!$A$5:$A$94=$B5)*(Levels!$B$5:$B$94=3)*(COUNTIFS(Progress!$B$5:$B$3000,$A5,Progress!$G$5:$G$3000,Levels!$G$5:$G$94)>0))*(LEFT(I5,1)="3")+SUMPRODUCT((Levels!$A$5:$A$94=$B5)*(Levels!$B$5:$B$94=4)*(COUNTIFS(Progress!$B$5:$B$3000,$A5,Progress!$G$5:$G$3000,Levels!$G$5:$G$94)>0))*(LEFT(I5,1)="4"))) | K5: =IF($A5="","",IF(COUNTIFS(Progress!$B$5:$B$3000,$A5)=0,"",SUMPRODUCT(MAX((Progress!$B$5:$B$3000=$A5)*Progress!$A$5:$A$3000))))
E6: =IF(OR($A6="",$B6=""),"",SUMPRODUCT((Levels!$A$5:$A$94=$B6)*(Levels!$B$5:$B$94=1)*(COUNTIFS(Progress!$B$5:$B$3000,$A6,Progress!$G$5:$G$3000,Levels!$G$5:$G$94)>0))&" / "&COUNTIFS(Levels!$A$5:$A$94,$B6,Levels!$B$5:$B$94,1)) | F6: =IF(OR($A6="",$B6=""),"",SUMPRODUCT((Levels!$A$5:$A$94=$B6)*(Levels!$B$5:$B$94=2)*(COUNTIFS(Progress!$B$5:$B$3000,$A6,Progress!$G$5:$G$3000,Levels!$G$5:$G$94)>0))&" / "&COUNTIFS(Levels!$A$5:$A$94,$B6,Levels!$B$5:$B$94,2)) | G6: =IF(OR($A6="",$B6=""),"",SUMPRODUCT((Levels!$A$5:$A$94=$B6)*(Levels!$B$5:$B$94=3)*(COUNTIFS(Progress!$B$5:$B$3000,$A6,Progress!$G$5:$G$3000,Levels!$G$5:$G$94)>0))&" / "&COUNTIFS(Levels!$A$5:$A$94,$B6,Levels!$B$5:$B$94,3)) | H6: =IF(OR($A6="",$B6=""),"",SUMPRODUCT((Levels!$A$5:$A$94=$B6)*(Levels!$B$5:$B$94=4)*(COUNTIFS(Progress!$B$5:$B$3000,$A6,Progress!$G$5:$G$3000,Levels!$G$5:$G$94)>0))&" / "&COUNTIFS(Levels!$A$5:$A$94,$B6,Levels!$B$5:$B$94,4)) | I6: =IF(OR($A6="",$B6=""),"",IF(SUMPRODUCT((Levels!$A$5:$A$94=$B6)*(Levels!$B$5:$B$94=1)*(COUNTIFS(Progress!$B$5:$B$3000,$A6,Progress!$G$5:$G$3000,Levels!$G$5:$G$94)>0))<COUNTIFS(Levels!$A$5:$A$94,$B6,Levels!$B$5:$B$94,1),"1 Rookie",IF(SUMPRODUCT((Levels!$A$5:$A$94=$B6)*(Levels!$B$5:$B$94=2)*(COUNTIFS(Progress!$B$5:$B$3000,$A6,Progress!$G$5:$G$3000,Levels!$G$5:$G$94)>0))<COUNTIFS(Levels!$A$5:$A$94,$B6,Levels!$B$5:$B$94,2),"2 Contender",IF(SUMPRODUCT((Levels!$A$5:$A$94=$B6)*(Levels!$B$5:$B$94=3)*(COUNTIFS(Progress!$B$5:$B$3000,$A6,Progress!$G$5:$G$3000,Levels!$G$5:$G$94)>0))<COUNTIFS(Levels!$A$5:$A$94,$B6,Levels!$B$5:$B$94,3),"3 Challenger",IF(SUMPRODUCT((Levels!$A$5:$A$94=$B6)*(Levels!$B$5:$B$94=4)*(COUNTIFS(Progress!$B$5:$B$3000,$A6,Progress!$G$5:$G$3000,Levels!$G$5:$G$94)>0))<COUNTIFS(Levels!$A$5:$A$94,$B6,Levels!$B$5:$B$94,4),"4 Champion","All done"))))) | J6: =IF(OR(I6="",I6="All done"),"",COUNTIFS(Levels!$A$5:$A$94,$B6,Levels!$B$5:$B$94,1)*(LEFT(I6,1)="1")+COUNTIFS(Levels!$A$5:$A$94,$B6,Levels!$B$5:$B$94,2)*(LEFT(I6,1)="2")+COUNTIFS(Levels!$A$5:$A$94,$B6,Levels!$B$5:$B$94,3)*(LEFT(I6,1)="3")+COUNTIFS(Levels!$A$5:$A$94,$B6,Levels!$B$5:$B$94,4)*(LEFT(I6,1)="4")-(SUMPRODUCT((Levels!$A$5:$A$94=$B6)*(Levels!$B$5:$B$94=1)*(COUNTIFS(Progress!$B$5:$B$3000,$A6,Progress!$G$5:$G$3000,Levels!$G$5:$G$94)>0))*(LEFT(I6,1)="1")+SUMPRODUCT((Levels!$A$5:$A$94=$B6)*(Levels!$B$5:$B$94=2)*(COUNTIFS(Progress!$B$5:$B$3000,$A6,Progress!$G$5:$G$3000,Levels!$G$5:$G$94)>0))*(LEFT(I6,1)="2")+SUMPRODUCT((Levels!$A$5:$A$94=$B6)*(Levels!$B$5:$B$94=3)*(COUNTIFS(Progress!$B$5:$B$3000,$A6,Progress!$G$5:$G$3000,Levels!$G$5:$G$94)>0))*(LEFT(I6,1)="3")+SUMPRODUCT((Levels!$A$5:$A$94=$B6)*(Levels!$B$5:$B$94=4)*(COUNTIFS(Progress!$B$5:$B$3000,$A6,Progress!$G$5:$G$3000,Levels!$G$5:$G$94)>0))*(LEFT(I6,1)="4"))) | K6: =IF($A6="","",IF(COUNTIFS(Progress!$B$5:$B$3000,$A6)=0,"",SUMPRODUCT(MAX((Progress!$B$5:$B$3000=$A6)*Progress!$A$5:$A$3000))))
E7: =IF(OR($A7="",$B7=""),"",SUMPRODUCT((Levels!$A$5:$A$94=$B7)*(Levels!$B$5:$B$94=1)*(COUNTIFS(Progress!$B$5:$B$3000,$A7,Progress!$G$5:$G$3000,Levels!$G$5:$G$94)>0))&" / "&COUNTIFS(Levels!$A$5:$A$94,$B7,Levels!$B$5:$B$94,1)) | F7: =IF(OR($A7="",$B7=""),"",SUMPRODUCT((Levels!$A$5:$A$94=$B7)*(Levels!$B$5:$B$94=2)*(COUNTIFS(Progress!$B$5:$B$3000,$A7,Progress!$G$5:$G$3000,Levels!$G$5:$G$94)>0))&" / "&COUNTIFS(Levels!$A$5:$A$94,$B7,Levels!$B$5:$B$94,2)) | G7: =IF(OR($A7="",$B7=""),"",SUMPRODUCT((Levels!$A$5:$A$94=$B7)*(Levels!$B$5:$B$94=3)*(COUNTIFS(Progress!$B$5:$B$3000,$A7,Progress!$G$5:$G$3000,Levels!$G$5:$G$94)>0))&" / "&COUNTIFS(Levels!$A$5:$A$94,$B7,Levels!$B$5:$B$94,3)) | H7: =IF(OR($A7="",$B7=""),"",SUMPRODUCT((Levels!$A$5:$A$94=$B7)*(Levels!$B$5:$B$94=4)*(COUNTIFS(Progress!$B$5:$B$3000,$A7,Progress!$G$5:$G$3000,Levels!$G$5:$G$94)>0))&" / "&COUNTIFS(Levels!$A$5:$A$94,$B7,Levels!$B$5:$B$94,4)) | I7: =IF(OR($A7="",$B7=""),"",IF(SUMPRODUCT((Levels!$A$5:$A$94=$B7)*(Levels!$B$5:$B$94=1)*(COUNTIFS(Progress!$B$5:$B$3000,$A7,Progress!$G$5:$G$3000,Levels!$G$5:$G$94)>0))<COUNTIFS(Levels!$A$5:$A$94,$B7,Levels!$B$5:$B$94,1),"1 Rookie",IF(SUMPRODUCT((Levels!$A$5:$A$94=$B7)*(Levels!$B$5:$B$94=2)*(COUNTIFS(Progress!$B$5:$B$3000,$A7,Progress!$G$5:$G$3000,Levels!$G$5:$G$94)>0))<COUNTIFS(Levels!$A$5:$A$94,$B7,Levels!$B$5:$B$94,2),"2 Contender",IF(SUMPRODUCT((Levels!$A$5:$A$94=$B7)*(Levels!$B$5:$B$94=3)*(COUNTIFS(Progress!$B$5:$B$3000,$A7,Progress!$G$5:$G$3000,Levels!$G$5:$G$94)>0))<COUNTIFS(Levels!$A$5:$A$94,$B7,Levels!$B$5:$B$94,3),"3 Challenger",IF(SUMPRODUCT((Levels!$A$5:$A$94=$B7)*(Levels!$B$5:$B$94=4)*(COUNTIFS(Progress!$B$5:$B$3000,$A7,Progress!$G$5:$G$3000,Levels!$G$5:$G$94)>0))<COUNTIFS(Levels!$A$5:$A$94,$B7,Levels!$B$5:$B$94,4),"4 Champion","All done"))))) | J7: =IF(OR(I7="",I7="All done"),"",COUNTIFS(Levels!$A$5:$A$94,$B7,Levels!$B$5:$B$94,1)*(LEFT(I7,1)="1")+COUNTIFS(Levels!$A$5:$A$94,$B7,Levels!$B$5:$B$94,2)*(LEFT(I7,1)="2")+COUNTIFS(Levels!$A$5:$A$94,$B7,Levels!$B$5:$B$94,3)*(LEFT(I7,1)="3")+COUNTIFS(Levels!$A$5:$A$94,$B7,Levels!$B$5:$B$94,4)*(LEFT(I7,1)="4")-(SUMPRODUCT((Levels!$A$5:$A$94=$B7)*(Levels!$B$5:$B$94=1)*(COUNTIFS(Progress!$B$5:$B$3000,$A7,Progress!$G$5:$G$3000,Levels!$G$5:$G$94)>0))*(LEFT(I7,1)="1")+SUMPRODUCT((Levels!$A$5:$A$94=$B7)*(Levels!$B$5:$B$94=2)*(COUNTIFS(Progress!$B$5:$B$3000,$A7,Progress!$G$5:$G$3000,Levels!$G$5:$G$94)>0))*(LEFT(I7,1)="2")+SUMPRODUCT((Levels!$A$5:$A$94=$B7)*(Levels!$B$5:$B$94=3)*(COUNTIFS(Progress!$B$5:$B$3000,$A7,Progress!$G$5:$G$3000,Levels!$G$5:$G$94)>0))*(LEFT(I7,1)="3")+SUMPRODUCT((Levels!$A$5:$A$94=$B7)*(Levels!$B$5:$B$94=4)*(COUNTIFS(Progress!$B$5:$B$3000,$A7,Progress!$G$5:$G$3000,Levels!$G$5:$G$94)>0))*(LEFT(I7,1)="4"))) | K7: =IF($A7="","",IF(COUNTIFS(Progress!$B$5:$B$3000,$A7)=0,"",SUMPRODUCT(MAX((Progress!$B$5:$B$3000=$A7)*Progress!$A$5:$A$3000))))
E8: =IF(OR($A8="",$B8=""),"",SUMPRODUCT((Levels!$A$5:$A$94=$B8)*(Levels!$B$5:$B$94=1)*(COUNTIFS(Progress!$B$5:$B$3000,$A8,Progress!$G$5:$G$3000,Levels!$G$5:$G$94)>0))&" / "&COUNTIFS(Levels!$A$5:$A$94,$B8,Levels!$B$5:$B$94,1)) | F8: =IF(OR($A8="",$B8=""),"",SUMPRODUCT((Levels!$A$5:$A$94=$B8)*(Levels!$B$5:$B$94=2)*(COUNTIFS(Progress!$B$5:$B$3000,$A8,Progress!$G$5:$G$3000,Levels!$G$5:$G$94)>0))&" / "&COUNTIFS(Levels!$A$5:$A$94,$B8,Levels!$B$5:$B$94,2)) | G8: =IF(OR($A8="",$B8=""),"",SUMPRODUCT((Levels!$A$5:$A$94=$B8)*(Levels!$B$5:$B$94=3)*(COUNTIFS(Progress!$B$5:$B$3000,$A8,Progress!$G$5:$G$3000,Levels!$G$5:$G$94)>0))&" / "&COUNTIFS(Levels!$A$5:$A$94,$B8,Levels!$B$5:$B$94,3)) | H8: =IF(OR($A8="",$B8=""),"",SUMPRODUCT((Levels!$A$5:$A$94=$B8)*(Levels!$B$5:$B$94=4)*(COUNTIFS(Progress!$B$5:$B$3000,$A8,Progress!$G$5:$G$3000,Levels!$G$5:$G$94)>0))&" / "&COUNTIFS(Levels!$A$5:$A$94,$B8,Levels!$B$5:$B$94,4)) | I8: =IF(OR($A8="",$B8=""),"",IF(SUMPRODUCT((Levels!$A$5:$A$94=$B8)*(Levels!$B$5:$B$94=1)*(COUNTIFS(Progress!$B$5:$B$3000,$A8,Progress!$G$5:$G$3000,Levels!$G$5:$G$94)>0))<COUNTIFS(Levels!$A$5:$A$94,$B8,Levels!$B$5:$B$94,1),"1 Rookie",IF(SUMPRODUCT((Levels!$A$5:$A$94=$B8)*(Levels!$B$5:$B$94=2)*(COUNTIFS(Progress!$B$5:$B$3000,$A8,Progress!$G$5:$G$3000,Levels!$G$5:$G$94)>0))<COUNTIFS(Levels!$A$5:$A$94,$B8,Levels!$B$5:$B$94,2),"2 Contender",IF(SUMPRODUCT((Levels!$A$5:$A$94=$B8)*(Levels!$B$5:$B$94=3)*(COUNTIFS(Progress!$B$5:$B$3000,$A8,Progress!$G$5:$G$3000,Levels!$G$5:$G$94)>0))<COUNTIFS(Levels!$A$5:$A$94,$B8,Levels!$B$5:$B$94,3),"3 Challenger",IF(SUMPRODUCT((Levels!$A$5:$A$94=$B8)*(Levels!$B$5:$B$94=4)*(COUNTIFS(Progress!$B$5:$B$3000,$A8,Progress!$G$5:$G$3000,Levels!$G$5:$G$94)>0))<COUNTIFS(Levels!$A$5:$A$94,$B8,Levels!$B$5:$B$94,4),"4 Champion","All done"))))) | J8: =IF(OR(I8="",I8="All done"),"",COUNTIFS(Levels!$A$5:$A$94,$B8,Levels!$B$5:$B$94,1)*(LEFT(I8,1)="1")+COUNTIFS(Levels!$A$5:$A$94,$B8,Levels!$B$5:$B$94,2)*(LEFT(I8,1)="2")+COUNTIFS(Levels!$A$5:$A$94,$B8,Levels!$B$5:$B$94,3)*(LEFT(I8,1)="3")+COUNTIFS(Levels!$A$5:$A$94,$B8,Levels!$B$5:$B$94,4)*(LEFT(I8,1)="4")-(SUMPRODUCT((Levels!$A$5:$A$94=$B8)*(Levels!$B$5:$B$94=1)*(COUNTIFS(Progress!$B$5:$B$3000,$A8,Progress!$G$5:$G$3000,Levels!$G$5:$G$94)>0))*(LEFT(I8,1)="1")+SUMPRODUCT((Levels!$A$5:$A$94=$B8)*(Levels!$B$5:$B$94=2)*(COUNTIFS(Progress!$B$5:$B$3000,$A8,Progress!$G$5:$G$3000,Levels!$G$5:$G$94)>0))*(LEFT(I8,1)="2")+SUMPRODUCT((Levels!$A$5:$A$94=$B8)*(Levels!$B$5:$B$94=3)*(COUNTIFS(Progress!$B$5:$B$3000,$A8,Progress!$G$5:$G$3000,Levels!$G$5:$G$94)>0))*(LEFT(I8,1)="3")+SUMPRODUCT((Levels!$A$5:$A$94=$B8)*(Levels!$B$5:$B$94=4)*(COUNTIFS(Progress!$B$5:$B$3000,$A8,Progress!$G$5:$G$3000,Levels!$G$5:$G$94)>0))*(LEFT(I8,1)="4"))) | K8: =IF($A8="","",IF(COUNTIFS(Progress!$B$5:$B$3000,$A8)=0,"",SUMPRODUCT(MAX((Progress!$B$5:$B$3000=$A8)*Progress!$A$5:$A$3000))))
E9: =IF(OR($A9="",$B9=""),"",SUMPRODUCT((Levels!$A$5:$A$94=$B9)*(Levels!$B$5:$B$94=1)*(COUNTIFS(Progress!$B$5:$B$3000,$A9,Progress!$G$5:$G$3000,Levels!$G$5:$G$94)>0))&" / "&COUNTIFS(Levels!$A$5:$A$94,$B9,Levels!$B$5:$B$94,1)) | F9: =IF(OR($A9="",$B9=""),"",SUMPRODUCT((Levels!$A$5:$A$94=$B9)*(Levels!$B$5:$B$94=2)*(COUNTIFS(Progress!$B$5:$B$3000,$A9,Progress!$G$5:$G$3000,Levels!$G$5:$G$94)>0))&" / "&COUNTIFS(Levels!$A$5:$A$94,$B9,Levels!$B$5:$B$94,2)) | G9: =IF(OR($A9="",$B9=""),"",SUMPRODUCT((Levels!$A$5:$A$94=$B9)*(Levels!$B$5:$B$94=3)*(COUNTIFS(Progress!$B$5:$B$3000,$A9,Progress!$G$5:$G$3000,Levels!$G$5:$G$94)>0))&" / "&COUNTIFS(Levels!$A$5:$A$94,$B9,Levels!$B$5:$B$94,3)) | H9: =IF(OR($A9="",$B9=""),"",SUMPRODUCT((Levels!$A$5:$A$94=$B9)*(Levels!$B$5:$B$94=4)*(COUNTIFS(Progress!$B$5:$B$3000,$A9,Progress!$G$5:$G$3000,Levels!$G$5:$G$94)>0))&" / "&COUNTIFS(Levels!$A$5:$A$94,$B9,Levels!$B$5:$B$94,4)) | I9: =IF(OR($A9="",$B9=""),"",IF(SUMPRODUCT((Levels!$A$5:$A$94=$B9)*(Levels!$B$5:$B$94=1)*(COUNTIFS(Progress!$B$5:$B$3000,$A9,Progress!$G$5:$G$3000,Levels!$G$5:$G$94)>0))<COUNTIFS(Levels!$A$5:$A$94,$B9,Levels!$B$5:$B$94,1),"1 Rookie",IF(SUMPRODUCT((Levels!$A$5:$A$94=$B9)*(Levels!$B$5:$B$94=2)*(COUNTIFS(Progress!$B$5:$B$3000,$A9,Progress!$G$5:$G$3000,Levels!$G$5:$G$94)>0))<COUNTIFS(Levels!$A$5:$A$94,$B9,Levels!$B$5:$B$94,2),"2 Contender",IF(SUMPRODUCT((Levels!$A$5:$A$94=$B9)*(Levels!$B$5:$B$94=3)*(COUNTIFS(Progress!$B$5:$B$3000,$A9,Progress!$G$5:$G$3000,Levels!$G$5:$G$94)>0))<COUNTIFS(Levels!$A$5:$A$94,$B9,Levels!$B$5:$B$94,3),"3 Challenger",IF(SUMPRODUCT((Levels!$A$5:$A$94=$B9)*(Levels!$B$5:$B$94=4)*(COUNTIFS(Progress!$B$5:$B$3000,$A9,Progress!$G$5:$G$3000,Levels!$G$5:$G$94)>0))<COUNTIFS(Levels!$A$5:$A$94,$B9,Levels!$B$5:$B$94,4),"4 Champion","All done"))))) | J9: =IF(OR(I9="",I9="All done"),"",COUNTIFS(Levels!$A$5:$A$94,$B9,Levels!$B$5:$B$94,1)*(LEFT(I9,1)="1")+COUNTIFS(Levels!$A$5:$A$94,$B9,Levels!$B$5:$B$94,2)*(LEFT(I9,1)="2")+COUNTIFS(Levels!$A$5:$A$94,$B9,Levels!$B$5:$B$94,3)*(LEFT(I9,1)="3")+COUNTIFS(Levels!$A$5:$A$94,$B9,Levels!$B$5:$B$94,4)*(LEFT(I9,1)="4")-(SUMPRODUCT((Levels!$A$5:$A$94=$B9)*(Levels!$B$5:$B$94=1)*(COUNTIFS(Progress!$B$5:$B$3000,$A9,Progress!$G$5:$G$3000,Levels!$G$5:$G$94)>0))*(LEFT(I9,1)="1")+SUMPRODUCT((Levels!$A$5:$A$94=$B9)*(Levels!$B$5:$B$94=2)*(COUNTIFS(Progress!$B$5:$B$3000,$A9,Progress!$G$5:$G$3000,Levels!$G$5:$G$94)>0))*(LEFT(I9,1)="2")+SUMPRODUCT((Levels!$A$5:$A$94=$B9)*(Levels!$B$5:$B$94=3)*(COUNTIFS(Progress!$B$5:$B$3000,$A9,Progress!$G$5:$G$3000,Levels!$G$5:$G$94)>0))*(LEFT(I9,1)="3")+SUMPRODUCT((Levels!$A$5:$A$94=$B9)*(Levels!$B$5:$B$94=4)*(COUNTIFS(Progress!$B$5:$B$3000,$A9,Progress!$G$5:$G$3000,Levels!$G$5:$G$94)>0))*(LEFT(I9,1)="4"))) | K9: =IF($A9="","",IF(COUNTIFS(Progress!$B$5:$B$3000,$A9)=0,"",SUMPRODUCT(MAX((Progress!$B$5:$B$3000=$A9)*Progress!$A$5:$A$3000))))
E10: =IF(OR($A10="",$B10=""),"",SUMPRODUCT((Levels!$A$5:$A$94=$B10)*(Levels!$B$5:$B$94=1)*(COUNTIFS(Progress!$B$5:$B$3000,$A10,Progress!$G$5:$G$3000,Levels!$G$5:$G$94)>0))&" / "&COUNTIFS(Levels!$A$5:$A$94,$B10,Levels!$B$5:$B$94,1)) | F10: =IF(OR($A10="",$B10=""),"",SUMPRODUCT((Levels!$A$5:$A$94=$B10)*(Levels!$B$5:$B$94=2)*(COUNTIFS(Progress!$B$5:$B$3000,$A10,Progress!$G$5:$G$3000,Levels!$G$5:$G$94)>0))&" / "&COUNTIFS(Levels!$A$5:$A$94,$B10,Levels!$B$5:$B$94,2)) | G10: =IF(OR($A10="",$B10=""),"",SUMPRODUCT((Levels!$A$5:$A$94=$B10)*(Levels!$B$5:$B$94=3)*(COUNTIFS(Progress!$B$5:$B$3000,$A10,Progress!$G$5:$G$3000,Levels!$G$5:$G$94)>0))&" / "&COUNTIFS(Levels!$A$5:$A$94,$B10,Levels!$B$5:$B$94,3)) | H10: =IF(OR($A10="",$B10=""),"",SUMPRODUCT((Levels!$A$5:$A$94=$B10)*(Levels!$B$5:$B$94=4)*(COUNTIFS(Progress!$B$5:$B$3000,$A10,Progress!$G$5:$G$3000,Levels!$G$5:$G$94)>0))&" / "&COUNTIFS(Levels!$A$5:$A$94,$B10,Levels!$B$5:$B$94,4)) | I10: =IF(OR($A10="",$B10=""),"",IF(SUMPRODUCT((Levels!$A$5:$A$94=$B10)*(Levels!$B$5:$B$94=1)*(COUNTIFS(Progress!$B$5:$B$3000,$A10,Progress!$G$5:$G$3000,Levels!$G$5:$G$94)>0))<COUNTIFS(Levels!$A$5:$A$94,$B10,Levels!$B$5:$B$94,1),"1 Rookie",IF(SUMPRODUCT((Levels!$A$5:$A$94=$B10)*(Levels!$B$5:$B$94=2)*(COUNTIFS(Progress!$B$5:$B$3000,$A10,Progress!$G$5:$G$3000,Levels!$G$5:$G$94)>0))<COUNTIFS(Levels!$A$5:$A$94,$B10,Levels!$B$5:$B$94,2),"2 Contender",IF(SUMPRODUCT((Levels!$A$5:$A$94=$B10)*(Levels!$B$5:$B$94=3)*(COUNTIFS(Progress!$B$5:$B$3000,$A10,Progress!$G$5:$G$3000,Levels!$G$5:$G$94)>0))<COUNTIFS(Levels!$A$5:$A$94,$B10,Levels!$B$5:$B$94,3),"3 Challenger",IF(SUMPRODUCT((Levels!$A$5:$A$94=$B10)*(Levels!$B$5:$B$94=4)*(COUNTIFS(Progress!$B$5:$B$3000,$A10,Progress!$G$5:$G$3000,Levels!$G$5:$G$94)>0))<COUNTIFS(Levels!$A$5:$A$94,$B10,Levels!$B$5:$B$94,4),"4 Champion","All done"))))) | J10: =IF(OR(I10="",I10="All done"),"",COUNTIFS(Levels!$A$5:$A$94,$B10,Levels!$B$5:$B$94,1)*(LEFT(I10,1)="1")+COUNTIFS(Levels!$A$5:$A$94,$B10,Levels!$B$5:$B$94,2)*(LEFT(I10,1)="2")+COUNTIFS(Levels!$A$5:$A$94,$B10,Levels!$B$5:$B$94,3)*(LEFT(I10,1)="3")+COUNTIFS(Levels!$A$5:$A$94,$B10,Levels!$B$5:$B$94,4)*(LEFT(I10,1)="4")-(SUMPRODUCT((Levels!$A$5:$A$94=$B10)*(Levels!$B$5:$B$94=1)*(COUNTIFS(Progress!$B$5:$B$3000,$A10,Progress!$G$5:$G$3000,Levels!$G$5:$G$94)>0))*(LEFT(I10,1)="1")+SUMPRODUCT((Levels!$A$5:$A$94=$B10)*(Levels!$B$5:$B$94=2)*(COUNTIFS(Progress!$B$5:$B$3000,$A10,Progress!$G$5:$G$3000,Levels!$G$5:$G$94)>0))*(LEFT(I10,1)="2")+SUMPRODUCT((Levels!$A$5:$A$94=$B10)*(Levels!$B$5:$B$94=3)*(COUNTIFS(Progress!$B$5:$B$3000,$A10,Progress!$G$5:$G$3000,Levels!$G$5:$G$94)>0))*(LEFT(I10,1)="3")+SUMPRODUCT((Levels!$A$5:$A$94=$B10)*(Levels!$B$5:$B$94=4)*(COUNTIFS(Progress!$B$5:$B$3000,$A10,Progress!$G$5:$G$3000,Levels!$G$5:$G$94)>0))*(LEFT(I10,1)="4"))) | K10: =IF($A10="","",IF(COUNTIFS(Progress!$B$5:$B$3000,$A10)=0,"",SUMPRODUCT(MAX((Progress!$B$5:$B$3000=$A10)*Progress!$A$5:$A$3000))))
E11: =IF(OR($A11="",$B11=""),"",SUMPRODUCT((Levels!$A$5:$A$94=$B11)*(Levels!$B$5:$B$94=1)*(COUNTIFS(Progress!$B$5:$B$3000,$A11,Progress!$G$5:$G$3000,Levels!$G$5:$G$94)>0))&" / "&COUNTIFS(Levels!$A$5:$A$94,$B11,Levels!$B$5:$B$94,1)) | F11: =IF(OR($A11="",$B11=""),"",SUMPRODUCT((Levels!$A$5:$A$94=$B11)*(Levels!$B$5:$B$94=2)*(COUNTIFS(Progress!$B$5:$B$3000,$A11,Progress!$G$5:$G$3000,Levels!$G$5:$G$94)>0))&" / "&COUNTIFS(Levels!$A$5:$A$94,$B11,Levels!$B$5:$B$94,2)) | G11: =IF(OR($A11="",$B11=""),"",SUMPRODUCT((Levels!$A$5:$A$94=$B11)*(Levels!$B$5:$B$94=3)*(COUNTIFS(Progress!$B$5:$B$3000,$A11,Progress!$G$5:$G$3000,Levels!$G$5:$G$94)>0))&" / "&COUNTIFS(Levels!$A$5:$A$94,$B11,Levels!$B$5:$B$94,3)) | H11: =IF(OR($A11="",$B11=""),"",SUMPRODUCT((Levels!$A$5:$A$94=$B11)*(Levels!$B$5:$B$94=4)*(COUNTIFS(Progress!$B$5:$B$3000,$A11,Progress!$G$5:$G$3000,Levels!$G$5:$G$94)>0))&" / "&COUNTIFS(Levels!$A$5:$A$94,$B11,Levels!$B$5:$B$94,4)) | I11: =IF(OR($A11="",$B11=""),"",IF(SUMPRODUCT((Levels!$A$5:$A$94=$B11)*(Levels!$B$5:$B$94=1)*(COUNTIFS(Progress!$B$5:$B$3000,$A11,Progress!$G$5:$G$3000,Levels!$G$5:$G$94)>0))<COUNTIFS(Levels!$A$5:$A$94,$B11,Levels!$B$5:$B$94,1),"1 Rookie",IF(SUMPRODUCT((Levels!$A$5:$A$94=$B11)*(Levels!$B$5:$B$94=2)*(COUNTIFS(Progress!$B$5:$B$3000,$A11,Progress!$G$5:$G$3000,Levels!$G$5:$G$94)>0))<COUNTIFS(Levels!$A$5:$A$94,$B11,Levels!$B$5:$B$94,2),"2 Contender",IF(SUMPRODUCT((Levels!$A$5:$A$94=$B11)*(Levels!$B$5:$B$94=3)*(COUNTIFS(Progress!$B$5:$B$3000,$A11,Progress!$G$5:$G$3000,Levels!$G$5:$G$94)>0))<COUNTIFS(Levels!$A$5:$A$94,$B11,Levels!$B$5:$B$94,3),"3 Challenger",IF(SUMPRODUCT((Levels!$A$5:$A$94=$B11)*(Levels!$B$5:$B$94=4)*(COUNTIFS(Progress!$B$5:$B$3000,$A11,Progress!$G$5:$G$3000,Levels!$G$5:$G$94)>0))<COUNTIFS(Levels!$A$5:$A$94,$B11,Levels!$B$5:$B$94,4),"4 Champion","All done"))))) | J11: =IF(OR(I11="",I11="All done"),"",COUNTIFS(Levels!$A$5:$A$94,$B11,Levels!$B$5:$B$94,1)*(LEFT(I11,1)="1")+COUNTIFS(Levels!$A$5:$A$94,$B11,Levels!$B$5:$B$94,2)*(LEFT(I11,1)="2")+COUNTIFS(Levels!$A$5:$A$94,$B11,Levels!$B$5:$B$94,3)*(LEFT(I11,1)="3")+COUNTIFS(Levels!$A$5:$A$94,$B11,Levels!$B$5:$B$94,4)*(LEFT(I11,1)="4")-(SUMPRODUCT((Levels!$A$5:$A$94=$B11)*(Levels!$B$5:$B$94=1)*(COUNTIFS(Progress!$B$5:$B$3000,$A11,Progress!$G$5:$G$3000,Levels!$G$5:$G$94)>0))*(LEFT(I11,1)="1")+SUMPRODUCT((Levels!$A$5:$A$94=$B11)*(Levels!$B$5:$B$94=2)*(COUNTIFS(Progress!$B$5:$B$3000,$A11,Progress!$G$5:$G$3000,Levels!$G$5:$G$94)>0))*(LEFT(I11,1)="2")+SUMPRODUCT((Levels!$A$5:$A$94=$B11)*(Levels!$B$5:$B$94=3)*(COUNTIFS(Progress!$B$5:$B$3000,$A11,Progress!$G$5:$G$3000,Levels!$G$5:$G$94)>0))*(LEFT(I11,1)="3")+SUMPRODUCT((Levels!$A$5:$A$94=$B11)*(Levels!$B$5:$B$94=4)*(COUNTIFS(Progress!$B$5:$B$3000,$A11,Progress!$G$5:$G$3000,Levels!$G$5:$G$94)>0))*(LEFT(I11,1)="4"))) | K11: =IF($A11="","",IF(COUNTIFS(Progress!$B$5:$B$3000,$A11)=0,"",SUMPRODUCT(MAX((Progress!$B$5:$B$3000=$A11)*Progress!$A$5:$A$3000))))
E12: =IF(OR($A12="",$B12=""),"",SUMPRODUCT((Levels!$A$5:$A$94=$B12)*(Levels!$B$5:$B$94=1)*(COUNTIFS(Progress!$B$5:$B$3000,$A12,Progress!$G$5:$G$3000,Levels!$G$5:$G$94)>0))&" / "&COUNTIFS(Levels!$A$5:$A$94,$B12,Levels!$B$5:$B$94,1)) | F12: =IF(OR($A12="",$B12=""),"",SUMPRODUCT((Levels!$A$5:$A$94=$B12)*(Levels!$B$5:$B$94=2)*(COUNTIFS(Progress!$B$5:$B$3000,$A12,Progress!$G$5:$G$3000,Levels!$G$5:$G$94)>0))&" / "&COUNTIFS(Levels!$A$5:$A$94,$B12,Levels!$B$5:$B$94,2)) | G12: =IF(OR($A12="",$B12=""),"",SUMPRODUCT((Levels!$A$5:$A$94=$B12)*(Levels!$B$5:$B$94=3)*(COUNTIFS(Progress!$B$5:$B$3000,$A12,Progress!$G$5:$G$3000,Levels!$G$5:$G$94)>0))&" / "&COUNTIFS(Levels!$A$5:$A$94,$B12,Levels!$B$5:$B$94,3)) | H12: =IF(OR($A12="",$B12=""),"",SUMPRODUCT((Levels!$A$5:$A$94=$B12)*(Levels!$B$5:$B$94=4)*(COUNTIFS(Progress!$B$5:$B$3000,$A12,Progress!$G$5:$G$3000,Levels!$G$5:$G$94)>0))&" / "&COUNTIFS(Levels!$A$5:$A$94,$B12,Levels!$B$5:$B$94,4)) | I12: =IF(OR($A12="",$B12=""),"",IF(SUMPRODUCT((Levels!$A$5:$A$94=$B12)*(Levels!$B$5:$B$94=1)*(COUNTIFS(Progress!$B$5:$B$3000,$A12,Progress!$G$5:$G$3000,Levels!$G$5:$G$94)>0))<COUNTIFS(Levels!$A$5:$A$94,$B12,Levels!$B$5:$B$94,1),"1 Rookie",IF(SUMPRODUCT((Levels!$A$5:$A$94=$B12)*(Levels!$B$5:$B$94=2)*(COUNTIFS(Progress!$B$5:$B$3000,$A12,Progress!$G$5:$G$3000,Levels!$G$5:$G$94)>0))<COUNTIFS(Levels!$A$5:$A$94,$B12,Levels!$B$5:$B$94,2),"2 Contender",IF(SUMPRODUCT((Levels!$A$5:$A$94=$B12)*(Levels!$B$5:$B$94=3)*(COUNTIFS(Progress!$B$5:$B$3000,$A12,Progress!$G$5:$G$3000,Levels!$G$5:$G$94)>0))<COUNTIFS(Levels!$A$5:$A$94,$B12,Levels!$B$5:$B$94,3),"3 Challenger",IF(SUMPRODUCT((Levels!$A$5:$A$94=$B12)*(Levels!$B$5:$B$94=4)*(COUNTIFS(Progress!$B$5:$B$3000,$A12,Progress!$G$5:$G$3000,Levels!$G$5:$G$94)>0))<COUNTIFS(Levels!$A$5:$A$94,$B12,Levels!$B$5:$B$94,4),"4 Champion","All done"))))) | J12: =IF(OR(I12="",I12="All done"),"",COUNTIFS(Levels!$A$5:$A$94,$B12,Levels!$B$5:$B$94,1)*(LEFT(I12,1)="1")+COUNTIFS(Levels!$A$5:$A$94,$B12,Levels!$B$5:$B$94,2)*(LEFT(I12,1)="2")+COUNTIFS(Levels!$A$5:$A$94,$B12,Levels!$B$5:$B$94,3)*(LEFT(I12,1)="3")+COUNTIFS(Levels!$A$5:$A$94,$B12,Levels!$B$5:$B$94,4)*(LEFT(I12,1)="4")-(SUMPRODUCT((Levels!$A$5:$A$94=$B12)*(Levels!$B$5:$B$94=1)*(COUNTIFS(Progress!$B$5:$B$3000,$A12,Progress!$G$5:$G$3000,Levels!$G$5:$G$94)>0))*(LEFT(I12,1)="1")+SUMPRODUCT((Levels!$A$5:$A$94=$B12)*(Levels!$B$5:$B$94=2)*(COUNTIFS(Progress!$B$5:$B$3000,$A12,Progress!$G$5:$G$3000,Levels!$G$5:$G$94)>0))*(LEFT(I12,1)="2")+SUMPRODUCT((Levels!$A$5:$A$94=$B12)*(Levels!$B$5:$B$94=3)*(COUNTIFS(Progress!$B$5:$B$3000,$A12,Progress!$G$5:$G$3000,Levels!$G$5:$G$94)>0))*(LEFT(I12,1)="3")+SUMPRODUCT((Levels!$A$5:$A$94=$B12)*(Levels!$B$5:$B$94=4)*(COUNTIFS(Progress!$B$5:$B$3000,$A12,Progress!$G$5:$G$3000,Levels!$G$5:$G$94)>0))*(LEFT(I12,1)="4"))) | K12: =IF($A12="","",IF(COUNTIFS(Progress!$B$5:$B$3000,$A12)=0,"",SUMPRODUCT(MAX((Progress!$B$5:$B$3000=$A12)*Progress!$A$5:$A$3000))))
E13: =IF(OR($A13="",$B13=""),"",SUMPRODUCT((Levels!$A$5:$A$94=$B13)*(Levels!$B$5:$B$94=1)*(COUNTIFS(Progress!$B$5:$B$3000,$A13,Progress!$G$5:$G$3000,Levels!$G$5:$G$94)>0))&" / "&COUNTIFS(Levels!$A$5:$A$94,$B13,Levels!$B$5:$B$94,1)) | F13: =IF(OR($A13="",$B13=""),"",SUMPRODUCT((Levels!$A$5:$A$94=$B13)*(Levels!$B$5:$B$94=2)*(COUNTIFS(Progress!$B$5:$B$3000,$A13,Progress!$G$5:$G$3000,Levels!$G$5:$G$94)>0))&" / "&COUNTIFS(Levels!$A$5:$A$94,$B13,Levels!$B$5:$B$94,2)) | G13: =IF(OR($A13="",$B13=""),"",SUMPRODUCT((Levels!$A$5:$A$94=$B13)*(Levels!$B$5:$B$94=3)*(COUNTIFS(Progress!$B$5:$B$3000,$A13,Progress!$G$5:$G$3000,Levels!$G$5:$G$94)>0))&" / "&COUNTIFS(Levels!$A$5:$A$94,$B13,Levels!$B$5:$B$94,3)) | H13: =IF(OR($A13="",$B13=""),"",SUMPRODUCT((Levels!$A$5:$A$94=$B13)*(Levels!$B$5:$B$94=4)*(COUNTIFS(Progress!$B$5:$B$3000,$A13,Progress!$G$5:$G$3000,Levels!$G$5:$G$94)>0))&" / "&COUNTIFS(Levels!$A$5:$A$94,$B13,Levels!$B$5:$B$94,4)) | I13: =IF(OR($A13="",$B13=""),"",IF(SUMPRODUCT((Levels!$A$5:$A$94=$B13)*(Levels!$B$5:$B$94=1)*(COUNTIFS(Progress!$B$5:$B$3000,$A13,Progress!$G$5:$G$3000,Levels!$G$5:$G$94)>0))<COUNTIFS(Levels!$A$5:$A$94,$B13,Levels!$B$5:$B$94,1),"1 Rookie",IF(SUMPRODUCT((Levels!$A$5:$A$94=$B13)*(Levels!$B$5:$B$94=2)*(COUNTIFS(Progress!$B$5:$B$3000,$A13,Progress!$G$5:$G$3000,Levels!$G$5:$G$94)>0))<COUNTIFS(Levels!$A$5:$A$94,$B13,Levels!$B$5:$B$94,2),"2 Contender",IF(SUMPRODUCT((Levels!$A$5:$A$94=$B13)*(Levels!$B$5:$B$94=3)*(COUNTIFS(Progress!$B$5:$B$3000,$A13,Progress!$G$5:$G$3000,Levels!$G$5:$G$94)>0))<COUNTIFS(Levels!$A$5:$A$94,$B13,Levels!$B$5:$B$94,3),"3 Challenger",IF(SUMPRODUCT((Levels!$A$5:$A$94=$B13)*(Levels!$B$5:$B$94=4)*(COUNTIFS(Progress!$B$5:$B$3000,$A13,Progress!$G$5:$G$3000,Levels!$G$5:$G$94)>0))<COUNTIFS(Levels!$A$5:$A$94,$B13,Levels!$B$5:$B$94,4),"4 Champion","All done"))))) | J13: =IF(OR(I13="",I13="All done"),"",COUNTIFS(Levels!$A$5:$A$94,$B13,Levels!$B$5:$B$94,1)*(LEFT(I13,1)="1")+COUNTIFS(Levels!$A$5:$A$94,$B13,Levels!$B$5:$B$94,2)*(LEFT(I13,1)="2")+COUNTIFS(Levels!$A$5:$A$94,$B13,Levels!$B$5:$B$94,3)*(LEFT(I13,1)="3")+COUNTIFS(Levels!$A$5:$A$94,$B13,Levels!$B$5:$B$94,4)*(LEFT(I13,1)="4")-(SUMPRODUCT((Levels!$A$5:$A$94=$B13)*(Levels!$B$5:$B$94=1)*(COUNTIFS(Progress!$B$5:$B$3000,$A13,Progress!$G$5:$G$3000,Levels!$G$5:$G$94)>0))*(LEFT(I13,1)="1")+SUMPRODUCT((Levels!$A$5:$A$94=$B13)*(Levels!$B$5:$B$94=2)*(COUNTIFS(Progress!$B$5:$B$3000,$A13,Progress!$G$5:$G$3000,Levels!$G$5:$G$94)>0))*(LEFT(I13,1)="2")+SUMPRODUCT((Levels!$A$5:$A$94=$B13)*(Levels!$B$5:$B$94=3)*(COUNTIFS(Progress!$B$5:$B$3000,$A13,Progress!$G$5:$G$3000,Levels!$G$5:$G$94)>0))*(LEFT(I13,1)="3")+SUMPRODUCT((Levels!$A$5:$A$94=$B13)*(Levels!$B$5:$B$94=4)*(COUNTIFS(Progress!$B$5:$B$3000,$A13,Progress!$G$5:$G$3000,Levels!$G$5:$G$94)>0))*(LEFT(I13,1)="4"))) | K13: =IF($A13="","",IF(COUNTIFS(Progress!$B$5:$B$3000,$A13)=0,"",SUMPRODUCT(MAX((Progress!$B$5:$B$3000=$A13)*Progress!$A$5:$A$3000))))
E14: =IF(OR($A14="",$B14=""),"",SUMPRODUCT((Levels!$A$5:$A$94=$B14)*(Levels!$B$5:$B$94=1)*(COUNTIFS(Progress!$B$5:$B$3000,$A14,Progress!$G$5:$G$3000,Levels!$G$5:$G$94)>0))&" / "&COUNTIFS(Levels!$A$5:$A$94,$B14,Levels!$B$5:$B$94,1)) | F14: =IF(OR($A14="",$B14=""),"",SUMPRODUCT((Levels!$A$5:$A$94=$B14)*(Levels!$B$5:$B$94=2)*(COUNTIFS(Progress!$B$5:$B$3000,$A14,Progress!$G$5:$G$3000,Levels!$G$5:$G$94)>0))&" / "&COUNTIFS(Levels!$A$5:$A$94,$B14,Levels!$B$5:$B$94,2)) | G14: =IF(OR($A14="",$B14=""),"",SUMPRODUCT((Levels!$A$5:$A$94=$B14)*(Levels!$B$5:$B$94=3)*(COUNTIFS(Progress!$B$5:$B$3000,$A14,Progress!$G$5:$G$3000,Levels!$G$5:$G$94)>0))&" / "&COUNTIFS(Levels!$A$5:$A$94,$B14,Levels!$B$5:$B$94,3)) | H14: =IF(OR($A14="",$B14=""),"",SUMPRODUCT((Levels!$A$5:$A$94=$B14)*(Levels!$B$5:$B$94=4)*(COUNTIFS(Progress!$B$5:$B$3000,$A14,Progress!$G$5:$G$3000,Levels!$G$5:$G$94)>0))&" / "&COUNTIFS(Levels!$A$5:$A$94,$B14,Levels!$B$5:$B$94,4)) | I14: =IF(OR($A14="",$B14=""),"",IF(SUMPRODUCT((Levels!$A$5:$A$94=$B14)*(Levels!$B$5:$B$94=1)*(COUNTIFS(Progress!$B$5:$B$3000,$A14,Progress!$G$5:$G$3000,Levels!$G$5:$G$94)>0))<COUNTIFS(Levels!$A$5:$A$94,$B14,Levels!$B$5:$B$94,1),"1 Rookie",IF(SUMPRODUCT((Levels!$A$5:$A$94=$B14)*(Levels!$B$5:$B$94=2)*(COUNTIFS(Progress!$B$5:$B$3000,$A14,Progress!$G$5:$G$3000,Levels!$G$5:$G$94)>0))<COUNTIFS(Levels!$A$5:$A$94,$B14,Levels!$B$5:$B$94,2),"2 Contender",IF(SUMPRODUCT((Levels!$A$5:$A$94=$B14)*(Levels!$B$5:$B$94=3)*(COUNTIFS(Progress!$B$5:$B$3000,$A14,Progress!$G$5:$G$3000,Levels!$G$5:$G$94)>0))<COUNTIFS(Levels!$A$5:$A$94,$B14,Levels!$B$5:$B$94,3),"3 Challenger",IF(SUMPRODUCT((Levels!$A$5:$A$94=$B14)*(Levels!$B$5:$B$94=4)*(COUNTIFS(Progress!$B$5:$B$3000,$A14,Progress!$G$5:$G$3000,Levels!$G$5:$G$94)>0))<COUNTIFS(Levels!$A$5:$A$94,$B14,Levels!$B$5:$B$94,4),"4 Champion","All done"))))) | J14: =IF(OR(I14="",I14="All done"),"",COUNTIFS(Levels!$A$5:$A$94,$B14,Levels!$B$5:$B$94,1)*(LEFT(I14,1)="1")+COUNTIFS(Levels!$A$5:$A$94,$B14,Levels!$B$5:$B$94,2)*(LEFT(I14,1)="2")+COUNTIFS(Levels!$A$5:$A$94,$B14,Levels!$B$5:$B$94,3)*(LEFT(I14,1)="3")+COUNTIFS(Levels!$A$5:$A$94,$B14,Levels!$B$5:$B$94,4)*(LEFT(I14,1)="4")-(SUMPRODUCT((Levels!$A$5:$A$94=$B14)*(Levels!$B$5:$B$94=1)*(COUNTIFS(Progress!$B$5:$B$3000,$A14,Progress!$G$5:$G$3000,Levels!$G$5:$G$94)>0))*(LEFT(I14,1)="1")+SUMPRODUCT((Levels!$A$5:$A$94=$B14)*(Levels!$B$5:$B$94=2)*(COUNTIFS(Progress!$B$5:$B$3000,$A14,Progress!$G$5:$G$3000,Levels!$G$5:$G$94)>0))*(LEFT(I14,1)="2")+SUMPRODUCT((Levels!$A$5:$A$94=$B14)*(Levels!$B$5:$B$94=3)*(COUNTIFS(Progress!$B$5:$B$3000,$A14,Progress!$G$5:$G$3000,Levels!$G$5:$G$94)>0))*(LEFT(I14,1)="3")+SUMPRODUCT((Levels!$A$5:$A$94=$B14)*(Levels!$B$5:$B$94=4)*(COUNTIFS(Progress!$B$5:$B$3000,$A14,Progress!$G$5:$G$3000,Levels!$G$5:$G$94)>0))*(LEFT(I14,1)="4"))) | K14: =IF($A14="","",IF(COUNTIFS(Progress!$B$5:$B$3000,$A14)=0,"",SUMPRODUCT(MAX((Progress!$B$5:$B$3000=$A14)*Progress!$A$5:$A$3000))))
E15: =IF(OR($A15="",$B15=""),"",SUMPRODUCT((Levels!$A$5:$A$94=$B15)*(Levels!$B$5:$B$94=1)*(COUNTIFS(Progress!$B$5:$B$3000,$A15,Progress!$G$5:$G$3000,Levels!$G$5:$G$94)>0))&" / "&COUNTIFS(Levels!$A$5:$A$94,$B15,Levels!$B$5:$B$94,1)) | F15: =IF(OR($A15="",$B15=""),"",SUMPRODUCT((Levels!$A$5:$A$94=$B15)*(Levels!$B$5:$B$94=2)*(COUNTIFS(Progress!$B$5:$B$3000,$A15,Progress!$G$5:$G$3000,Levels!$G$5:$G$94)>0))&" / "&COUNTIFS(Levels!$A$5:$A$94,$B15,Levels!$B$5:$B$94,2)) | G15: =IF(OR($A15="",$B15=""),"",SUMPRODUCT((Levels!$A$5:$A$94=$B15)*(Levels!$B$5:$B$94=3)*(COUNTIFS(Progress!$B$5:$B$3000,$A15,Progress!$G$5:$G$3000,Levels!$G$5:$G$94)>0))&" / "&COUNTIFS(Levels!$A$5:$A$94,$B15,Levels!$B$5:$B$94,3)) | H15: =IF(OR($A15="",$B15=""),"",SUMPRODUCT((Levels!$A$5:$A$94=$B15)*(Levels!$B$5:$B$94=4)*(COUNTIFS(Progress!$B$5:$B$3000,$A15,Progress!$G$5:$G$3000,Levels!$G$5:$G$94)>0))&" / "&COUNTIFS(Levels!$A$5:$A$94,$B15,Levels!$B$5:$B$94,4)) | I15: =IF(OR($A15="",$B15=""),"",IF(SUMPRODUCT((Levels!$A$5:$A$94=$B15)*(Levels!$B$5:$B$94=1)*(COUNTIFS(Progress!$B$5:$B$3000,$A15,Progress!$G$5:$G$3000,Levels!$G$5:$G$94)>0))<COUNTIFS(Levels!$A$5:$A$94,$B15,Levels!$B$5:$B$94,1),"1 Rookie",IF(SUMPRODUCT((Levels!$A$5:$A$94=$B15)*(Levels!$B$5:$B$94=2)*(COUNTIFS(Progress!$B$5:$B$3000,$A15,Progress!$G$5:$G$3000,Levels!$G$5:$G$94)>0))<COUNTIFS(Levels!$A$5:$A$94,$B15,Levels!$B$5:$B$94,2),"2 Contender",IF(SUMPRODUCT((Levels!$A$5:$A$94=$B15)*(Levels!$B$5:$B$94=3)*(COUNTIFS(Progress!$B$5:$B$3000,$A15,Progress!$G$5:$G$3000,Levels!$G$5:$G$94)>0))<COUNTIFS(Levels!$A$5:$A$94,$B15,Levels!$B$5:$B$94,3),"3 Challenger",IF(SUMPRODUCT((Levels!$A$5:$A$94=$B15)*(Levels!$B$5:$B$94=4)*(COUNTIFS(Progress!$B$5:$B$3000,$A15,Progress!$G$5:$G$3000,Levels!$G$5:$G$94)>0))<COUNTIFS(Levels!$A$5:$A$94,$B15,Levels!$B$5:$B$94,4),"4 Champion","All done"))))) | J15: =IF(OR(I15="",I15="All done"),"",COUNTIFS(Levels!$A$5:$A$94,$B15,Levels!$B$5:$B$94,1)*(LEFT(I15,1)="1")+COUNTIFS(Levels!$A$5:$A$94,$B15,Levels!$B$5:$B$94,2)*(LEFT(I15,1)="2")+COUNTIFS(Levels!$A$5:$A$94,$B15,Levels!$B$5:$B$94,3)*(LEFT(I15,1)="3")+COUNTIFS(Levels!$A$5:$A$94,$B15,Levels!$B$5:$B$94,4)*(LEFT(I15,1)="4")-(SUMPRODUCT((Levels!$A$5:$A$94=$B15)*(Levels!$B$5:$B$94=1)*(COUNTIFS(Progress!$B$5:$B$3000,$A15,Progress!$G$5:$G$3000,Levels!$G$5:$G$94)>0))*(LEFT(I15,1)="1")+SUMPRODUCT((Levels!$A$5:$A$94=$B15)*(Levels!$B$5:$B$94=2)*(COUNTIFS(Progress!$B$5:$B$3000,$A15,Progress!$G$5:$G$3000,Levels!$G$5:$G$94)>0))*(LEFT(I15,1)="2")+SUMPRODUCT((Levels!$A$5:$A$94=$B15)*(Levels!$B$5:$B$94=3)*(COUNTIFS(Progress!$B$5:$B$3000,$A15,Progress!$G$5:$G$3000,Levels!$G$5:$G$94)>0))*(LEFT(I15,1)="3")+SUMPRODUCT((Levels!$A$5:$A$94=$B15)*(Levels!$B$5:$B$94=4)*(COUNTIFS(Progress!$B$5:$B$3000,$A15,Progress!$G$5:$G$3000,Levels!$G$5:$G$94)>0))*(LEFT(I15,1)="4"))) | K15: =IF($A15="","",IF(COUNTIFS(Progress!$B$5:$B$3000,$A15)=0,"",SUMPRODUCT(MAX((Progress!$B$5:$B$3000=$A15)*Progress!$A$5:$A$3000))))
E16: =IF(OR($A16="",$B16=""),"",SUMPRODUCT((Levels!$A$5:$A$94=$B16)*(Levels!$B$5:$B$94=1)*(COUNTIFS(Progress!$B$5:$B$3000,$A16,Progress!$G$5:$G$3000,Levels!$G$5:$G$94)>0))&" / "&COUNTIFS(Levels!$A$5:$A$94,$B16,Levels!$B$5:$B$94,1)) | F16: =IF(OR($A16="",$B16=""),"",SUMPRODUCT((Levels!$A$5:$A$94=$B16)*(Levels!$B$5:$B$94=2)*(COUNTIFS(Progress!$B$5:$B$3000,$A16,Progress!$G$5:$G$3000,Levels!$G$5:$G$94)>0))&" / "&COUNTIFS(Levels!$A$5:$A$94,$B16,Levels!$B$5:$B$94,2)) | G16: =IF(OR($A16="",$B16=""),"",SUMPRODUCT((Levels!$A$5:$A$94=$B16)*(Levels!$B$5:$B$94=3)*(COUNTIFS(Progress!$B$5:$B$3000,$A16,Progress!$G$5:$G$3000,Levels!$G$5:$G$94)>0))&" / "&COUNTIFS(Levels!$A$5:$A$94,$B16,Levels!$B$5:$B$94,3)) | H16: =IF(OR($A16="",$B16=""),"",SUMPRODUCT((Levels!$A$5:$A$94=$B16)*(Levels!$B$5:$B$94=4)*(COUNTIFS(Progress!$B$5:$B$3000,$A16,Progress!$G$5:$G$3000,Levels!$G$5:$G$94)>0))&" / "&COUNTIFS(Levels!$A$5:$A$94,$B16,Levels!$B$5:$B$94,4)) | I16: =IF(OR($A16="",$B16=""),"",IF(SUMPRODUCT((Levels!$A$5:$A$94=$B16)*(Levels!$B$5:$B$94=1)*(COUNTIFS(Progress!$B$5:$B$3000,$A16,Progress!$G$5:$G$3000,Levels!$G$5:$G$94)>0))<COUNTIFS(Levels!$A$5:$A$94,$B16,Levels!$B$5:$B$94,1),"1 Rookie",IF(SUMPRODUCT((Levels!$A$5:$A$94=$B16)*(Levels!$B$5:$B$94=2)*(COUNTIFS(Progress!$B$5:$B$3000,$A16,Progress!$G$5:$G$3000,Levels!$G$5:$G$94)>0))<COUNTIFS(Levels!$A$5:$A$94,$B16,Levels!$B$5:$B$94,2),"2 Contender",IF(SUMPRODUCT((Levels!$A$5:$A$94=$B16)*(Levels!$B$5:$B$94=3)*(COUNTIFS(Progress!$B$5:$B$3000,$A16,Progress!$G$5:$G$3000,Levels!$G$5:$G$94)>0))<COUNTIFS(Levels!$A$5:$A$94,$B16,Levels!$B$5:$B$94,3),"3 Challenger",IF(SUMPRODUCT((Levels!$A$5:$A$94=$B16)*(Levels!$B$5:$B$94=4)*(COUNTIFS(Progress!$B$5:$B$3000,$A16,Progress!$G$5:$G$3000,Levels!$G$5:$G$94)>0))<COUNTIFS(Levels!$A$5:$A$94,$B16,Levels!$B$5:$B$94,4),"4 Champion","All done"))))) | J16: =IF(OR(I16="",I16="All done"),"",COUNTIFS(Levels!$A$5:$A$94,$B16,Levels!$B$5:$B$94,1)*(LEFT(I16,1)="1")+COUNTIFS(Levels!$A$5:$A$94,$B16,Levels!$B$5:$B$94,2)*(LEFT(I16,1)="2")+COUNTIFS(Levels!$A$5:$A$94,$B16,Levels!$B$5:$B$94,3)*(LEFT(I16,1)="3")+COUNTIFS(Levels!$A$5:$A$94,$B16,Levels!$B$5:$B$94,4)*(LEFT(I16,1)="4")-(SUMPRODUCT((Levels!$A$5:$A$94=$B16)*(Levels!$B$5:$B$94=1)*(COUNTIFS(Progress!$B$5:$B$3000,$A16,Progress!$G$5:$G$3000,Levels!$G$5:$G$94)>0))*(LEFT(I16,1)="1")+SUMPRODUCT((Levels!$A$5:$A$94=$B16)*(Levels!$B$5:$B$94=2)*(COUNTIFS(Progress!$B$5:$B$3000,$A16,Progress!$G$5:$G$3000,Levels!$G$5:$G$94)>0))*(LEFT(I16,1)="2")+SUMPRODUCT((Levels!$A$5:$A$94=$B16)*(Levels!$B$5:$B$94=3)*(COUNTIFS(Progress!$B$5:$B$3000,$A16,Progress!$G$5:$G$3000,Levels!$G$5:$G$94)>0))*(LEFT(I16,1)="3")+SUMPRODUCT((Levels!$A$5:$A$94=$B16)*(Levels!$B$5:$B$94=4)*(COUNTIFS(Progress!$B$5:$B$3000,$A16,Progress!$G$5:$G$3000,Levels!$G$5:$G$94)>0))*(LEFT(I16,1)="4"))) | K16: =IF($A16="","",IF(COUNTIFS(Progress!$B$5:$B$3000,$A16)=0,"",SUMPRODUCT(MAX((Progress!$B$5:$B$3000=$A16)*Progress!$A$5:$A$3000))))
... E154: =IF(OR($A154="",$B154=""),"",SUMPRODUCT((Levels!$A$5:$A$94=$B154)*(Levels!$B$5:$B$94=1)*(COUNTIFS(Progress!$B$5:$B$3000,$A154,Progress!$G$5:$G$3000,Levels!$G$5:$G$94)>0))&" / "&COUNTIFS(Levels!$A$5:$A$94,$B154,Levels!$B$5:$B$94,1)) | F154: =IF(OR($A154="",$B154=""),"",SUMPRODUCT((Levels!$A$5:$A$94=$B154)*(Levels!$B$5:$B$94=2)*(COUNTIFS(Progress!$B$5:$B$3000,$A154,Progress!$G$5:$G$3000,Levels!$G$5:$G$94)>0))&" / "&COUNTIFS(Levels!$A$5:$A$94,$B154,Levels!$B$5:$B$94,2)) | G154: =IF(OR($A154="",$B154=""),"",SUMPRODUCT((Levels!$A$5:$A$94=$B154)*(Levels!$B$5:$B$94=3)*(COUNTIFS(Progress!$B$5:$B$3000,$A154,Progress!$G$5:$G$3000,Levels!$G$5:$G$94)>0))&" / "&COUNTIFS(Levels!$A$5:$A$94,$B154,Levels!$B$5:$B$94,3)) | H154: =IF(OR($A154="",$B154=""),"",SUMPRODUCT((Levels!$A$5:$A$94=$B154)*(Levels!$B$5:$B$94=4)*(COUNTIFS(Progress!$B$5:$B$3000,$A154,Progress!$G$5:$G$3000,Levels!$G$5:$G$94)>0))&" / "&COUNTIFS(Levels!$A$5:$A$94,$B154,Levels!$B$5:$B$94,4)) | I154: =IF(OR($A154="",$B154=""),"",IF(SUMPRODUCT((Levels!$A$5:$A$94=$B154)*(Levels!$B$5:$B$94=1)*(COUNTIFS(Progress!$B$5:$B$3000,$A154,Progress!$G$5:$G$3000,Levels!$G$5:$G$94)>0))<COUNTIFS(Levels!$A$5:$A$94,$B154,Levels!$B$5:$B$94,1),"1 Rookie",IF(SUMPRODUCT((Levels!$A$5:$A$94=$B154)*(Levels!$B$5:$B$94=2)*(COUNTIFS(Progress!$B$5:$B$3000,$A154,Progress!$G$5:$G$3000,Levels!$G$5:$G$94)>0))<COUNTIFS(Levels!$A$5:$A$94,$B154,Levels!$B$5:$B$94,2),"2 Contender",IF(SUMPRODUCT((Levels!$A$5:$A$94=$B154)*(Levels!$B$5:$B$94=3)*(COUNTIFS(Progress!$B$5:$B$3000,$A154,Progress!$G$5:$G$3000,Levels!$G$5:$G$94)>0))<COUNTIFS(Levels!$A$5:$A$94,$B154,Levels!$B$5:$B$94,3),"3 Challenger",IF(SUMPRODUCT((Levels!$A$5:$A$94=$B154)*(Levels!$B$5:$B$94=4)*(COUNTIFS(Progress!$B$5:$B$3000,$A154,Progress!$G$5:$G$3000,Levels!$G$5:$G$94)>0))<COUNTIFS(Levels!$A$5:$A$94,$B154,Levels!$B$5:$B$94,4),"4 Champion","All done"))))) | J154: =IF(OR(I154="",I154="All done"),"",COUNTIFS(Levels!$A$5:$A$94,$B154,Levels!$B$5:$B$94,1)*(LEFT(I154,1)="1")+COUNTIFS(Levels!$A$5:$A$94,$B154,Levels!$B$5:$B$94,2)*(LEFT(I154,1)="2")+COUNTIFS(Levels!$A$5:$A$94,$B154,Levels!$B$5:$B$94,3)*(LEFT(I154,1)="3")+COUNTIFS(Levels!$A$5:$A$94,$B154,Levels!$B$5:$B$94,4)*(LEFT(I154,1)="4")-(SUMPRODUCT((Levels!$A$5:$A$94=$B154)*(Levels!$B$5:$B$94=1)*(COUNTIFS(Progress!$B$5:$B$3000,$A154,Progress!$G$5:$G$3000,Levels!$G$5:$G$94)>0))*(LEFT(I154,1)="1")+SUMPRODUCT((Levels!$A$5:$A$94=$B154)*(Levels!$B$5:$B$94=2)*(COUNTIFS(Progress!$B$5:$B$3000,$A154,Progress!$G$5:$G$3000,Levels!$G$5:$G$94)>0))*(LEFT(I154,1)="2")+SUMPRODUCT((Levels!$A$5:$A$94=$B154)*(Levels!$B$5:$B$94=3)*(COUNTIFS(Progress!$B$5:$B$3000,$A154,Progress!$G$5:$G$3000,Levels!$G$5:$G$94)>0))*(LEFT(I154,1)="3")+SUMPRODUCT((Levels!$A$5:$A$94=$B154)*(Levels!$B$5:$B$94=4)*(COUNTIFS(Progress!$B$5:$B$3000,$A154,Progress!$G$5:$G$3000,Levels!$G$5:$G$94)>0))*(LEFT(I154,1)="4"))) | K154: =IF($A154="","",IF(COUNTIFS(Progress!$B$5:$B$3000,$A154)=0,"",SUMPRODUCT(MAX((Progress!$B$5:$B$3000=$A154)*Progress!$A$5:$A$3000))))

Sheet Progress
A1: PROGRESS
A2: One row each time a coach sees a skill done well. Pick the athlete and the skill; class and level fill in.
A4: Date passed | B4: Athlete | C4: Skill | D4: Coach | E4: Note | F4: Class | G4: Key | H4: Level
F5: =IF(B5="","",IFERROR(INDEX(Roster!$B$5:$B$154,MATCH(B5,Roster!$A$5:$A$154,0)),"Not on roster")) | G5: =IF(OR(B5="",C5=""),"",F5&" | "&C5) | H5: =IF(G5="","",IFERROR(INDEX(Levels!$C$5:$C$94,MATCH(G5,Levels!$G$5:$G$94,0)),"Not this class's skill"))
F6: =IF(B6="","",IFERROR(INDEX(Roster!$B$5:$B$154,MATCH(B6,Roster!$A$5:$A$154,0)),"Not on roster")) | G6: =IF(OR(B6="",C6=""),"",F6&" | "&C6) | H6: =IF(G6="","",IFERROR(INDEX(Levels!$C$5:$C$94,MATCH(G6,Levels!$G$5:$G$94,0)),"Not this class's skill"))
F7: =IF(B7="","",IFERROR(INDEX(Roster!$B$5:$B$154,MATCH(B7,Roster!$A$5:$A$154,0)),"Not on roster")) | G7: =IF(OR(B7="",C7=""),"",F7&" | "&C7) | H7: =IF(G7="","",IFERROR(INDEX(Levels!$C$5:$C$94,MATCH(G7,Levels!$G$5:$G$94,0)),"Not this class's skill"))
F8: =IF(B8="","",IFERROR(INDEX(Roster!$B$5:$B$154,MATCH(B8,Roster!$A$5:$A$154,0)),"Not on roster")) | G8: =IF(OR(B8="",C8=""),"",F8&" | "&C8) | H8: =IF(G8="","",IFERROR(INDEX(Levels!$C$5:$C$94,MATCH(G8,Levels!$G$5:$G$94,0)),"Not this class's skill"))
F9: =IF(B9="","",IFERROR(INDEX(Roster!$B$5:$B$154,MATCH(B9,Roster!$A$5:$A$154,0)),"Not on roster")) | G9: =IF(OR(B9="",C9=""),"",F9&" | "&C9) | H9: =IF(G9="","",IFERROR(INDEX(Levels!$C$5:$C$94,MATCH(G9,Levels!$G$5:$G$94,0)),"Not this class's skill"))
F10: =IF(B10="","",IFERROR(INDEX(Roster!$B$5:$B$154,MATCH(B10,Roster!$A$5:$A$154,0)),"Not on roster")) | G10: =IF(OR(B10="",C10=""),"",F10&" | "&C10) | H10: =IF(G10="","",IFERROR(INDEX(Levels!$C$5:$C$94,MATCH(G10,Levels!$G$5:$G$94,0)),"Not this class's skill"))
F11: =IF(B11="","",IFERROR(INDEX(Roster!$B$5:$B$154,MATCH(B11,Roster!$A$5:$A$154,0)),"Not on roster")) | G11: =IF(OR(B11="",C11=""),"",F11&" | "&C11) | H11: =IF(G11="","",IFERROR(INDEX(Levels!$C$5:$C$94,MATCH(G11,Levels!$G$5:$G$94,0)),"Not this class's skill"))
F12: =IF(B12="","",IFERROR(INDEX(Roster!$B$5:$B$154,MATCH(B12,Roster!$A$5:$A$154,0)),"Not on roster")) | G12: =IF(OR(B12="",C12=""),"",F12&" | "&C12) | H12: =IF(G12="","",IFERROR(INDEX(Levels!$C$5:$C$94,MATCH(G12,Levels!$G$5:$G$94,0)),"Not this class's skill"))
F13: =IF(B13="","",IFERROR(INDEX(Roster!$B$5:$B$154,MATCH(B13,Roster!$A$5:$A$154,0)),"Not on roster")) | G13: =IF(OR(B13="",C13=""),"",F13&" | "&C13) | H13: =IF(G13="","",IFERROR(INDEX(Levels!$C$5:$C$94,MATCH(G13,Levels!$G$5:$G$94,0)),"Not this class's skill"))
F14: =IF(B14="","",IFERROR(INDEX(Roster!$B$5:$B$154,MATCH(B14,Roster!$A$5:$A$154,0)),"Not on roster")) | G14: =IF(OR(B14="",C14=""),"",F14&" | "&C14) | H14: =IF(G14="","",IFERROR(INDEX(Levels!$C$5:$C$94,MATCH(G14,Levels!$G$5:$G$94,0)),"Not this class's skill"))
F15: =IF(B15="","",IFERROR(INDEX(Roster!$B$5:$B$154,MATCH(B15,Roster!$A$5:$A$154,0)),"Not on roster")) | G15: =IF(OR(B15="",C15=""),"",F15&" | "&C15) | H15: =IF(G15="","",IFERROR(INDEX(Levels!$C$5:$C$94,MATCH(G15,Levels!$G$5:$G$94,0)),"Not this class's skill"))
F16: =IF(B16="","",IFERROR(INDEX(Roster!$B$5:$B$154,MATCH(B16,Roster!$A$5:$A$154,0)),"Not on roster")) | G16: =IF(OR(B16="",C16=""),"",F16&" | "&C16) | H16: =IF(G16="","",IFERROR(INDEX(Levels!$C$5:$C$94,MATCH(G16,Levels!$G$5:$G$94,0)),"Not this class's skill"))
... F3000: =IF(B3000="","",IFERROR(INDEX(Roster!$B$5:$B$154,MATCH(B3000,Roster!$A$5:$A$154,0)),"Not on roster")) | G3000: =IF(OR(B3000="",C3000=""),"",F3000&" | "&C3000) | H3000: =IF(G3000="","",IFERROR(INDEX(Levels!$C$5:$C$94,MATCH(G3000,Levels!$G$5:$G$94,0)),"Not this class's skill"))

Sheet Levels
A1: LEVELS
A2: The skills for each level. Change the wording if you like, but keep each class's skills together and in level order.
A4: Class | B4: Level | C4: Level name | D4: Skill | E4: How it's checked | F4: Drill in the Coaching Library | G4: Key
A5: Kids Boxing | B5: 1 | C5: Rookie | D5: Stance and guard | E5: Holds a good stance and guard for 20 seconds while the coach checks | F5: Stance and guard | G5: =IF(D5="","",A5&" | "&D5) -> Kids Boxing | Stance and guard
A6: Kids Boxing | B6: 1 | C6: Rookie | D6: Step-drag footwork | E6: Steps forward, back, left and right without crossing the feet | F6: Step-drag footwork | G6: =IF(D6="","",A6&" | "&D6) -> Kids Boxing | Step-drag footwork
A7: Kids Boxing | B7: 1 | C7: Rookie | D7: Jab on pads | E7: 10 jabs on the pads, each one back to the guard | F7: Jab on pads | G7: =IF(D7="","",A7&" | "&D7) -> Kids Boxing | Jab on pads
A8: Kids Boxing | B8: 1 | C8: Rookie | D8: Rope-less skipping | E8: 30 seconds of jump-rope footwork (no rope) | F8: Jump rope | G8: =IF(D8="","",A8&" | "&D8) -> Kids Boxing | Rope-less skipping
A9: Kids Boxing | B9: 1 | C9: Rookie | D9: Gym rules | E9: Stops on the whistle, takes water breaks, puts gloves on and off safely | G9: =IF(D9="","",A9&" | "&D9) -> Kids Boxing | Gym rules
A10: Kids Boxing | B10: 2 | C10: Contender | D10: 1-2 on pads | E10: Jab-cross on the pads with the back foot pivoting | F10: 1-2 on pads | G10: =IF(D10="","",A10&" | "&D10) -> Kids Boxing | 1-2 on pads
A11: Kids Boxing | B11: 2 | C11: Contender | D11: Footwork ladder | E11: One ladder pattern start to finish without stopping | F11: Footwork ladder and cones | G11: =IF(D11="","",A11&" | "&D11) -> Kids Boxing | Footwork ladder
A12: Kids Boxing | B12: 2 | C12: Contender | D12: Slips | E12: Slips left and right along the slip line | F12: Slip line | G12: =IF(D12="","",A12&" | "&D12) -> Kids Boxing | Slips
A13: Kids Boxing | B13: 2 | C13: Contender | D13: Bag round | E13: One 1-minute heavy bag round with the guard up | F13: Heavy bag rounds | G13: =IF(D13="","",A13&" | "&D13) -> Kids Boxing | Bag round
A14: Kids Boxing | B14: 2 | C14: Contender | D14: Glove tag | E14: Stays in stance for a whole round of glove tag | F14: Glove tag | G14: =IF(D14="","",A14&" | "&D14) -> Kids Boxing | Glove tag
A15: Kids Boxing | B15: 3 | C15: Challenger | D15: Jab-step-jab | E15: Jab, step in, jab on the pads | F15: Jab on pads | G15: =IF(D15="","",A15&" | "&D15) -> Kids Boxing | Jab-step-jab
A16: Kids Boxing | B16: 3 | C16: Challenger | D16: Slip and counter | E16: Slips, then jabs straight back, on the slip line | F16: Slip line | G16: =IF(D16="","",A16&" | "&D16) -> Kids Boxing | Slip and counter
A17: Kids Boxing | B17: 3 | C17: Challenger | D17: Bob and weave | E17: Ducks under the low rope with the knees, guard up | F17: Bob and weave under the rope | G17: =IF(D17="","",A17&" | "&D17) -> Kids Boxing | Bob and weave
A18: Kids Boxing | B18: 3 | C18: Challenger | D18: Pad target speed | E18: Hits the right pad on the coach's call, quickly and cleanly | F18: Pad target game | G18: =IF(D18="","",A18&" | "&D18) -> Kids Boxing | Pad target speed
A19: Kids Boxing | B19: 3 | C19: Challenger | D19: Two bag rounds | E19: Two 1-minute bag rounds with good stance | F19: Heavy bag rounds | G19: =IF(D19="","",A19&" | "&D19) -> Kids Boxing | Two bag rounds
A20: Kids Boxing | B20: 4 | C20: Champion | D20: Combination | E20: 1-2, slip, 1-2 on the pads | F20: 1-2 on pads | G20: =IF(D20="","",A20&" | "&D20) -> Kids Boxing | Combination
A21: Kids Boxing | B21: 4 | C21: Champion | D21: Pivots | E21: Pivots and changes direction on the coach's call | F21: Follow the leader footwork | G21: =IF(D21="","",A21&" | "&D21) -> Kids Boxing | Pivots
... A41: Wrestling | B41: 4 | C41: Champion | D41: Pin with control | E41: Holds a pin for 3 seconds with control | F41: Half nelson turn | G41: =IF(D41="","",A41&" | "&D41) -> Wrestling | Pin with control
A42: Wrestling | B42: 4 | C42: Champion | D42: Sportsmanship | E42: Shakes hands, follows the coach's calls, wins and loses well | G42: =IF(D42="","",A42&" | "&D42) -> Wrestling | Sportsmanship
A43: Wrestling | B43: 4 | C43: Champion | D43: Teaches breakfalls | E43: Shows a newer kid the back breakfall | F43: Breakfalls | G43: =IF(D43="","",A43&" | "&D43) -> Wrestling | Teaches breakfalls
A44: Wrestling | B44: 4 | C44: Champion | D44: Conditioning | E44: 10 sprawls back to stance in 30 seconds | F44: Sprawl drill | G44: =IF(D44="","",A44&" | "&D44) -> Wrestling | Conditioning
A45: Boxing 11-14 | B45: 1 | C45: Rookie | D45: Stance and guard | E45: Good stance and guard, weight on the balls of the feet | F45: Stance and guard | G45: =IF(D45="","",A45&" | "&D45) -> Boxing 11-14 | Stance and guard
A46: Boxing 11-14 | B46: 1 | C46: Rookie | D46: Footwork | E46: Step-drag in all four directions in stance | F46: Step-drag footwork | G46: =IF(D46="","",A46&" | "&D46) -> Boxing 11-14 | Footwork
A47: Boxing 11-14 | B47: 1 | C47: Rookie | D47: Jab and 1-2 | E47: Jab and 1-2 on the pads with the hands back to the face | F47: 1-2 on pads | G47: =IF(D47="","",A47&" | "&D47) -> Boxing 11-14 | Jab and 1-2
A48: Boxing 11-14 | B48: 1 | C48: Rookie | D48: Rope-less skipping | E48: Two minutes of jump-rope footwork (no rope) | F48: Jump rope | G48: =IF(D48="","",A48&" | "&D48) -> Boxing 11-14 | Rope-less skipping
A49: Boxing 11-14 | B49: 1 | C49: Rookie | D49: Wraps and rules | E49: Wraps own hands correctly and knows the gym's safety rules | G49: =IF(D49="","",A49&" | "&D49) -> Boxing 11-14 | Wraps and rules
A50: Boxing 11-14 | B50: 2 | C50: Contender | D50: 1-2-3 | E50: Jab, cross, lead hook on the pads | F50: 1-2-3 on pads | G50: =IF(D50="","",A50&" | "&D50) -> Boxing 11-14 | 1-2-3
A51: Boxing 11-14 | B51: 2 | C51: Contender | D51: Called combinations | E51: Throws the coach's called combinations without dropping the hands | F51: Coach-called combinations | G51: =IF(D51="","",A51&" | "&D51) -> Boxing 11-14 | Called combinations
A52: Boxing 11-14 | B52: 2 | C52: Contender | D52: Slip and counter | E52: Slips both sides on the line with a counter | F52: Slip line | G52: =IF(D52="","",A52&" | "&D52) -> Boxing 11-14 | Slip and counter
A53: Boxing 11-14 | B53: 2 | C53: Contender | D53: Bag rounds | E53: Two 2-minute bag rounds | F53: Heavy bag rounds | G53: =IF(D53="","",A53&" | "&D53) -> Boxing 11-14 | Bag rounds
A54: Boxing 11-14 | B54: 2 | C54: Contender | D54: Footwork ladder | E54: Ladder patterns at speed, guard up | F54: Footwork ladder and cones | G54: =IF(D54="","",A54&" | "&D54) -> Boxing 11-14 | Footwork ladder
A55: Boxing 11-14 | B55: 3 | C55: Challenger | D55: Bob and weave | E55: Bob and weave under the rope with the knees | F55: Bob and weave under the rope | G55: =IF(D55="","",A55&" | "&D55) -> Boxing 11-14 | Bob and weave
A56: Boxing 11-14 | B56: 3 | C56: Challenger | D56: Body touch control | E56: Body-only touch drill: stays light and in control | F56: Body-only partner touch | G56: =IF(D56="","",A56&" | "&D56) -> Boxing 11-14 | Body touch control
