Workbook

Sheet Start Here
A1: CCCL MARKETING KIT
A2: How each show sells out: the campaign week by week, where tickets come from, whether ads are worth it, posters, the shot list and the Canva kit. Built for Cody Purtell by Kyle. Opens in Google Sheets or Excel.
B4: IN ORDER
A5: 1 | B5: Show Setup | C5: Show date, ticket link, CCCL's pages, and the numbers that decide if an ad is worth it.
A6: 2 | B6: Campaign | C6: Every post, poster, press release and push from 16 weeks out to the highlight video after. Dates follow the show date.
A7: 3 | B7: Ticket Sources | C7: One Eventbrite tracking link or code per source (each fighter, posters, each ad...). Copy the sales in weekly to see what works.
A8: 4 | B8: Ads | C8: Optional. Test small, keep only ads that sell tickets under the target cost, stop the rest.
A9: 5 | B9: Livestream | C9: What a paid stream could bring in (Eventbrite online ticket or Dacast), and the other options with their risks.
A10: 6 | B10: Poster Drop | C10: Where the posters go in the show town, and when they come down.
A11: 7 | B11: Shot List | C11: Photos and video to get on fight night, and whose OK each one needs.
A12: 8 | B12: Canva Kit | C12: CCCL colours, fonts and sizes, and the starter designs to import into Canva.
B14: THE BIG IDEAS
B15: Fighters sell tickets | C15: In 2026 fighters told friends and family informally. Give each one a personal link and a promo pack, and track it: it's usually the biggest source at amateur shows.
B16: Measure everything | C16: If a post, poster or ad doesn't have its own link or code, you can't tell if it worked.
B17: Ads only if they pay | C17: Every paid ticket is worth about $73 to CCCL. An ad is only worth running if it sells tickets for well under that.
B18: Real numbers only | C18: 400 tickets and 15 sponsors at the first show are real. Never post made-up crowd or viewer numbers.
B19: Kids | C19: No youth athletes in ads. Photos or video of kids only with a parent's written OK. Never name anyone under 18 in a press release.
B21: WORKS WITH
B22: Fight Night Kit | C22: Same show date. Press list, fighters and the Results & Report tab.
B23: Constrictor HQ | C23: Drafted posts go on the Content Calendar and wait on the Approvals tab for Cody's OK.
B24: Claude | C24: The bbg-cccl-social skill drafts the whole campaign, captions and fighter promo packs from this sheet.

Sheet Show Setup
A1: SHOW SETUP
A2: Fill this in once per show. The campaign dates and the 'worth it' checks use these numbers.
A4: THE SHOW
A5: Show name | B5: CCCL 2
A6: Town | D6: Fill in once the show is booked; use the same town and date as the Fight Night Kit.
A7: Show date | D7: Fill in once the show is booked: the campaign dates follow it. Until then they stay blank.
A8: Eventbrite ticket link | D8: The main link. Every source on the Ticket Sources tab gets its own tracking link or code.
A9: CCCL Facebook page | D9: CCCL's own page (Kyle, Oct 2026).
A10: CCCL Instagram | D10: CCCL's own account.
A11: Hashtags | B11: #CCCL #CottageCountryCombatLeague #AmateurMMA | D11: Add the town: #Haliburton, #Peterborough, #Kingston...
A13: IS A PAID AD WORTH IT?
A14: Money CCCL keeps per paid ticket ($) | B14: 73 | D14: From the Profit Predictor (Compare tab, 'Total per paid ticket'). About $73 at 2026 prices after Eventbrite's Canadian fees (3.5% + $1.29 per ticket, plus 2.9% processing).
A15: Most you'll pay in ads to sell one ticket ($) | B15: 20 | D15: STARTING POINT. Below $73 the ad pays for itself on paper, but some of those buyers would have come anyway, so aim well under it. Raise it if ads clearly bring new people.
A16: First test budget per ad ($) | B16: 50 | D16: Spend a little, check the tickets on that ad's tracking link after a week, then keep or stop.

Sheet Campaign
A1: SHOW CAMPAIGN
A2: Everything that sells tickets, week by week. Dates follow Show Setup. Every post needs Cody's OK (Approvals tab in Constrictor HQ). Matches the Countdown tab in the Fight Night Kit.
A4: Weeks before (minus = days after) | B4: Date | C4: Channel | D4: What to do | E4: Graphic / asset | F4: Owner | G4: Status | H4: Notes
A5: 16 | B5: =IF('Show Setup'!$B$7="","",IF(A5>=0,'Show Setup'!$B$7-A5*7,'Show Setup'!$B$7-A5)) | C5: CCCL Facebook + Instagram | D5: Save the date: town, venue, date. Share to BBG's pages. | E5: 01 (as Save the date) + 02 story | F5: Kyle | G5: To do
A6: 16 | B6: =IF('Show Setup'!$B$7="","",IF(A6>=0,'Show Setup'!$B$7-A6*7,'Show Setup'!$B$7-A6)) | C6: Facebook event | D6: Create the Facebook event on the CCCL page; ask BBG, the venue and sponsors to co-host or share. | E6: 09 Facebook event cover | F6: Kyle | G6: To do
A7: 14 | B7: =IF('Show Setup'!$B$7="","",IF(A7>=0,'Show Setup'!$B$7-A7*7,'Show Setup'!$B$7-A7)) | C7: Eventbrite | D7: Tickets on sale. Make a tracking link for every source on the Ticket Sources tab (Marketing > Tracking links) before sharing anything. Add the Meta Pixel (Marketing > Tracking pixels) if you'll run ads. | F7: Kyle | G7: To do
A8: 14 | B8: =IF('Show Setup'!$B$7="","",IF(A8>=0,'Show Setup'!$B$7-A8*7,'Show Setup'!$B$7-A8)) | C8: CCCL Facebook + Instagram | D8: Tickets on sale post with prices and the link. Pin it. | E8: 01 Tickets on sale + 02 story | F8: Kyle | G8: To do
A9: 14 | B9: =IF('Show Setup'!$B$7="","",IF(A9>=0,'Show Setup'!$B$7-A9*7,'Show Setup'!$B$7-A9)) | C9: Press | D9: Release 1: show announced (Fight Night Kit, Press tab). | F9: Cody | G9: To do
A10: 14 | B10: =IF('Show Setup'!$B$7="","",IF(A10>=0,'Show Setup'!$B$7-A10*7,'Show Setup'!$B$7-A10)) | C10: Community calendars | D10: List the show on kawarthaNOW, Moose FM and the town's event calendar. | F10: Kyle | G10: To do
A11: 14 | B11: =IF('Show Setup'!$B$7="","",IF(A11>=0,'Show Setup'!$B$7-A11*7,'Show Setup'!$B$7-A11)) | C11: Email | D11: Email last show's ticket buyers from Eventbrite (Marketing > Email your audience; up to 250 emails a day). | F11: Kyle | G11: To do
A12: 13 | B12: =IF('Show Setup'!$B$7="","",IF(A12>=0,'Show Setup'!$B$7-A12*7,'Show Setup'!$B$7-A12)) | C12: CCCL Facebook + Instagram | D12: Sponsors wanted: 'put your business cage-side' with the sponsor sheet. | E12: Sponsors wanted | F12: Kyle | G12: To do
A13: 12 | B13: =IF('Show Setup'!$B$7="","",IF(A13>=0,'Show Setup'!$B$7-A13*7,'Show Setup'!$B$7-A13)) | C13: CCCL Facebook + Instagram | D13: Fighters wanted: Ontario gyms, link to the sign-up form. | E13: Fighters wanted | F13: Kyle | G13: To do
A14: 12 | B14: =IF('Show Setup'!$B$7="","",IF(A14>=0,'Show Setup'!$B$7-A14*7,'Show Setup'!$B$7-A14)) | C14: Gym (BBG) | D14: Members and families: group-ticket push at the gym and in the members' chat. | F14: Cody | G14: To do
A15: 10 | B15: =IF('Show Setup'!$B$7="","",IF(A15>=0,'Show Setup'!$B$7-A15*7,'Show Setup'!$B$7-A15)) | C15: Posters | D15: Posters up around town with a QR code to the posters' tracking link (Poster Drop tab). | E15: 03 Poster (11x17 and letter) | F15: Volunteer | G15: To do
A16: 10 | B16: =IF('Show Setup'!$B$7="","",IF(A16>=0,'Show Setup'!$B$7-A16*7,'Show Setup'!$B$7-A16)) | C16: Shorts / Reels / TikTok | D16: Behind the scenes: Cody training, the venue, why this town. 30-60 seconds. | F16: Kyle | G16: To do
A17: 8 | B17: =IF('Show Setup'!$B$7="","",IF(A17>=0,'Show Setup'!$B$7-A17*7,'Show Setup'!$B$7-A17)) | C17: Paid ads (optional) | D17: Ad test 1: small budget, its own tracking link. Check after a week (Ads tab). | E17: Ad image | F17: Kyle | G17: To do
A18: 8 | B18: =IF('Show Setup'!$B$7="","",IF(A18>=0,'Show Setup'!$B$7-A18*7,'Show Setup'!$B$7-A18)) | C18: CCCL Facebook + Instagram | D18: Thank-you post for sponsors signed so far (only what their package includes). | E18: 07 Sponsor thank-you | F18: Kyle | G18: To do
A19: 6 | B19: =IF('Show Setup'!$B$7="","",IF(A19>=0,'Show Setup'!$B$7-A19*7,'Show Setup'!$B$7-A19)) | C19: Fighters | D19: Send each confirmed fighter their Fighter Package (through the coach) and adults their promo pack: personal ticket link, ready-made posts, graphics. | E19: 11 + 12 I'm fighting (each adult) | F19: Cody | G19: To do
A20: 6 | B20: =IF('Show Setup'!$B$7="","",IF(A20>=0,'Show Setup'!$B$7-A20*7,'Show Setup'!$B$7-A20)) | C20: CCCL Facebook + Instagram | D20: Fighter spotlights start: one or two a week, adults who agree only. | E20: 06 Fighter spotlight | F20: Kyle | G20: To do
A21: 5 | B21: =IF('Show Setup'!$B$7="","",IF(A21>=0,'Show Setup'!$B$7-A21*7,'Show Setup'!$B$7-A21)) | C21: Radio | D21: Pitch an interview or event listing to local radio (Moose FM, Quinte News...). | F21: Cody | G21: To do
A22: 4 | B22: =IF('Show Setup'!$B$7="","",IF(A22>=0,'Show Setup'!$B$7-A22*7,'Show Setup'!$B$7-A22)) | C22: CCCL Facebook + Instagram | D22: Fight card announced: official bouts only, adults only by name. Swap the early posters for the main-event poster. | E22: 04 + 16 card, 05 vs, 10 poster | F22: Kyle | G22: To do
A23: 4 | B23: =IF('Show Setup'!$B$7="","",IF(A23>=0,'Show Setup'!$B$7-A23*7,'Show Setup'!$B$7-A23)) | C23: Press | D23: Release 2: the card (Fight Night Kit, Press tab). | F23: Cody | G23: To do
A24: 4 | B24: =IF('Show Setup'!$B$7="","",IF(A24>=0,'Show Setup'!$B$7-A24*7,'Show Setup'!$B$7-A24)) | C24: Sponsors | D24: Individual posts for Title, Gold and Silver; one group post for Bronze and Community. Send each sponsor a share kit. | E24: 15 Proud sponsor | F24: Kyle | G24: To do
A25: 3 | B25: =IF('Show Setup'!$B$7="","",IF(A25>=0,'Show Setup'!$B$7-A25*7,'Show Setup'!$B$7-A25)) | C25: Paid ads (optional) | D25: Scale only ads under the target cost per ticket; stop the rest. | F25: Kyle | G25: To do
A26: 3 | B26: =IF('Show Setup'!$B$7="","",IF(A26>=0,'Show Setup'!$B$7-A26*7,'Show Setup'!$B$7-A26)) | C26: Stories | D26: Countdown stories: 21, 14, 7 days. | E26: 02 Countdown story | F26: Kyle | G26: To do
A27: 2 | B27: =IF('Show Setup'!$B$7="","",IF(A27>=0,'Show Setup'!$B$7-A27*7,'Show Setup'!$B$7-A27)) | C27: CCCL Facebook + Instagram | D27: VIP tables or tickets running low, only if it's true (Ticket Tracker). | F27: Kyle | G27: To do
A28: 2 | B28: =IF('Show Setup'!$B$7="","",IF(A28>=0,'Show Setup'!$B$7-A28*7,'Show Setup'!$B$7-A28)) | C28: CCCL Facebook + Instagram | D28: Livestream link announced for people who can't come. | E28: Livestream | F28: Kyle | G28: To do
A29: 1 | B29: =IF('Show Setup'!$B$7="","",IF(A29>=0,'Show Setup'!$B$7-A29*7,'Show Setup'!$B$7-A29)) | C29: CCCL Facebook + Instagram | D29: Fight week: final card graphic, doors time, parking, what to bring. | E29: 16 Fight card story | F29: Kyle | G29: To do
A30: 1 | B30: =IF('Show Setup'!$B$7="","",IF(A30>=0,'Show Setup'!$B$7-A30*7,'Show Setup'!$B$7-A30)) | C30: Fighters + gyms | D30: Fight week reminder to every fighter and coach to share their link one last time. | F30: Cody | G30: To do
A31: 0 | B31: =IF('Show Setup'!$B$7="","",IF(A31>=0,'Show Setup'!$B$7-A31*7,'Show Setup'!$B$7-A31)) | C31: Stories / live | D31: Show day: weigh-in results post once weigh-ins are done, 'doors at 6', clips between bouts. No youth without a parent's OK. | E31: 13 Weigh-in results | F31: Kyle | G31: To do
A32: -1 | B32: =IF('Show Setup'!$B$7="","",IF(A32>=0,'Show Setup'!$B$7-A32*7,'Show Setup'!$B$7-A32)) | C32: CCCL Facebook + Instagram | D32: The day after: official results and thank-you to fighters, officials, medical staff, volunteers, venue. | E32: 08 Results | F32: Kyle | G32: To do
A33: -1 | B33: =IF('Show Setup'!$B$7="","",IF(A33>=0,'Show Setup'!$B$7-A33*7,'Show Setup'!$B$7-A33)) | C33: Fighters | D33: The day after: each adult fighter's result post: WIN, or THANK YOU for a loss. Official results only. | E33: 14 Win (each adult) | F33: Kyle | G33: To do
A34: -1 | B34: =IF('Show Setup'!$B$7="","",IF(A34>=0,'Show Setup'!$B$7-A34*7,'Show Setup'!$B$7-A34)) | C34: Press | D34: The day after: Release 3, results (official only). | F34: Cody | G34: To do
A35: -3 | B35: =IF('Show Setup'!$B$7="","",IF(A35>=0,'Show Setup'!$B$7-A35*7,'Show Setup'!$B$7-A35)) | C35: Sponsors | D35: Thank-you posts with photos of their banners and logos (within 3 days). | E35: 07 Sponsor thank-you | F35: Kyle | G35: To do
A36: -7 | B36: =IF('Show Setup'!$B$7="","",IF(A36>=0,'Show Setup'!$B$7-A36*7,'Show Setup'!$B$7-A36)) | C36: YouTube + Shorts / Reels | D36: Highlight video and clips; 'next show' teaser. | E36: Thumbnail | F36: Kyle | G36: To do
A37: -7 | B37: =IF('Show Setup'!$B$7="","",IF(A37>=0,'Show Setup'!$B$7-A37*7,'Show Setup'!$B$7-A37)) | C37: Report | D37: Which sources sold tickets (Ticket Sources tab) into the Fight Night Kit's Results & Report. | F37: Kyle | G37: To do
B38: =IF(OR(A38="",'Show Setup'!$B$7=""),"",IF(A38>=0,'Show Setup'!$B$7-A38*7,'Show Setup'!$B$7-A38))
B39: =IF(OR(A39="",'Show Setup'!$B$7=""),"",IF(A39>=0,'Show Setup'!$B$7-A39*7,'Show Setup'!$B$7-A39))
B40: =IF(OR(A40="",'Show Setup'!$B$7=""),"",IF(A40>=0,'Show Setup'!$B$7-A40*7,'Show Setup'!$B$7-A40))
B41: =IF(OR(A41="",'Show Setup'!$B$7=""),"",IF(A41>=0,'Show Setup'!$B$7-A41*7,'Show Setup'!$B$7-A41))
...

Sheet Ticket Sources
A1: WHERE THE TICKETS CAME FROM
A2: Give every source its own Eventbrite tracking link (Marketing > Tracking links), then copy the sales per link in each week (Reporting > Tracking links). That's how you find out which posts, posters, fighters and ads actually sell tickets.
A4: Total tickets sold (from Eventbrite) | D4: Share with a known source | F4: =IF(N(B4)=0,"",B5/B4)
A5: Tickets with a known source | B5: =SUM(E8:E87) -> 0 | D5: Use tracking links, not promo codes: an Eventbrite promo code has to give a discount or unlock a hidden ticket. Sponsor tickets: add them as Complimentary attendees (Manage Attendees > Add Attendees), which has no fees.
A7: Source | B7: Type | C7: Tracking link or code | D7: Cost ($) | E7: Tickets sold | F7: Ticket money ($) | G7: Cost per ticket | H7: Worth it? | I7: Notes
A8: CCCL Facebook (posts and event) | B8: Social (free) | G8: =IF(OR(N(D8)=0,N(E8)=0),"",D8/E8) | H8: =IF(A8="","",IF(N(D8)=0,IF(N(E8)>0,"Free",""),IF(N(E8)=0,"No sales yet",IF(G8<='Show Setup'!$B$15,"Worth it",IF(G8<='Show Setup'!$B$14,"Pays, barely","Not worth it")))))
A9: CCCL Instagram | B9: Social (free) | G9: =IF(OR(N(D9)=0,N(E9)=0),"",D9/E9) | H9: =IF(A9="","",IF(N(D9)=0,IF(N(E9)>0,"Free",""),IF(N(E9)=0,"No sales yet",IF(G9<='Show Setup'!$B$15,"Worth it",IF(G9<='Show Setup'!$B$14,"Pays, barely","Not worth it")))))
A10: BBG Facebook + Instagram | B10: Social (free) | G10: =IF(OR(N(D10)=0,N(E10)=0),"",D10/E10) | H10: =IF(A10="","",IF(N(D10)=0,IF(N(E10)>0,"Free",""),IF(N(E10)=0,"No sales yet",IF(G10<='Show Setup'!$B$15,"Worth it",IF(G10<='Show Setup'!$B$14,"Pays, barely","Not worth it")))))
A11: Cody's page (Facebook + Instagram) | B11: Social (free) | G11: =IF(OR(N(D11)=0,N(E11)=0),"",D11/E11) | H11: =IF(A11="","",IF(N(D11)=0,IF(N(E11)>0,"Free",""),IF(N(E11)=0,"No sales yet",IF(G11<='Show Setup'!$B$15,"Worth it",IF(G11<='Show Setup'!$B$14,"Pays, barely","Not worth it")))))
A12: Posters (QR code) | B12: Poster | G12: =IF(OR(N(D12)=0,N(E12)=0),"",D12/E12) | H12: =IF(A12="","",IF(N(D12)=0,IF(N(E12)>0,"Free",""),IF(N(E12)=0,"No sales yet",IF(G12<='Show Setup'!$B$15,"Worth it",IF(G12<='Show Setup'!$B$14,"Pays, barely","Not worth it")))))
A13: Press releases | B13: Press / radio | G13: =IF(OR(N(D13)=0,N(E13)=0),"",D13/E13) | H13: =IF(A13="","",IF(N(D13)=0,IF(N(E13)>0,"Free",""),IF(N(E13)=0,"No sales yet",IF(G13<='Show Setup'!$B$15,"Worth it",IF(G13<='Show Setup'!$B$14,"Pays, barely","Not worth it")))))
A14: Radio | B14: Press / radio | G14: =IF(OR(N(D14)=0,N(E14)=0),"",D14/E14) | H14: =IF(A14="","",IF(N(D14)=0,IF(N(E14)>0,"Free",""),IF(N(E14)=0,"No sales yet",IF(G14<='Show Setup'!$B$15,"Worth it",IF(G14<='Show Setup'!$B$14,"Pays, barely","Not worth it")))))
A15: Community calendars | B15: Calendar | G15: =IF(OR(N(D15)=0,N(E15)=0),"",D15/E15) | H15: =IF(A15="","",IF(N(D15)=0,IF(N(E15)>0,"Free",""),IF(N(E15)=0,"No sales yet",IF(G15<='Show Setup'!$B$15,"Worth it",IF(G15<='Show Setup'!$B$14,"Pays, barely","Not worth it")))))
A16: Email to past buyers | B16: Email | G16: =IF(OR(N(D16)=0,N(E16)=0),"",D16/E16) | H16: =IF(A16="","",IF(N(D16)=0,IF(N(E16)>0,"Free",""),IF(N(E16)=0,"No sales yet",IF(G16<='Show Setup'!$B$15,"Worth it",IF(G16<='Show Setup'!$B$14,"Pays, barely","Not worth it")))))
A17: BBG members | B17: Gym | G17: =IF(OR(N(D17)=0,N(E17)=0),"",D17/E17) | H17: =IF(A17="","",IF(N(D17)=0,IF(N(E17)>0,"Free",""),IF(N(E17)=0,"No sales yet",IF(G17<='Show Setup'!$B$15,"Worth it",IF(G17<='Show Setup'!$B$14,"Pays, barely","Not worth it")))))
A18: Fighter: [name] | B18: Fighter | G18: =IF(OR(N(D18)=0,N(E18)=0),"",D18/E18) | H18: =IF(A18="","",IF(N(D18)=0,IF(N(E18)>0,"Free",""),IF(N(E18)=0,"No sales yet",IF(G18<='Show Setup'!$B$15,"Worth it",IF(G18<='Show Setup'!$B$14,"Pays, barely","Not worth it")))))
A19: Fighter: [name] | B19: Fighter | G19: =IF(OR(N(D19)=0,N(E19)=0),"",D19/E19) | H19: =IF(A19="","",IF(N(D19)=0,IF(N(E19)>0,"Free",""),IF(N(E19)=0,"No sales yet",IF(G19<='Show Setup'!$B$15,"Worth it",IF(G19<='Show Setup'!$B$14,"Pays, barely","Not worth it")))))
... A49: Walk-up at the door | B49: Walk-up | G49: =IF(OR(N(D49)=0,N(E49)=0),"",D49/E49) | H49: =IF(A49="","",IF(N(D49)=0,IF(N(E49)>0,"Free",""),IF(N(E49)=0,"No sales yet",IF(G49<='Show Setup'!$B$15,"Worth it",IF(G49<='Show Setup'!$B$14,"Pays, barely","Not worth it")))))
G50: =IF(OR(N(D50)=0,N(E50)=0),"",D50/E50) | H50: =IF(A50="","",IF(N(D50)=0,IF(N(E50)>0,"Free",""),IF(N(E50)=0,"No sales yet",IF(G50<='Show Setup'!$B$15,"Worth it",IF(G50<='Show Setup'!$B$14,"Pays, barely","Not worth it")))))
G51: =IF(OR(N(D51)=0,N(E51)=0),"",D51/E51) | H51: =IF(A51="","",IF(N(D51)=0,IF(N(E51)>0,"Free",""),IF(N(E51)=0,"No sales yet",IF(G51<='Show Setup'!$B$15,"Worth it",IF(G51<='Show Setup'!$B$14,"Pays, barely","Not worth it")))))
G52: =IF(OR(N(D52)=0,N(E52)=0),"",D52/E52) | H52: =IF(A52="","",IF(N(D52)=0,IF(N(E52)>0,"Free",""),IF(N(E52)=0,"No sales yet",IF(G52<='Show Setup'!$B$15,"Worth it",IF(G52<='Show Setup'!$B$14,"Pays, barely","Not worth it")))))
G53: =IF(OR(N(D53)=0,N(E53)=0),"",D53/E53) | H53: =IF(A53="","",IF(N(D53)=0,IF(N(E53)>0,"Free",""),IF(N(E53)=0,"No sales yet",IF(G53<='Show Setup'!$B$15,"Worth it",IF(G53<='Show Setup'!$B$14,"Pays, barely","Not worth it")))))
G54: =IF(OR(N(D54)=0,N(E54)=0),"",D54/E54) | H54: =IF(A54="","",IF(N(D54)=0,IF(N(E54)>0,"Free",""),IF(N(E54)=0,"No sales yet",IF(G54<='Show Setup'!$B$15,"Worth it",IF(G54<='Show Setup'!$B$14,"Pays, barely","Not worth it")))))
G55: =IF(OR(N(D55)=0,N(E55)=0),"",D55/E55) | H55: =IF(A55="","",IF(N(D55)=0,IF(N(E55)>0,"Free",""),IF(N(E55)=0,"No sales yet",IF(G55<='Show Setup'!$B$15,"Worth it",IF(G55<='Show Setup'!$B$14,"Pays, barely","Not worth it")))))
G56: =IF(OR(N(D56)=0,N(E56)=0),"",D56/E56) | H56: =IF(A56="","",IF(N(D56)=0,IF(N(E56)>0,"Free",""),IF(N(E56)=0,"No sales yet",IF(G56<='Show Setup'!$B$15,"Worth it",IF(G56<='Show Setup'!$B$14,"Pays, barely","Not worth it")))))
G57: =IF(OR(N(D57)=0,N(E57)=0),"",D57/E57) | H57: =IF(A57="","",IF(N(D57)=0,IF(N(E57)>0,"Free",""),IF(N(E57)=0,"No sales yet",IF(G57<='Show Setup'!$B$15,"Worth it",IF(G57<='Show Setup'!$B$14,"Pays, barely","Not worth it")))))
G58: =IF(OR(N(D58)=0,N(E58)=0),"",D58/E58) | H58: =IF(A58="","",IF(N(D58)=0,IF(N(E58)>0,"Free",""),IF(N(E58)=0,"No sales yet",IF(G58<='Show Setup'!$B$15,"Worth it",IF(G58<='Show Setup'!$B$14,"Pays, barely","Not worth it")))))
G59: =IF(OR(N(D59)=0,N(E59)=0),"",D59/E59) | H59: =IF(A59="","",IF(N(D59)=0,IF(N(E59)>0,"Free",""),IF(N(E59)=0,"No sales yet",IF(G59<='Show Setup'!$B$15,"Worth it",IF(G59<='Show Setup'!$B$14,"Pays, barely","Not worth it")))))
G60: =IF(OR(N(D60)=0,N(E60)=0),"",D60/E60) | H60: =IF(A60="","",IF(N(D60)=0,IF(N(E60)>0,"Free",""),IF(N(E60)=0,"No sales yet",IF(G60<='Show Setup'!$B$15,"Worth it",IF(G60<='Show Setup'!$B$14,"Pays, barely","Not worth it")))))
G61: =IF(OR(N(D61)=0,N(E61)=0),"",D61/E61) | H61: =IF(A61="","",IF(N(D61)=0,IF(N(E61)>0,"Free",""),IF(N(E61)=0,"No sales yet",IF(G61<='Show Setup'!$B$15,"Worth it",IF(G61<='Show Setup'!$B$14,"Pays, barely","Not worth it")))))
... G87: =IF(OR(N(D87)=0,N(E87)=0),"",D87/E87) | H87: =IF(A87="","",IF(N(D87)=0,IF(N(E87)>0,"Free",""),IF(N(E87)=0,"No sales yet",IF(G87<='Show Setup'!$B$15,"Worth it",IF(G87<='Show Setup'!$B$14,"Pays, barely","Not worth it")))))
A90: BY TYPE
A91: Type | B91: Tickets | C91: Cost ($) | D91: Cost per ticket
A92: Social (free) | B92: =SUMIF($B$8:$B$87,A92,$E$8:$E$87) -> 0 | C92: =SUMIF($B$8:$B$87,A92,$D$8:$D$87) -> 0 | D92: =IF(OR(C92=0,B92=0),"",C92/B92)
A93: Fighter | B93: =SUMIF($B$8:$B$87,A93,$E$8:$E$87) -> 0 | C93: =SUMIF($B$8:$B$87,A93,$D$8:$D$87) -> 0 | D93: =IF(OR(C93=0,B93=0),"",C93/B93)
A94: Gym | B94: =SUMIF($B$8:$B$87,A94,$E$8:$E$87) -> 0 | C94: =SUMIF($B$8:$B$87,A94,$D$8:$D$87) -> 0 | D94: =IF(OR(C94=0,B94=0),"",C94/B94)
A95: Sponsor | B95: =SUMIF($B$8:$B$87,A95,$E$8:$E$87) -> 0 | C95: =SUMIF($B$8:$B$87,A95,$D$8:$D$87) -> 0 | D95: =IF(OR(C95=0,B95=0),"",C95/B95)
A96: Ad | B96: =SUMIF($B$8:$B$87,A96,$E$8:$E$87) -> 0 | C96: =SUMIF($B$8:$B$87,A96,$D$8:$D$87) -> 0 | D96: =IF(OR(C96=0,B96=0),"",C96/B96)
A97: Poster | B97: =SUMIF($B$8:$B$87,A97,$E$8:$E$87) -> 0 | C97: =SUMIF($B$8:$B$87,A97,$D$8:$D$87) -> 0 | D97: =IF(OR(C97=0,B97=0),"",C97/B97)
A98: Press / radio | B98: =SUMIF($B$8:$B$87,A98,$E$8:$E$87) -> 0 | C98: =SUMIF($B$8:$B$87,A98,$D$8:$D$87) -> 0 | D98: =IF(OR(C98=0,B98=0),"",C98/B98)
...

Sheet Ads
A1: AD TESTS
A2: Only spend where it pays. Each ad gets its own tracking link. Start with the test budget on Show Setup, check its tickets after a week, keep ads under the target cost per ticket and stop the rest.
A4: Start date | B4: Platform | C4: Ad or boosted post | D4: Who it targets | E4: Tracking link name | F4: Spent ($) | G4: Link clicks | H4: Tickets (from its link) | I4: Cost per ticket | J4: Keep or stop? | K4: Notes
I5: =IF(OR(N(F5)=0,N(H5)=0),"",F5/H5) | J5: =IF(N(F5)=0,"",IF(N(H5)=0,IF(F5>='Show Setup'!$B$16,"STOP: no sales","Wait"),IF(I5<='Show Setup'!$B$15,"KEEP",IF(I5<='Show Setup'!$B$14,"Maybe: pays, barely","STOP"))))
I6: =IF(OR(N(F6)=0,N(H6)=0),"",F6/H6) | J6: =IF(N(F6)=0,"",IF(N(H6)=0,IF(F6>='Show Setup'!$B$16,"STOP: no sales","Wait"),IF(I6<='Show Setup'!$B$15,"KEEP",IF(I6<='Show Setup'!$B$14,"Maybe: pays, barely","STOP"))))
I7: =IF(OR(N(F7)=0,N(H7)=0),"",F7/H7) | J7: =IF(N(F7)=0,"",IF(N(H7)=0,IF(F7>='Show Setup'!$B$16,"STOP: no sales","Wait"),IF(I7<='Show Setup'!$B$15,"KEEP",IF(I7<='Show Setup'!$B$14,"Maybe: pays, barely","STOP"))))
I8: =IF(OR(N(F8)=0,N(H8)=0),"",F8/H8) | J8: =IF(N(F8)=0,"",IF(N(H8)=0,IF(F8>='Show Setup'!$B$16,"STOP: no sales","Wait"),IF(I8<='Show Setup'!$B$15,"KEEP",IF(I8<='Show Setup'!$B$14,"Maybe: pays, barely","STOP"))))
I9: =IF(OR(N(F9)=0,N(H9)=0),"",F9/H9) | J9: =IF(N(F9)=0,"",IF(N(H9)=0,IF(F9>='Show Setup'!$B$16,"STOP: no sales","Wait"),IF(I9<='Show Setup'!$B$15,"KEEP",IF(I9<='Show Setup'!$B$14,"Maybe: pays, barely","STOP"))))
I10: =IF(OR(N(F10)=0,N(H10)=0),"",F10/H10) | J10: =IF(N(F10)=0,"",IF(N(H10)=0,IF(F10>='Show Setup'!$B$16,"STOP: no sales","Wait"),IF(I10<='Show Setup'!$B$15,"KEEP",IF(I10<='Show Setup'!$B$14,"Maybe: pays, barely","STOP"))))
I11: =IF(OR(N(F11)=0,N(H11)=0),"",F11/H11) | J11: =IF(N(F11)=0,"",IF(N(H11)=0,IF(F11>='Show Setup'!$B$16,"STOP: no sales","Wait"),IF(I11<='Show Setup'!$B$15,"KEEP",IF(I11<='Show Setup'!$B$14,"Maybe: pays, barely","STOP"))))
I12: =IF(OR(N(F12)=0,N(H12)=0),"",F12/H12) | J12: =IF(N(F12)=0,"",IF(N(H12)=0,IF(F12>='Show Setup'!$B$16,"STOP: no sales","Wait"),IF(I12<='Show Setup'!$B$15,"KEEP",IF(I12<='Show Setup'!$B$14,"Maybe: pays, barely","STOP"))))
I13: =IF(OR(N(F13)=0,N(H13)=0),"",F13/H13) | J13: =IF(N(F13)=0,"",IF(N(H13)=0,IF(F13>='Show Setup'!$B$16,"STOP: no sales","Wait"),IF(I13<='Show Setup'!$B$15,"KEEP",IF(I13<='Show Setup'!$B$14,"Maybe: pays, barely","STOP"))))
I14: =IF(OR(N(F14)=0,N(H14)=0),"",F14/H14) | J14: =IF(N(F14)=0,"",IF(N(H14)=0,IF(F14>='Show Setup'!$B$16,"STOP: no sales","Wait"),IF(I14<='Show Setup'!$B$15,"KEEP",IF(I14<='Show Setup'!$B$14,"Maybe: pays, barely","STOP"))))
I15: =IF(OR(N(F15)=0,N(H15)=0),"",F15/H15) | J15: =IF(N(F15)=0,"",IF(N(H15)=0,IF(F15>='Show Setup'!$B$16,"STOP: no sales","Wait"),IF(I15<='Show Setup'!$B$15,"KEEP",IF(I15<='Show Setup'!$B$14,"Maybe: pays, barely","STOP"))))
I16: =IF(OR(N(F16)=0,N(H16)=0),"",F16/H16) | J16: =IF(N(F16)=0,"",IF(N(H16)=0,IF(F16>='Show Setup'!$B$16,"STOP: no sales","Wait"),IF(I16<='Show Setup'!$B$15,"KEEP",IF(I16<='Show Setup'!$B$14,"Maybe: pays, barely","STOP"))))
... I34: =IF(OR(N(F34)=0,N(H34)=0),"",F34/H34) | J34: =IF(N(F34)=0,"",IF(N(H34)=0,IF(F34>='Show Setup'!$B$16,"STOP: no sales","Wait"),IF(I34<='Show Setup'!$B$15,"KEEP",IF(I34<='Show Setup'!$B$14,"Maybe: pays, barely","STOP"))))
A36: How to: use the ad's own tracking link as its website link. Target a radius around the show town (Meta allows 1-80 km around a pin) and adults 18+ (19+ if the ad mentions a bar). Ads Manager shows the minimum daily budget in dollars when you set it; a few dollars a day is enough to test. Optional: add the Meta Pixel in Eventbrite (Marketing > Tracking pixels) so Meta sees purchases.
A37: Ad rules: Meta bans shocking or excessively violent images, so use face-offs, posed fighter photos and event graphics, never blood or a knockout. No youth athletes in ads. No alcohol in any ad that could reach under-19s. Real numbers only ('400 tickets sold at our first show').

Sheet Livestream
A1: LIVESTREAM: CAN IT MAKE MONEY?
A2: The 2026 stream made nothing. Two simple ways to charge for it, worked out for your numbers, plus what else is out there. Whatever you choose, the Athletics Commission gets a recording if the show is filmed.
A4: YOUR NUMBERS (ESTIMATES: change them)
A5: Stream ticket price ($) | B5: 15 | C5: ESTIMATE. What a viewer pays to watch.
A6: People who buy the stream | B6: 50 | C6: ESTIMATE. Fighters' families out of town are the likely buyers.
A7: US dollar in Canadian dollars | B7: 1.38 | C7: ESTIMATE. Check today's rate; Dacast charges in US dollars.
A8: Dacast plan for one month (US$) | B8: 39 | C8: Dacast lists plans from about US$39 to US$63 a month; the paywall may be an add-on. Check before signing up.
A10: WHAT CCCL WOULD KEEP
A11: Option | B11: Fees per buyer ($) | C11: CCCL keeps per buyer ($) | D11: Monthly or fixed cost ($) | E11: CCCL keeps in total ($) | F11: How it works
A12: Eventbrite online ticket | B12: =$B$5*0.035+1.29+$B$5*0.029 -> 2.25 | C12: =$B$5-B12 -> 12.75 | D12: 0 | E12: =C12*$B$6-D12 -> 637.5 | F12: A separate online event on Eventbrite. Buyers get a private page with the stream link. Same Canadian fees as tickets (3.5% + $1.29, plus 2.9%). Links can be shared, so some people will watch for free.
A13: Dacast pay-per-view | B13: =$B$5*0.099+0.4*$B$7 -> 2.037 | C13: =$B$5-B13 -> 12.963 | D13: =$B$8*$B$7 -> 53.82 | E13: =C13*$B$6-D13 -> 594.33 | F13: A paywall around the stream: 9.9% + US$0.40 per sale plus a monthly plan. Harder to share than a link.
A15: OTHER OPTIONS (researched Oct 2026)
A16: TrillerTV | B16: Pay-per-view platform, but risky for 2027: AEW sued it in May 2026 for unpaid revenue and its operating company told a court it can't pay its debts. | F16: https://cultaholic.com/posts/aew-files-lawsuit-against-trillertv-for-overdue-payments
A17: UFC Fight Pass | B17: Carries bigger Canadian promotions under multi-year deals. A long-term goal, not a 2027 option. | F17: https://www.sportskeeda.com/mma/news-ufc-fight-pass-announces-multi-year-streaming-right-deal-3-canadian-mma-promotions
A18: Vimeo OTT | B18: Live pay-per-view only on a custom-priced Enterprise plan. | F18: https://vimeo.com/ott/pricing
A19: YouTube | B19: YouTube pays creators 70% of channel memberships and Super Chat. Members-only streams need a channel with 500+ subscribers and 3,000 watch hours. | F19: https://support.google.com/youtube/answer/72902?hl=en
A20: Facebook Stars | B20: Viewers send Stars; Meta pays 1 cent per Star. Facebook's paid online events ended in 2023. | F20: https://creators.facebook.com/tools/stars
A22: The safest money from the stream is sponsors: every package already includes the livestream (logo or name sized by level). Charging for the stream only makes sense once enough out-of-town family and fans want to watch. Put any stream money on the Predictor's Inputs tab.

Sheet Poster Drop
A1: POSTER DROP
A2: Where the posters go in the show town. Ask first, put them up about 10 weeks out, take them down after the show. Every poster has the QR code for the posters' tracking link.
A4: Place | B4: Kind of place | C4: Area / address | D4: Asked permission? | E4: Put up (date) | F4: Taken down (date) | G4: Notes
A5: Every sponsor's business | B5: Sponsor
A6: The venue's lobby and front doors | B6: Venue
A7: Grocery store community boards | B7: Community board
A8: Gas stations and convenience stores | B8: Store
A9: Coffee shops (Tim Hortons, local cafes) | B9: Restaurant / cafe
A10: Every gym and fitness studio in town | B10: Gym
A11: Public library board | B11: Community board
A12: Legion, Lions or community hall | B12: Community board
A13: Hardware and farm supply stores | B13: Store
A14: Restaurants and pubs (adults) | B14: Restaurant / cafe
A15: Barber shops and salons | B15: Store
A16: Motels, cottage resorts and campgrounds (summer) | B16: Tourism
A17: Arena bulletin boards (other arenas nearby) | B17: Community board
A66: The first rows are reminders of the kinds of places that work in small towns. Replace them with real places. No posters at schools.

Sheet Shot List
A1: FIGHT NIGHT SHOT LIST
A2: Photos and video to grab on the night, for the highlight video, sponsor thank-yous, press and next year's sponsor pitch.
A4: Shot | B4: When | C4: Used for | D4: Consent needed | E4: Who films | F4: Got it?
A5: Empty venue, wide, before doors | B5: Afternoon | C5: Highlight intro, venue thank-you | D5: None | E5: Kyle
A6: Cage build time-lapse | B6: Load-in | C6: Reels / Shorts | D6: Crew OK | E6: Kyle
A7: Every sponsor's banner with the crowd behind it | B7: During the show | C7: Sponsor thank-you emails and posts | D7: None (crowd shot) | E7: Kyle
A8: Weigh-ins on the scale | B8: Weigh-ins | C8: Stories, fighter posts | D8: Adult fighters who agree only | E8: Kyle
A9: Fighters' walkouts | B9: Each bout | C9: Highlight video | D9: Fighter agrees (sign-up form) | E9: Kyle
A10: Crowd reactions, packed seats | B10: Main card | C10: Next year's sponsor pitch, ads | D10: None (crowd shot) | E10: Kyle
A11: Each finish and each hand raised | B11: Each bout | C11: Results posts, highlight video | D11: Fighter agrees | E11: Kyle
A12: Cody's welcome and the Title Sponsor read | B12: Opening | C12: Sponsor thank-you, highlight | D12: None | E12: Kyle
A13: Short winner interviews (15 seconds) | B13: After each bout | C13: Reels / Shorts, press | D13: Adult winners who agree | E13: Kyle
A14: VIP tables and sponsor guests | B14: During the show | C14: Next year's VIP table sales | D14: Ask the table first | E14: Kyle
A15: Volunteers and officials at work | B15: During the show | C15: Thank-you post | D15: Ask first | E15: Kyle
A16: Merch table and event shirts | B16: Intermission | C16: Merch posts | D16: None | E16: Kyle
... A18: Youth grappling | B18: Youth matches | C18: Only if a parent has said yes | D18: Parent's written OK for every child shown | E18: Kyle

Sheet Canva Kit
A1: CANVA KIT
A2: Sizes, colours and fonts for CCCL graphics in Canva, and the starter designs in the Marketing folder.
A4: COLOURS (from the CCCL logo)
A5: Near-black | B5: #151C19 | D5: Backgrounds
A6: Forest green | B6: #354940 | D6: Panels, headers
A7: Dark green | B7: #26362F | D7: Cards, footers
A8: Cream | B8: #F2ECDC | D8: Text on dark, badges
A9: Red (maple leaf) | B9: #AE2221 | D9: One accent per design: the date, VS, a price
A10: Bright red (big text on dark) | B10: #D9483B | D10: Headlines on near-black
A12: FONTS (all free in Canva)
A13: Anton | D13: Headlines: tall, condensed, all caps, like the logo (the starter designs use it)
A14: Oswald (SemiBold) | D14: Subheads, fighter names, dates
A15: Inter | D15: Small text: venue, tickets, sponsor lines
A17: SIZES
A18: Format | B18: Size (px) | C18: Ratio | D18: Use | E18: Source
A19: Instagram + Facebook feed post (use this) | B19: 1080 x 1350 | C19: 4:5 | D19: Most posts. The starter designs use it. | E19: sproutsocial.com social image sizes guide (Oct 2026)
A20: Instagram 3:4 post | B20: 1080 x 1440 | C20: 3:4 | D20: Supported since May 2025; the profile grid crops to 3:4, so keep text away from the top and bottom edges | E20: 9to5mac.com, May 29 2025
A21: Stories and Reels | B21: 1080 x 1920 | C21: 9:16 | D21: Countdowns, show day. Keep text inside the middle 1080 x 1610 | E21: sproutsocial.com
A22: Facebook event cover | B22: 1920 x 1005 | C22: about 1.91:1 | D22: The Facebook event. Keep the title and date in the middle 60% | E22: postfa.st (Meta no longer publishes a spec)
A23: Facebook link / landscape | B23: 1200 x 628 | C23: 1.91:1 | D23: Shared links, some ads | E23: blog.hootsuite.com
A24: Poster | B24: 11 x 17 in (also letter 8.5 x 11) | D24: Printed posters with the QR code
A26: STARTER DESIGNS (Marketing / Canva starter designs folder)
A27: 01 Tickets on sale (post) | D27: Weeks 16 and 14
A28: 02 Countdown story | D28: 21, 14 and 7 days out
A29: 03 Poster, early (11x17) | D29: Week 10, printed with the QR code
A30: 04 Fight card (post) | D30: Card announced, fight week
A31: 05 Fighter vs fighter | D31: One per adult bout, weeks 4 to 1
A32: 06 Fighter spotlight | D32: Weeks 6 to 2, adults who agree
A33: 07 Sponsor thank-you | D33: Week 8 and after the show
A34: 08 Results | D34: Day after, official only
A35: 09 Facebook event cover | D35: Week 16
A36: 10 Poster with main event (11x17) | D36: Once the main event is signed
A37: 11 I'm fighting (post) | D37: Each adult fighter, week 6
A38: 12 I'm fighting (story) | D38: Each adult fighter, with the link sticker
... A42: 16 Fight card (story) | D42: Card announced, fight week
A44: Logo files: Brand/CCCL logo.png and Brand/CCCL logo (transparent).png. Keep the logo round and uncropped; put it on dark backgrounds or the cream badge. Never put alcohol logos on youth content.
A46: CANVA: GOOD TO KNOW (canva.com help, Oct 2026)
A47: Importing the starter PDFs | B47: Create a design > Import file > pick the PDF. Every word is its own text box; the background is one image (lock it). If a font gets swapped, re-pick Anton, Oswald or Inter. Photos: delete the grey photo box and drop the photo into a Frame (Elements > Frames).
A48: Free vs Pro | B48: Free Canva works for all of this. Pro (about $142 CAD a year) adds a full Brand Kit with all the CCCL colours, saved brand templates and one-click resizing (post to story).
A49: Claude + Canva | B49: Canva has a connector for Claude that works on free Canva: Claude can make, edit and export designs. Filling a saved template automatically (Autofill) needs Pro.
...
